Workbook
Name _R: ed_physicians!$R$2:$R$4203
Name AA: ed_physicians!$AA$2:$AA$4203
Name AB: ed_physicians!$AB$2:$AB$4203
Name AC: ed_physicians!$AC$2:$AC$4203
Name AD: ed_physicians!$AD$2:$AD$4203
Name AE: ed_physicians!$AE$2:$AE$4203
Name AF: ed_physicians!$AF$2:$AF$4203
Name AG: ed_physicians!$AG$2:$AG$4203
Name AH: ed_physicians!$AH$2:$AH$4203
Name AI: ed_physicians!$AI$2:$AI$4203
Name AJ: ed_physicians!$AJ$2:$AJ$4203
Name AK: ed_physicians!$AK$2:$AK$4203
Name AL: ed_physicians!$AL$2:$AL$4203
Name AM: ed_physicians!$AM$2:$AM$4203
Name AN: ed_physicians!$AN$2:$AN$4203
Name AO: ed_physicians!$AO$2:$AO$4203
Name AP: ed_physicians!$AP$2:$AP$4203
Name AQ: ed_physicians!$AQ$2:$AQ$4203
Name AR: ed_physicians!$AR$2:$AR$4203
Name AS: ed_physicians!$AS$2:$AS$4203
Name AT: ed_physicians!$AT$2:$AT$4203
Name AU: ed_physicians!$AU$2:$AU$4203
Name AV: ed_physicians!$AV$2:$AV$4203
Name AW: ed_physicians!$AW$2:$AW$4203
Name AX: ed_physicians!$AX$2:$AX$4203
Name AY: ed_physicians!$AY$2:$AY$4203
Name AZ: ed_physicians!$AZ$2:$AZ$4203
Name G: ed_physicians!$G$2:$G$4203
Name H: ed_physicians!$H$2:$H$4203
Name I: ed_physicians!$I$2:$I$4203
Name J: ed_physicians!$J$2:$J$4203
Name K: ed_physicians!$K$2:$K$4203
Name L: ed_physicians!$L$2:$L$4203
Name M: ed_physicians!$M$2:$M$4203
Name N: ed_physicians!$N$2:$N$4203
Name O: ed_physicians!$O$2:$O$4203
Name P: ed_physicians!$P$2:$P$4203
Name Period: ed_physicians!$B$2:$B$4203
Name Provider: ed_physicians!$E$2:$E$4203
Name Q: ed_physicians!$Q$2:$Q$4203
Name S: ed_physicians!$S$2:$S$4203
Name Site: ed_physicians!$C$2:$C$4203
Name T: ed_physicians!$T$2:$T$4203
Name U: ed_physicians!$U$2:$U$4203
Name V: ed_physicians!$V$2:$V$4203
Name W: ed_physicians!$W$2:$W$4203
Name X: ed_physicians!$X$2:$X$4203
Name Y: ed_physicians!$Y$2:$Y$4203
Name Z: ed_physicians!$Z$2:$Z$4203

Sheet DESCRIPTIONS
A2: COLUMN | B2: DESCRIPTION
A3: Total Pts : | B3: Total number of patients with an Arrival Date Timestamp, a valid ER mapped location, and not an OBED patient at the Emergency department
A4: Duplicate MSE : | B4: Percentage of total patients that were greeted by the same provider within the same minute. Use ADM.PAT.zcus.div.rws.er.phys.greet.analysis for detail.
A5: Avg In Bed to Phy Greet : | B5: Placed in bed to greeted by physician
A6: Avg Arrive to Phy Greet : | B6: Arrived to greeted by physician | F6: Patient Satisfaction | G6: Performance/Output
A7: Avg Prov Greet to First Clinical Order : | B7: The average time taken from when a patient is greeted by a physician until they receive their first clinical order. To be included, a test must be a RAD, CT, NM, MRI, US, EKG, LAB, MIC, MED, IV or iSTAT Order for Point of Care and order by a midlevel or physician
A9: Avg Phy Greet to disp-A : | B9: Greeted by physician to disposition; admitted patients only
A10: Avg Phy Greet to disp-D : | B10: Greeted by physician to disposition; departed patients only
A11: Avg LOS Admitted Pts : | B11: Admitted patients Length of stay (Arrival to depart from ED)
A12: Avg LOS Departed Pts : | B12: Departed patients Length of stay (Arrival to depart from ED)
A13: Avg LOS low acuity : | B13: Triage level 4 and 5 patients Length of stay (Arrival to depart from ED)
A14: CT and US Utilization : | B14: CT and Ultrasound Utilization percentage breakdown by Admitted, Departed and Pediatric patients
A15: LPMSE : | B15: Number of patients left prior to Medical screening.
A16: LPT : | B16: Number of patients left prior to treatment.
A17: LPT/LPMSE% : | B17: Percentage of patients left prior to Medical screening/treatment.
A18: AMA : | B18: Number of patients left against medical advice.
A19: AMA% : | B19: Percentage of patients left against medical advice.
... A25: Avg Depart to PDOC Signed : | B25: The average of the PDOC Signed Date/Time minus the Depart Date/Time of when they physically leave

Sheet arrival_data
K1: 9
A2: Site | B2: Metrico | C2: Period | D2: Patients | E2: Low_Acc_Pts | F2: Low_Acc% | G2: Avg_in_minutos | H2: Mean_WT | I2: Mean | AB2: Patients | AC2: Avg_in_minutes | AD2: Mean
A3: Hunters Creek | B3: Arrival_to_Provider_Patients | C3: Jan | D3: =Arrival_to_Provider!$D$83 -> 2167 | E3: 1115 | F3: =IF(ISERROR(E3/D3),0,E3/D3) -> 0.51453623 | G3: =Arrival_to_Provider!$E$83 -> 8.2505768 | H3: =G3*(D3/SUM(D$3:D$12)) -> 0.51782663 | I3: =SUM(H$3:H$12) -> 8.9696469 | AB3: =CHOOSE($K$1,D3,D13,D23,D33,D43,D53,D63,D73,D83,D93,D103,D113) -> 1892 | AC3: =CHOOSE($K$1,G3,G13,G23,G33,G43,G53,G63,G73,G83,G93,G103,G113) -> 4.7315011 | AD3: =CHOOSE($K$1,I3,I13,I23,I33,I43,I53,I63,I73,I83,I93,I103,I113) -> 8.6980941 | AF3: 1 | AG3: Hunters Creek
A4: JFK-BB | B4: Arrival_to_Provider_Patients | C4: Jan | D4: =Arrival_to_Provider!$D$128 -> 942 | E4: 417 | F4: =IF(ISERROR(E4/D4),0,E4/D4) -> 0.44267516 | G4: =Arrival_to_Provider!$E$128 -> 6.0360934 | H4: =G4*(D4/SUM(D$3:D$12)) -> 0.16468271 | I4: =SUM(H$3:H$12) -> 8.9696469 | AB4: =CHOOSE($K$1,D4,D14,D24,D34,D44,D54,D64,D74,D84,D94,D104,D114) -> 563 | AC4: =CHOOSE($K$1,G4,G14,G24,G34,G44,G54,G64,G74,G84,G94,G104,G114) -> 5.6802842 | AD4: =CHOOSE($K$1,I4,I14,I24,I34,I44,I54,I64,I74,I84,I94,I104,I114) -> 8.6980941 | AF4: 2 | AG4: JFK-BB
A5: JFK-Main | B5: Arrival_to_Provider_Patients | C5: Jan | D5: =Arrival_to_Provider!$D$219 -> 7680 | E5: 1087 | F5: =IF(ISERROR(E5/D5),0,E5/D5) -> 0.14153646 | G5: =Arrival_to_Provider!$E$219 -> 8.2153646 | H5: =G5*(D5/SUM(D$3:D$12)) -> 1.8273815 | I5: =SUM(H$3:H$12) -> 8.9696469 | AB5: =CHOOSE($K$1,D5,D15,D25,D35,D45,D55,D65,D75,D85,D95,D105,D115) -> 6622 | AC5: =CHOOSE($K$1,G5,G15,G25,G35,G45,G55,G65,G75,G85,G95,G105,G115) -> 6.974026 | AD5: =CHOOSE($K$1,I5,I15,I25,I35,I45,I55,I65,I75,I85,I95,I105,I115) -> 8.6980941 | AF5: 3 | AG5: JFK-Main
A6: JFK-PBG | B6: Arrival_to_Provider_Patients | C6: Jan | D6: =Arrival_to_Provider!$D$243 -> 444 | E6: 165 | F6: =IF(ISERROR(E6/D6),0,E6/D6) -> 0.37162162 | G6: =Arrival_to_Provider!$E$243 -> 4.6689189 | H6: =G6*(D6/SUM(D$3:D$12)) -> 0.060039969 | I6: =SUM(H$3:H$12) -> 8.9696469 | AB6: =CHOOSE($K$1,D6,D16,D26,D36,D46,D56,D66,D76,D86,D96,D106,D116) -> 298 | AC6: =CHOOSE($K$1,G6,G16,G26,G36,G46,G56,G66,G76,G86,G96,G106,G116) -> 4.2986577 | AD6: =CHOOSE($K$1,I6,I16,I26,I36,I46,I56,I66,I76,I86,I96,I106,I116) -> 8.6980941 | AF6: 4 | AG6: JFK-PBG
A7: Kendall | B7: Arrival_to_Provider_Patients | C7: Jan | D7: =Arrival_to_Provider!$D$380 -> 7354 | E7: 1354 | F7: =IF(ISERROR(E7/D7),0,E7/D7) -> 0.18411749 | G7: =Arrival_to_Provider!$E$380 -> 10.288958 | H7: =G7*(D7/SUM(D$3:D$12)) -> 2.1914733 | I7: =SUM(H$3:H$12) -> 8.9696469 | AB7: =CHOOSE($K$1,D7,D17,D27,D37,D47,D57,D67,D77,D87,D97,D107,D117) -> 6361 | AC7: =CHOOSE($K$1,G7,G17,G27,G37,G47,G57,G67,G77,G87,G97,G107,G117) -> 21.205015 | AD7: =CHOOSE($K$1,I7,I17,I27,I37,I47,I57,I67,I77,I87,I97,I107,I117) -> 8.6980941 | AF7: 5 | AG7: Kendall
A8: Ocala | B8: Arrival_to_Provider_Patients | C8: Jan | D8: =Arrival_to_Provider!$D$504 -> 3973 | E8: 760 | F8: =IF(ISERROR(E8/D8),0,E8/D8) -> 0.19129122 | G8: =Arrival_to_Provider!$E$504 -> 5.7528316 | H8: =G8*(D8/SUM(D$3:D$12)) -> 0.66197469 | I8: =SUM(H$3:H$12) -> 8.9696469 | AB8: =CHOOSE($K$1,D8,D18,D28,D38,D48,D58,D68,D78,D88,D98,D108,D118) -> 3715 | AC8: =CHOOSE($K$1,G8,G18,G28,G38,G48,G58,G68,G78,G88,G98,G108,G118) -> 4.2657143 | AD8: =CHOOSE($K$1,I8,I18,I28,I38,I48,I58,I68,I78,I88,I98,I108,I118) -> 8.6980941 | AF8: 6 | AG8: Ocala
A9: Osceola | B9: Arrival_to_Provider_Patients | C9: Jan | D9: =Arrival_to_Provider!$D$661 -> 4795 | E9: 1073 | F9: =IF(ISERROR(E9/D9),0,E9/D9) -> 0.22377477 | G9: =Arrival_to_Provider!$E$661 -> 13.433785 | H9: =G9*(D9/SUM(D$3:D$12)) -> 1.8656414 | I9: =SUM(H$3:H$12) -> 8.9696469 | AB9: =CHOOSE($K$1,D9,D19,D29,D39,D49,D59,D69,D79,D89,D99,D109,D119) -> 5369 | AC9: =CHOOSE($K$1,G9,G19,G29,G39,G49,G59,G69,G79,G89,G99,G109,G119) -> 5.0445148 | AD9: =CHOOSE($K$1,I9,I19,I29,I39,I49,I59,I69,I79,I89,I99,I109,I119) -> 8.6980941 | AF9: 7 | AG9: Osceola
A10: Osceola PEDS (Loc 3) | B10: Arrival_to_Provider_Patients | C10: Jan | D10: =Arrival_to_Provider!$D$728 -> 1107 | E10: 469 | F10: =IF(ISERROR(E10/D10),0,E10/D10) -> 0.42366757 | G10: =Arrival_to_Provider!$E$728 -> 10.458898 | H10: =G10*(D10/SUM(D$3:D$12)) -> 0.33533177 | I10: =SUM(H$3:H$12) -> 8.9696469 | AB10: =CHOOSE($K$1,D10,D20,D30,D40,D50,D60,D70,D80,D90,D100,D110,D120) -> 0 | AC10: =CHOOSE($K$1,G10,G20,G30,G40,G50,G60,G70,G80,G90,G100,G110,G120) -> 0 | AD10: =CHOOSE($K$1,I10,I20,I30,I40,I50,I60,I70,I80,I90,I100,I110,I120) -> 8.6980941 | AF10: 8 | AG10: Osceola PEDS (Loc 3)
A11: Summerfield | B11: Arrival_to_Provider_Patients | C11: Jan | D11: =Arrival_to_Provider!$D$805 -> 1650 | E11: 377 | F11: =IF(ISERROR(E11/D11),0,E11/D11) -> 0.22848485 | G11: =Arrival_to_Provider!$E$805 -> 8.8915152 | H11: =G11*(D11/SUM(D$3:D$12)) -> 0.42491384 | I11: =SUM(H$3:H$12) -> 8.9696469 | AB11: =CHOOSE($K$1,D11,D21,D31,D41,D51,D61,D71,D81,D91,D101,D111,D121) -> 1941 | AC11: =CHOOSE($K$1,G11,G21,G31,G41,G51,G61,G71,G81,G91,G101,G111,G121) -> 4.6517259 | AD11: =CHOOSE($K$1,I11,I21,I31,I41,I51,I61,I71,I81,I91,I101,I111,I121) -> 8.6980941 | AF11: 9 | AG11: Summerfield
A12: West Marion | B12: Arrival_to_Provider_Patients | C12: Jan | D12: =Arrival_to_Provider!$D$889 -> 4415 | E12: 2031 | F12: =IF(ISERROR(E12/D12),0,E12/D12) -> 0.46002265 | G12: =Arrival_to_Provider!$E$889 -> 7.197735 | H12: =G12*(D12/SUM(D$3:D$12)) -> 0.92038115 | I12: =SUM(H$3:H$12) -> 8.9696469 | AB12: =CHOOSE($K$1,D12,D22,D32,D42,D52,D62,D72,D82,D92,D102,D112,D122) -> 3928 | AC12: =CHOOSE($K$1,G12,G22,G32,G42,G52,G62,G72,G82,G92,G102,G112,G122) -> 5.2132338 | AD12: =CHOOSE($K$1,I12,I22,I32,I42,I52,I62,I72,I82,I92,I102,I112,I122) -> 8.6980941 | AF12: 10 | AG12: West Marion
A13: Hunters Creek | B13: Arrival_to_Provider_Patients | C13: Feb | D13: =Arrival_to_Provider!$J$83 -> 1999 | E13: 1111 | F13: =IF(ISERROR(E13/D13),0,E13/D13) -> 0.55577789 | G13: =Arrival_to_Provider!$K$83 -> 5.9304652 | H13: =G13*(D13/SUM(D$13:D$22)) -> 0.3672894 | I13: =SUM(H$13:H$22) -> 7.9330483 | AB13: =SUM(AB3:AB12) -> 30689 | AF13: 11
A14: JFK-BB | B14: Arrival_to_Provider_Patients | C14: Feb | D14: =Arrival_to_Provider!$J$128 -> 737 | E14: 329 | F14: =IF(ISERROR(E14/D14),0,E14/D14) -> 0.44640434 | G14: =Arrival_to_Provider!$K$128 -> 5.5712347 | H14: =G14*(D14/SUM(D$13:D$22)) -> 0.12721133 | I14: =SUM(H$13:H$22) -> 7.9330483 | AF14: 12
A15: JFK-Main | B15: Arrival_to_Provider_Patients | C15: Feb | D15: =Arrival_to_Provider!$J$219 -> 7131 | E15: 961 | F15: =IF(ISERROR(E15/D15),0,E15/D15) -> 0.13476371 | G15: =Arrival_to_Provider!$K$219 -> 8.7004628 | H15: =G15*(D15/SUM(D$13:D$22)) -> 1.9222047 | I15: =SUM(H$13:H$22) -> 7.9330483
A16: JFK-PBG | B16: Arrival_to_Provider_Patients | C16: Feb | D16: =Arrival_to_Provider!$J$243 -> 485 | E16: 219 | F16: =IF(ISERROR(E16/D16),0,E16/D16) -> 0.45154639 | G16: =Arrival_to_Provider!$K$243 -> 4.6536082 | H16: =G16*(D16/SUM(D$13:D$22)) -> 0.069925953 | I16: =SUM(H$13:H$22) -> 7.9330483
A17: Kendall | B17: Arrival_to_Provider_Patients | C17: Feb | D17: =Arrival_to_Provider!$J$380 -> 6684 | E17: 1229 | F17: =IF(ISERROR(E17/D17),0,E17/D17) -> 0.18387193 | G17: =Arrival_to_Provider!$K$380 -> 6.4763615 | H17: =G17*(D17/SUM(D$13:D$22)) -> 1.3411408 | I17: =SUM(H$13:H$22) -> 7.9330483
A18: Ocala | B18: Arrival_to_Provider_Patients | C18: Feb | D18: =Arrival_to_Provider!$J$504 -> 3672 | E18: 780 | F18: =IF(ISERROR(E18/D18),0,E18/D18) -> 0.2124183 | G18: =Arrival_to_Provider!$K$504 -> 5.9223856 | H18: =G18*(D18/SUM(D$13:D$22)) -> 0.6737615 | I18: =SUM(H$13:H$22) -> 7.9330483
A19: Osceola | B19: Arrival_to_Provider_Patients | C19: Feb | D19: =Arrival_to_Provider!$J$661 -> 4426 | E19: 1033 | F19: =IF(ISERROR(E19/D19),0,E19/D19) -> 0.23339358 | G19: =Arrival_to_Provider!$K$661 -> 11.496159 | H19: =G19*(D19/SUM(D$13:D$22)) -> 1.5764166 | I19: =SUM(H$13:H$22) -> 7.9330483
A20: Osceola PEDS (Loc 3) | B20: Arrival_to_Provider_Patients | C20: Feb | D20: =Arrival_to_Provider!$J$728 -> 1204 | E20: 593 | F20: =IF(ISERROR(E20/D20),0,E20/D20) -> 0.49252492 | G20: =Arrival_to_Provider!$K$728 -> 9.5415282 | H20: =G20*(D20/SUM(D$13:D$22)) -> 0.35591908 | I20: =SUM(H$13:H$22) -> 7.9330483
A21: Summerfield | B21: Arrival_to_Provider_Patients | C21: Feb | D21: =Arrival_to_Provider!$J$805 -> 1754 | E21: 265 | F21: =IF(ISERROR(E21/D21),0,E21/D21) -> 0.15108324 | G21: =Arrival_to_Provider!$K$805 -> 11.051881 | H21: =G21*(D21/SUM(D$13:D$22)) -> 0.60058246 | I21: =SUM(H$13:H$22) -> 7.9330483
A22: West Marion | B22: Arrival_to_Provider_Patients | C22: Feb | D22: =Arrival_to_Provider!$J$889 -> 4185 | E22: 1868 | F22: =IF(ISERROR(E22/D22),0,E22/D22) -> 0.44635603 | G22: =Arrival_to_Provider!$K$889 -> 6.9304659 | H22: =G22*(D22/SUM(D$13:D$22)) -> 0.89859652 | I22: =SUM(H$13:H$22) -> 7.9330483
A23: Hunters Creek | B23: Arrival_to_Provider_Patients | C23: Mar | D23: =Arrival_to_Provider!$P$83 -> 2153 | E23: 1129 | F23: =IF(ISERROR(E23/D23),0,E23/D23) -> 0.52438458 | G23: =Arrival_to_Provider!$Q$83 -> 5.3896888 | H23: =G23*(D23/SUM(D$23:D$32)) -> 0.33438995 | I23: =SUM(H$23:H$32) -> 7.4883292
A24: JFK-BB | B24: Arrival_to_Provider_Patients | C24: Mar | D24: =Arrival_to_Provider!$P$128 -> 774 | E24: 293 | F24: =IF(ISERROR(E24/D24),0,E24/D24) -> 0.37855297 | G24: =Arrival_to_Provider!$Q$128 -> 4.8591731 | H24: =G24*(D24/SUM(D$23:D$32)) -> 0.10837992 | I24: =SUM(H$23:H$32) -> 7.4883292
A25: JFK-Main | B25: Arrival_to_Provider_Patients | C25: Mar | D25: =Arrival_to_Provider!$P$219 -> 7843 | E25: 1018 | F25: =IF(ISERROR(E25/D25),0,E25/D25) -> 0.12979727 | G25: =Arrival_to_Provider!$Q$219 -> 8.2750223 | H25: =G25*(D25/SUM(D$23:D$32)) -> 1.870238 | I25: =SUM(H$23:H$32) -> 7.4883292
A26: JFK-PBG | B26: Arrival_to_Provider_Patients | C26: Mar | D26: =Arrival_to_Provider!$P$243 -> 463 | E26: 190 | F26: =IF(ISERROR(E26/D26),0,E26/D26) -> 0.41036717 | G26: =Arrival_to_Provider!$Q$243 -> 4.2008639 | H26: =G26*(D26/SUM(D$23:D$32)) -> 0.056048643 | I26: =SUM(H$23:H$32) -> 7.4883292
A27: Kendall | B27: Arrival_to_Provider_Patients | C27: Mar | D27: =Arrival_to_Provider!$P$380 -> 7350 | E27: 1346 | F27: =IF(ISERROR(E27/D27),0,E27/D27) -> 0.18312925 | G27: =Arrival_to_Provider!$Q$380 -> 5.8473469 | H27: =G27*(D27/SUM(D$23:D$32)) -> 1.2384877 | I27: =SUM(H$23:H$32) -> 7.4883292
A28: Ocala | B28: Arrival_to_Provider_Patients | C28: Mar | D28: =Arrival_to_Provider!$P$504 -> 3867 | E28: 780 | F28: =IF(ISERROR(E28/D28),0,E28/D28) -> 0.20170675 | G28: =Arrival_to_Provider!$Q$504 -> 5.412723 | H28: =G28*(D28/SUM(D$23:D$32)) -> 0.60316408 | I28: =SUM(H$23:H$32) -> 7.4883292
A29: Osceola | B29: Arrival_to_Provider_Patients | C29: Mar | D29: =Arrival_to_Provider!$P$661 -> 4678 | E29: 1041 | F29: =IF(ISERROR(E29/D29),0,E29/D29) -> 0.222531 | G29: =Arrival_to_Provider!$Q$661 -> 10.941214 | H29: =G29*(D29/SUM(D$23:D$32)) -> 1.4749294 | I29: =SUM(H$23:H$32) -> 7.4883292
A30: Osceola PEDS (Loc 3) | B30: Arrival_to_Provider_Patients | C30: Mar | D30: =Arrival_to_Provider!$P$728 -> 1240 | E30: 606 | F30: =IF(ISERROR(E30/D30),0,E30/D30) -> 0.48870968 | G30: =Arrival_to_Provider!$Q$728 -> 7.608871 | H30: =G30*(D30/SUM(D$23:D$32)) -> 0.27188635 | I30: =SUM(H$23:H$32) -> 7.4883292
A31: Summerfield | B31: Arrival_to_Provider_Patients | C31: Mar | D31: =Arrival_to_Provider!$P$805 -> 1910 | E31: 381 | F31: =IF(ISERROR(E31/D31),0,E31/D31) -> 0.19947644 | G31: =Arrival_to_Provider!$Q$805 -> 13.467539 | H31: =G31*(D31/SUM(D$23:D$32)) -> 0.74125411 | I31: =SUM(H$23:H$32) -> 7.4883292
A32: West Marion | B32: Arrival_to_Provider_Patients | C32: Mar | D32: =Arrival_to_Provider!$P$889 -> 4424 | E32: 2052 | F32: =IF(ISERROR(E32/D32),0,E32/D32) -> 0.46383363 | G32: =Arrival_to_Provider!$Q$889 -> 6.193264 | H32: =G32*(D32/SUM(D$23:D$32)) -> 0.78955103 | I32: =SUM(H$23:H$32) -> 7.4883292
A33: Hunters Creek | B33: Arrival_to_Provider_Patients | C33: Apr | D33: =Arrival_to_Provider!$V$83 -> 2110 | E33: 1060 | F33: =IF(ISERROR(E33/D33),0,E33/D33) -> 0.50236967 | G33: =Arrival_to_Provider!$W$83 -> 4.8118483 | H33: =G33*(D33/SUM(D$33:D$42)) -> 0.30705256 | I33: =SUM(H$33:H$42) -> 6.940271
A34: JFK-BB | B34: Arrival_to_Provider_Patients | C34: Apr | D34: =Arrival_to_Provider!$V$128 -> 751 | E34: 281 | F34: =IF(ISERROR(E34/D34),0,E34/D34) -> 0.37416778 | G34: =Arrival_to_Provider!$W$128 -> 5.8189081 | H34: =G34*(D34/SUM(D$33:D$42)) -> 0.13215992 | I34: =SUM(H$33:H$42) -> 6.940271
A35: JFK-Main | B35: Arrival_to_Provider_Patients | C35: Apr | D35: =Arrival_to_Provider!$V$219 -> 7402 | E35: 976 | F35: =IF(ISERROR(E35/D35),0,E35/D35) -> 0.13185626 | G35: =Arrival_to_Provider!$W$219 -> 7.9035396 | H35: =G35*(D35/SUM(D$33:D$42)) -> 1.7692494 | I35: =SUM(H$33:H$42) -> 6.940271 | AB35: Period | AC35: Patients | AD35: Avg Wait | AE35: Weight | AF35: Mean | AG35: Goal
A36: JFK-PBG | B36: Arrival_to_Provider_Patients | C36: Apr | D36: =Arrival_to_Provider!$V$243 -> 416 | E36: 166 | F36: =IF(ISERROR(E36/D36),0,E36/D36) -> 0.39903846 | G36: =Arrival_to_Provider!$W$243 -> 4.0697115 | H36: =G36*(D36/SUM(D$33:D$42)) -> 0.051200629 | I36: =SUM(H$33:H$42) -> 6.940271 | AB36: Jan | AC36: =SUM(D3:D12) -> 34527 | AD36: 8.9696469 | AE36: =AD36*(AC36/SUM($AC$36:$AC$47)) -> 0.79521732 | AF36: =SUM($AE$36:$AE$47) -> 6.8225282 | AG36: 20 | AH36: =AE36/SUM($AE$36:$AE$47) -> 0.11655757
A37: Kendall | B37: Arrival_to_Provider_Patients | C37: Apr | D37: =Arrival_to_Provider!$V$380 -> 6745 | E37: 1293 | F37: =IF(ISERROR(E37/D37),0,E37/D37) -> 0.19169755 | G37: =Arrival_to_Provider!$W$380 -> 5.5389177 | H37: =G37*(D37/SUM(D$33:D$42)) -> 1.1298615 | I37: =SUM(H$33:H$42) -> 6.940271 | AB37: Feb | AC37: =SUM(D13:D22) -> 32277 | AD37: 7.9330483 | AE37: =AD37*(AC37/SUM($AC$36:$AC$47)) -> 0.65748356 | AF37: =SUM($AE$36:$AE$47) -> 6.8225282 | AG37: 20 | AH37: =AE37/SUM($AE$36:$AE$47) -> 0.09636949
A38: Ocala | B38: Arrival_to_Provider_Patients | C38: Apr | D38: =Arrival_to_Provider!$V$504 -> 3814 | E38: 702 | F38: =IF(ISERROR(E38/D38),0,E38/D38) -> 0.18405873 | G38: =Arrival_to_Provider!$W$504 -> 4.131096 | H38: =G38*(D38/SUM(D$33:D$42)) -> 0.47650154 | I38: =SUM(H$33:H$42) -> 6.940271 | AB38: Mar | AC38: =SUM(D23:D32) -> 34702 | AD38: 7.4883292 | AE38: =AD38*(AC38/SUM($AC$36:$AC$47)) -> 0.66725382 | AF38: =SUM($AE$36:$AE$47) -> 6.8225282 | AG38: 20 | AH38: =AE38/SUM($AE$36:$AE$47) -> 0.097801549
A39: Osceola | B39: Arrival_to_Provider_Patients | C39: Apr | D39: =Arrival_to_Provider!$V$661 -> 4507 | E39: 989 | F39: =IF(ISERROR(E39/D39),0,E39/D39) -> 0.21943643 | G39: =Arrival_to_Provider!$W$661 -> 11.642112 | H39: =G39*(D39/SUM(D$33:D$42)) -> 1.5868566 | I39: =SUM(H$33:H$42) -> 6.940271 | AB39: Apr | AC39: =SUM(D33:D42) -> 33066 | AD39: 6.940271 | AE39: =AD39*(AC39/SUM($AC$36:$AC$47)) -> 0.58926375 | AF39: =SUM($AE$36:$AE$47) -> 6.8225282 | AG39: 20 | AH39: =AE39/SUM($AE$36:$AE$47) -> 0.086370292
A40: Osceola PEDS (Loc 3) | B40: Arrival_to_Provider_Patients | C40: Apr | D40: =Arrival_to_Provider!$V$728 -> 1194 | E40: 597 | F40: =IF(ISERROR(E40/D40),0,E40/D40) -> 0.5 | G40: =Arrival_to_Provider!$W$728 -> 6.3634841 | H40: =G40*(D40/SUM(D$33:D$42)) -> 0.22978286 | I40: =SUM(H$33:H$42) -> 6.940271 | AB40: May | AC40: =SUM(D43:D52) -> 33241 | AD40: 6.3081135 | AE40: =AD40*(AC40/SUM($AC$36:$AC$47)) -> 0.538425 | AF40: =SUM($AE$36:$AE$47) -> 6.8225282 | AG40: 20 | AH40: =AE40/SUM($AE$36:$AE$47) -> 0.078918692
...

Sheet Arrival_to_Provider
A1: ED Physician Metrics: Arrival to Provider
D2: Jan | J2: Feb | P2: =LEFT(P3,3) -> Mar | V2: =LEFT(V3,3) -> Apr | AB2: =LEFT(AB3,3) -> May | AH2: =LEFT(AH3,3) -> Jun | AN2: =LEFT(AN3,3) -> Jul | AT2: =LEFT(AT3,3) -> Aug | AZ2: =LEFT(AZ3,3) -> Sep | BF2: =LEFT(BF3,3) -> Oct | BL2: Nov | BR2: Dec
D3: Jan | J3: Feb | P3: Mar | V3: Apr | AB3: May | AH3: Jun | AN3: Jul | AT3: Aug | AZ3: Sep | BF3: Oct | BL3: Nov | BR3: Dec
D4: Patients | E4: Avg Wait | F4: Med Wait | G4: SITE_WT | H4: PER_WT | J4: Patients | K4: Avg Wait | L4: Med Wait | M4: SITE_WT | N4: PER_WT | P4: Patients | Q4: Avg Wait | R4: Med Wait | S4: SITE_WT | T4: PER_WT | V4: Patients | W4: Avg Wait | X4: Med Wait | Y4: SITE_WT | Z4: PER_WT | AB4: Patients | AC4: Avg Wait | AD4: Med Wait | AE4: SITE_WT | AF4: PER_WT | AH4: Patients | AI4: Avg Wait | AJ4: Med Wait | AK4: SITE_WT | AL4: PER_WT | AN4: Patients | AO4: Avg Wait | AP4: Med Wait | AQ4: SITE_WT | AR4: PER_WT | AT4: Patients | AU4: Avg Wait | AV4: Med Wait | AW4: SITE_WT | AX4: PER_WT | AZ4: Patients | BA4: Avg Wait | BB4: Med Wait | BC4: SITE_WT | BD4: PER_WT | BF4: Patients | BG4: Avg Wait | BH4: Med Wait | BI4: SITE_WT | BJ4: PER_WT | BL4: Patients | BM4: Avg Wait | BN4: Med Wait | BO4: SITE_WT | BP4: PER_WT | BR4: Patients | BS4: Avg Wait | BT4: Med Wait | BU4: SITE_WT | BV4: PER_WT
A5: Hunters Creek
B6: AMICO MD, KENDRA L | D6: {=SUM(IF(Period=$D$2,IF(Site=$A$5,IF(Provider=$B6,I))))} -> 41 | E6: {=SUM(IF(Period=$D$2,IF(Site=$A$5,IF(Provider=$B6,J))))} -> 12.707317 | G6: =E6*(D6/D$83) -> 0.24042455 | H6: =E6*(D6/D$891) -> 0.01508964 | J6: {=SUM(IF(Period=$J$2,IF(Site=$A$5,IF(Provider=$B6,I))))} -> 15 | K6: {=SUM(IF(Period=$J$2,IF(Site=$A$5,IF(Provider=$B6,J))))} -> 4.6666667 | M6: =K6*(J6/J$83) -> 0.035017509 | N6: =K6*(J6/J$891) -> 0.002168727 | P6: {=SUM(IF(Period=$P$2,IF(Site=$A$5,IF(Provider=$B6,I))))} -> 13 | Q6: {=SUM(IF(Period=$P$2,IF(Site=$A$5,IF(Provider=$B6,J))))} -> 3.3076923 | S6: =Q6*(P6/P$83) -> 0.019972132 | T6: =Q6*(P6/P$891) -> 0.0012391217 | V6: {=SUM(IF(Period=$V$2,IF(Site=$A$5,IF(Provider=$B6,I))))} -> 0 | W6: {=SUM(IF(Period=$V$2,IF(Site=$A$5,IF(Provider=$B6,J))))} -> 0 | Y6: =W6*(V6/V$83) -> 0 | Z6: =W6*(V6/V$891) -> 0 | AB6: {=SUM(IF(Period=$AB$2,IF(Site=$A$5,IF(Provider=$B6,I))))} -> 0 | AC6: {=SUM(IF(Period=$AB$2,IF(Site=$A$5,IF(Provider=$B6,J))))} -> 0 | AE6: =AC6*(AB6/AB$83) -> 0 | AF6: =AC6*(AB6/AB$891) -> 0 | AH6: {=SUM(IF(Period=$AH$2,IF(Site=$A$5,IF(Provider=$B6,I))))} -> 0 | AI6: {=SUM(IF(Period=$AH$2,IF(Site=$A$5,IF(Provider=$B6,J))))} -> 0 | AK6: =AI6*(AH6/AH$83) -> 0 | AL6: =AI6*(AH6/AH$891) -> 0 | AN6: {=SUM(IF(Period=$AN$2,IF(Site=$A$5,IF(Provider=$B6,I))))} -> 1 | AO6: {=SUM(IF(Period=$AN$2,IF(Site=$A$5,IF(Provider=$B6,J))))} -> 6 | AQ6: =AO6*(AN6/AN$83) -> 0.0030643514 | AR6: =AO6*(AN6/AN$891) -> 0.0001918772 | AT6: {=SUM(IF(Period=$AT$2,IF(Site=$A$5,IF(Provider=$B6,I))))} -> 1 | AU6: {=SUM(IF(Period=$AT$2,IF(Site=$A$5,IF(Provider=$B6,J))))} -> 2 | AW6: =AU6*(AT6/AT$83) -> 0.00098135427 | AX6: =AU6*(AT6/AT$891) -> 6.3017929e-05 | AZ6: {=SUM(IF(Period=$AZ$2,IF(Site=$A$5,IF(Provider=$B6,I))))} -> 19 | BA6: {=SUM(IF(Period=$AZ$2,IF(Site=$A$5,IF(Provider=$B6,J))))} -> 3.2631579 | BC6: =BA6*(AZ6/AZ$83) -> 0.032769556 | BD6: =BA6*(AZ6/AZ$891) -> 0.0020202678 | BF6: {=SUM(IF(Period=$BF$2,IF(Site=$A$5,IF(Provider=$B6,I))))} -> 1 | BG6: {=SUM(IF(Period=$BF$2,IF(Site=$A$5,IF(Provider=$B6,J))))} -> 9 | BI6: =BG6*(BF6/BF$83) -> 0.004491018 | BJ6: =BG6*(BF6/BF$891) -> 0.00027848258 | BL6: {=SUM(IF(Period=$BL$2,IF(Site=$A$5,IF(Provider=$B6,I))))} -> 2 | BM6: {=SUM(IF(Period=$BL$2,IF(Site=$A$5,IF(Provider=$B6,J))))} -> 2 | BO6: =BM6*(BL6/BL$83) -> 0.0018604651 | BP6: =BM6*(BL6/BL$891) -> 0.00012436651 | BR6: {=SUM(IF(Period=$BR$2,IF(Site=$A$5,IF(Provider=$B6,I))))} -> 1 | BS6: {=SUM(IF(Period=$BR$2,IF(Site=$A$5,IF(Provider=$B6,J))))} -> 6 | BU6: =BS6*(BR6/BR$83) -> 0.0024174053 | BV6: =BS6*(BR6/BR$891) -> 0.00017599953
B7: BABB ARNP, LISA J | D7: {=SUM(IF(Period=$D$2,IF(Site=$A$5,IF(Provider=$B7,I))))} -> 30 | E7: {=SUM(IF(Period=$D$2,IF(Site=$A$5,IF(Provider=$B7,J))))} -> 3.0333333 | G7: =E7*(D7/D$83) -> 0.041993539 | H7: =E7*(D7/D$891) -> 0.0026356185 | J7: {=SUM(IF(Period=$J$2,IF(Site=$A$5,IF(Provider=$B7,I))))} -> 36 | K7: {=SUM(IF(Period=$J$2,IF(Site=$A$5,IF(Provider=$B7,J))))} -> 7.3333333 | M7: =K7*(J7/J$83) -> 0.13206603 | N7: =K7*(J7/J$891) -> 0.0081791988 | P7: {=SUM(IF(Period=$P$2,IF(Site=$A$5,IF(Provider=$B7,I))))} -> 0 | Q7: {=SUM(IF(Period=$P$2,IF(Site=$A$5,IF(Provider=$B7,J))))} -> 0 | S7: =Q7*(P7/P$83) -> 0 | T7: =Q7*(P7/P$891) -> 0 | V7: {=SUM(IF(Period=$V$2,IF(Site=$A$5,IF(Provider=$B7,I))))} -> 62 | W7: {=SUM(IF(Period=$V$2,IF(Site=$A$5,IF(Provider=$B7,J))))} -> 3.9193548 | Y7: =W7*(V7/V$83) -> 0.11516588 | Z7: =W7*(V7/V$891) -> 0.0073489385 | AB7: {=SUM(IF(Period=$AB$2,IF(Site=$A$5,IF(Provider=$B7,I))))} -> 39 | AC7: {=SUM(IF(Period=$AB$2,IF(Site=$A$5,IF(Provider=$B7,J))))} -> 2.9487179 | AE7: =AC7*(AB7/AB$83) -> 0.055825243 | AF7: =AC7*(AB7/AB$891) -> 0.003459583 | AH7: {=SUM(IF(Period=$AH$2,IF(Site=$A$5,IF(Provider=$B7,I))))} -> 39 | AI7: {=SUM(IF(Period=$AH$2,IF(Site=$A$5,IF(Provider=$B7,J))))} -> 5.1794872 | AK7: =AI7*(AH7/AH$83) -> 0.10171198 | AL7: =AI7*(AH7/AH$891) -> 0.0068787033 | AN7: {=SUM(IF(Period=$AN$2,IF(Site=$A$5,IF(Provider=$B7,I))))} -> 42 | AO7: {=SUM(IF(Period=$AN$2,IF(Site=$A$5,IF(Provider=$B7,J))))} -> 4.1666667 | AQ7: =AO7*(AN7/AN$83) -> 0.089376915 | AR7: =AO7*(AN7/AN$891) -> 0.0055964183 | AT7: {=SUM(IF(Period=$AT$2,IF(Site=$A$5,IF(Provider=$B7,I))))} -> 0 | AU7: {=SUM(IF(Period=$AT$2,IF(Site=$A$5,IF(Provider=$B7,J))))} -> 0 | AW7: =AU7*(AT7/AT$83) -> 0 | AX7: =AU7*(AT7/AT$891) -> 0 | AZ7: {=SUM(IF(Period=$AZ$2,IF(Site=$A$5,IF(Provider=$B7,I))))} -> 0 | BA7: {=SUM(IF(Period=$AZ$2,IF(Site=$A$5,IF(Provider=$B7,J))))} -> 0 | BC7: =BA7*(AZ7/AZ$83) -> 0 | BD7: =BA7*(AZ7/AZ$891) -> 0 | BF7: {=SUM(IF(Period=$BF$2,IF(Site=$A$5,IF(Provider=$B7,I))))} -> 0 | BG7: {=SUM(IF(Period=$BF$2,IF(Site=$A$5,IF(Provider=$B7,J))))} -> 0 | BI7: =BG7*(BF7/BF$83) -> 0 | BJ7: =BG7*(BF7/BF$891) -> 0 | BL7: {=SUM(IF(Period=$BL$2,IF(Site=$A$5,IF(Provider=$B7,I))))} -> 61 | BM7: {=SUM(IF(Period=$BL$2,IF(Site=$A$5,IF(Provider=$B7,J))))} -> 2.9836066 | BO7: =BM7*(BL7/BL$83) -> 0.084651163 | BP7: =BM7*(BL7/BL$891) -> 0.0056586761 | BR7: {=SUM(IF(Period=$BR$2,IF(Site=$A$5,IF(Provider=$B7,I))))} -> 28 | BS7: {=SUM(IF(Period=$BR$2,IF(Site=$A$5,IF(Provider=$B7,J))))} -> 9.3214286 | BU7: =BS7*(BR7/BR$83) -> 0.10515713 | BV7: =BS7*(BR7/BR$891) -> 0.0076559796
B8: BALLINGER MD, BETHANY LUCILLE | D8: {=SUM(IF(Period=$D$2,IF(Site=$A$5,IF(Provider=$B8,I))))} -> 0 | E8: {=SUM(IF(Period=$D$2,IF(Site=$A$5,IF(Provider=$B8,J))))} -> 0 | G8: =E8*(D8/D$83) -> 0 | H8: =E8*(D8/D$891) -> 0 | J8: {=SUM(IF(Period=$J$2,IF(Site=$A$5,IF(Provider=$B8,I))))} -> 0 | K8: {=SUM(IF(Period=$J$2,IF(Site=$A$5,IF(Provider=$B8,J))))} -> 0 | M8: =K8*(J8/J$83) -> 0 | N8: =K8*(J8/J$891) -> 0 | P8: {=SUM(IF(Period=$P$2,IF(Site=$A$5,IF(Provider=$B8,I))))} -> 0 | Q8: {=SUM(IF(Period=$P$2,IF(Site=$A$5,IF(Provider=$B8,J))))} -> 0 | S8: =Q8*(P8/P$83) -> 0 | T8: =Q8*(P8/P$891) -> 0 | V8: {=SUM(IF(Period=$V$2,IF(Site=$A$5,IF(Provider=$B8,I))))} -> 0 | W8: {=SUM(IF(Period=$V$2,IF(Site=$A$5,IF(Provider=$B8,J))))} -> 0 | Y8: =W8*(V8/V$83) -> 0 | Z8: =W8*(V8/V$891) -> 0 | AB8: {=SUM(IF(Period=$AB$2,IF(Site=$A$5,IF(Provider=$B8,I))))} -> 0 | AC8: {=SUM(IF(Period=$AB$2,IF(Site=$A$5,IF(Provider=$B8,J))))} -> 0 | AE8: =AC8*(AB8/AB$83) -> 0 | AF8: =AC8*(AB8/AB$891) -> 0 | AH8: {=SUM(IF(Period=$AH$2,IF(Site=$A$5,IF(Provider=$B8,I))))} -> 0 | AI8: {=SUM(IF(Period=$AH$2,IF(Site=$A$5,IF(Provider=$B8,J))))} -> 0 | AK8: =AI8*(AH8/AH$83) -> 0 | AL8: =AI8*(AH8/AH$891) -> 0 | AN8: {=SUM(IF(Period=$AN$2,IF(Site=$A$5,IF(Provider=$B8,I))))} -> 0 | AO8: {=SUM(IF(Period=$AN$2,IF(Site=$A$5,IF(Provider=$B8,J))))} -> 0 | AQ8: =AO8*(AN8/AN$83) -> 0 | AR8: =AO8*(AN8/AN$891) -> 0 | AT8: {=SUM(IF(Period=$AT$2,IF(Site=$A$5,IF(Provider=$B8,I))))} -> 2 | AU8: {=SUM(IF(Period=$AT$2,IF(Site=$A$5,IF(Provider=$B8,J))))} -> 3 | AW8: =AU8*(AT8/AT$83) -> 0.0029440628 | AX8: =AU8*(AT8/AT$891) -> 0.00018905379 | AZ8: {=SUM(IF(Period=$AZ$2,IF(Site=$A$5,IF(Provider=$B8,I))))} -> 0 | BA8: {=SUM(IF(Period=$AZ$2,IF(Site=$A$5,IF(Provider=$B8,J))))} -> 0 | BC8: =BA8*(AZ8/AZ$83) -> 0 | BD8: =BA8*(AZ8/AZ$891) -> 0 | BF8: {=SUM(IF(Period=$BF$2,IF(Site=$A$5,IF(Provider=$B8,I))))} -> 0 | BG8: {=SUM(IF(Period=$BF$2,IF(Site=$A$5,IF(Provider=$B8,J))))} -> 0 | BI8: =BG8*(BF8/BF$83) -> 0 | BJ8: =BG8*(BF8/BF$891) -> 0 | BL8: {=SUM(IF(Period=$BL$2,IF(Site=$A$5,IF(Provider=$B8,I))))} -> 0 | BM8: {=SUM(IF(Period=$BL$2,IF(Site=$A$5,IF(Provider=$B8,J))))} -> 0 | BO8: =BM8*(BL8/BL$83) -> 0 | BP8: =BM8*(BL8/BL$891) -> 0 | BR8: {=SUM(IF(Period=$BR$2,IF(Site=$A$5,IF(Provider=$B8,I))))} -> 0 | BS8: {=SUM(IF(Period=$BR$2,IF(Site=$A$5,IF(Provider=$B8,J))))} -> 0 | BU8: =BS8*(BR8/BR$83) -> 0 | BV8: =BS8*(BR8/BR$891) -> 0
B9: BANERJEE DO, PUSHPAL R | D9: {=SUM(IF(Period=$D$2,IF(Site=$A$5,IF(Provider=$B9,I))))} -> 0 | E9: {=SUM(IF(Period=$D$2,IF(Site=$A$5,IF(Provider=$B9,J))))} -> 0 | G9: =E9*(D9/D$83) -> 0 | H9: =E9*(D9/D$891) -> 0 | J9: {=SUM(IF(Period=$J$2,IF(Site=$A$5,IF(Provider=$B9,I))))} -> 41 | K9: {=SUM(IF(Period=$J$2,IF(Site=$A$5,IF(Provider=$B9,J))))} -> 3.5365854 | M9: =K9*(J9/J$83) -> 0.072536268 | N9: =K9*(J9/J$891) -> 0.004492363 | P9: {=SUM(IF(Period=$P$2,IF(Site=$A$5,IF(Provider=$B9,I))))} -> 0 | Q9: {=SUM(IF(Period=$P$2,IF(Site=$A$5,IF(Provider=$B9,J))))} -> 0 | S9: =Q9*(P9/P$83) -> 0 | T9: =Q9*(P9/P$891) -> 0 | V9: {=SUM(IF(Period=$V$2,IF(Site=$A$5,IF(Provider=$B9,I))))} -> 0 | W9: {=SUM(IF(Period=$V$2,IF(Site=$A$5,IF(Provider=$B9,J))))} -> 0 | Y9: =W9*(V9/V$83) -> 0 | Z9: =W9*(V9/V$891) -> 0 | AB9: {=SUM(IF(Period=$AB$2,IF(Site=$A$5,IF(Provider=$B9,I))))} -> 0 | AC9: {=SUM(IF(Period=$AB$2,IF(Site=$A$5,IF(Provider=$B9,J))))} -> 0 | AE9: =AC9*(AB9/AB$83) -> 0 | AF9: =AC9*(AB9/AB$891) -> 0 | AH9: {=SUM(IF(Period=$AH$2,IF(Site=$A$5,IF(Provider=$B9,I))))} -> 0 | AI9: {=SUM(IF(Period=$AH$2,IF(Site=$A$5,IF(Provider=$B9,J))))} -> 0 | AK9: =AI9*(AH9/AH$83) -> 0 | AL9: =AI9*(AH9/AH$891) -> 0 | AN9: {=SUM(IF(Period=$AN$2,IF(Site=$A$5,IF(Provider=$B9,I))))} -> 0 | AO9: {=SUM(IF(Period=$AN$2,IF(Site=$A$5,IF(Provider=$B9,J))))} -> 0 | AQ9: =AO9*(AN9/AN$83) -> 0 | AR9: =AO9*(AN9/AN$891) -> 0 | AT9: {=SUM(IF(Period=$AT$2,IF(Site=$A$5,IF(Provider=$B9,I))))} -> 16 | AU9: {=SUM(IF(Period=$AT$2,IF(Site=$A$5,IF(Provider=$B9,J))))} -> 2.6875 | AW9: =AU9*(AT9/AT$83) -> 0.021099117 | AX9: =AU9*(AT9/AT$891) -> 0.0013548855 | AZ9: {=SUM(IF(Period=$AZ$2,IF(Site=$A$5,IF(Provider=$B9,I))))} -> 23 | BA9: {=SUM(IF(Period=$AZ$2,IF(Site=$A$5,IF(Provider=$B9,J))))} -> 3.3478261 | BC9: =BA9*(AZ9/AZ$83) -> 0.040697674 | BD9: =BA9*(AZ9/AZ$891) -> 0.0025090423 | BF9: {=SUM(IF(Period=$BF$2,IF(Site=$A$5,IF(Provider=$B9,I))))} -> 0 | BG9: {=SUM(IF(Period=$BF$2,IF(Site=$A$5,IF(Provider=$B9,J))))} -> 0 | BI9: =BG9*(BF9/BF$83) -> 0 | BJ9: =BG9*(BF9/BF$891) -> 0 | BL9: {=SUM(IF(Period=$BL$2,IF(Site=$A$5,IF(Provider=$B9,I))))} -> 34 | BM9: {=SUM(IF(Period=$BL$2,IF(Site=$A$5,IF(Provider=$B9,J))))} -> 4.4411765 | BO9: =BM9*(BL9/BL$83) -> 0.070232558 | BP9: =BM9*(BL9/BL$891) -> 0.0046948357 | BR9: {=SUM(IF(Period=$BR$2,IF(Site=$A$5,IF(Provider=$B9,I))))} -> 2 | BS9: {=SUM(IF(Period=$BR$2,IF(Site=$A$5,IF(Provider=$B9,J))))} -> 2.5 | BU9: =BS9*(BR9/BR$83) -> 0.0020145044 | BV9: =BS9*(BR9/BR$891) -> 0.00014666628
B10: BENZING MD, ADAM C | D10: {=SUM(IF(Period=$D$2,IF(Site=$A$5,IF(Provider=$B10,I))))} -> 0 | E10: {=SUM(IF(Period=$D$2,IF(Site=$A$5,IF(Provider=$B10,J))))} -> 0 | G10: =E10*(D10/D$83) -> 0 | H10: =E10*(D10/D$891) -> 0 | J10: {=SUM(IF(Period=$J$2,IF(Site=$A$5,IF(Provider=$B10,I))))} -> 0 | K10: {=SUM(IF(Period=$J$2,IF(Site=$A$5,IF(Provider=$B10,J))))} -> 0 | M10: =K10*(J10/J$83) -> 0 | N10: =K10*(J10/J$891) -> 0 | P10: {=SUM(IF(Period=$P$2,IF(Site=$A$5,IF(Provider=$B10,I))))} -> 0 | Q10: {=SUM(IF(Period=$P$2,IF(Site=$A$5,IF(Provider=$B10,J))))} -> 0 | S10: =Q10*(P10/P$83) -> 0 | T10: =Q10*(P10/P$891) -> 0 | V10: {=SUM(IF(Period=$V$2,IF(Site=$A$5,IF(Provider=$B10,I))))} -> 0 | W10: {=SUM(IF(Period=$V$2,IF(Site=$A$5,IF(Provider=$B10,J))))} -> 0 | Y10: =W10*(V10/V$83) -> 0 | Z10: =W10*(V10/V$891) -> 0 | AB10: {=SUM(IF(Period=$AB$2,IF(Site=$A$5,IF(Provider=$B10,I))))} -> 0 | AC10: {=SUM(IF(Period=$AB$2,IF(Site=$A$5,IF(Provider=$B10,J))))} -> 0 | AE10: =AC10*(AB10/AB$83) -> 0 | AF10: =AC10*(AB10/AB$891) -> 0 | AH10: {=SUM(IF(Period=$AH$2,IF(Site=$A$5,IF(Provider=$B10,I))))} -> 0 | AI10: {=SUM(IF(Period=$AH$2,IF(Site=$A$5,IF(Provider=$B10,J))))} -> 0 | AK10: =AI10*(AH10/AH$83) -> 0 | AL10: =AI10*(AH10/AH$891) -> 0 | AN10: {=SUM(IF(Period=$AN$2,IF(Site=$A$5,IF(Provider=$B10,I))))} -> 0 | AO10: {=SUM(IF(Period=$AN$2,IF(Site=$A$5,IF(Provider=$B10,J))))} -> 0 | AQ10: =AO10*(AN10/AN$83) -> 0 | AR10: =AO10*(AN10/AN$891) -> 0 | AT10: {=SUM(IF(Period=$AT$2,IF(Site=$A$5,IF(Provider=$B10,I))))} -> 1 | AU10: {=SUM(IF(Period=$AT$2,IF(Site=$A$5,IF(Provider=$B10,J))))} -> 6 | AW10: =AU10*(AT10/AT$83) -> 0.0029440628 | AX10: =AU10*(AT10/AT$891) -> 0.00018905379 | AZ10: {=SUM(IF(Period=$AZ$2,IF(Site=$A$5,IF(Provider=$B10,I))))} -> 0 | BA10: {=SUM(IF(Period=$AZ$2,IF(Site=$A$5,IF(Provider=$B10,J))))} -> 0 | BC10: =BA10*(AZ10/AZ$83) -> 0 | BD10: =BA10*(AZ10/AZ$891) -> 0 | BF10: {=SUM(IF(Period=$BF$2,IF(Site=$A$5,IF(Provider=$B10,I))))} -> 0 | BG10: {=SUM(IF(Period=$BF$2,IF(Site=$A$5,IF(Provider=$B10,J))))} -> 0 | BI10: =BG10*(BF10/BF$83) -> 0 | BJ10: =BG10*(BF10/BF$891) -> 0 | BL10: {=SUM(IF(Period=$BL$2,IF(Site=$A$5,IF(Provider=$B10,I))))} -> 1 | BM10: {=SUM(IF(Period=$BL$2,IF(Site=$A$5,IF(Provider=$B10,J))))} -> 13 | BO10: =BM10*(BL10/BL$83) -> 0.0060465116 | BP10: =BM10*(BL10/BL$891) -> 0.00040419115 | BR10: {=SUM(IF(Period=$BR$2,IF(Site=$A$5,IF(Provider=$B10,I))))} -> 0 | BS10: {=SUM(IF(Period=$BR$2,IF(Site=$A$5,IF(Provider=$B10,J))))} -> 0 | BU10: =BS10*(BR10/BR$83) -> 0 | BV10: =BS10*(BR10/BR$891) -> 0
B11: CABRERA DO, ROLANDO G | D11: {=SUM(IF(Period=$D$2,IF(Site=$A$5,IF(Provider=$B11,I))))} -> 0 | E11: {=SUM(IF(Period=$D$2,IF(Site=$A$5,IF(Provider=$B11,J))))} -> 0 | G11: =E11*(D11/D$83) -> 0 | H11: =E11*(D11/D$891) -> 0 | J11: {=SUM(IF(Period=$J$2,IF(Site=$A$5,IF(Provider=$B11,I))))} -> 0 | K11: {=SUM(IF(Period=$J$2,IF(Site=$A$5,IF(Provider=$B11,J))))} -> 0 | M11: =K11*(J11/J$83) -> 0 | N11: =K11*(J11/J$891) -> 0 | P11: {=SUM(IF(Period=$P$2,IF(Site=$A$5,IF(Provider=$B11,I))))} -> 0 | Q11: {=SUM(IF(Period=$P$2,IF(Site=$A$5,IF(Provider=$B11,J))))} -> 0 | S11: =Q11*(P11/P$83) -> 0 | T11: =Q11*(P11/P$891) -> 0 | V11: {=SUM(IF(Period=$V$2,IF(Site=$A$5,IF(Provider=$B11,I))))} -> 0 | W11: {=SUM(IF(Period=$V$2,IF(Site=$A$5,IF(Provider=$B11,J))))} -> 0 | Y11: =W11*(V11/V$83) -> 0 | Z11: =W11*(V11/V$891) -> 0 | AB11: {=SUM(IF(Period=$AB$2,IF(Site=$A$5,IF(Provider=$B11,I))))} -> 0 | AC11: {=SUM(IF(Period=$AB$2,IF(Site=$A$5,IF(Provider=$B11,J))))} -> 0 | AE11: =AC11*(AB11/AB$83) -> 0 | AF11: =AC11*(AB11/AB$891) -> 0 | AH11: {=SUM(IF(Period=$AH$2,IF(Site=$A$5,IF(Provider=$B11,I))))} -> 1 | AI11: {=SUM(IF(Period=$AH$2,IF(Site=$A$5,IF(Provider=$B11,J))))} -> 8 | AK11: =AI11*(AH11/AH$83) -> 0.0040281974 | AL11: =AI11*(AH11/AH$891) -> 0.00027242389 | AN11: {=SUM(IF(Period=$AN$2,IF(Site=$A$5,IF(Provider=$B11,I))))} -> 0 | AO11: {=SUM(IF(Period=$AN$2,IF(Site=$A$5,IF(Provider=$B11,J))))} -> 0 | AQ11: =AO11*(AN11/AN$83) -> 0 | AR11: =AO11*(AN11/AN$891) -> 0 | AT11: {=SUM(IF(Period=$AT$2,IF(Site=$A$5,IF(Provider=$B11,I))))} -> 0 | AU11: {=SUM(IF(Period=$AT$2,IF(Site=$A$5,IF(Provider=$B11,J))))} -> 0 | AW11: =AU11*(AT11/AT$83) -> 0 | AX11: =AU11*(AT11/AT$891) -> 0 | AZ11: {=SUM(IF(Period=$AZ$2,IF(Site=$A$5,IF(Provider=$B11,I))))} -> 1 | BA11: {=SUM(IF(Period=$AZ$2,IF(Site=$A$5,IF(Provider=$B11,J))))} -> 1 | BC11: =BA11*(AZ11/AZ$83) -> 0.00052854123 | BD11: =BA11*(AZ11/AZ$891) -> 3.2584965e-05 | BF11: {=SUM(IF(Period=$BF$2,IF(Site=$A$5,IF(Provider=$B11,I))))} -> 2 | BG11: {=SUM(IF(Period=$BF$2,IF(Site=$A$5,IF(Provider=$B11,J))))} -> 4 | BI11: =BG11*(BF11/BF$83) -> 0.003992016 | BJ11: =BG11*(BF11/BF$891) -> 0.00024754007 | BL11: {=SUM(IF(Period=$BL$2,IF(Site=$A$5,IF(Provider=$B11,I))))} -> 1 | BM11: {=SUM(IF(Period=$BL$2,IF(Site=$A$5,IF(Provider=$B11,J))))} -> 7 | BO11: =BM11*(BL11/BL$83) -> 0.003255814 | BP11: =BM11*(BL11/BL$891) -> 0.00021764139 | BR11: {=SUM(IF(Period=$BR$2,IF(Site=$A$5,IF(Provider=$B11,I))))} -> 1 | BS11: {=SUM(IF(Period=$BR$2,IF(Site=$A$5,IF(Provider=$B11,J))))} -> 3 | BU11: =BS11*(BR11/BR$83) -> 0.0012087027 | BV11: =BS11*(BR11/BR$891) -> 8.7999765e-05
B12: CHANDLER MD, MARK R | D12: {=SUM(IF(Period=$D$2,IF(Site=$A$5,IF(Provider=$B12,I))))} -> 219 | E12: {=SUM(IF(Period=$D$2,IF(Site=$A$5,IF(Provider=$B12,J))))} -> 9.5753425 | G12: =E12*(D12/D$83) -> 0.96769728 | H12: =E12*(D12/D$891) -> 0.060735077 | J12: {=SUM(IF(Period=$J$2,IF(Site=$A$5,IF(Provider=$B12,I))))} -> 132 | K12: {=SUM(IF(Period=$J$2,IF(Site=$A$5,IF(Provider=$B12,J))))} -> 6.3484848 | M12: =K12*(J12/J$83) -> 0.4192096 | N12: =K12*(J12/J$891) -> 0.02596276 | P12: {=SUM(IF(Period=$P$2,IF(Site=$A$5,IF(Provider=$B12,I))))} -> 232 | Q12: {=SUM(IF(Period=$P$2,IF(Site=$A$5,IF(Provider=$B12,J))))} -> 6.6163793 | S12: =Q12*(P12/P$83) -> 0.71295866 | T12: =Q12*(P12/P$891) -> 0.044233762 | V12: {=SUM(IF(Period=$V$2,IF(Site=$A$5,IF(Provider=$B12,I))))} -> 210 | W12: {=SUM(IF(Period=$V$2,IF(Site=$A$5,IF(Provider=$B12,J))))} -> 5.0333333 | Y12: =W12*(V12/V$83) -> 0.50094787 | Z12: =W12*(V12/V$891) -> 0.03196637 | AB12: {=SUM(IF(Period=$AB$2,IF(Site=$A$5,IF(Provider=$B12,I))))} -> 248 | AC12: {=SUM(IF(Period=$AB$2,IF(Site=$A$5,IF(Provider=$B12,J))))} -> 4.5766129 | AE12: =AC12*(AB12/AB$83) -> 0.55097087 | AF12: =AC12*(AB12/AB$891) -> 0.03414458 | AH12: {=SUM(IF(Period=$AH$2,IF(Site=$A$5,IF(Provider=$B12,I))))} -> 250 | AI12: {=SUM(IF(Period=$AH$2,IF(Site=$A$5,IF(Provider=$B12,J))))} -> 4.26 | AK12: =AI12*(AH12/AH$83) -> 0.53625378 | AL12: =AI12*(AH12/AH$891) -> 0.036266431 | AN12: {=SUM(IF(Period=$AN$2,IF(Site=$A$5,IF(Provider=$B12,I))))} -> 161 | AO12: {=SUM(IF(Period=$AN$2,IF(Site=$A$5,IF(Provider=$B12,J))))} -> 4.8695652 | AQ12: =AO12*(AN12/AN$83) -> 0.40040858 | AR12: =AO12*(AN12/AN$891) -> 0.025071954 | AT12: {=SUM(IF(Period=$AT$2,IF(Site=$A$5,IF(Provider=$B12,I))))} -> 162 | AU12: {=SUM(IF(Period=$AT$2,IF(Site=$A$5,IF(Provider=$B12,J))))} -> 4.6358025 | AW12: =AU12*(AT12/AT$83) -> 0.36849853 | AX12: =AU12*(AT12/AT$891) -> 0.023663232 | AZ12: {=SUM(IF(Period=$AZ$2,IF(Site=$A$5,IF(Provider=$B12,I))))} -> 199 | BA12: {=SUM(IF(Period=$AZ$2,IF(Site=$A$5,IF(Provider=$B12,J))))} -> 5.201005 | BC12: =BA12*(AZ12/AZ$83) -> 0.54704017 | BD12: =BA12*(AZ12/AZ$891) -> 0.033725439 | BF12: {=SUM(IF(Period=$BF$2,IF(Site=$A$5,IF(Provider=$B12,I))))} -> 200 | BG12: {=SUM(IF(Period=$BF$2,IF(Site=$A$5,IF(Provider=$B12,J))))} -> 3.835 | BI12: =BG12*(BF12/BF$83) -> 0.38273453 | BJ12: =BG12*(BF12/BF$891) -> 0.023732904 | BL12: {=SUM(IF(Period=$BL$2,IF(Site=$A$5,IF(Provider=$B12,I))))} -> 211 | BM12: {=SUM(IF(Period=$BL$2,IF(Site=$A$5,IF(Provider=$B12,J))))} -> 4.4597156 | BO12: =BM12*(BL12/BL$83) -> 0.43767442 | BP12: =BM12*(BL12/BL$891) -> 0.029257221 | BR12: {=SUM(IF(Period=$BR$2,IF(Site=$A$5,IF(Provider=$B12,I))))} -> 196 | BS12: {=SUM(IF(Period=$BR$2,IF(Site=$A$5,IF(Provider=$B12,J))))} -> 5.6428571 | BU12: =BS12*(BR12/BR$83) -> 0.44560838 | BV12: =BS12*(BR12/BR$891) -> 0.03244258
B13: CHIANG MD, JAMES | D13: {=SUM(IF(Period=$D$2,IF(Site=$A$5,IF(Provider=$B13,I))))} -> 0 | E13: {=SUM(IF(Period=$D$2,IF(Site=$A$5,IF(Provider=$B13,J))))} -> 0 | G13: =E13*(D13/D$83) -> 0 | H13: =E13*(D13/D$891) -> 0 | J13: {=SUM(IF(Period=$J$2,IF(Site=$A$5,IF(Provider=$B13,I))))} -> 0 | K13: {=SUM(IF(Period=$J$2,IF(Site=$A$5,IF(Provider=$B13,J))))} -> 0 | M13: =K13*(J13/J$83) -> 0 | N13: =K13*(J13/J$891) -> 0 | P13: {=SUM(IF(Period=$P$2,IF(Site=$A$5,IF(Provider=$B13,I))))} -> 0 | Q13: {=SUM(IF(Period=$P$2,IF(Site=$A$5,IF(Provider=$B13,J))))} -> 0 | S13: =Q13*(P13/P$83) -> 0 | T13: =Q13*(P13/P$891) -> 0 | V13: {=SUM(IF(Period=$V$2,IF(Site=$A$5,IF(Provider=$B13,I))))} -> 0 | W13: {=SUM(IF(Period=$V$2,IF(Site=$A$5,IF(Provider=$B13,J))))} -> 0 | Y13: =W13*(V13/V$83) -> 0 | Z13: =W13*(V13/V$891) -> 0 | AB13: {=SUM(IF(Period=$AB$2,IF(Site=$A$5,IF(Provider=$B13,I))))} -> 0 | AC13: {=SUM(IF(Period=$AB$2,IF(Site=$A$5,IF(Provider=$B13,J))))} -> 0 | AE13: =AC13*(AB13/AB$83) -> 0 | AF13: =AC13*(AB13/AB$891) -> 0 | AH13: {=SUM(IF(Period=$AH$2,IF(Site=$A$5,IF(Provider=$B13,I))))} -> 0 | AI13: {=SUM(IF(Period=$AH$2,IF(Site=$A$5,IF(Provider=$B13,J))))} -> 0 | AK13: =AI13*(AH13/AH$83) -> 0 | AL13: =AI13*(AH13/AH$891) -> 0 | AN13: {=SUM(IF(Period=$AN$2,IF(Site=$A$5,IF(Provider=$B13,I))))} -> 0 | AO13: {=SUM(IF(Period=$AN$2,IF(Site=$A$5,IF(Provider=$B13,J))))} -> 0 | AQ13: =AO13*(AN13/AN$83) -> 0 | AR13: =AO13*(AN13/AN$891) -> 0 | AT13: {=SUM(IF(Period=$AT$2,IF(Site=$A$5,IF(Provider=$B13,I))))} -> 0 | AU13: {=SUM(IF(Period=$AT$2,IF(Site=$A$5,IF(Provider=$B13,J))))} -> 0 | AW13: =AU13*(AT13/AT$83) -> 0 | AX13: =AU13*(AT13/AT$891) -> 0 | AZ13: {=SUM(IF(Period=$AZ$2,IF(Site=$A$5,IF(Provider=$B13,I))))} -> 0 | BA13: {=SUM(IF(Period=$AZ$2,IF(Site=$A$5,IF(Provider=$B13,J))))} -> 0 | BC13: =BA13*(AZ13/AZ$83) -> 0 | BD13: =BA13*(AZ13/AZ$891) -> 0 | BF13: {=SUM(IF(Period=$BF$2,IF(Site=$A$5,IF(Provider=$B13,I))))} -> 0 | BG13: {=SUM(IF(Period=$BF$2,IF(Site=$A$5,IF(Provider=$B13,J))))} -> 0 | BI13: =BG13*(BF13/BF$83) -> 0 | BJ13: =BG13*(BF13/BF$891) -> 0 | BL13: {=SUM(IF(Period=$BL$2,IF(Site=$A$5,IF(Provider=$B13,I))))} -> 3 | BM13: {=SUM(IF(Period=$BL$2,IF(Site=$A$5,IF(Provider=$B13,J))))} -> 3.3333333 | BO13: =BM13*(BL13/BL$83) -> 0.0046511628 | BP13: =BM13*(BL13/BL$891) -> 0.00031091627 | BR13: {=SUM(IF(Period=$BR$2,IF(Site=$A$5,IF(Provider=$B13,I))))} -> 0 | BS13: {=SUM(IF(Period=$BR$2,IF(Site=$A$5,IF(Provider=$B13,J))))} -> 0 | BU13: =BS13*(BR13/BR$83) -> 0 | BV13: =BS13*(BR13/BR$891) -> 0
B14: COLARIC MD, KENNETH B | D14: {=SUM(IF(Period=$D$2,IF(Site=$A$5,IF(Provider=$B14,I))))} -> 0 | E14: {=SUM(IF(Period=$D$2,IF(Site=$A$5,IF(Provider=$B14,J))))} -> 0 | G14: =E14*(D14/D$83) -> 0 | H14: =E14*(D14/D$891) -> 0 | J14: {=SUM(IF(Period=$J$2,IF(Site=$A$5,IF(Provider=$B14,I))))} -> 0 | K14: {=SUM(IF(Period=$J$2,IF(Site=$A$5,IF(Provider=$B14,J))))} -> 0 | M14: =K14*(J14/J$83) -> 0 | N14: =K14*(J14/J$891) -> 0 | P14: {=SUM(IF(Period=$P$2,IF(Site=$A$5,IF(Provider=$B14,I))))} -> 0 | Q14: {=SUM(IF(Period=$P$2,IF(Site=$A$5,IF(Provider=$B14,J))))} -> 0 | S14: =Q14*(P14/P$83) -> 0 | T14: =Q14*(P14/P$891) -> 0 | V14: {=SUM(IF(Period=$V$2,IF(Site=$A$5,IF(Provider=$B14,I))))} -> 0 | W14: {=SUM(IF(Period=$V$2,IF(Site=$A$5,IF(Provider=$B14,J))))} -> 0 | Y14: =W14*(V14/V$83) -> 0 | Z14: =W14*(V14/V$891) -> 0 | AB14: {=SUM(IF(Period=$AB$2,IF(Site=$A$5,IF(Provider=$B14,I))))} -> 0 | AC14: {=SUM(IF(Period=$AB$2,IF(Site=$A$5,IF(Provider=$B14,J))))} -> 0 | AE14: =AC14*(AB14/AB$83) -> 0 | AF14: =AC14*(AB14/AB$891) -> 0 | AH14: {=SUM(IF(Period=$AH$2,IF(Site=$A$5,IF(Provider=$B14,I))))} -> 8 | AI14: {=SUM(IF(Period=$AH$2,IF(Site=$A$5,IF(Provider=$B14,J))))} -> 3.125 | AK14: =AI14*(AH14/AH$83) -> 0.012588117 | AL14: =AI14*(AH14/AH$891) -> 0.00085132466 | AN14: {=SUM(IF(Period=$AN$2,IF(Site=$A$5,IF(Provider=$B14,I))))} -> 74 | AO14: {=SUM(IF(Period=$AN$2,IF(Site=$A$5,IF(Provider=$B14,J))))} -> 4.5540541 | AQ14: =AO14*(AN14/AN$83) -> 0.1721144 | AR14: =AO14*(AN14/AN$891) -> 0.010777103 | AT14: {=SUM(IF(Period=$AT$2,IF(Site=$A$5,IF(Provider=$B14,I))))} -> 13 | AU14: {=SUM(IF(Period=$AT$2,IF(Site=$A$5,IF(Provider=$B14,J))))} -> 7.0769231 | AW14: =AU14*(AT14/AT$83) -> 0.045142296 | AX14: =AU14*(AT14/AT$891) -> 0.0028988247 | AZ14: {=SUM(IF(Period=$AZ$2,IF(Site=$A$5,IF(Provider=$B14,I))))} -> 73 | BA14: {=SUM(IF(Period=$AZ$2,IF(Site=$A$5,IF(Provider=$B14,J))))} -> 4.9589041 | BC14: =BA14*(AZ14/AZ$83) -> 0.19133192 | BD14: =BA14*(AZ14/AZ$891) -> 0.011795757 | BF14: {=SUM(IF(Period=$BF$2,IF(Site=$A$5,IF(Provider=$B14,I))))} -> 0 | BG14: {=SUM(IF(Period=$BF$2,IF(Site=$A$5,IF(Provider=$B14,J))))} -> 0 | BI14: =BG14*(BF14/BF$83) -> 0 | BJ14: =BG14*(BF14/BF$891) -> 0 | BL14: {=SUM(IF(Period=$BL$2,IF(Site=$A$5,IF(Provider=$B14,I))))} -> 24 | BM14: {=SUM(IF(Period=$BL$2,IF(Site=$A$5,IF(Provider=$B14,J))))} -> 10.041667 | BO14: =BM14*(BL14/BL$83) -> 0.11209302 | BP14: =BM14*(BL14/BL$891) -> 0.0074930821 | BR14: {=SUM(IF(Period=$BR$2,IF(Site=$A$5,IF(Provider=$B14,I))))} -> 0 | BS14: {=SUM(IF(Period=$BR$2,IF(Site=$A$5,IF(Provider=$B14,J))))} -> 0 | BU14: =BS14*(BR14/BR$83) -> 0 | BV14: =BS14*(BR14/BR$891) -> 0
B15: COLON CRUZ MD, EDDID | D15: {=SUM(IF(Period=$D$2,IF(Site=$A$5,IF(Provider=$B15,I))))} -> 0 | E15: {=SUM(IF(Period=$D$2,IF(Site=$A$5,IF(Provider=$B15,J))))} -> 0 | G15: =E15*(D15/D$83) -> 0 | H15: =E15*(D15/D$891) -> 0 | J15: {=SUM(IF(Period=$J$2,IF(Site=$A$5,IF(Provider=$B15,I))))} -> 0 | K15: {=SUM(IF(Period=$J$2,IF(Site=$A$5,IF(Provider=$B15,J))))} -> 0 | M15: =K15*(J15/J$83) -> 0 | N15: =K15*(J15/J$891) -> 0 | P15: {=SUM(IF(Period=$P$2,IF(Site=$A$5,IF(Provider=$B15,I))))} -> 0 | Q15: {=SUM(IF(Period=$P$2,IF(Site=$A$5,IF(Provider=$B15,J))))} -> 0 | S15: =Q15*(P15/P$83) -> 0 | T15: =Q15*(P15/P$891) -> 0 | V15: {=SUM(IF(Period=$V$2,IF(Site=$A$5,IF(Provider=$B15,I))))} -> 0 | W15: {=SUM(IF(Period=$V$2,IF(Site=$A$5,IF(Provider=$B15,J))))} -> 0 | Y15: =W15*(V15/V$83) -> 0 | Z15: =W15*(V15/V$891) -> 0 | AB15: {=SUM(IF(Period=$AB$2,IF(Site=$A$5,IF(Provider=$B15,I))))} -> 0 | AC15: {=SUM(IF(Period=$AB$2,IF(Site=$A$5,IF(Provider=$B15,J))))} -> 0 | AE15: =AC15*(AB15/AB$83) -> 0 | AF15: =AC15*(AB15/AB$891) -> 0 | AH15: {=SUM(IF(Period=$AH$2,IF(Site=$A$5,IF(Provider=$B15,I))))} -> 0 | AI15: {=SUM(IF(Period=$AH$2,IF(Site=$A$5,IF(Provider=$B15,J))))} -> 0 | AK15: =AI15*(AH15/AH$83) -> 0 | AL15: =AI15*(AH15/AH$891) -> 0 | AN15: {=SUM(IF(Period=$AN$2,IF(Site=$A$5,IF(Provider=$B15,I))))} -> 0 | AO15: {=SUM(IF(Period=$AN$2,IF(Site=$A$5,IF(Provider=$B15,J))))} -> 0 | AQ15: =AO15*(AN15/AN$83) -> 0 | AR15: =AO15*(AN15/AN$891) -> 0 | AT15: {=SUM(IF(Period=$AT$2,IF(Site=$A$5,IF(Provider=$B15,I))))} -> 0 | AU15: {=SUM(IF(Period=$AT$2,IF(Site=$A$5,IF(Provider=$B15,J))))} -> 0 | AW15: =AU15*(AT15/AT$83) -> 0 | AX15: =AU15*(AT15/AT$891) -> 0 | AZ15: {=SUM(IF(Period=$AZ$2,IF(Site=$A$5,IF(Provider=$B15,I))))} -> 1 | BA15: {=SUM(IF(Period=$AZ$2,IF(Site=$A$5,IF(Provider=$B15,J))))} -> 1 | BC15: =BA15*(AZ15/AZ$83) -> 0.00052854123 | BD15: =BA15*(AZ15/AZ$891) -> 3.2584965e-05 | BF15: {=SUM(IF(Period=$BF$2,IF(Site=$A$5,IF(Provider=$B15,I))))} -> 0 | BG15: {=SUM(IF(Period=$BF$2,IF(Site=$A$5,IF(Provider=$B15,J))))} -> 0 | BI15: =BG15*(BF15/BF$83) -> 0 | BJ15: =BG15*(BF15/BF$891) -> 0 | BL15: {=SUM(IF(Period=$BL$2,IF(Site=$A$5,IF(Provider=$B15,I))))} -> 0 | BM15: {=SUM(IF(Period=$BL$2,IF(Site=$A$5,IF(Provider=$B15,J))))} -> 0 | BO15: =BM15*(BL15/BL$83) -> 0 | BP15: =BM15*(BL15/BL$891) -> 0 | BR15: {=SUM(IF(Period=$BR$2,IF(Site=$A$5,IF(Provider=$B15,I))))} -> 0 | BS15: {=SUM(IF(Period=$BR$2,IF(Site=$A$5,IF(Provider=$B15,J))))} -> 0 | BU15: =BS15*(BR15/BR$83) -> 0 | BV15: =BS15*(BR15/BR$891) -> 0
B16: CONTI PA, LORETTA M | D16: {=SUM(IF(Period=$D$2,IF(Site=$A$5,IF(Provider=$B16,I))))} -> 0 | E16: {=SUM(IF(Period=$D$2,IF(Site=$A$5,IF(Provider=$B16,J))))} -> 0 | G16: =E16*(D16/D$83) -> 0 | H16: =E16*(D16/D$891) -> 0 | J16: {=SUM(IF(Period=$J$2,IF(Site=$A$5,IF(Provider=$B16,I))))} -> 0 | K16: {=SUM(IF(Period=$J$2,IF(Site=$A$5,IF(Provider=$B16,J))))} -> 0 | M16: =K16*(J16/J$83) -> 0 | N16: =K16*(J16/J$891) -> 0 | P16: {=SUM(IF(Period=$P$2,IF(Site=$A$5,IF(Provider=$B16,I))))} -> 0 | Q16: {=SUM(IF(Period=$P$2,IF(Site=$A$5,IF(Provider=$B16,J))))} -> 0 | S16: =Q16*(P16/P$83) -> 0 | T16: =Q16*(P16/P$891) -> 0 | V16: {=SUM(IF(Period=$V$2,IF(Site=$A$5,IF(Provider=$B16,I))))} -> 0 | W16: {=SUM(IF(Period=$V$2,IF(Site=$A$5,IF(Provider=$B16,J))))} -> 0 | Y16: =W16*(V16/V$83) -> 0 | Z16: =W16*(V16/V$891) -> 0 | AB16: {=SUM(IF(Period=$AB$2,IF(Site=$A$5,IF(Provider=$B16,I))))} -> 0 | AC16: {=SUM(IF(Period=$AB$2,IF(Site=$A$5,IF(Provider=$B16,J))))} -> 0 | AE16: =AC16*(AB16/AB$83) -> 0 | AF16: =AC16*(AB16/AB$891) -> 0 | AH16: {=SUM(IF(Period=$AH$2,IF(Site=$A$5,IF(Provider=$B16,I))))} -> 0 | AI16: {=SUM(IF(Period=$AH$2,IF(Site=$A$5,IF(Provider=$B16,J))))} -> 0 | AK16: =AI16*(AH16/AH$83) -> 0 | AL16: =AI16*(AH16/AH$891) -> 0 | AN16: {=SUM(IF(Period=$AN$2,IF(Site=$A$5,IF(Provider=$B16,I))))} -> 0 | AO16: {=SUM(IF(Period=$AN$2,IF(Site=$A$5,IF(Provider=$B16,J))))} -> 0 | AQ16: =AO16*(AN16/AN$83) -> 0 | AR16: =AO16*(AN16/AN$891) -> 0 | AT16: {=SUM(IF(Period=$AT$2,IF(Site=$A$5,IF(Provider=$B16,I))))} -> 14 | AU16: {=SUM(IF(Period=$AT$2,IF(Site=$A$5,IF(Provider=$B16,J))))} -> 4.2142857 | AW16: =AU16*(AT16/AT$83) -> 0.028949951 | AX16: =AU16*(AT16/AT$891) -> 0.0018590289 | AZ16: {=SUM(IF(Period=$AZ$2,IF(Site=$A$5,IF(Provider=$B16,I))))} -> 37 | BA16: {=SUM(IF(Period=$AZ$2,IF(Site=$A$5,IF(Provider=$B16,J))))} -> 3.2162162 | BC16: =BA16*(AZ16/AZ$83) -> 0.062896406 | BD16: =BA16*(AZ16/AZ$891) -> 0.0038776109 | BF16: {=SUM(IF(Period=$BF$2,IF(Site=$A$5,IF(Provider=$B16,I))))} -> 38 | BG16: {=SUM(IF(Period=$BF$2,IF(Site=$A$5,IF(Provider=$B16,J))))} -> 3.7368421 | BI16: =BG16*(BF16/BF$83) -> 0.070858283 | BJ16: =BG16*(BF16/BF$891) -> 0.0043938363 | BL16: {=SUM(IF(Period=$BL$2,IF(Site=$A$5,IF(Provider=$B16,I))))} -> 62 | BM16: {=SUM(IF(Period=$BL$2,IF(Site=$A$5,IF(Provider=$B16,J))))} -> 3.3225806 | BO16: =BM16*(BL16/BL$83) -> 0.095813953 | BP16: =BM16*(BL16/BL$891) -> 0.0064048752 | BR16: {=SUM(IF(Period=$BR$2,IF(Site=$A$5,IF(Provider=$B16,I))))} -> 119 | BS16: {=SUM(IF(Period=$BR$2,IF(Site=$A$5,IF(Provider=$B16,J))))} -> 5.8907563 | BU16: =BS16*(BR16/BR$83) -> 0.28243352 | BV16: =BS16*(BR16/BR$891) -> 0.020562612
B17: CRAEN MD, ALEXANDRA | D17: {=SUM(IF(Period=$D$2,IF(Site=$A$5,IF(Provider=$B17,I))))} -> 0 | E17: {=SUM(IF(Period=$D$2,IF(Site=$A$5,IF(Provider=$B17,J))))} -> 0 | G17: =E17*(D17/D$83) -> 0 | H17: =E17*(D17/D$891) -> 0 | J17: {=SUM(IF(Period=$J$2,IF(Site=$A$5,IF(Provider=$B17,I))))} -> 0 | K17: {=SUM(IF(Period=$J$2,IF(Site=$A$5,IF(Provider=$B17,J))))} -> 0 | M17: =K17*(J17/J$83) -> 0 | N17: =K17*(J17/J$891) -> 0 | P17: {=SUM(IF(Period=$P$2,IF(Site=$A$5,IF(Provider=$B17,I))))} -> 0 | Q17: {=SUM(IF(Period=$P$2,IF(Site=$A$5,IF(Provider=$B17,J))))} -> 0 | S17: =Q17*(P17/P$83) -> 0 | T17: =Q17*(P17/P$891) -> 0 | V17: {=SUM(IF(Period=$V$2,IF(Site=$A$5,IF(Provider=$B17,I))))} -> 0 | W17: {=SUM(IF(Period=$V$2,IF(Site=$A$5,IF(Provider=$B17,J))))} -> 0 | Y17: =W17*(V17/V$83) -> 0 | Z17: =W17*(V17/V$891) -> 0 | AB17: {=SUM(IF(Period=$AB$2,IF(Site=$A$5,IF(Provider=$B17,I))))} -> 0 | AC17: {=SUM(IF(Period=$AB$2,IF(Site=$A$5,IF(Provider=$B17,J))))} -> 0 | AE17: =AC17*(AB17/AB$83) -> 0 | AF17: =AC17*(AB17/AB$891) -> 0 | AH17: {=SUM(IF(Period=$AH$2,IF(Site=$A$5,IF(Provider=$B17,I))))} -> 0 | AI17: {=SUM(IF(Period=$AH$2,IF(Site=$A$5,IF(Provider=$B17,J))))} -> 0 | AK17: =AI17*(AH17/AH$83) -> 0 | AL17: =AI17*(AH17/AH$891) -> 0 | AN17: {=SUM(IF(Period=$AN$2,IF(Site=$A$5,IF(Provider=$B17,I))))} -> 0 | AO17: {=SUM(IF(Period=$AN$2,IF(Site=$A$5,IF(Provider=$B17,J))))} -> 0 | AQ17: =AO17*(AN17/AN$83) -> 0 | AR17: =AO17*(AN17/AN$891) -> 0 | AT17: {=SUM(IF(Period=$AT$2,IF(Site=$A$5,IF(Provider=$B17,I))))} -> 0 | AU17: {=SUM(IF(Period=$AT$2,IF(Site=$A$5,IF(Provider=$B17,J))))} -> 0 | AW17: =AU17*(AT17/AT$83) -> 0 | AX17: =AU17*(AT17/AT$891) -> 0 | AZ17: {=SUM(IF(Period=$AZ$2,IF(Site=$A$5,IF(Provider=$B17,I))))} -> 1 | BA17: {=SUM(IF(Period=$AZ$2,IF(Site=$A$5,IF(Provider=$B17,J))))} -> 3 | BC17: =BA17*(AZ17/AZ$83) -> 0.0015856237 | BD17: =BA17*(AZ17/AZ$891) -> 9.7754896e-05 | BF17: {=SUM(IF(Period=$BF$2,IF(Site=$A$5,IF(Provider=$B17,I))))} -> 0 | BG17: {=SUM(IF(Period=$BF$2,IF(Site=$A$5,IF(Provider=$B17,J))))} -> 0 | BI17: =BG17*(BF17/BF$83) -> 0 | BJ17: =BG17*(BF17/BF$891) -> 0 | BL17: {=SUM(IF(Period=$BL$2,IF(Site=$A$5,IF(Provider=$B17,I))))} -> 0 | BM17: {=SUM(IF(Period=$BL$2,IF(Site=$A$5,IF(Provider=$B17,J))))} -> 0 | BO17: =BM17*(BL17/BL$83) -> 0 | BP17: =BM17*(BL17/BL$891) -> 0 | BR17: {=SUM(IF(Period=$BR$2,IF(Site=$A$5,IF(Provider=$B17,I))))} -> 0 | BS17: {=SUM(IF(Period=$BR$2,IF(Site=$A$5,IF(Provider=$B17,J))))} -> 0 | BU17: =BS17*(BR17/BR$83) -> 0 | BV17: =BS17*(BR17/BR$891) -> 0
... B82: WILLIS MD, SCOTT | D82: {=SUM(IF(Period=$D$2,IF(Site=$A$5,IF(Provider=$B82,I))))} -> 37 | E82: {=SUM(IF(Period=$D$2,IF(Site=$A$5,IF(Provider=$B82,J))))} -> 5.8648649 | G82: =E82*(D82/D$83) -> 0.10013844 | H82: =E82*(D82/D$891) -> 0.0062849364 | J82: {=SUM(IF(Period=$J$2,IF(Site=$A$5,IF(Provider=$B82,I))))} -> 87 | K82: {=SUM(IF(Period=$J$2,IF(Site=$A$5,IF(Provider=$B82,J))))} -> 4.3333333 | M82: =K82*(J82/J$83) -> 0.1885943 | N82: =K82*(J82/J$891) -> 0.011680144 | P82: {=SUM(IF(Period=$P$2,IF(Site=$A$5,IF(Provider=$B82,I))))} -> 23 | Q82: {=SUM(IF(Period=$P$2,IF(Site=$A$5,IF(Provider=$B82,J))))} -> 4.7391304 | S82: =Q82*(P82/P$83) -> 0.050627032 | T82: =Q82*(P82/P$891) -> 0.0031410293 | V82: {=SUM(IF(Period=$V$2,IF(Site=$A$5,IF(Provider=$B82,I))))} -> 1 | W82: {=SUM(IF(Period=$V$2,IF(Site=$A$5,IF(Provider=$B82,J))))} -> 2 | Y82: =W82*(V82/V$83) -> 0.0009478673 | Z82: =W82*(V82/V$891) -> 6.048509e-05 | AB82: {=SUM(IF(Period=$AB$2,IF(Site=$A$5,IF(Provider=$B82,I))))} -> 0 | AC82: {=SUM(IF(Period=$AB$2,IF(Site=$A$5,IF(Provider=$B82,J))))} -> 0 | AE82: =AC82*(AB82/AB$83) -> 0 | AF82: =AC82*(AB82/AB$891) -> 0 | AH82: {=SUM(IF(Period=$AH$2,IF(Site=$A$5,IF(Provider=$B82,I))))} -> 22 | AI82: {=SUM(IF(Period=$AH$2,IF(Site=$A$5,IF(Provider=$B82,J))))} -> 3.5909091 | AK82: =AI82*(AH82/AH$83) -> 0.039778449 | AL82: =AI82*(AH82/AH$891) -> 0.0026901859 | AN82: {=SUM(IF(Period=$AN$2,IF(Site=$A$5,IF(Provider=$B82,I))))} -> 60 | AO82: {=SUM(IF(Period=$AN$2,IF(Site=$A$5,IF(Provider=$B82,J))))} -> 5.75 | AQ82: =AO82*(AN82/AN$83) -> 0.1762002 | AR82: =AO82*(AN82/AN$891) -> 0.011032939 | AT82: {=SUM(IF(Period=$AT$2,IF(Site=$A$5,IF(Provider=$B82,I))))} -> 38 | AU82: {=SUM(IF(Period=$AT$2,IF(Site=$A$5,IF(Provider=$B82,J))))} -> 4.5263158 | AW82: =AU82*(AT82/AT$83) -> 0.084396467 | AX82: =AU82*(AT82/AT$891) -> 0.0054195419 | AZ82: {=SUM(IF(Period=$AZ$2,IF(Site=$A$5,IF(Provider=$B82,I))))} -> 0 | BA82: {=SUM(IF(Period=$AZ$2,IF(Site=$A$5,IF(Provider=$B82,J))))} -> 0 | BC82: =BA82*(AZ82/AZ$83) -> 0 | BD82: =BA82*(AZ82/AZ$891) -> 0 | BF82: {=SUM(IF(Period=$BF$2,IF(Site=$A$5,IF(Provider=$B82,I))))} -> 0 | BG82: {=SUM(IF(Period=$BF$2,IF(Site=$A$5,IF(Provider=$B82,J))))} -> 0 | BI82: =BG82*(BF82/BF$83) -> 0 | BJ82: =BG82*(BF82/BF$891) -> 0 | BL82: {=SUM(IF(Period=$BL$2,IF(Site=$A$5,IF(Provider=$B82,I))))} -> 277 | BM82: {=SUM(IF(Period=$BL$2,IF(Site=$A$5,IF(Provider=$B82,J))))} -> 3.8844765 | BO82: =BM82*(BL82/BL$83) -> 0.50046512 | BP82: =BM82*(BL82/BL$891) -> 0.033454591 | BR82: {=SUM(IF(Period=$BR$2,IF(Site=$A$5,IF(Provider=$B82,I))))} -> 335 | BS82: {=SUM(IF(Period=$BR$2,IF(Site=$A$5,IF(Provider=$B82,J))))} -> 5.9402985 | BU82: =BS82*(BR82/BR$83) -> 0.80177276 | BV82: =BS82*(BR82/BR$891) -> 0.058373178
B83: Subtotal | D83: =SUM(D6:D82) -> 2167 | E83: =SUM(G6:G82) -> 8.2505768 | F83: =MEDIAN(E6,E7,E12,E18,E25,E27,E28,E29,E30,E31,E34,E41,E43,E44,E49,E50,E52,E53,E56,E60,E61,E62,E71,E76,E82) -> 6.5333333 | J83: =SUM(J6:J82) -> 1999 | K83: =SUM(M6:M82) -> 5.9304652 | L83: =MEDIAN(K6,K7,K9,K12,K18,K20,K25,K27,K28,K30,K31,K33,K34,K38,K40,K41,K43,K44,K48,K50,K52,K53,K56,K60,K61,K62,K75,K76,K82) -> 5 | P83: =SUM(P6:P82) -> 2153 | Q83: =SUM(S6:S82) -> 5.3896888 | R83: =MEDIAN(Q6,Q12,Q18,Q25,Q27,Q28,Q30,Q31,Q33,Q34,Q41,Q43,Q47,Q50,Q52,Q53,Q56,Q59,Q61,Q62,Q71,Q76,Q78,Q82) -> 4.7758065 | V83: =SUM(V6:V82) -> 2110 | W83: =SUM(Y6:Y82) -> 4.8118483 | X83: =MEDIAN(W7,W12,W18,W25,W27,W28,W29,W30,W31,W33,W34,W35,W43,W50,W52,W53,W56,W59,W60,W61,W62,W71,W76,W78,W82) -> 4.1428571 | AB83: =SUM(AB6:AB82) -> 2060 | AC83: =SUM(AE6:AE82) -> 4.238835 | AD83: =MEDIAN(AC7,AC12,AC18,AC21,AC25,AC27,AC28,AC30,AC31,AC34,AC42,AC43,AC47,AC49,AC50,AC52,AC53,AC56,AC59,AC61,AC65,AC71,AC75,AC76) -> 3.7760417 | AH83: =SUM(AH6:AH82) -> 1986 | AI83: =SUM(AK6:AK82) -> 5.7507849 | AJ83: =MEDIAN(AI7,AI11,AI12,AI14,AI18,AI21:AI25,AI27:AI34,AI42:AI44,AI50,AI53,AI56:AI57,AI60:AI61,AI66:AI67,AI71,AI74:AI76,AI78,AI82) -> 4.26 | AN83: =SUM(AN6:AN82) -> 1958 | AO83: =SUM(AQ6:AQ82) -> 4.9550562 | AP83: =MEDIAN(AO6:AO7,AO12,AO14,AO18:AO19,AO21,AO23,AO25,AO27:AO28,AO30:AO31,AO33:AO34,AO36,AO39,AO42:AO44,AO49:AO51,AO53,AO56,AO59,AO61,AO65:AO66,AO71,AO74:AO78,AO82) -> 4.4880952 | AT83: =SUM(AT6:AT82) -> 2038 | AU83: =SUM(AW6:AW82) -> 5.0613346 | AV83: =MEDIAN(AU6,AU8:AU10,AU12,AU14,AU16,AU18,AU21,AU23,AU25,AU27:AU29,AU31:AU35,AU43,AU45,AU47,AU49:AU51,AU53,AU56,AU58:AU59,AU61,AU69,AU71:AU73,AU76:AU77,AU82) -> 4.6358025 | AZ83: =SUM(AZ6:AZ82) -> 1892 | BA83: =SUM(BC6:BC82) -> 4.7315011 | BB83: =MEDIAN(BA6,BA9,BA11:BA12,BA14:BA18,BA23,BA28:BA29,BA33:BA34,BA43:BA44,BA46,BA50:BA51,BA53,BA55:BA56,BA59,BA61,BA63,BA65:BA66,BA68,BA71,BA77:BA78) -> 4 | BF83: =SUM(BF6:BF82) -> 2004 | BG83: =SUM(BI6:BI82) -> 3.9354395 | BH83: =MEDIAN(BG6,BG11:BG12,BG16,BG18,BG21,BG23:BG28,BG31,BG33:BG34,BG37:BG38,BG43:BG44,BG46:BG47,BG50,BG53,BG56,BG58:BG59,BG61,BG64,BG71:BG72,BG77:BG78) -> 3.8284589 | BL83: =SUM(BL6:BL82) -> 2150 | BM83: =SUM(BO6:BO82) -> 4.9781999 | BN83: =MEDIAN(BM6:BM7,BM9:BM14,BM16,BM18:BM19,BM23,BM27:BM29,BM31,BM33:BM35,BM37,BM43,BM46:BM47,BM50,BM53:BM54,BM56,BM59,BM66,BM71,BM76,BM79:BM80,BM82) -> 4.2684192 | BR83: =SUM(BR6:BR82) -> 2482 | BS83: =SUM(BU6:BU82) -> 6.3136896 | BT83: =MEDIAN(BS6:BS7,BS9,BS11:BS12,BS16,BS18:BS19,BS23,BS25,BS27,BS31,BS33:BS34,BS36:BS38,BS43:BS44,BS46,BS50,BS53,BS56,BS59,BS61,BS64,BS66,BS70:BS71,BS76:BS77,BS79,BS81:BS82) -> 5.6547619
A85: JFK-BB
B86: ALEMAN-BRIZUELA MD, VLADANA | D86: {=SUM(IF(Period=$D$2,IF(Site=$A$85,IF(Provider=$B86,I))))} -> 0 | E86: {=SUM(IF(Period=$D$2,IF(Site=$A$85,IF(Provider=$B86,J))))} -> 0 | G86: =E86*(D86/D$128) -> 0 | H86: =E86*(D86/D$891) -> 0 | J86: {=SUM(IF(Period=$J$2,IF(Site=$A$85,IF(Provider=$B86,I))))} -> 0 | K86: {=SUM(IF(Period=$J$2,IF(Site=$A$85,IF(Provider=$B86,J))))} -> 0 | M86: =K86*(J86/J$128) -> 0 | N86: =K86*(J86/J$891) -> 0 | P86: {=SUM(IF(Period=$P$2,IF(Site=$A$85,IF(Provider=$B86,I))))} -> 0 | Q86: {=SUM(IF(Period=$P$2,IF(Site=$A$85,IF(Provider=$B86,J))))} -> 0 | S86: =Q86*(P86/P$128) -> 0 | T86: =Q86*(P86/P$891) -> 0 | V86: {=SUM(IF(Period=$V$2,IF(Site=$A$85,IF(Provider=$B86,I))))} -> 57 | W86: {=SUM(IF(Period=$V$2,IF(Site=$A$85,IF(Provider=$B86,J))))} -> 8.245614 | Y86: =W86*(V86/V$128) -> 0.62583222 | Z86: =W86*(V86/V$891) -> 0.014213996 | AB86: {=SUM(IF(Period=$AB$2,IF(Site=$A$85,IF(Provider=$B86,I))))} -> 31 | AC86: {=SUM(IF(Period=$AB$2,IF(Site=$A$85,IF(Provider=$B86,J))))} -> 3.0645161 | AE86: =AC86*(AB86/AB$128) -> 0.16435986 | AF86: =AC86*(AB86/AB$891) -> 0.0028579164 | AH86: {=SUM(IF(Period=$AH$2,IF(Site=$A$85,IF(Provider=$B86,I))))} -> 0 | AI86: {=SUM(IF(Period=$AH$2,IF(Site=$A$85,IF(Provider=$B86,J))))} -> 0 | AK86: =AI86*(AH86/AH$128) -> 0 | AL86: =AI86*(AH86/AH$891) -> 0 | AN86: {=SUM(IF(Period=$AN$2,IF(Site=$A$85,IF(Provider=$B86,I))))} -> 0 | AO86: {=SUM(IF(Period=$AN$2,IF(Site=$A$85,IF(Provider=$B86,J))))} -> 0 | AQ86: =AO86*(AN86/AN$128) -> 0 | AR86: =AO86*(AN86/AN$891) -> 0 | AT86: {=SUM(IF(Period=$AT$2,IF(Site=$A$85,IF(Provider=$B86,I))))} -> 0 | AU86: {=SUM(IF(Period=$AT$2,IF(Site=$A$85,IF(Provider=$B86,J))))} -> 0 | AW86: =AU86*(AT86/AT$128) -> 0 | AX86: =AU86*(AT86/AT$891) -> 0 | AZ86: {=SUM(IF(Period=$AZ$2,IF(Site=$A$85,IF(Provider=$B86,I))))} -> 0 | BA86: {=SUM(IF(Period=$AZ$2,IF(Site=$A$85,IF(Provider=$B86,J))))} -> 0 | BC86: =BA86*(AZ86/AZ$128) -> 0 | BD86: =BA86*(AZ86/AZ$891) -> 0 | BF86: {=SUM(IF(Period=$BF$2,IF(Site=$A$85,IF(Provider=$B86,I))))} -> 0 | BG86: {=SUM(IF(Period=$BF$2,IF(Site=$A$85,IF(Provider=$B86,J))))} -> 0 | BI86: =BG86*(BF86/BF$128) -> 0 | BJ86: =BG86*(BF86/BF$891) -> 0 | BL86: {=SUM(IF(Period=$BL$2,IF(Site=$A$85,IF(Provider=$B86,I))))} -> 0 | BM86: {=SUM(IF(Period=$BL$2,IF(Site=$A$85,IF(Provider=$B86,J))))} -> 0 | BO86: =BM86*(BL86/BL$128) -> 0 | BP86: =BM86*(BL86/BL$891) -> 0 | BR86: {=SUM(IF(Period=$BR$2,IF(Site=$A$85,IF(Provider=$B86,I))))} -> 0 | BS86: {=SUM(IF(Period=$BR$2,IF(Site=$A$85,IF(Provider=$B86,J))))} -> 0 | BU86: =BS86*(BR86/BR$128) -> 0 | BV86: =BS86*(BR86/BR$891) -> 0
