Workbook
Name Period: data!$B$2:$B$1803
Name Site: data!$C$2:$C$1803

Sheet Summary by Site
B1: 2017 ED Incentives
D4: Jan | E4: Feb | F4: Mar | G4: Apr | H4: May | I4: Jun | J4: Jul | K4: Aug | L4: Sep | M4: Oct | N4: Nov | O4: Dec | Q4: Q1 | R4: Q2 | S4: Q3 | T4: Q4
B5: Baptist
A6: 12_Lead_ECG_for_Chest_Pain_Cases | C6: 12 Lead ECG for Chest Pain Cases | D6: {=SUM(IF(Period=D$4,IF(Site=$B$5,data!$G$2:$G$1784)))} -> 141 | E6: {=SUM(IF(Period=E$4,IF(Site=$B$5,data!$G$2:$G$1784)))} -> 297 | F6: {=SUM(IF(Period=F$4,IF(Site=$B$5,data!$G$2:$G$1784)))} -> 395 | G6: {=SUM(IF(Period=G$4,IF(Site=$B$5,data!$G$2:$G$1784)))} -> 391 | H6: {=SUM(IF(Period=H$4,IF(Site=$B$5,data!$G$2:$G$1784)))} -> 456 | I6: {=SUM(IF(Period=I$4,IF(Site=$B$5,data!$G$2:$G$1784)))} -> 427 | J6: {=SUM(IF(Period=J$4,IF(Site=$B$5,data!$G$2:$G$1784)))} -> 471 | K6: {=SUM(IF(Period=K$4,IF(Site=$B$5,data!$G$2:$G$1784)))} -> 393 | ... O6: {=SUM(IF(Period=O$4,IF(Site=$B$5,data!$G$2:$G$1784)))} -> 216 | Q6: =SUM(D6:F6) -> 833 | R6: =SUM(G6:I6) -> 1274 | S6: =SUM(J6:L6) -> 1231 | T6: =SUM(M6:O6) -> 825
A7: 3120F | C7: 3120F | D7: {=SUM(IF(Period=D$4,IF(Site=$B$5,data!$H$2:$H$1784)))} -> 141 | E7: {=SUM(IF(Period=E$4,IF(Site=$B$5,data!$H$2:$H$1784)))} -> 297 | F7: {=SUM(IF(Period=F$4,IF(Site=$B$5,data!$H$2:$H$1784)))} -> 395 | G7: {=SUM(IF(Period=G$4,IF(Site=$B$5,data!$H$2:$H$1784)))} -> 389 | H7: {=SUM(IF(Period=H$4,IF(Site=$B$5,data!$H$2:$H$1784)))} -> 454 | I7: {=SUM(IF(Period=I$4,IF(Site=$B$5,data!$H$2:$H$1784)))} -> 425 | J7: {=SUM(IF(Period=J$4,IF(Site=$B$5,data!$H$2:$H$1784)))} -> 468 | K7: {=SUM(IF(Period=K$4,IF(Site=$B$5,data!$H$2:$H$1784)))} -> 389 | ... O7: {=SUM(IF(Period=O$4,IF(Site=$B$5,data!$H$2:$H$1784)))} -> 215 | Q7: =SUM(D7:F7) -> 833 | R7: =SUM(G7:I7) -> 1268 | S7: =SUM(J7:L7) -> 1223 | T7: =SUM(M7:O7) -> 822
A8: 3120F_1P | C8: 3120F 1P | D8: {=SUM(IF(Period=D$4,IF(Site=$B$5,data!$I$2:$I$1784)))} -> 0 | E8: {=SUM(IF(Period=E$4,IF(Site=$B$5,data!$I$2:$I$1784)))} -> 0 | F8: {=SUM(IF(Period=F$4,IF(Site=$B$5,data!$I$2:$I$1784)))} -> 0 | G8: {=SUM(IF(Period=G$4,IF(Site=$B$5,data!$I$2:$I$1784)))} -> 0 | H8: {=SUM(IF(Period=H$4,IF(Site=$B$5,data!$I$2:$I$1784)))} -> 1 | I8: {=SUM(IF(Period=I$4,IF(Site=$B$5,data!$I$2:$I$1784)))} -> 0 | J8: {=SUM(IF(Period=J$4,IF(Site=$B$5,data!$I$2:$I$1784)))} -> 0 | K8: {=SUM(IF(Period=K$4,IF(Site=$B$5,data!$I$2:$I$1784)))} -> 2 | ... O8: {=SUM(IF(Period=O$4,IF(Site=$B$5,data!$I$2:$I$1784)))} -> 0 | Q8: =SUM(D8:F8) -> 0 | R8: =SUM(G8:I8) -> 1 | S8: =SUM(J8:L8) -> 2 | T8: =SUM(M8:O8) -> 0
A9: 3120F_2P | C9: 3120F 2P | D9: {=SUM(IF(Period=D$4,IF(Site=$B$5,data!$J$2:$J$1784)))} -> 0 | E9: {=SUM(IF(Period=E$4,IF(Site=$B$5,data!$J$2:$J$1784)))} -> 0 | F9: {=SUM(IF(Period=F$4,IF(Site=$B$5,data!$J$2:$J$1784)))} -> 0 | G9: {=SUM(IF(Period=G$4,IF(Site=$B$5,data!$J$2:$J$1784)))} -> 2 | H9: {=SUM(IF(Period=H$4,IF(Site=$B$5,data!$J$2:$J$1784)))} -> 0 | I9: {=SUM(IF(Period=I$4,IF(Site=$B$5,data!$J$2:$J$1784)))} -> 1 | J9: {=SUM(IF(Period=J$4,IF(Site=$B$5,data!$J$2:$J$1784)))} -> 0 | K9: {=SUM(IF(Period=K$4,IF(Site=$B$5,data!$J$2:$J$1784)))} -> 1 | ... O9: {=SUM(IF(Period=O$4,IF(Site=$B$5,data!$J$2:$J$1784)))} -> 0 | Q9: =SUM(D9:F9) -> 0 | R9: =SUM(G9:I9) -> 3 | S9: =SUM(J9:L9) -> 1 | T9: =SUM(M9:O9) -> 0
A10: 3120F_8P | C10: 3120F 8P | D10: {=SUM(IF(Period=D$4,IF(Site=$B$5,data!$K$2:$K$1784)))} -> 0 | E10: {=SUM(IF(Period=E$4,IF(Site=$B$5,data!$K$2:$K$1784)))} -> 0 | F10: {=SUM(IF(Period=F$4,IF(Site=$B$5,data!$K$2:$K$1784)))} -> 0 | G10: {=SUM(IF(Period=G$4,IF(Site=$B$5,data!$K$2:$K$1784)))} -> 0 | H10: {=SUM(IF(Period=H$4,IF(Site=$B$5,data!$K$2:$K$1784)))} -> 1 | I10: {=SUM(IF(Period=I$4,IF(Site=$B$5,data!$K$2:$K$1784)))} -> 1 | J10: {=SUM(IF(Period=J$4,IF(Site=$B$5,data!$K$2:$K$1784)))} -> 3 | K10: {=SUM(IF(Period=K$4,IF(Site=$B$5,data!$K$2:$K$1784)))} -> 1 | ... O10: {=SUM(IF(Period=O$4,IF(Site=$B$5,data!$K$2:$K$1784)))} -> 1 | Q10: =SUM(D10:F10) -> 0 | R10: =SUM(G10:I10) -> 2 | S10: =SUM(J10:L10) -> 5 | T10: =SUM(M10:O10) -> 3
A11: 12_Lead_ECG_for_Chest_Pain_Performance_Score | C11: 12 Lead ECG for Chest Pain Performance Score | D11: =IF(D6=0,0,SUM(D7:D9)/D6) -> 1 | E11: =IF(E6=0,0,SUM(E7:E9)/E6) -> 1 | F11: =IF(F6=0,0,SUM(F7:F9)/F6) -> 1 | G11: =IF(G6=0,0,SUM(G7:G9)/G6) -> 1 | H11: =IF(H6=0,0,SUM(H7:H9)/H6) -> 0.99780702 | I11: =IF(I6=0,0,SUM(I7:I9)/I6) -> 0.99765808 | J11: =IF(J6=0,0,SUM(J7:J9)/J6) -> 0.99363057 | K11: =IF(K6=0,0,SUM(K7:K9)/K6) -> 0.99745547 | ... O11: =IF(O6=0,0,SUM(O7:O9)/O6) -> 0.99537037 | Q11: =IF(Q6=0,0,SUM(Q7:Q9)/Q6) -> 1 | R11: =IF(R6=0,0,SUM(R7:R9)/R6) -> 0.99843014 | S11: =IF(S6=0,0,SUM(S7:S9)/S6) -> 0.99593826 | T11: =IF(T6=0,0,SUM(T7:T9)/T6) -> 0.99636364
A12: BP_Screening_Cases | C12: BP Screening Cases | D12: {=SUM(IF(Period=D$4,IF(Site=$B$5,data!$M$2:$M$1784)))} -> 2830 | E12: {=SUM(IF(Period=E$4,IF(Site=$B$5,data!$M$2:$M$1784)))} -> 5233 | F12: {=SUM(IF(Period=F$4,IF(Site=$B$5,data!$M$2:$M$1784)))} -> 6524 | G12: {=SUM(IF(Period=G$4,IF(Site=$B$5,data!$M$2:$M$1784)))} -> 6211 | H12: {=SUM(IF(Period=H$4,IF(Site=$B$5,data!$M$2:$M$1784)))} -> 6625 | I12: {=SUM(IF(Period=I$4,IF(Site=$B$5,data!$M$2:$M$1784)))} -> 6422 | J12: {=SUM(IF(Period=J$4,IF(Site=$B$5,data!$M$2:$M$1784)))} -> 6804 | K12: {=SUM(IF(Period=K$4,IF(Site=$B$5,data!$M$2:$M$1784)))} -> 6328 | ... O12: {=SUM(IF(Period=O$4,IF(Site=$B$5,data!$M$2:$M$1784)))} -> 3493 | Q12: =SUM(D12:F12) -> 14587 | R12: =SUM(G12:I12) -> 19258 | S12: =SUM(J12:L12) -> 19474 | T12: =SUM(M12:O12) -> 12391
A13: G8783_Normal_BP_no_followup_needed | C13: G8783 Normal BP no followup needed | D13: {=SUM(IF(Period=D$4,IF(Site=$B$5,data!$N$2:$N$1784)))} -> 781 | E13: {=SUM(IF(Period=E$4,IF(Site=$B$5,data!$N$2:$N$1784)))} -> 1041 | F13: {=SUM(IF(Period=F$4,IF(Site=$B$5,data!$N$2:$N$1784)))} -> 1186 | G13: {=SUM(IF(Period=G$4,IF(Site=$B$5,data!$N$2:$N$1784)))} -> 1212 | H13: {=SUM(IF(Period=H$4,IF(Site=$B$5,data!$N$2:$N$1784)))} -> 1079 | I13: {=SUM(IF(Period=I$4,IF(Site=$B$5,data!$N$2:$N$1784)))} -> 977 | J13: {=SUM(IF(Period=J$4,IF(Site=$B$5,data!$N$2:$N$1784)))} -> 973 | K13: {=SUM(IF(Period=K$4,IF(Site=$B$5,data!$N$2:$N$1784)))} -> 944 | ... O13: {=SUM(IF(Period=O$4,IF(Site=$B$5,data!$N$2:$N$1784)))} -> 622 | Q13: =SUM(D13:F13) -> 3008 | R13: =SUM(G13:I13) -> 3268 | S13: =SUM(J13:L13) -> 2972 | T13: =SUM(M13:O13) -> 2262
A14: G8784_Not_eligible--active_HTN_pt refuses_emergent_case | C14: G8784 Not eligible--active HTN pt refuses emergent case | D14: {=SUM(IF(Period=D$4,IF(Site=$B$5,data!$O$2:$O$1784)))} -> 140 | E14: {=SUM(IF(Period=E$4,IF(Site=$B$5,data!$O$2:$O$1784)))} -> 0 | F14: {=SUM(IF(Period=F$4,IF(Site=$B$5,data!$O$2:$O$1784)))} -> 0 | G14: {=SUM(IF(Period=G$4,IF(Site=$B$5,data!$O$2:$O$1784)))} -> 0 | H14: {=SUM(IF(Period=H$4,IF(Site=$B$5,data!$O$2:$O$1784)))} -> 0 | I14: {=SUM(IF(Period=I$4,IF(Site=$B$5,data!$O$2:$O$1784)))} -> 0 | J14: {=SUM(IF(Period=J$4,IF(Site=$B$5,data!$O$2:$O$1784)))} -> 0 | K14: {=SUM(IF(Period=K$4,IF(Site=$B$5,data!$O$2:$O$1784)))} -> 0 | ... O14: {=SUM(IF(Period=O$4,IF(Site=$B$5,data!$O$2:$O$1784)))} -> 0 | Q14: =SUM(D14:F14) -> 140 | R14: =SUM(G14:I14) -> 0 | S14: =SUM(J14:L14) -> 0 | T14: =SUM(M14:O14) -> 0
A15: G8785_BP_not_documented | C15: G8785 BP not documented | D15: {=SUM(IF(Period=D$4,IF(Site=$B$5,data!$P$2:$P$1784)))} -> 1 | E15: {=SUM(IF(Period=E$4,IF(Site=$B$5,data!$P$2:$P$1784)))} -> 0 | F15: {=SUM(IF(Period=F$4,IF(Site=$B$5,data!$P$2:$P$1784)))} -> 3 | G15: {=SUM(IF(Period=G$4,IF(Site=$B$5,data!$P$2:$P$1784)))} -> 6 | H15: {=SUM(IF(Period=H$4,IF(Site=$B$5,data!$P$2:$P$1784)))} -> 9 | I15: {=SUM(IF(Period=I$4,IF(Site=$B$5,data!$P$2:$P$1784)))} -> 1 | J15: {=SUM(IF(Period=J$4,IF(Site=$B$5,data!$P$2:$P$1784)))} -> 5 | K15: {=SUM(IF(Period=K$4,IF(Site=$B$5,data!$P$2:$P$1784)))} -> 0 | ... O15: {=SUM(IF(Period=O$4,IF(Site=$B$5,data!$P$2:$P$1784)))} -> 0 | Q15: =SUM(D15:F15) -> 4 | R15: =SUM(G15:I15) -> 16 | S15: =SUM(J15:L15) -> 8 | T15: =SUM(M15:O15) -> 5
A16: G8950_elevated_BP_with_followup | C16: G8950 elevated BP with followup | D16: {=SUM(IF(Period=D$4,IF(Site=$B$5,data!$Q$2:$Q$1784)))} -> 1900 | E16: {=SUM(IF(Period=E$4,IF(Site=$B$5,data!$Q$2:$Q$1784)))} -> 2383 | F16: {=SUM(IF(Period=F$4,IF(Site=$B$5,data!$Q$2:$Q$1784)))} -> 2641 | G16: {=SUM(IF(Period=G$4,IF(Site=$B$5,data!$Q$2:$Q$1784)))} -> 2499 | H16: {=SUM(IF(Period=H$4,IF(Site=$B$5,data!$Q$2:$Q$1784)))} -> 2894 | I16: {=SUM(IF(Period=I$4,IF(Site=$B$5,data!$Q$2:$Q$1784)))} -> 2889 | J16: {=SUM(IF(Period=J$4,IF(Site=$B$5,data!$Q$2:$Q$1784)))} -> 3075 | K16: {=SUM(IF(Period=K$4,IF(Site=$B$5,data!$Q$2:$Q$1784)))} -> 2794 | ... O16: {=SUM(IF(Period=O$4,IF(Site=$B$5,data!$Q$2:$Q$1784)))} -> 1424 | Q16: =SUM(D16:F16) -> 6924 | R16: =SUM(G16:I16) -> 8282 | S16: =SUM(J16:L16) -> 8538 | T16: =SUM(M16:O16) -> 5139
A17: G8952_elevated_BP_no_followup | C17: G8952 elevated BP no followup | D17: {=SUM(IF(Period=D$4,IF(Site=$B$5,data!$R$2:$R$1784)))} -> 9 | E17: {=SUM(IF(Period=E$4,IF(Site=$B$5,data!$R$2:$R$1784)))} -> 4 | F17: {=SUM(IF(Period=F$4,IF(Site=$B$5,data!$R$2:$R$1784)))} -> 19 | G17: {=SUM(IF(Period=G$4,IF(Site=$B$5,data!$R$2:$R$1784)))} -> 14 | H17: {=SUM(IF(Period=H$4,IF(Site=$B$5,data!$R$2:$R$1784)))} -> 10 | I17: {=SUM(IF(Period=I$4,IF(Site=$B$5,data!$R$2:$R$1784)))} -> 8 | J17: {=SUM(IF(Period=J$4,IF(Site=$B$5,data!$R$2:$R$1784)))} -> 2 | K17: {=SUM(IF(Period=K$4,IF(Site=$B$5,data!$R$2:$R$1784)))} -> 6 | ... O17: {=SUM(IF(Period=O$4,IF(Site=$B$5,data!$R$2:$R$1784)))} -> 0 | Q17: =SUM(D17:F17) -> 32 | R17: =SUM(G17:I17) -> 32 | S17: =SUM(J17:L17) -> 11 | T17: =SUM(M17:O17) -> 8
A18: G9744_Not_eligible--active_HTN_Pt refuses_emergent_case | C18: G9744 Not eligible--active HTN Pt refuses emergent case | D18: {=SUM(IF(Period=D$4,IF(Site=$B$5,data!$S$2:$S$1784)))} -> 0 | E18: {=SUM(IF(Period=E$4,IF(Site=$B$5,data!$S$2:$S$1784)))} -> 1792 | F18: {=SUM(IF(Period=F$4,IF(Site=$B$5,data!$S$2:$S$1784)))} -> 2656 | G18: {=SUM(IF(Period=G$4,IF(Site=$B$5,data!$S$2:$S$1784)))} -> 2457 | H18: {=SUM(IF(Period=H$4,IF(Site=$B$5,data!$S$2:$S$1784)))} -> 2604 | I18: {=SUM(IF(Period=I$4,IF(Site=$B$5,data!$S$2:$S$1784)))} -> 2534 | J18: {=SUM(IF(Period=J$4,IF(Site=$B$5,data!$S$2:$S$1784)))} -> 2734 | K18: {=SUM(IF(Period=K$4,IF(Site=$B$5,data!$S$2:$S$1784)))} -> 2572 | ... O18: {=SUM(IF(Period=O$4,IF(Site=$B$5,data!$S$2:$S$1784)))} -> 1432 | Q18: =SUM(D18:F18) -> 4448 | R18: =SUM(G18:I18) -> 7595 | S18: =SUM(J18:L18) -> 7907 | T18: =SUM(M18:O18) -> 4942
A19: G9745_Reason_given_for_no_screening_or_recommending_followup | C19: G9745 Reason given for no screening or recommending followup | D19: {=SUM(IF(Period=D$4,IF(Site=$B$5,data!$T$2:$T$1784)))} -> 0 | E19: {=SUM(IF(Period=E$4,IF(Site=$B$5,data!$T$2:$T$1784)))} -> 13 | F19: {=SUM(IF(Period=F$4,IF(Site=$B$5,data!$T$2:$T$1784)))} -> 19 | G19: {=SUM(IF(Period=G$4,IF(Site=$B$5,data!$T$2:$T$1784)))} -> 23 | H19: {=SUM(IF(Period=H$4,IF(Site=$B$5,data!$T$2:$T$1784)))} -> 29 | I19: {=SUM(IF(Period=I$4,IF(Site=$B$5,data!$T$2:$T$1784)))} -> 13 | J19: {=SUM(IF(Period=J$4,IF(Site=$B$5,data!$T$2:$T$1784)))} -> 15 | K19: {=SUM(IF(Period=K$4,IF(Site=$B$5,data!$T$2:$T$1784)))} -> 12 | ... O19: {=SUM(IF(Period=O$4,IF(Site=$B$5,data!$T$2:$T$1784)))} -> 15 | Q19: =SUM(D19:F19) -> 32 | R19: =SUM(G19:I19) -> 65 | S19: =SUM(J19:L19) -> 38 | T19: =SUM(M19:O19) -> 35
A20: BP_Screening_Performance_Score | C20: BP Screening Performance Score | D20: =IF(D12=0,0,(D13+D14+D16)/D12) -> 0.99681979 | E20: =IF(E12=0,0,(E13+E14+E16+E18+E19)/E12) -> 0.99923562 | F20: =IF(F12=0,0,(F13+F14+F16+F18+F19)/F12) -> 0.99662784 | G20: =IF(G12=0,0,(G13+G14+G16+G18+G19)/G12) -> 0.99677991 | H20: =IF(H12=0,0,(H13+H14+H16+H18+H19)/H12) -> 0.99713208 | I20: =IF(I12=0,0,(I13+I14+I16+I18+I19)/I12) -> 0.99859857 | J20: =IF(J12=0,0,(J13+J14+J16+J18+J19)/J12) -> 0.99897119 | K20: =IF(K12=0,0,(K13+K14+K16+K18+K19)/K12) -> 0.99905183 | L20: =IF(L12=0,0,(L13+L14+L16+L18+L19)/L12) -> 0.99905393 | ... O20: =IF(O12=0,0,(O13+O14+O16+O18+O19)/O12) -> 1 | Q20: =IF(Q12=0,0,(Q13+Q14+Q16+Q18+Q19)/Q12) -> 0.9976006 | R20: =IF(R12=0,0,(R13+R14+R16+R18+R19)/R12) -> 0.99750753 | S20: =IF(S12=0,0,(S13+S14+S16+S18+S19)/S12) -> 0.99902434 | T20: =IF(T12=0,0,(T13+T14+T16+T18+T19)/T12) -> 0.99895085
A21: Overall_Score | C21: Overall Score | D21: =IF(AND(D6=0,D12=0),0,(SUM(D7:D9)+D13+D14+D16+D18+D19)/(D6+D12)) -> 0.99697072 | E21: =IF(AND(E6=0,E12=0),0,(SUM(E7:E9)+E13+E14+E16+E18+E19)/(E6+E12)) -> 0.99927667 | F21: =IF(AND(F6=0,F12=0),0,(SUM(F7:F9)+F13+F14+F16+F18+F19)/(F6+F12)) -> 0.99682035 | G21: =IF(AND(G6=0,G12=0),0,(SUM(G7:G9)+G13+G14+G16+G18+G19)/(G6+G12)) -> 0.99697061 | H21: =IF(AND(H6=0,H12=0),0,(SUM(H7:H9)+H13+H14+H16+H18+H19)/(H6+H12)) -> 0.99717554 | I21: =IF(AND(I6=0,I12=0),0,(SUM(I7:I9)+I13+I14+I16+I18+I19)/(I6+I12)) -> 0.99853993 | J21: =IF(AND(J6=0,J12=0),0,(SUM(J7:J9)+J13+J14+J16+J18+J19)/(J6+J12)) -> 0.99862543 | K21: =IF(AND(K6=0,K12=0),0,(SUM(K7:K9)+K13+K14+K16+K18+K19)/(K6+K12)) -> 0.99895849 | ... O21: =IF(AND(O6=0,O12=0),0,(SUM(O7:O9)+O13+O14+O16+O18+O19)/(O6+O12)) -> 0.99973039 | Q21: =IF(AND(Q6=0,Q12=0),0,(SUM(Q7:Q9)+Q13+Q14+Q16+Q18+Q19)/(Q6+Q12)) -> 0.99773022 | R21: =IF(AND(R6=0,R12=0),0,(SUM(R7:R9)+R13+R14+R16+R18+R19)/(R6+R12)) -> 0.99756478 | S21: =IF(AND(S6=0,S12=0),0,(SUM(S7:S9)+S13+S14+S16+S18+S19)/(S6+S12)) -> 0.99884086 | T21: =IF(AND(T6=0,T12=0),0,(SUM(T7:T9)+T13+T14+T16+T18+T19)/(T6+T12)) -> 0.99878935
B23: JFK-Main
A24: 12_Lead_ECG_for_Chest_Pain_Cases | C24: 12 Lead ECG for Chest Pain Cases | D24: {=SUM(IF(Period=D$4,IF(Site=$B$23,data!$G$2:$G$1784)))} -> 399 | E24: {=SUM(IF(Period=E$4,IF(Site=$B$23,data!$G$2:$G$1784)))} -> 447 | F24: {=SUM(IF(Period=F$4,IF(Site=$B$23,data!$G$2:$G$1784)))} -> 450 | G24: {=SUM(IF(Period=G$4,IF(Site=$B$23,data!$G$2:$G$1784)))} -> 425 | H24: {=SUM(IF(Period=H$4,IF(Site=$B$23,data!$G$2:$G$1784)))} -> 453 | I24: {=SUM(IF(Period=I$4,IF(Site=$B$23,data!$G$2:$G$1784)))} -> 393 | J24: {=SUM(IF(Period=J$4,IF(Site=$B$23,data!$G$2:$G$1784)))} -> 446 | K24: {=SUM(IF(Period=K$4,IF(Site=$B$23,data!$G$2:$G$1784)))} -> 429 | ... O24: {=SUM(IF(Period=O$4,IF(Site=$B$23,data!$G$2:$G$1784)))} -> 225 | Q24: =SUM(D24:F24) -> 1296 | R24: =SUM(G24:I24) -> 1271 | S24: =SUM(J24:L24) -> 1254 | T24: =SUM(M24:O24) -> 1022
A25: 3120F | C25: 3120F | D25: {=SUM(IF(Period=D$4,IF(Site=$B$23,data!$H$2:$H$1784)))} -> 398 | E25: {=SUM(IF(Period=E$4,IF(Site=$B$23,data!$H$2:$H$1784)))} -> 435 | F25: {=SUM(IF(Period=F$4,IF(Site=$B$23,data!$H$2:$H$1784)))} -> 448 | G25: {=SUM(IF(Period=G$4,IF(Site=$B$23,data!$H$2:$H$1784)))} -> 423 | H25: {=SUM(IF(Period=H$4,IF(Site=$B$23,data!$H$2:$H$1784)))} -> 447 | I25: {=SUM(IF(Period=I$4,IF(Site=$B$23,data!$H$2:$H$1784)))} -> 388 | J25: {=SUM(IF(Period=J$4,IF(Site=$B$23,data!$H$2:$H$1784)))} -> 445 | K25: {=SUM(IF(Period=K$4,IF(Site=$B$23,data!$H$2:$H$1784)))} -> 428 | ... O25: {=SUM(IF(Period=O$4,IF(Site=$B$23,data!$H$2:$H$1784)))} -> 225 | Q25: =SUM(D25:F25) -> 1281 | R25: =SUM(G25:I25) -> 1258 | S25: =SUM(J25:L25) -> 1250 | T25: =SUM(M25:O25) -> 1017
A26: 3120F_1P | C26: 3120F 1P | D26: {=SUM(IF(Period=D$4,IF(Site=$B$23,data!$I$2:$I$1784)))} -> 0 | E26: {=SUM(IF(Period=E$4,IF(Site=$B$23,data!$I$2:$I$1784)))} -> 9 | F26: {=SUM(IF(Period=F$4,IF(Site=$B$23,data!$I$2:$I$1784)))} -> 0 | G26: {=SUM(IF(Period=G$4,IF(Site=$B$23,data!$I$2:$I$1784)))} -> 0 | H26: {=SUM(IF(Period=H$4,IF(Site=$B$23,data!$I$2:$I$1784)))} -> 0 | I26: {=SUM(IF(Period=I$4,IF(Site=$B$23,data!$I$2:$I$1784)))} -> 0 | J26: {=SUM(IF(Period=J$4,IF(Site=$B$23,data!$I$2:$I$1784)))} -> 0 | K26: {=SUM(IF(Period=K$4,IF(Site=$B$23,data!$I$2:$I$1784)))} -> 0 | ... O26: {=SUM(IF(Period=O$4,IF(Site=$B$23,data!$I$2:$I$1784)))} -> 0 | Q26: =SUM(D26:F26) -> 9 | R26: =SUM(G26:I26) -> 0 | S26: =SUM(J26:L26) -> 0 | T26: =SUM(M26:O26) -> 1
A27: 3120F_2P | C27: 3120F 2P | D27: {=SUM(IF(Period=D$4,IF(Site=$B$23,data!$J$2:$J$1784)))} -> 0 | E27: {=SUM(IF(Period=E$4,IF(Site=$B$23,data!$J$2:$J$1784)))} -> 0 | F27: {=SUM(IF(Period=F$4,IF(Site=$B$23,data!$J$2:$J$1784)))} -> 0 | G27: {=SUM(IF(Period=G$4,IF(Site=$B$23,data!$J$2:$J$1784)))} -> 0 | H27: {=SUM(IF(Period=H$4,IF(Site=$B$23,data!$J$2:$J$1784)))} -> 0 | I27: {=SUM(IF(Period=I$4,IF(Site=$B$23,data!$J$2:$J$1784)))} -> 0 | J27: {=SUM(IF(Period=J$4,IF(Site=$B$23,data!$J$2:$J$1784)))} -> 0 | K27: {=SUM(IF(Period=K$4,IF(Site=$B$23,data!$J$2:$J$1784)))} -> 0 | ... O27: {=SUM(IF(Period=O$4,IF(Site=$B$23,data!$J$2:$J$1784)))} -> 0 | Q27: =SUM(D27:F27) -> 0 | R27: =SUM(G27:I27) -> 0 | S27: =SUM(J27:L27) -> 0 | T27: =SUM(M27:O27) -> 0
A28: 3120F_8P | C28: 3120F 8P | D28: {=SUM(IF(Period=D$4,IF(Site=$B$23,data!$K$2:$K$1784)))} -> 1 | E28: {=SUM(IF(Period=E$4,IF(Site=$B$23,data!$K$2:$K$1784)))} -> 3 | F28: {=SUM(IF(Period=F$4,IF(Site=$B$23,data!$K$2:$K$1784)))} -> 2 | G28: {=SUM(IF(Period=G$4,IF(Site=$B$23,data!$K$2:$K$1784)))} -> 2 | H28: {=SUM(IF(Period=H$4,IF(Site=$B$23,data!$K$2:$K$1784)))} -> 6 | I28: {=SUM(IF(Period=I$4,IF(Site=$B$23,data!$K$2:$K$1784)))} -> 5 | J28: {=SUM(IF(Period=J$4,IF(Site=$B$23,data!$K$2:$K$1784)))} -> 1 | K28: {=SUM(IF(Period=K$4,IF(Site=$B$23,data!$K$2:$K$1784)))} -> 1 | ... O28: {=SUM(IF(Period=O$4,IF(Site=$B$23,data!$K$2:$K$1784)))} -> 0 | Q28: =SUM(D28:F28) -> 6 | R28: =SUM(G28:I28) -> 13 | S28: =SUM(J28:L28) -> 4 | T28: =SUM(M28:O28) -> 4
A29: 12_Lead_ECG_for_Chest_Pain_Performance_Score | C29: 12 Lead ECG for Chest Pain Performance Score | D29: =IF(D24=0,0,SUM(D25:D27)/D24) -> 0.99749373 | E29: =IF(E24=0,0,SUM(E25:E27)/E24) -> 0.99328859 | F29: =IF(F24=0,0,SUM(F25:F27)/F24) -> 0.99555556 | G29: =IF(G24=0,0,SUM(G25:G27)/G24) -> 0.99529412 | H29: =IF(H24=0,0,SUM(H25:H27)/H24) -> 0.98675497 | I29: =IF(I24=0,0,SUM(I25:I27)/I24) -> 0.98727735 | J29: =IF(J24=0,0,SUM(J25:J27)/J24) -> 0.99775785 | K29: =IF(K24=0,0,SUM(K25:K27)/K24) -> 0.997669 | ... O29: =IF(O24=0,0,SUM(O25:O27)/O24) -> 1 | Q29: =IF(Q24=0,0,SUM(Q25:Q27)/Q24) -> 0.99537037 | R29: =IF(R24=0,0,SUM(R25:R27)/R24) -> 0.98977183 | S29: =IF(S24=0,0,SUM(S25:S27)/S24) -> 0.99681021 | T29: =IF(T24=0,0,SUM(T25:T27)/T24) -> 0.99608611
A30: BP_Screening_Cases | C30: BP Screening Cases | D30: {=SUM(IF(Period=D$4,IF(Site=$B$23,data!$M$2:$M$1784)))} -> 4237 | E30: {=SUM(IF(Period=E$4,IF(Site=$B$23,data!$M$2:$M$1784)))} -> 7045 | F30: {=SUM(IF(Period=F$4,IF(Site=$B$23,data!$M$2:$M$1784)))} -> 6552 | G30: {=SUM(IF(Period=G$4,IF(Site=$B$23,data!$M$2:$M$1784)))} -> 6075 | H30: {=SUM(IF(Period=H$4,IF(Site=$B$23,data!$M$2:$M$1784)))} -> 6251 | I30: {=SUM(IF(Period=I$4,IF(Site=$B$23,data!$M$2:$M$1784)))} -> 5279 | J30: {=SUM(IF(Period=J$4,IF(Site=$B$23,data!$M$2:$M$1784)))} -> 6029 | K30: {=SUM(IF(Period=K$4,IF(Site=$B$23,data!$M$2:$M$1784)))} -> 5877 | ... O30: {=SUM(IF(Period=O$4,IF(Site=$B$23,data!$M$2:$M$1784)))} -> 3410 | Q30: =SUM(D30:F30) -> 17834 | R30: =SUM(G30:I30) -> 17605 | S30: =SUM(J30:L30) -> 17430 | T30: =SUM(M30:O30) -> 14788
A31: G8783_Normal_BP_no_followup_needed | C31: G8783 Normal BP no followup needed | D31: {=SUM(IF(Period=D$4,IF(Site=$B$23,data!$N$2:$N$1784)))} -> 1365 | E31: {=SUM(IF(Period=E$4,IF(Site=$B$23,data!$N$2:$N$1784)))} -> 1444 | F31: {=SUM(IF(Period=F$4,IF(Site=$B$23,data!$N$2:$N$1784)))} -> 1467 | G31: {=SUM(IF(Period=G$4,IF(Site=$B$23,data!$N$2:$N$1784)))} -> 1486 | H31: {=SUM(IF(Period=H$4,IF(Site=$B$23,data!$N$2:$N$1784)))} -> 1405 | I31: {=SUM(IF(Period=I$4,IF(Site=$B$23,data!$N$2:$N$1784)))} -> 981 | J31: {=SUM(IF(Period=J$4,IF(Site=$B$23,data!$N$2:$N$1784)))} -> 1183 | K31: {=SUM(IF(Period=K$4,IF(Site=$B$23,data!$N$2:$N$1784)))} -> 1074 | ... O31: {=SUM(IF(Period=O$4,IF(Site=$B$23,data!$N$2:$N$1784)))} -> 591 | Q31: =SUM(D31:F31) -> 4276 | R31: =SUM(G31:I31) -> 3872 | S31: =SUM(J31:L31) -> 3292 | T31: =SUM(M31:O31) -> 2596
A32: G8784_Not_eligible--active_HTN_pt refuses_emergent_case | C32: G8784 Not eligible--active HTN pt refuses emergent case | D32: {=SUM(IF(Period=D$4,IF(Site=$B$23,data!$O$2:$O$1784)))} -> 353 | E32: {=SUM(IF(Period=E$4,IF(Site=$B$23,data!$O$2:$O$1784)))} -> 0 | F32: {=SUM(IF(Period=F$4,IF(Site=$B$23,data!$O$2:$O$1784)))} -> 0 | G32: {=SUM(IF(Period=G$4,IF(Site=$B$23,data!$O$2:$O$1784)))} -> 0 | H32: {=SUM(IF(Period=H$4,IF(Site=$B$23,data!$O$2:$O$1784)))} -> 0 | I32: {=SUM(IF(Period=I$4,IF(Site=$B$23,data!$O$2:$O$1784)))} -> 1 | J32: {=SUM(IF(Period=J$4,IF(Site=$B$23,data!$O$2:$O$1784)))} -> 0 | K32: {=SUM(IF(Period=K$4,IF(Site=$B$23,data!$O$2:$O$1784)))} -> 0 | ... O32: {=SUM(IF(Period=O$4,IF(Site=$B$23,data!$O$2:$O$1784)))} -> 0 | Q32: =SUM(D32:F32) -> 353 | R32: =SUM(G32:I32) -> 1 | S32: =SUM(J32:L32) -> 0 | T32: =SUM(M32:O32) -> 0
A33: G8785_BP_not_documented | C33: G8785 BP not documented | D33: {=SUM(IF(Period=D$4,IF(Site=$B$23,data!$P$2:$P$1784)))} -> 3 | E33: {=SUM(IF(Period=E$4,IF(Site=$B$23,data!$P$2:$P$1784)))} -> 8 | F33: {=SUM(IF(Period=F$4,IF(Site=$B$23,data!$P$2:$P$1784)))} -> 8 | G33: {=SUM(IF(Period=G$4,IF(Site=$B$23,data!$P$2:$P$1784)))} -> 4 | H33: {=SUM(IF(Period=H$4,IF(Site=$B$23,data!$P$2:$P$1784)))} -> 22 | I33: {=SUM(IF(Period=I$4,IF(Site=$B$23,data!$P$2:$P$1784)))} -> 2337 | J33: {=SUM(IF(Period=J$4,IF(Site=$B$23,data!$P$2:$P$1784)))} -> 7 | K33: {=SUM(IF(Period=K$4,IF(Site=$B$23,data!$P$2:$P$1784)))} -> 5 | ... O33: {=SUM(IF(Period=O$4,IF(Site=$B$23,data!$P$2:$P$1784)))} -> 4 | Q33: =SUM(D33:F33) -> 19 | R33: =SUM(G33:I33) -> 2363 | S33: =SUM(J33:L33) -> 17 | T33: =SUM(M33:O33) -> 26
A34: G8950_elevated_BP_with_followup | C34: G8950 elevated BP with followup | D34: {=SUM(IF(Period=D$4,IF(Site=$B$23,data!$Q$2:$Q$1784)))} -> 2459 | E34: {=SUM(IF(Period=E$4,IF(Site=$B$23,data!$Q$2:$Q$1784)))} -> 2783 | F34: {=SUM(IF(Period=F$4,IF(Site=$B$23,data!$Q$2:$Q$1784)))} -> 2442 | G34: {=SUM(IF(Period=G$4,IF(Site=$B$23,data!$Q$2:$Q$1784)))} -> 2308 | H34: {=SUM(IF(Period=H$4,IF(Site=$B$23,data!$Q$2:$Q$1784)))} -> 2742 | I34: {=SUM(IF(Period=I$4,IF(Site=$B$23,data!$Q$2:$Q$1784)))} -> 67 | J34: {=SUM(IF(Period=J$4,IF(Site=$B$23,data!$Q$2:$Q$1784)))} -> 2733 | K34: {=SUM(IF(Period=K$4,IF(Site=$B$23,data!$Q$2:$Q$1784)))} -> 2745 | ... O34: {=SUM(IF(Period=O$4,IF(Site=$B$23,data!$Q$2:$Q$1784)))} -> 1580 | Q34: =SUM(D34:F34) -> 7684 | R34: =SUM(G34:I34) -> 5117 | S34: =SUM(J34:L34) -> 7932 | T34: =SUM(M34:O34) -> 6625
A35: G8952_elevated_BP_no_followup | C35: G8952 elevated BP no followup | D35: {=SUM(IF(Period=D$4,IF(Site=$B$23,data!$R$2:$R$1784)))} -> 57 | E35: {=SUM(IF(Period=E$4,IF(Site=$B$23,data!$R$2:$R$1784)))} -> 47 | F35: {=SUM(IF(Period=F$4,IF(Site=$B$23,data!$R$2:$R$1784)))} -> 36 | G35: {=SUM(IF(Period=G$4,IF(Site=$B$23,data!$R$2:$R$1784)))} -> 72 | H35: {=SUM(IF(Period=H$4,IF(Site=$B$23,data!$R$2:$R$1784)))} -> 36 | I35: {=SUM(IF(Period=I$4,IF(Site=$B$23,data!$R$2:$R$1784)))} -> 1855 | J35: {=SUM(IF(Period=J$4,IF(Site=$B$23,data!$R$2:$R$1784)))} -> 52 | K35: {=SUM(IF(Period=K$4,IF(Site=$B$23,data!$R$2:$R$1784)))} -> 32 | ... O35: {=SUM(IF(Period=O$4,IF(Site=$B$23,data!$R$2:$R$1784)))} -> 23 | Q35: =SUM(D35:F35) -> 140 | R35: =SUM(G35:I35) -> 1963 | S35: =SUM(J35:L35) -> 130 | T35: =SUM(M35:O35) -> 76
A36: G9744_Not_eligible--active_HTN_Pt refuses_emergent_case | C36: G9744 Not eligible--active HTN Pt refuses emergent case | D36: {=SUM(IF(Period=D$4,IF(Site=$B$23,data!$S$2:$S$1784)))} -> 0 | E36: {=SUM(IF(Period=E$4,IF(Site=$B$23,data!$S$2:$S$1784)))} -> 2680 | F36: {=SUM(IF(Period=F$4,IF(Site=$B$23,data!$S$2:$S$1784)))} -> 2535 | G36: {=SUM(IF(Period=G$4,IF(Site=$B$23,data!$S$2:$S$1784)))} -> 2157 | H36: {=SUM(IF(Period=H$4,IF(Site=$B$23,data!$S$2:$S$1784)))} -> 2007 | I36: {=SUM(IF(Period=I$4,IF(Site=$B$23,data!$S$2:$S$1784)))} -> 38 | J36: {=SUM(IF(Period=J$4,IF(Site=$B$23,data!$S$2:$S$1784)))} -> 2014 | K36: {=SUM(IF(Period=K$4,IF(Site=$B$23,data!$S$2:$S$1784)))} -> 1992 | ... O36: {=SUM(IF(Period=O$4,IF(Site=$B$23,data!$S$2:$S$1784)))} -> 1200 | Q36: =SUM(D36:F36) -> 5215 | R36: =SUM(G36:I36) -> 4202 | S36: =SUM(J36:L36) -> 5953 | T36: =SUM(M36:O36) -> 5400
A37: G9745_Reason_given_for_no_screening_or_recommending_followup | C37: G9745 Reason given for no screening or recommending followup | D37: {=SUM(IF(Period=D$4,IF(Site=$B$23,data!$T$2:$T$1784)))} -> 0 | E37: {=SUM(IF(Period=E$4,IF(Site=$B$23,data!$T$2:$T$1784)))} -> 83 | F37: {=SUM(IF(Period=F$4,IF(Site=$B$23,data!$T$2:$T$1784)))} -> 64 | G37: {=SUM(IF(Period=G$4,IF(Site=$B$23,data!$T$2:$T$1784)))} -> 48 | H37: {=SUM(IF(Period=H$4,IF(Site=$B$23,data!$T$2:$T$1784)))} -> 39 | I37: {=SUM(IF(Period=I$4,IF(Site=$B$23,data!$T$2:$T$1784)))} -> 27.753831 | J37: {=SUM(IF(Period=J$4,IF(Site=$B$23,data!$T$2:$T$1784)))} -> 40 | K37: {=SUM(IF(Period=K$4,IF(Site=$B$23,data!$T$2:$T$1784)))} -> 29 | ... O37: {=SUM(IF(Period=O$4,IF(Site=$B$23,data!$T$2:$T$1784)))} -> 12 | Q37: =SUM(D37:F37) -> 147 | R37: =SUM(G37:I37) -> 114.75383 | S37: =SUM(J37:L37) -> 106 | T37: =SUM(M37:O37) -> 65
A38: BP_Screening_Performance_Score | C38: BP Screening Performance Score | D38: =IF(D30=0,0,(D31+D32+D34)/D30) -> 0.98583904 | E38: =IF(E30=0,0,(E31+E32+E34+E36+E37)/E30) -> 0.99219304 | F38: =IF(F30=0,0,(F31+F32+F34+F36+F37)/F30) -> 0.99328449 | G38: =IF(G30=0,0,(G31+G32+G34+G36+G37)/G30) -> 0.98748971 | H38: =IF(H30=0,0,(H31+H32+H34+H36+H37)/H30) -> 0.99072148 | I38: =IF(I30=0,0,(I31+I32+I34+I36+I37)/I30) -> 0.21116761 | J38: =IF(J30=0,0,(J31+J32+J34+J36+J37)/J30) -> 0.99021397 | K38: =IF(K30=0,0,(K31+K32+K34+K36+K37)/K30) -> 0.99370427 | L38: =IF(L30=0,0,(L31+L32+L34+L36+L37)/L30) -> 0.99076756 | ... O38: =IF(O30=0,0,(O31+O32+O34+O36+O37)/O30) -> 0.99208211 | Q38: =IF(Q30=0,0,(Q31+Q32+Q34+Q36+Q37)/Q30) -> 0.99108445 | R38: =IF(R30=0,0,(R31+R32+R34+R36+R37)/R30) -> 0.75585083 | S38: =IF(S30=0,0,(S31+S32+S34+S36+S37)/S30) -> 0.99156627 | T38: =IF(T30=0,0,(T31+T32+T34+T36+T37)/T30) -> 0.99310252
A39: Overall_Score | C39: Overall Score | D39: =IF(AND(D24=0,D30=0),0,(SUM(D25:D27)+D31+D32+D34+D36+D37)/(D24+D30)) -> 0.98684211 | E39: =IF(AND(E24=0,E30=0),0,(SUM(E25:E27)+E31+E32+E34+E36+E37)/(E24+E30)) -> 0.99225841 | F39: =IF(AND(F24=0,F30=0),0,(SUM(F25:F27)+F31+F32+F34+F36+F37)/(F24+F30)) -> 0.99343045 | G39: =IF(AND(G24=0,G30=0),0,(SUM(G25:G27)+G31+G32+G34+G36+G37)/(G24+G30)) -> 0.988 | H39: =IF(AND(H24=0,H30=0),0,(SUM(H25:H27)+H31+H32+H34+H36+H37)/(H24+H30)) -> 0.99045346 | I39: =IF(AND(I24=0,I30=0),0,(SUM(I25:I27)+I31+I32+I34+I36+I37)/(I24+I30)) -> 0.26494249 | J39: =IF(AND(J24=0,J30=0),0,(SUM(J25:J27)+J31+J32+J34+J36+J37)/(J24+J30)) -> 0.99073359 | K39: =IF(AND(K24=0,K30=0),0,(SUM(K25:K27)+K31+K32+K34+K36+K37)/(K24+K30)) -> 0.99397399 | ... O39: =IF(AND(O24=0,O30=0),0,(SUM(O25:O27)+O31+O32+O34+O36+O37)/(O24+O30)) -> 0.99257221 | Q39: =IF(AND(Q24=0,Q30=0),0,(SUM(Q25:Q27)+Q31+Q32+Q34+Q36+Q37)/(Q24+Q30)) -> 0.9913748 | R39: =IF(AND(R24=0,R30=0),0,(SUM(R25:R27)+R31+R32+R34+R36+R37)/(R24+R30)) -> 0.77160171 | S39: =IF(AND(S24=0,S30=0),0,(SUM(S25:S27)+S31+S32+S34+S36+S37)/(S24+S30)) -> 0.99191822 | T39: =IF(AND(T24=0,T30=0),0,(SUM(T25:T27)+T31+T32+T34+T36+T37)/(T24+T30)) -> 0.99329538
B41: Jupiter
A42: 12_Lead_ECG_for_Chest_Pain_Cases | C42: 12 Lead ECG for Chest Pain Cases | D42: {=SUM(IF(Period=D$4,IF(Site=$B$41,data!$G$2:$G$1784)))} -> 121 | E42: {=SUM(IF(Period=E$4,IF(Site=$B$41,data!$G$2:$G$1784)))} -> 157 | F42: {=SUM(IF(Period=F$4,IF(Site=$B$41,data!$G$2:$G$1784)))} -> 189 | G42: {=SUM(IF(Period=G$4,IF(Site=$B$41,data!$G$2:$G$1784)))} -> 159 | H42: {=SUM(IF(Period=H$4,IF(Site=$B$41,data!$G$2:$G$1784)))} -> 156 | I42: {=SUM(IF(Period=I$4,IF(Site=$B$41,data!$G$2:$G$1784)))} -> 131 | J42: {=SUM(IF(Period=J$4,IF(Site=$B$41,data!$G$2:$G$1784)))} -> 169 | K42: {=SUM(IF(Period=K$4,IF(Site=$B$41,data!$G$2:$G$1784)))} -> 161 | ... O42: {=SUM(IF(Period=O$4,IF(Site=$B$41,data!$G$2:$G$1784)))} -> 46 | Q42: =SUM(D42:F42) -> 467 | R42: =SUM(G42:I42) -> 446 | S42: =SUM(J42:L42) -> 450 | T42: =SUM(M42:O42) -> 341
A43: 3120F | C43: 3120F | D43: {=SUM(IF(Period=D$4,IF(Site=$B$41,data!$H$2:$H$1784)))} -> 121 | E43: {=SUM(IF(Period=E$4,IF(Site=$B$41,data!$H$2:$H$1784)))} -> 157 | F43: {=SUM(IF(Period=F$4,IF(Site=$B$41,data!$H$2:$H$1784)))} -> 189 | G43: {=SUM(IF(Period=G$4,IF(Site=$B$41,data!$H$2:$H$1784)))} -> 159 | H43: {=SUM(IF(Period=H$4,IF(Site=$B$41,data!$H$2:$H$1784)))} -> 156 | I43: {=SUM(IF(Period=I$4,IF(Site=$B$41,data!$H$2:$H$1784)))} -> 131 | J43: {=SUM(IF(Period=J$4,IF(Site=$B$41,data!$H$2:$H$1784)))} -> 168 | K43: {=SUM(IF(Period=K$4,IF(Site=$B$41,data!$H$2:$H$1784)))} -> 160 | ... O43: {=SUM(IF(Period=O$4,IF(Site=$B$41,data!$H$2:$H$1784)))} -> 46 | Q43: =SUM(D43:F43) -> 467 | R43: =SUM(G43:I43) -> 446 | S43: =SUM(J43:L43) -> 448 | T43: =SUM(M43:O43) -> 340
A44: 3120F_1P | C44: 3120F 1P | D44: {=SUM(IF(Period=D$4,IF(Site=$B$41,data!$I$2:$I$1784)))} -> 0 | E44: {=SUM(IF(Period=E$4,IF(Site=$B$41,data!$I$2:$I$1784)))} -> 0 | F44: {=SUM(IF(Period=F$4,IF(Site=$B$41,data!$I$2:$I$1784)))} -> 0 | G44: {=SUM(IF(Period=G$4,IF(Site=$B$41,data!$I$2:$I$1784)))} -> 0 | H44: {=SUM(IF(Period=H$4,IF(Site=$B$41,data!$I$2:$I$1784)))} -> 0 | I44: {=SUM(IF(Period=I$4,IF(Site=$B$41,data!$I$2:$I$1784)))} -> 0 | J44: {=SUM(IF(Period=J$4,IF(Site=$B$41,data!$I$2:$I$1784)))} -> 0 | K44: {=SUM(IF(Period=K$4,IF(Site=$B$41,data!$I$2:$I$1784)))} -> 1 | ... O44: {=SUM(IF(Period=O$4,IF(Site=$B$41,data!$I$2:$I$1784)))} -> 0 | Q44: =SUM(D44:F44) -> 0 | R44: =SUM(G44:I44) -> 0 | S44: =SUM(J44:L44) -> 1 | T44: =SUM(M44:O44) -> 0
...

Sheet data_transformed
A1: Site | B1: Period | C1: Metric | D1: Measure
A2: Baptist | B2: Jan | C2: 12 Lead ECG for Chest Pain Cases | D2: ='Summary by Site'!$D$6 -> 141
A3: Baptist | B3: Jan | C3: 3120F | D3: ='Summary by Site'!$D$7 -> 141
A4: Baptist | B4: Jan | C4: 3120F 1P | D4: ='Summary by Site'!$D$8 -> 0
A5: Baptist | B5: Jan | C5: 3120F 2P | D5: ='Summary by Site'!$D$9 -> 0
A6: Baptist | B6: Jan | C6: 3120F 8P | D6: ='Summary by Site'!$D$10 -> 0
A7: Baptist | B7: Jan | C7: 12 Lead ECG for Chest Pain Performance Score | D7: ='Summary by Site'!$D$11 -> 1
A8: Baptist | B8: Jan | C8: BP Screening Cases | D8: ='Summary by Site'!$D$12 -> 2830
A9: Baptist | B9: Jan | C9: G8783 Normal BP no followup needed | D9: ='Summary by Site'!$D$13 -> 781
A10: Baptist | B10: Jan | C10: G8784 Not eligible--active HTN pt refuses emergent case | D10: ='Summary by Site'!$D$14 -> 140
A11: Baptist | B11: Jan | C11: G8785 BP not documented | D11: ='Summary by Site'!$D$15 -> 1
A12: Baptist | B12: Jan | C12: G8950 elevated BP with followup | D12: ='Summary by Site'!$D$16 -> 1900
A13: Baptist | B13: Jan | C13: G8952 elevated BP no followup | D13: ='Summary by Site'!$D$17 -> 9
A14: Baptist | B14: Jan | C14: G9744 Not eligible--active HTN Pt refuses emergent case | D14: ='Summary by Site'!$D$18 -> 0
A15: Baptist | B15: Jan | C15: G9745 Reason given for no screening or recommending followup | D15: ='Summary by Site'!$D$19 -> 0
A16: Baptist | B16: Jan | C16: BP Screening Performance Score | D16: ='Summary by Site'!$D$20 -> 0.99681979
A17: Baptist | B17: Jan | C17: Overall Score | D17: ='Summary by Site'!$D$21 -> 0.99697072
A18: Baptist | B18: Feb | C18: 12 Lead ECG for Chest Pain Cases | D18: ='Summary by Site'!$E$6 -> 297
A19: Baptist | B19: Feb | C19: 3120F | D19: ='Summary by Site'!$E$7 -> 297
A20: Baptist | B20: Feb | C20: 3120F 1P | D20: ='Summary by Site'!$E$8 -> 0
A21: Baptist | B21: Feb | C21: 3120F 2P | D21: ='Summary by Site'!$E$9 -> 0
A22: Baptist | B22: Feb | C22: 3120F 8P | D22: ='Summary by Site'!$E$10 -> 0
A23: Baptist | B23: Feb | C23: 12 Lead ECG for Chest Pain Performance Score | D23: ='Summary by Site'!$E$11 -> 1
A24: Baptist | B24: Feb | C24: BP Screening Cases | D24: ='Summary by Site'!$E$12 -> 5233
A25: Baptist | B25: Feb | C25: G8783 Normal BP no followup needed | D25: ='Summary by Site'!$E$13 -> 1041
A26: Baptist | B26: Feb | C26: G8784 Not eligible--active HTN pt refuses emergent case | D26: ='Summary by Site'!$E$14 -> 0
A27: Baptist | B27: Feb | C27: G8785 BP not documented | D27: ='Summary by Site'!$E$15 -> 0
A28: Baptist | B28: Feb | C28: G8950 elevated BP with followup | D28: ='Summary by Site'!$E$16 -> 2383
A29: Baptist | B29: Feb | C29: G8952 elevated BP no followup | D29: ='Summary by Site'!$E$17 -> 4
A30: Baptist | B30: Feb | C30: G9744 Not eligible--active HTN Pt refuses emergent case | D30: ='Summary by Site'!$E$18 -> 1792
A31: Baptist | B31: Feb | C31: G9745 Reason given for no screening or recommending followup | D31: ='Summary by Site'!$E$19 -> 13
A32: Baptist | B32: Feb | C32: BP Screening Performance Score | D32: ='Summary by Site'!$E$20 -> 0.99923562
A33: Baptist | B33: Feb | C33: Overall Score | D33: ='Summary by Site'!$E$21 -> 0.99927667
A34: Baptist | B34: Mar | C34: 12 Lead ECG for Chest Pain Cases | D34: ='Summary by Site'!$F$6 -> 395
A35: Baptist | B35: Mar | C35: 3120F | D35: ='Summary by Site'!$F$7 -> 395
A36: Baptist | B36: Mar | C36: 3120F 1P | D36: ='Summary by Site'!$F$8 -> 0
A37: Baptist | B37: Mar | C37: 3120F 2P | D37: ='Summary by Site'!$F$9 -> 0
A38: Baptist | B38: Mar | C38: 3120F 8P | D38: ='Summary by Site'!$F$10 -> 0
A39: Baptist | B39: Mar | C39: 12 Lead ECG for Chest Pain Performance Score | D39: ='Summary by Site'!$F$11 -> 1
A40: Baptist | B40: Mar | C40: BP Screening Cases | D40: ='Summary by Site'!$F$12 -> 6524
...

Sheet data
A1: Year | B1: Period | C1: Site | D1: Prov_Num | E1: Prov_Num_Lawson | F1: Provider_Name | G1: 12_Lead_ECG_for_Chest_Pain_Cases | H1: 3120F | I1: 3120F_1P | J1: 3120F_2P | K1: 3120F_8P | L1: 12_Lead_ECG_for_Chest_Pain_Performance_Score | M1: BP_Screening_Cases | N1: G8783_Normal_BP_no_followup_needed | O1: G8784_Not_eligible--active_HTN_pt refuses_emergent_case | P1: G8785_BP_not_documented | Q1: G8950_elevated_BP_with_followup | R1: G8952_elevated_BP_no_followup | S1: G9744_Not_eligible--active_HTN_Pt refuses_emergent_case | T1: G9745_Reason_given_for_no_screening_or_recommending_followup | U1: BP_Screening_Performance_Score | V1: Overall_Score
A2: 2017 | B2: Jan | C2: Baptist | D2: 53 | E2: 4713 | F2: ARNOLD-DOBAL DO, KARIN A | G2: 2 | H2: 2 | I2: 0 | J2: 0 | K2: 0 | L2: =IF(G2=0,0,SUM(H2:J2)/G2) -> 1 | M2: 155 | N2: 40 | O2: 10 | P2: 0 | Q2: 104 | R2: 1 | S2: 0 | T2: 0 | U2: =(N2+O2+Q2)/M2 -> 0.99354839 | V2: =(H2+I2+J2+N2+O2+Q2)/(G2+M2) -> 0.99363057
A3: 2017 | B3: Jan | C3: Baptist | D3: 243 | E3: 4498 | F3: BAKHTIARI MD, POOPAK G | G3: 0 | H3: 0 | I3: 0 | J3: 0 | K3: 0 | L3: =IF(G3=0,0,SUM(H3:J3)/G3) -> 0 | M3: 57 | N3: 16 | O3: 1 | P3: 0 | Q3: 40 | R3: 0 | S3: 0 | T3: 0 | U3: =(N3+O3+Q3)/M3 -> 1 | V3: =(H3+I3+J3+N3+O3+Q3)/(G3+M3) -> 1
A4: 2017 | B4: Jan | C4: Baptist | D4: 16594 | E4: 119329 | F4: BETANCOURT DO, ANDREA | G4: 0 | H4: 0 | I4: 0 | J4: 0 | K4: 0 | L4: =IF(G4=0,0,SUM(H4:J4)/G4) -> 0 | M4: 77 | N4: 21 | O4: 6 | P4: 0 | Q4: 49 | R4: 1 | S4: 0 | T4: 0 | U4: =(N4+O4+Q4)/M4 -> 0.98701299 | V4: =(H4+I4+J4+N4+O4+Q4)/(G4+M4) -> 0.98701299
A5: 2017 | B5: Jan | C5: Baptist | D5: 335 | E5: 2726 | F5: BRAZDA MD, MICHAEL T | G5: 16 | H5: 16 | I5: 0 | J5: 0 | K5: 0 | L5: =IF(G5=0,0,SUM(H5:J5)/G5) -> 1 | M5: 103 | N5: 24 | O5: 4 | P5: 0 | Q5: 75 | R5: 0 | S5: 0 | T5: 0 | U5: =(N5+O5+Q5)/M5 -> 1 | V5: =(H5+I5+J5+N5+O5+Q5)/(G5+M5) -> 1
A6: 2017 | B6: Jan | C6: Baptist | D6: 473 | E6: 5243 | F6: DAMORE MD, DANIEL T | G6: 3 | H6: 3 | I6: 0 | J6: 0 | K6: 0 | L6: =IF(G6=0,0,SUM(H6:J6)/G6) -> 1 | M6: 120 | N6: 44 | O6: 5 | P6: 0 | Q6: 71 | R6: 0 | S6: 0 | T6: 0 | U6: =(N6+O6+Q6)/M6 -> 1 | V6: =(H6+I6+J6+N6+O6+Q6)/(G6+M6) -> 1
A7: 2017 | B7: Jan | C7: Baptist | D7: 67 | E7: 2833 | F7: DIAZ DO, ELAINE | G7: 3 | H7: 3 | I7: 0 | J7: 0 | K7: 0 | L7: =IF(G7=0,0,SUM(H7:J7)/G7) -> 1 | M7: 24 | N7: 10 | O7: 0 | P7: 0 | Q7: 14 | R7: 0 | S7: 0 | T7: 0 | U7: =(N7+O7+Q7)/M7 -> 1 | V7: =(H7+I7+J7+N7+O7+Q7)/(G7+M7) -> 1
A8: 2017 | B8: Jan | C8: Baptist | D8: 3621 | E8: 9748 | F8: ELETTO DO, SARAH J | G8: 1 | H8: 1 | I8: 0 | J8: 0 | K8: 0 | L8: =IF(G8=0,0,SUM(H8:J8)/G8) -> 1 | M8: 69 | N8: 13 | O8: 4 | P8: 0 | Q8: 52 | R8: 0 | S8: 0 | T8: 0 | U8: =(N8+O8+Q8)/M8 -> 1 | V8: =(H8+I8+J8+N8+O8+Q8)/(G8+M8) -> 1
A9: 2017 | B9: Jan | C9: Baptist | D9: 567 | E9: 3218 | F9: ESCATEL MD, EVA | G9: 10 | H9: 10 | I9: 0 | J9: 0 | K9: 0 | L9: =IF(G9=0,0,SUM(H9:J9)/G9) -> 1 | M9: 179 | N9: 48 | O9: 3 | P9: 0 | Q9: 128 | R9: 0 | S9: 0 | T9: 0 | U9: =(N9+O9+Q9)/M9 -> 1 | V9: =(H9+I9+J9+N9+O9+Q9)/(G9+M9) -> 1
A10: 2017 | B10: Jan | C10: Baptist | D10: 627 | E10: 3693 | F10: FRIEDMAN MD, ANTHONY | G10: 38 | H10: 38 | I10: 0 | J10: 0 | K10: 0 | L10: =IF(G10=0,0,SUM(H10:J10)/G10) -> 1 | M10: 179 | N10: 56 | O10: 8 | P10: 0 | Q10: 115 | R10: 0 | S10: 0 | T10: 0 | U10: =(N10+O10+Q10)/M10 -> 1 | V10: =(H10+I10+J10+N10+O10+Q10)/(G10+M10) -> 1
A11: 2017 | B11: Jan | C11: Baptist | D11: 130 | E11: 5419 | F11: GARCIA DO, ALEXANDER | G11: 4 | H11: 4 | I11: 0 | J11: 0 | K11: 0 | L11: =IF(G11=0,0,SUM(H11:J11)/G11) -> 1 | M11: 89 | N11: 27 | O11: 5 | P11: 1 | Q11: 57 | R11: 0 | S11: 0 | T11: 0 | U11: =(N11+O11+Q11)/M11 -> 1 | V11: =(H11+I11+J11+N11+O11+Q11)/(G11+M11) -> 1
A12: 2017 | B12: Jan | C12: Baptist | D12: 1397 | E12: 3661 | F12: GARCIA-GONZALEZ MD, MIGDALIA I | G12: 2 | H12: 2 | I12: 0 | J12: 0 | K12: 0 | L12: =IF(G12=0,0,SUM(H12:J12)/G12) -> 1 | M12: 68 | N12: 15 | O12: 4 | P12: 0 | Q12: 49 | R12: 0 | S12: 0 | T12: 0 | U12: =(N12+O12+Q12)/M12 -> 1 | V12: =(H12+I12+J12+N12+O12+Q12)/(G12+M12) -> 1
A13: 2017 | B13: Jan | C13: Baptist | D13: 1508 | E13: 3157 | F13: HASPIL-CORGAN MD, TESSA A | G13: 0 | H13: 0 | I13: 0 | J13: 0 | K13: 0 | L13: =IF(G13=0,0,SUM(H13:J13)/G13) -> 0 | M13: 46 | N13: 18 | O13: 3 | P13: 0 | Q13: 25 | R13: 0 | S13: 0 | T13: 0 | U13: =(N13+O13+Q13)/M13 -> 1 | V13: =(H13+I13+J13+N13+O13+Q13)/(G13+M13) -> 1
... A72: 2017 | B72: Jan | C72: West Marion | D72: 543 | E72: 10917 | F72: STEENSTRA DO, ROBYN | G72: 18 | H72: 18 | I72: 0 | J72: 0 | K72: 0 | L72: =IF(G72=0,0,SUM(H72:J72)/G72) -> 1 | M72: 170 | N72: 31 | O72: 14 | P72: 0 | Q72: 121 | R72: 4 | S72: 0 | T72: 0 | U72: =(N72+O72+Q72)/M72 -> 0.97647059 | V72: =(H72+I72+J72+N72+O72+Q72)/(G72+M72) -> 0.9787234
A73: 2017 | B73: Jan | C73: West Marion | D73: 576 | E73: 122114 | F73: VITERITTI DO, JOHN J | G73: 7 | H73: 7 | I73: 0 | J73: 0 | K73: 0 | L73: =IF(G73=0,0,SUM(H73:J73)/G73) -> 1 | M73: 92 | N73: 14 | O73: 8 | P73: 0 | Q73: 70 | R73: 0 | S73: 0 | T73: 0 | U73: =IF(M73=0,0,((N73+O73+Q73)/M73)) -> 1 | V73: =(H73+I73+J73+N73+O73+Q73)/(G73+M73) -> 1
A74: 2017 | B74: Jan | C74: West Marion | D74: 536 | E74: 10757 | F74: VON BARGEN DO, WILLIAM F | G74: 1 | H74: 1 | I74: 0 | J74: 0 | K74: 0 | L74: =IF(G74=0,0,SUM(H74:J74)/G74) -> 1 | M74: 304 | N74: 40 | O74: 15 | P74: 0 | Q74: 238 | R74: 11 | S74: 0 | T74: 0 | U74: =IF(M74=0,0,((N74+O74+Q74)/M74)) -> 0.96381579 | V74: =(H74+I74+J74+N74+O74+Q74)/(G74+M74) -> 0.96393443
A75: 2017 | B75: Jan | C75: West Marion | D75: 588 | E75: 122737 | F75: WAXLER DO, JENNIFER L | G75: 0 | H75: 0 | I75: 0 | J75: 0 | K75: 0 | L75: =IF(G75=0,0,SUM(H75:J75)/G75) -> 0 | M75: 30 | N75: 2 | O75: 2 | P75: 0 | Q75: 26 | R75: 0 | S75: 0 | T75: 0 | U75: =IF(M75=0,0,((N75+O75+Q75)/M75)) -> 1 | V75: =(H75+I75+J75+N75+O75+Q75)/(G75+M75) -> 1
A76: 2017 | B76: Jan | C76: West Marion | D76: 550 | E76: 119292 | F76: WELBERN MD, VANESSA R | G76: 16 | H76: 16 | I76: 0 | J76: 0 | K76: 0 | L76: =IF(G76=0,0,SUM(H76:J76)/G76) -> 1 | M76: 177 | N76: 28 | O76: 2 | P76: 0 | Q76: 147 | R76: 0 | S76: 0 | T76: 0 | U76: =IF(M76=0,0,((N76+O76+Q76)/M76)) -> 1 | V76: =(H76+I76+J76+N76+O76+Q76)/(G76+M76) -> 1
A77: 2017 | B77: Jan | C77: West Marion | D77: 563 | E77: 5246 | F77: WILSON MD, DAVID L | G77: 0 | H77: 0 | I77: 0 | J77: 0 | K77: 0 | L77: =IF(G77=0,0,SUM(H77:J77)/G77) -> 0 | M77: 5 | N77: 1 | O77: 0 | P77: 0 | Q77: 4 | R77: 0 | S77: 0 | T77: 0 | U77: =IF(M77=0,0,((N77+O77+Q77)/M77)) -> 1 | V77: =(H77+I77+J77+N77+O77+Q77)/(G77+M77) -> 1
A78: 2017 | B78: Jan | C78: JFK-Main | D78: 137 | E78: 5010 | F78: BOJAN MD, DAVID | G78: 17 | H78: 17 | I78: 0 | J78: 0 | K78: 0 | L78: =IF(G78=0,0,SUM(H78:J78)/G78) -> 1 | M78: 105 | N78: 41 | O78: 4 | P78: 0 | Q78: 55 | R78: 5 | S78: 0 | T78: 0 | U78: =IF(M78=0,0,((N78+O78+Q78)/M78)) -> 0.95238095 | V78: =(H78+I78+J78+N78+O78+Q78)/(G78+M78) -> 0.95901639
A79: 2017 | B79: Jan | C79: JFK-Main | D79: 29 | E79: 4489 | F79: BOWRY MD, RIDDHI | G79: 16 | H79: 16 | I79: 0 | J79: 0 | K79: 0 | L79: =IF(G79=0,0,SUM(H79:J79)/G79) -> 1 | M79: 279 | N79: 102 | O79: 29 | P79: 0 | Q79: 147 | R79: 1 | S79: 0 | T79: 0 | U79: =IF(M79=0,0,((N79+O79+Q79)/M79)) -> 0.99641577 | V79: =(H79+I79+J79+N79+O79+Q79)/(G79+M79) -> 0.99661017
A80: 2017 | B80: Jan | C80: JFK-Main | D80: 38 | E80: 7115 | F80: BUCHHOLZ DO, KEITH L | G80: 17 | H80: 17 | I80: 0 | J80: 0 | K80: 0 | L80: =IF(G80=0,0,SUM(H80:J80)/G80) -> 1 | M80: 93 | N80: 28 | O80: 20 | P80: 0 | Q80: 39 | R80: 6 | S80: 0 | T80: 0 | U80: =IF(M80=0,0,((N80+O80+Q80)/M80)) -> 0.93548387 | V80: =(H80+I80+J80+N80+O80+Q80)/(G80+M80) -> 0.94545455
A81: 2017 | B81: Jan | C81: JFK-Main | D81: 58 | E81: 7621 | F81: BUI DO, TRIMINH H | G81: 34 | H81: 34 | I81: 0 | J81: 0 | K81: 0 | L81: =IF(G81=0,0,SUM(H81:J81)/G81) -> 1 | M81: 431 | N81: 135 | O81: 32 | P81: 1 | Q81: 263 | R81: 0 | S81: 0 | T81: 0 | U81: =IF(M81=0,0,((N81+O81+Q81)/M81)) -> 0.99767981 | V81: =(H81+I81+J81+N81+O81+Q81)/(G81+M81) -> 0.99784946
A82: 2017 | B82: Jan | C82: JFK-Main | D82: 112 | E82: 10769 | F82: CRANE MD, JOSEPH T | G82: 0 | H82: 0 | I82: 0 | J82: 0 | K82: 0 | L82: =IF(G82=0,0,SUM(H82:J82)/G82) -> 0 | M82: 32 | N82: 11 | O82: 8 | P82: 0 | Q82: 13 | R82: 0 | S82: 0 | T82: 0 | U82: =IF(M82=0,0,((N82+O82+Q82)/M82)) -> 1 | V82: =(H82+I82+J82+N82+O82+Q82)/(G82+M82) -> 1
A83: 2017 | B83: Jan | C83: JFK-Main | D83: 60 | E83: 7787 | F83: FISH DO, JAMES A | G83: 0 | H83: 0 | I83: 0 | J83: 0 | K83: 0 | L83: =IF(G83=0,0,SUM(H83:J83)/G83) -> 0 | M83: 1 | N83: 1 | O83: 0 | P83: 0 | Q83: 0 | R83: 0 | S83: 0 | T83: 0 | U83: =IF(M83=0,0,((N83+O83+Q83)/M83)) -> 1 | V83: =(H83+I83+J83+N83+O83+Q83)/(G83+M83) -> 1
A84: 2017 | B84: Jan | C84: JFK-Main | D84: 23 | E84: 5832 | F84: FOWLER MD, DAVID M | G84: 7 | H84: 7 | I84: 0 | J84: 0 | K84: 0 | L84: =IF(G84=0,0,SUM(H84:J84)/G84) -> 1 | M84: 54 | N84: 15 | O84: 10 | P84: 0 | Q84: 28 | R84: 1 | S84: 0 | T84: 0 | U84: =IF(M84=0,0,((N84+O84+Q84)/M84)) -> 0.98148148 | V84: =(H84+I84+J84+N84+O84+Q84)/(G84+M84) -> 0.98360656
... A92: 2017 | B92: Jan | C92: JFK-Main | D92: 70 | E92: 8358 | F92: LEMAY DO, CHRISTOPHER R | G92: 4 | H92: 4 | I92: 0 | J92: 0 | K92: 0 | L92: =IF(G92=0,0,SUM(H92:J92)/G92) -> 1 | M92: 24 | N92: 12 | O92: 0 | P92: 1 | Q92: 11 | R92: 0 | S92: 0 | T92: 0 | U92: =IF(M92=0,0,((N92+O92+Q92)/M92)) -> 0.95833333 | V92: =(H92+I92+J92+N92+O92+Q92)/(G92+M92) -> 0.96428571
A93: 2017 | B93: Jan | C93: JFK-Main | D93: 1 | E93: 6777 | F93: MCCAIG MD, CAMERON S | G93: 0 | H93: 0 | I93: 0 | J93: 0 | K93: 0 | L93: =IF(G93=0,0,SUM(H93:J93)/G93) -> 0 | M93: 0 | N93: 0 | O93: 0 | P93: 0 | Q93: 0 | R93: 0 | S93: 0 | T93: 0 | U93: =IF(M93=0,0,((N93+O93+Q93)/M93)) -> 0 | V93: 0
A94: 2017 | B94: Jan | C94: JFK-Main | D94: 52 | E94: 222222222 | F94: MCCALLA MD, TIFFANY N | G94: 0 | H94: 0 | I94: 0 | J94: 0 | K94: 0 | L94: =IF(G94=0,0,SUM(H94:J94)/G94) -> 0 | M94: 1 | N94: 1 | O94: 0 | P94: 0 | Q94: 0 | R94: 0 | S94: 0 | T94: 0 | U94: =IF(M94=0,0,((N94+O94+Q94)/M94)) -> 1 | V94: =(H94+I94+J94+N94+O94+Q94)/(G94+M94) -> 1
A95: 2017 | B95: Jan | C95: JFK-Main | D95: 65 | E95: 7806 | F95: MCDOW DO, CHRISTOPHER C | G95: 23 | H95: 23 | I95: 0 | J95: 0 | K95: 0 | L95: =IF(G95=0,0,SUM(H95:J95)/G95) -> 1 | M95: 257 | N95: 93 | O95: 6 | P95: 0 | Q95: 156 | R95: 2 | S95: 0 | T95: 0 | U95: =IF(M95=0,0,((N95+O95+Q95)/M95)) -> 0.9922179 | V95: =(H95+I95+J95+N95+O95+Q95)/(G95+M95) -> 0.99285714
A96: 2017 | B96: Jan | C96: JFK-Main | D96: 27 | E96: 4492 | F96: MEZE DO, MEZEDA | G96: 22 | H96: 22 | I96: 0 | J96: 0 | K96: 0 | L96: =IF(G96=0,0,SUM(H96:J96)/G96) -> 1 | M96: 253 | N96: 88 | O96: 18 | P96: 0 | Q96: 144 | R96: 3 | S96: 0 | T96: 0 | U96: =IF(M96=0,0,((N96+O96+Q96)/M96)) -> 0.98814229 | V96: =(H96+I96+J96+N96+O96+Q96)/(G96+M96) -> 0.98909091
A97: 2017 | B97: Jan | C97: JFK-Main | D97: 119 | E97: 8697 | F97: NECKRITZ DO, DAVID P | G97: 7 | H97: 7 | I97: 0 | J97: 0 | K97: 0 | L97: =IF(G97=0,0,SUM(H97:J97)/G97) -> 1 | M97: 431 | N97: 137 | O97: 10 | P97: 0 | Q97: 282 | R97: 2 | S97: 0 | T97: 0 | U97: =IF(M97=0,0,((N97+O97+Q97)/M97)) -> 0.99535963 | V97: =(H97+I97+J97+N97+O97+Q97)/(G97+M97) -> 0.99543379
A98: 2017 | B98: Jan | C98: JFK-Main | D98: 25 | E98: 4357 | F98: SALEHI MD, SHARIF | G98: 36 | H98: 36 | I98: 0 | J98: 0 | K98: 0 | L98: =IF(G98=0,0,SUM(H98:J98)/G98) -> 1 | M98: 235 | N98: 70 | O98: 32 | P98: 0 | Q98: 121 | R98: 12 | S98: 0 | T98: 0 | U98: =IF(M98=0,0,((N98+O98+Q98)/M98)) -> 0.94893617 | V98: =(H98+I98+J98+N98+O98+Q98)/(G98+M98) -> 0.95571956
A99: 2017 | B99: Jan | C99: JFK-Main | D99: 21 | E99: 5875 | F99: SCHEPPKE MD, KENNETH A | G99: 0 | H99: 0 | I99: 0 | J99: 0 | K99: 0 | L99: =IF(G99=0,0,SUM(H99:J99)/G99) -> 0 | M99: 1 | N99: 1 | O99: 0 | P99: 0 | Q99: 0 | R99: 0 | S99: 0 | T99: 0 | U99: =IF(M99=0,0,((N99+O99+Q99)/M99)) -> 1 | V99: =(H99+I99+J99+N99+O99+Q99)/(G99+M99) -> 1
A100: 2017 | B100: Jan | C100: JFK-Main | D100: 184 | E100: 120870 | F100: STURM MD, ANDREW P | G100: 26 | H100: 26 | I100: 0 | J100: 0 | K100: 0 | L100: =IF(G100=0,0,SUM(H100:J100)/G100) -> 1 | M100: 196 | N100: 61 | O100: 7 | P100: 0 | Q100: 128 | R100: 0 | S100: 0 | T100: 0 | U100: =IF(M100=0,0,((N100+O100+Q100)/M100)) -> 1 | V100: =(H100+I100+J100+N100+O100+Q100)/(G100+M100) -> 1
A101: 2017 | B101: Jan | C101: JFK-Main | D101: 142 | E101: 122502 | F101: ZALACAIN MD, JOAQUIN F | G101: 27 | H101: 27 | I101: 0 | J101: 0 | K101: 0 | L101: =IF(G101=0,0,SUM(H101:J101)/G101) -> 1 | M101: 261 | N101: 88 | O101: 30 | P101: 0 | Q101: 142 | R101: 1 | S101: 0 | T101: 0 | U101: =IF(M101=0,0,((N101+O101+Q101)/M101)) -> 0.99616858 | V101: =(H101+I101+J101+N101+O101+Q101)/(G101+M101) -> 0.99652778
A102: 2017 | B102: Jan | C102: Jupiter | D102: 489 | E102: 7740 | F102: ALLISON MD, TIMOTHY B | G102: 9 | H102: 9 | I102: 0 | J102: 0 | K102: 0 | L102: =IF(G102=0,0,SUM(H102:J102)/G102) -> 1 | M102: 128 | N102: 26 | O102: 6 | P102: 0 | Q102: 95 | R102: 1 | S102: 0 | T102: 0 | U102: =IF(M102=0,0,((N102+O102+Q102)/M102)) -> 0.9921875 | V102: =(H102+I102+J102+N102+O102+Q102)/(G102+M102) -> 0.99270073
A103: 2017 | B103: Jan | C103: Jupiter | D103: 2 | E103: 121285 | F103: BRADFORD DO, TODD H | G103: 0 | H103: 0 | I103: 0 | J103: 0 | K103: 0 | L103: =IF(G103=0,0,SUM(H103:J103)/G103) -> 0 | M103: 0 | N103: 0 | O103: 0 | P103: 0 | Q103: 0 | R103: 0 | S103: 0 | T103: 0 | U103: =IF(M103=0,0,((N103+O103+Q103)/M103)) -> 0 | V103: 0
A104: 2017 | B104: Jan | C104: Jupiter | D104: 492 | E104: 7744 | F104: CASKER MD, MARGERY V | G104: 14 | H104: 14 | I104: 0 | J104: 0 | K104: 0 | L104: =IF(G104=0,0,SUM(H104:J104)/G104) -> 1 | M104: 167 | N104: 48 | O104: 23 | P104: 0 | Q104: 94 | R104: 2 | S104: 0 | T104: 0 | U104: =IF(M104=0,0,((N104+O104+Q104)/M104)) -> 0.98802395 | V104: =(H104+I104+J104+N104+O104+Q104)/(G104+M104) -> 0.98895028
A105: 2017 | B105: Jan | C105: Jupiter | D105: 555 | E105: 119114 | F105: CHAPIN MD, ETHAN A | G105: 4 | H105: 4 | I105: 0 | J105: 0 | K105: 0 | L105: =IF(G105=0,0,SUM(H105:J105)/G105) -> 1 | M105: 80 | N105: 20 | O105: 4 | P105: 0 | Q105: 56 | R105: 0 | S105: 0 | T105: 0 | U105: =IF(M105=0,0,((N105+O105+Q105)/M105)) -> 1 | V105: =(H105+I105+J105+N105+O105+Q105)/(G105+M105) -> 1
...
