Workbook

Sheet Summary
A3: Site | B3: Meausre | C3: Year | D3: Jan | E3: Feb | F3: Mar | G3: Apr | H3: May | I3: Jun | J3: Jul | K3: Aug | L3: Sep | M3: Oct | N3: Nov | O3: Dec
A5: Baptist | B5: Mortalities | C5: 2017 | D5: 8 | E5: 12 | F5: 11 | G5: 4 | H5: 5 | I5: 6 | J5: 7 | K5: 9 | L5: 13 | M5: 7 | N5: 6 | O5: 10
A6: Baptist | B6: 72hr_Returns_Total | C6: 2017 | D6: 0 | E6: 0 | F6: 0 | G6: 0 | H6: 0 | I6: 0 | J6: 0 | K6: 0 | L6: 0 | M6: 0 | N6: 0 | O6: 0 | P6: Per PM, don't have this metric currently but MAY get it later
A7: Baptist | B7: 72hr_Returns_Admit | C7: 2017 | D7: 0 | E7: 0 | F7: 0 | G7: 0 | H7: 0 | I7: 0 | J7: 0 | K7: 0 | L7: 0 | M7: 0 | N7: 0 | O7: 0 | P7: Per PM, don't have this metric currently but MAY get it later
A9: Jupiter | B9: Mortalities | C9: 2017 | D9: 7 | E9: 0 | F9: 6 | G9: 0 | H9: 0 | I9: 0 | J9: 3 | K9: 4 | L9: 0 | M9: 3 | N9: 0 | O9: 0
A10: Jupiter | B10: 72hr_Returns_Total | C10: 2017 | D10: 74 | E10: 64 | F10: 79 | G10: 70 | H10: 74 | I10: 78 | J10: 72 | K10: 81 | L10: 53 | M10: 60 | N10: 0 | O10: 0
A11: Jupiter | B11: 72hr_Returns_Admit | C11: 2017 | D11: 29 | E11: 24 | F11: 29 | G11: 29 | H11: 24 | I11: 31 | J11: 31 | K11: 33 | L11: 25 | M11: 21 | N11: 0 | O11: 0
A13: Ocala | B13: Mortalities | C13: 2017 | D13: 5 | E13: 0 | F13: 2 | G13: 3 | H13: 5 | I13: 3 | J13: 3 | K13: 5 | L13: 1 | M13: 0 | N13: 0 | O13: 0
A14: Ocala | B14: 72hr_Returns_Total | C14: 2017 | D14: 26 | E14: 17 | F14: 17 | G14: 19 | H14: 16 | I14: 17 | J14: 47 | K14: 63 | L14: 42 | M14: 38 | N14: 39 | O14: 30
A15: Ocala | B15: 72hr_Returns_Admit | C15: 2017 | D15: 1 | E15: 2 | F15: 0 | G15: 3 | H15: 1 | I15: 1 | J15: 0 | K15: 4 | L15: 2 | M15: 2 | N15: 0 | O15: 2
A17: West Marion | B17: Mortalities | C17: 2017 | D17: 1 | E17: 2 | F17: 0 | G17: 2 | H17: 1 | I17: 1 | J17: 0 | K17: 1 | L17: 1 | M17: 0 | N17: 0 | O17: 0
A18: West Marion | B18: 72hr_Returns_Total | C18: 2017 | D18: 20 | E18: 27 | F18: 21 | G18: 14 | H18: 30 | I18: 20 | J18: 35 | K18: 43 | L18: 60 | M18: 57 | N18: 64 | O18: 55
A19: West Marion | B19: 72hr_Returns_Admit | C19: 2017 | D19: 1 | E19: 8 | F19: 3 | G19: 0 | H19: 1 | I19: 0 | J19: 2 | K19: 4 | L19: 1 | M19: 6 | N19: 0 | O19: 1
A21: Summerfield | B21: Mortalities | C21: 2017 | D21: 0 | E21: 0 | F21: 0 | G21: 0 | H21: 0 | I21: 1 | J21: 1 | K21: 2 | L21: 0 | M21: 0 | N21: 0 | O21: 0
A22: Summerfield | B22: 72hr_Returns_Total | C22: 2017 | D22: 2 | E22: 4 | F22: 8 | G22: 5 | H22: 3 | I22: 10 | J22: 13 | K22: 0 | L22: 0 | M22: 35 | N22: 28 | O22: 24
A23: Summerfield | B23: 72hr_Returns_Admit | C23: 2017 | D23: 0 | E23: 0 | F23: 0 | G23: 0 | H23: 0 | I23: 0 | J23: 0 | K23: 0 | L23: 0 | M23: 0 | N23: 0 | O23: 0
... A35: Kendall | B35: 72hr_Returns_Admit | C35: 2017 | D35: 57 | E35: 42 | F35: 34 | G35: 25 | H35: 31 | I35: 22 | J35: 63 | K35: 33 | L35: 22 | M35: 25 | N35: 22 | O35: 27

Sheet mortalities_72hr_returns
A1: Site | B1: Year | C1: Period | D1: Mortalities | E1: 72hr_Returns_Total | F1: 72hr_Returns_Admit
A2: Baptist | B2: 2017 | C2: Jan | D2: =Summary!$D$5 -> 8 | E2: =Summary!$D$6 -> 0 | F2: =Summary!$D$7 -> 0
A3: Baptist | B3: 2017 | C3: Feb | D3: =Summary!$E$5 -> 12 | E3: =Summary!$E$6 -> 0 | F3: =Summary!$E$7 -> 0
A4: Baptist | B4: 2017 | C4: Mar | D4: =Summary!$F$5 -> 11 | E4: =Summary!$F$6 -> 0 | F4: =Summary!$F$7 -> 0
A5: Baptist | B5: 2017 | C5: Apr | D5: =Summary!$G$5 -> 4 | E5: =Summary!$G$6 -> 0 | F5: =Summary!$G$7 -> 0
A6: Baptist | B6: 2017 | C6: May | D6: =Summary!$H$5 -> 5 | E6: =Summary!$H$6 -> 0 | F6: =Summary!$H$7 -> 0
A7: Baptist | B7: 2017 | C7: Jun | D7: =Summary!$I$5 -> 6 | E7: =Summary!$I$6 -> 0 | F7: =Summary!$I$7 -> 0
A8: Baptist | B8: 2017 | C8: Jul | D8: =Summary!$J$5 -> 7 | E8: =Summary!$J$6 -> 0 | F8: =Summary!$J$7 -> 0
A9: Baptist | B9: 2017 | C9: Aug | D9: =Summary!$K$5 -> 9 | E9: =Summary!$K$6 -> 0 | F9: =Summary!$K$7 -> 0
A10: Baptist | B10: 2017 | C10: Sep | D10: =Summary!$L$5 -> 13 | E10: =Summary!$L$6 -> 0 | F10: =Summary!$L$7 -> 0
A11: Baptist | B11: 2017 | C11: Oct | D11: =Summary!$M$5 -> 7 | E11: =Summary!$M$6 -> 0 | F11: =Summary!$M$7 -> 0
A12: Baptist | B12: 2017 | C12: Nov | D12: =Summary!$N$5 -> 6 | E12: =Summary!$N$6 -> 0 | F12: =Summary!$N$7 -> 0
A13: Baptist | B13: 2017 | C13: Dec | D13: =Summary!$O$5 -> 10 | E13: =Summary!$O$6 -> 0 | F13: =Summary!$O$7 -> 0
A14: Jupiter | B14: 2017 | C14: Jan | D14: =Summary!$D$9 -> 7 | E14: =Summary!$D$10 -> 74 | F14: =Summary!$D$11 -> 29
A15: Jupiter | B15: 2017 | C15: Feb | D15: =Summary!$E$9 -> 0 | E15: =Summary!$E$10 -> 64 | F15: =Summary!$E$11 -> 24
A16: Jupiter | B16: 2017 | C16: Mar | D16: =Summary!$F$9 -> 6 | E16: =Summary!$F$10 -> 79 | F16: =Summary!$F$11 -> 29
A17: Jupiter | B17: 2017 | C17: Apr | D17: =Summary!$G$9 -> 0 | E17: =Summary!$G$10 -> 70 | F17: =Summary!$G$11 -> 29
A18: Jupiter | B18: 2017 | C18: May | D18: =Summary!$H$9 -> 0 | E18: =Summary!$H$10 -> 74 | F18: =Summary!$H$11 -> 24
A19: Jupiter | B19: 2017 | C19: Jun | D19: =Summary!$I$9 -> 0 | E19: =Summary!$I$10 -> 78 | F19: =Summary!$I$11 -> 31
A20: Jupiter | B20: 2017 | C20: Jul | D20: =Summary!$J$9 -> 3 | E20: =Summary!$J$10 -> 72 | F20: =Summary!$J$11 -> 31
A21: Jupiter | B21: 2017 | C21: Aug | D21: =Summary!$K$9 -> 4 | E21: =Summary!$K$10 -> 81 | F21: =Summary!$K$11 -> 33
A22: Jupiter | B22: 2017 | C22: Sep | D22: =Summary!$L$9 -> 0 | E22: =Summary!$L$10 -> 53 | F22: =Summary!$L$11 -> 25
A23: Jupiter | B23: 2017 | C23: Oct | D23: =Summary!$M$9 -> 3 | E23: =Summary!$M$10 -> 60 | F23: =Summary!$M$11 -> 21
A24: Jupiter | B24: 2017 | C24: Nov | D24: =Summary!$N$9 -> 0 | E24: =Summary!$N$10 -> 0 | F24: =Summary!$N$11 -> 0
A25: Jupiter | B25: 2017 | C25: Dec | D25: =Summary!$O$9 -> 0 | E25: =Summary!$O$10 -> 0 | F25: =Summary!$O$11 -> 0
A26: Ocala | B26: 2017 | C26: Jan | D26: =Summary!$D$13 -> 5 | E26: =Summary!$D$14 -> 26 | F26: =Summary!$D$15 -> 1
A27: Ocala | B27: 2017 | C27: Feb | D27: =Summary!$E$13 -> 0 | E27: =Summary!$E$14 -> 17 | F27: =Summary!$E$15 -> 2
A28: Ocala | B28: 2017 | C28: Mar | D28: =Summary!$F$13 -> 2 | E28: =Summary!$F$14 -> 17 | F28: =Summary!$F$15 -> 0
A29: Ocala | B29: 2017 | C29: Apr | D29: =Summary!$G$13 -> 3 | E29: =Summary!$G$14 -> 19 | F29: =Summary!$G$15 -> 3
A30: Ocala | B30: 2017 | C30: May | D30: =Summary!$H$13 -> 5 | E30: =Summary!$H$14 -> 16 | F30: =Summary!$H$15 -> 1
A31: Ocala | B31: 2017 | C31: Jun | D31: =Summary!$I$13 -> 3 | E31: =Summary!$I$14 -> 17 | F31: =Summary!$I$15 -> 1
A32: Ocala | B32: 2017 | C32: Jul | D32: =Summary!$J$13 -> 3 | E32: =Summary!$J$14 -> 47 | F32: =Summary!$J$15 -> 0
A33: Ocala | B33: 2017 | C33: Aug | D33: =Summary!$K$13 -> 5 | E33: =Summary!$K$14 -> 63 | F33: =Summary!$K$15 -> 4
A34: Ocala | B34: 2017 | C34: Sep | D34: =Summary!$L$13 -> 1 | E34: =Summary!$L$14 -> 42 | F34: =Summary!$L$15 -> 2
A35: Ocala | B35: 2017 | C35: Oct | D35: =Summary!$M$13 -> 0 | E35: =Summary!$M$14 -> 38 | F35: =Summary!$M$15 -> 2
A36: Ocala | B36: 2017 | C36: Nov | D36: =Summary!$N$13 -> 0 | E36: =Summary!$N$14 -> 39 | F36: =Summary!$N$15 -> 0
A37: Ocala | B37: 2017 | C37: Dec | D37: =Summary!$O$13 -> 0 | E37: =Summary!$O$14 -> 30 | F37: =Summary!$O$15 -> 2
A38: West Marion | B38: 2017 | C38: Jan | D38: =Summary!$D$17 -> 1 | E38: =Summary!$D$18 -> 20 | F38: =Summary!$D$19 -> 1
A39: West Marion | B39: 2017 | C39: Feb | D39: =Summary!$E$17 -> 2 | E39: =Summary!$E$18 -> 27 | F39: =Summary!$E$19 -> 8
A40: West Marion | B40: 2017 | C40: Mar | D40: =Summary!$F$17 -> 0 | E40: =Summary!$F$18 -> 21 | F40: =Summary!$F$19 -> 3
...
