Workbook
Name Clinical_Performance: #REF!
Name Clinical_Performance: #REF!
Name DataRange: #REF!
Name DataRange: #REF!
Name DataRange: #REF!
Name DataRange: #REF!
Name DataRange: #REF!
Name DataRange: #REF!
Name DataRange: #REF!
Name DataRange: #REF!
Name DataRange: #REF!
Name DataRange: #REF!
Name DataRange: #REF!
Name DataRange: #REF!
Name DataRange: #REF!
Name DataRange: #REF!
Name DataRange: #REF!
Name DataRange: #REF!
Name DataRange: #REF!
Name DataRange: #REF!
Name DataRange: #REF!
Name DataRange: #REF!
Name DataRange: #REF!
Name DataRange: #REF!
Name DataRange: #REF!
Name DataRange: #REF!
Name DataRange: #REF!
Name DataRange: #REF!
Name HeaderRange: #REF!
Name HeaderRange: #REF!
Name HeaderRange: #REF!
Name HeaderRange: #REF!
Name HeaderRange: #REF!
Name HeaderRange: #REF!
Name HeaderRange: #REF!
Name HeaderRange: #REF!
Name HeaderRange: #REF!
Name HeaderRange: #REF!
Name HeaderRange: #REF!
Name HeaderRange: #REF!
Name HeaderRange: #REF!
Name HeaderRange: #REF!
Name HeaderRange: #REF!
Name HeaderRange: #REF!
Name HeaderRange: #REF!
Name HeaderRange: #REF!
Name HeaderRange: #REF!
Name HeaderRange: #REF!
Name HeaderRange: #REF!
Name HeaderRange: #REF!
Name HeaderRange: #REF!
Name HeaderRange: #REF!
Name HeaderRange: #REF!
Name HeaderRange: #REF!
Name SortRange: #REF!
Name SortRange: #REF!
Name SortRange: #REF!
Name SortRange: #REF!
Name SortRange: #REF!
Name SortRange: #REF!

Sheet JV QUARTER
B1: 42370 | C1: 42401 | D1: 42430 | E1: Q1 | H1: 42461 | I1: 42491 | J1: 42522 | K1: Q2
A2: Kendall | G2: Kendall
M3: Joint Venture - Q4 2015
A4: Total Patients | B4: 7558 | C4: 7752 | D4: 8404 | E4: =SUM(B4:D4) -> 23714 | G4: Total Patients | K4: =SUM(H4:J4) -> 0 | M4: Total Pts | N4: Arrival to Provider Greet | O4: Duplicate MSE | P4: Admitted Pts ALOS | Q4: Departed pts ALOS | R4: LPMSE + LPT | S4: AMA
A5: Arrival to Provider Greet | B5: 16 | C5: 16 | D5: 11 | E5: =((B5*B4)+(C5*C4)+(D5*D4))/SUM(B4:D4) -> 14.228051 | G5: Arrival to Provider Greet | K5: =SUMPRODUCT(H5:J5,H4:J4)/SUM(H4:J4) -> #DIV/0!
A6: Duplicate MSE | B6: 143 | C6: 171 | D6: 142 | E6: =SUM(B6:D6) -> 456 | G6: Duplicate MSE | K6: =SUM(H6:J6) -> 0 | M6: =SUM(K4,K37,K53,K69) -> 0 | N6: =((H5*H$4)+(I5*I$4)+(J5*J$4)+(H38*H$37)+(I38*I$37)+(J38*J$37)+(H54*H$53)+(I54*I$53)+(J54*J$53)+(H70*H$69)+(I70*I$69)+(J70*J$69))/SUM(E$4,E$37,E$53,E$69) -> 0 | O6: =SUM(K6,K39,K55,K71) -> 0 | P6: =((H10*H8)+(I10*I8)+(J10*J8)+(H43*H41)+(I43*I41)+(J43*J41)+(H59*H57)+(I59*I57)+(J59*J57)+(H75*H73)+(I75*I73)+(J75*J73))/SUM(K$8,K$41,K$57,K$73) -> #DIV/0! | Q6: =((H12*H13)+(I12*I13)+(J12*J13)+(H45*H46)+(I45*I46)+(J45*J46)+(H61*H62)+(I61*I62)+(J61*J62)+(H77*H78)+(I77*I78)+(J77*J78))/SUM(K$12,K$45,K$61,K$77) -> #DIV/0! | R6: =SUM(K14,K47,K63,K79) -> 0 | S6: =SUM(K16,K49,K65,K81) -> 0
A7: Duplicate MSE % | B7: =B6/B4 -> 0.018920349 | C7: =C6/C4 -> 0.022058824 | D7: =D6/D4 -> 0.016896716 | E7: =E6/E4 -> 0.019229147 | G7: Duplicate MSE % | H7: =H6/H4 -> #DIV/0! | I7: =I6/I4 -> #DIV/0! | J7: =J6/J4 -> #DIV/0! | K7: =K6/K4 -> #DIV/0! | O7: =(O6/M6) -> #DIV/0! | R7: =R6/M6 -> #DIV/0! | S7: =S6/M6 -> #DIV/0!
A8: Admitted Pts | B8: 1599 | C8: 1326 | D8: 1773 | E8: =SUM(B8:D8) -> 4698 | G8: Admitted Pts | K8: =SUM(H8:J8) -> 0
A9: Admitted Pts % | B9: =B8/B4 -> 0.21156391 | C9: =C8/C4 -> 0.17105263 | D9: =D8/D4 -> 0.21097097 | E9: =E8/E4 -> 0.19811082 | G9: Admitted Pts % | H9: =H8/H4 -> #DIV/0! | I9: =I8/I4 -> #DIV/0! | J9: =J8/J4 -> #DIV/0! | K9: =K8/K4 -> #DIV/0!
A10: Admitted Pts ALOS | B10: 459 | C10: 448 | D10: 362 | E10: =((B10*B8)+(C10*C8)+(D10*D8))/SUM(B8:D8) -> 419.28799 | G10: Admitted Pts ALOS | K10: =SUM(H10:J10) -> 0 | M10: Joint Venture - Q3 2015
A11: Departed Pts % | B11: =B12/B4 -> 0.78843609 | C11: =C12/C4 -> 0.82894737 | D11: =D12/D4 -> 0.78902903 | E11: =E12/E4 -> 0.80188918 | G11: Departed Pts % | H11: =H12/H4 -> #DIV/0! | I11: =I12/I4 -> #DIV/0! | J11: =J12/J4 -> #DIV/0! | K11: =K12/K4 -> #DIV/0! | M11: Total Pts | N11: Arrival to Provider Greet | O11: Duplicate MSE | P11: Admitted Pts ALOS | Q11: Departed pts ALOS | R11: LPMSE + LPT | S11: AMA
A12: Departed Pts | B12: =B4-B8 -> 5959 | C12: =C4-C8 -> 6426 | D12: =D4-D8 -> 6631 | E12: =SUM(B12:D12) -> 19016 | G12: Departed Pts | K12: =SUM(H12:J12) -> 0
A13: Departed pts ALOS | B13: 186 | C13: 194 | D13: 173 | E13: =((B13*B12)+(C13*C12)+(D13*D12))/SUM(B12:D12) -> 184.17023 | G13: Departed pts ALOS | K13: =SUMPRODUCT(H13:J13,H12:J12)/SUM(H12:J12) -> #DIV/0! | M13: =SUM(E4+E37+E53+E69) -> 50880 | N13: =((B5*B$4)+(C5*C$4)+(D5*D$4)+(B38*B$37)+(C38*C$37)+(D38*D$37)+(B54*B$53)+(C54*C$53)+(D54*D$53)+(B70*B$69)+(C70*C$69)+(D70*D$69))/SUM(E$69,E$53,E$37,E$4) -> 11.658943 | O13: =SUM(E6,E39,E55,E71) -> 1280 | P13: =((B10*B8)+(C10*C8)+(D10*D8)+(B43*B41)+(C43*C41)+(D43*D41)+(B59*B57)+(C59*C57)+(D59*D57)+(B75*B73)+(C75*C73)+(D75*D73))/SUM(E$73,E$57,E$41,E$8) -> 384.60894 | Q13: =((B12*B13)+(C12*C13)+(D12*D13)+(B45*B46)+(C45*C46)+(D45*D46)+(B61*B62)+(C61*C62)+(D61*D62)+(B77*B78)+(C77*C78)+(D77*D78))/SUM(E$12,E$45,E$61,E$77) -> 170.38159 | R13: =SUM(E14,E47,E63,E79) -> 1323 | S13: =SUM(E16,E49,E65,E81) -> 664
A14: LPMSE + LPT | B14: =3+284 -> 287 | C14: 305 | D14: 146 | E14: =SUM(B14:D14) -> 738 | G14: LPMSE + LPT | K14: =SUM(H14:J14) -> 0 | O14: =(O13/M13) -> 0.025157233 | R14: =R13/M13 -> 0.026002358 | S14: =S13/M13 -> 0.013050314
A15: LPMSE + LPT % | B15: =B14/B4 -> 0.037973009 | C15: =C14/C4 -> 0.039344685 | D15: =D14/D4 -> 0.01737268 | E15: =E14/E4 -> 0.031120857 | G15: LPMSE + LPT % | H15: =H14/H4 -> #DIV/0! | I15: =I14/I4 -> #DIV/0! | J15: =J14/J4 -> #DIV/0! | K15: =K14/K4 -> #DIV/0!
A16: AMA | B16: 54 | C16: 47 | D16: 55 | E16: =SUM(B16:D16) -> 156 | G16: AMA | K16: =SUM(H16:J16) -> 0
A17: AMA % | B17: =B16/B4 -> 0.0071447473 | C17: =C16/C4 -> 0.0060629515 | D17: =D16/D4 -> 0.0065445026 | E17: =E16/E4 -> 0.0065783925 | G17: AMA % | H17: =H16/H4 -> #DIV/0! | I17: =I16/I4 -> #DIV/0! | J17: =J16/J4 -> #DIV/0! | K17: =K16/K4 -> #DIV/0!
A18: Kendall PEDS | G18: Kendall PEDS
A20: Total Patients | B20: 1713 | C20: 2067 | D20: 2197 | E20: =SUM(B20:D20) -> 5977 | G20: Total Patients | K20: =SUM(H20:J20) -> 0
A21: Arrival to Provider Greet | E21: =((B21*B20)+(C21*C20)+(D21*D20))/SUM(B20:D20) -> 0 | G21: Arrival to Provider Greet | K21: =SUMPRODUCT(H21:J21,H20:J20)/SUM(H20:J20) -> #DIV/0!
A22: Duplicate MSE | E22: =SUM(B22:D22) -> 0 | G22: Duplicate MSE | K22: =SUM(H22:J22) -> 0
A23: Duplicate MSE % | B23: =B22/B20 -> 0 | C23: =C22/C20 -> 0 | D23: =D22/D20 -> 0 | E23: =E22/E20 -> 0 | G23: Duplicate MSE % | H23: =H22/H20 -> #DIV/0! | I23: =I22/I20 -> #DIV/0! | J23: =J22/J20 -> #DIV/0! | K23: =K22/K20 -> #DIV/0!
A24: Admitted Pts | E24: =SUM(B24:D24) -> 0 | G24: Admitted Pts | K24: =SUM(H24:J24) -> 0
A25: Admitted Pts % | B25: =B24/B20 -> 0 | C25: =C24/C20 -> 0 | D25: =D24/D20 -> 0 | E25: =E24/E20 -> 0 | G25: Admitted Pts % | H25: =H24/H20 -> #DIV/0! | I25: =I24/I20 -> #DIV/0! | J25: =J24/J20 -> #DIV/0! | K25: =K24/K20 -> #DIV/0!
A26: Admitted Pts ALOS | E26: =((B26*B24)+(C26*C24)+(D26*D24))/SUM(B24:D24) -> #DIV/0! | G26: Admitted Pts ALOS | K26: =SUM(H26:J26) -> 0
A27: Departed Pts % | B27: =B28/B20 -> 0 | C27: =C28/C20 -> 0 | D27: =D28/D20 -> 0 | E27: =E28/E20 -> 0 | G27: Departed Pts % | H27: =H28/H20 -> #DIV/0! | I27: =I28/I20 -> #DIV/0! | J27: =J28/J20 -> #DIV/0! | K27: =K28/K20 -> #DIV/0!
A28: Departed Pts | E28: =SUM(B28:D28) -> 0 | G28: Departed Pts | K28: =SUM(H28:J28) -> 0
A29: Departed pts ALOS | E29: =((B29*B28)+(C29*C28)+(D29*D28))/SUM(B28:D28) -> #DIV/0! | G29: Departed pts ALOS | K29: =SUMPRODUCT(H29:J29,H28:J28)/SUM(H28:J28) -> #DIV/0!
A30: LPMSE + LPT | E30: =SUM(B30:D30) -> 0 | G30: LPMSE + LPT | K30: =SUM(H30:J30) -> 0
A31: LPMSE + LPT % | B31: =B30/B20 -> 0 | C31: =C30/C20 -> 0 | D31: =D30/D20 -> 0 | E31: =E30/E20 -> 0 | G31: LPMSE + LPT % | H31: =H30/H20 -> #DIV/0! | I31: =I30/I20 -> #DIV/0! | J31: =J30/J20 -> #DIV/0! | K31: =K30/K20 -> #DIV/0!
A32: AMA | E32: =SUM(B32:D32) -> 0 | G32: AMA | K32: =SUM(H32:J32) -> 0
A33: AMA % | B33: =B32/B20 -> 0 | C33: =C32/C20 -> 0 | D33: =D32/D20 -> 0 | E33: =E32/E20 -> 0 | G33: AMA % | H33: =H32/H20 -> #DIV/0! | I33: =I32/I20 -> #DIV/0! | J33: =J32/J20 -> #DIV/0! | K33: =K32/K20 -> #DIV/0!
A35: JFK Main | G35: JFK Main
A37: Total Pts | B37: 7515 | C37: 7460 | D37: 8153 | E37: =SUM(B37:D37) -> 23128 | G37: Total Pts | K37: =SUM(H37:J37) -> 0
A38: Arrival to Provider Greet | B38: 10 | C38: 9 | D38: 10 | E38: =((B38*B37)+(C38*C37)+(D38*D37))/SUM(B37:D37) -> 9.6774473 | G38: Arrival to Provider Greet | K38: =SUMPRODUCT(H38:J38,H37:J37)/SUM(H37:J37) -> #DIV/0!
A39: Duplicate MSE | B39: 303 | C39: 308 | D39: 143 | E39: =SUM(B39:D39) -> 754 | G39: Duplicate MSE | K39: =SUM(H39:J39) -> 0
A40: Duplicate MSE % | B40: =B39/B37 -> 0.040319361 | C40: =C39/C37 -> 0.041286863 | D40: =D39/D37 -> 0.017539556 | E40: =E39/E37 -> 0.032601176 | G40: Duplicate MSE % | H40: =H39/H37 -> #DIV/0! | I40: =I39/I37 -> #DIV/0! | J40: =J39/J37 -> #DIV/0! | K40: =K39/K37 -> #DIV/0!
A41: Admitted Pts | B41: 3008 | C41: 2853 | D41: 3055 | E41: =SUM(B41:D41) -> 8916 | G41: Admitted Pts | K41: =SUM(H41:J41) -> 0
A42: Admitted Pts % | B42: =B41/B37 -> 0.40026613 | C42: =C41/C37 -> 0.38243968 | D42: =D41/D37 -> 0.3747087 | E42: =E41/E37 -> 0.38550675 | G42: Admitted Pts % | H42: =H41/H37 -> #DIV/0! | I42: =I41/I37 -> #DIV/0! | J42: =J41/J37 -> #DIV/0! | K42: =K41/K37 -> #DIV/0!
A43: Admitted Pts ALOS | B43: 352 | C43: 392 | D43: 367 | E43: =((B43*B41)+(C43*C41)+(D43*D41))/SUM(B41:D41) -> 369.9391 | G43: Admitted Pts ALOS | K43: =SUM(H43:J43) -> 0
...

Sheet JV DATA YTD
B1: 42370 | C1: 42401 | D1: 42430 | E1: 42461 | F1: 42491 | G1: 42522 | H1: 42552 | I1: 42583 | J1: 42614 | K1: 42644 | L1: 42675 | M1: 42705 | N1: 2016 YTD
A2: Kendall
P3: YTD
A4: Total Pts | B4: 7558 | C4: 7752 | D4: 8404 | N4: =SUM(B4:M4) -> 23714 | P4: Total Pts | Q4: Arr to Greet | R4: Duplicate MSE | S4: Departed pts ALOS | T4: LPMSE + LPT | U4: AMA
A5: Arrival to Provider Greet (Min) | B5: 16 | C5: 16 | D5: 11 | N5: =SUMPRODUCT(B5:K5,B4:K4)/SUM(B4:K4) -> 14.228051
A6: Duplicate MSE | B6: 143 | C6: 171 | D6: 142 | N6: =SUM(B6:M6) -> 456 | P6: =SUM(N4,N36,N52,N68) -> 50880 | Q6: =((N5*N4)+(N37*N36)+(N53*N52)+(N69*N68))/SUM(N68,N52,N36,N4) -> 11.658943 | R6: =SUM(N6,N38,N54,N70) -> 1280 | S6: =((N13*N12)+(N45*N44)+(N61*N60)+(N77*N76))/SUM(N76,N60,N44,N12) -> 170.38159 | T6: =SUM(N14,N46,N62,N78) -> 1323 | U6: =SUM(N16,N48,N64,N80) -> 664
A7: Duplicate MSE % | B7: =B6/B4 -> 0.018920349 | C7: =IFERROR(C6/C4,0) -> 0.022058824 | D7: =IFERROR(D6/D4,0) -> 0.016896716 | E7: =IFERROR(E6/E4,0) -> 0 | F7: =IFERROR(F6/F4,0) -> 0 | G7: =IFERROR(G6/G4,0) -> 0 | H7: =IFERROR(H6/H4,0) -> 0 | I7: =IFERROR(I6/I4,0) -> 0 | J7: =IFERROR(J6/J4,0) -> 0 | ... M7: =IFERROR(M6/M4,0) -> 0 | N7: =N6/N4 -> 0.019229147 | R7: =R6/P6 -> 0.025157233 | T7: =T6/P6 -> 0.026002358 | U7: =U6/P6 -> 0.013050314
A8: Admitted Pts (HCA Dashboard) | B8: 1599 | C8: 1326 | D8: 1773 | N8: =SUM(B8:M8) -> 4698
A9: % Admitted Pts (HCA Dashboard) | B9: =B8/B4 -> 0.21156391 | C9: =IFERROR(C8/C4,0) -> 0.17105263 | D9: =IFERROR(D8/D4,0) -> 0.21097097 | E9: =IFERROR(E8/E4,0) -> 0 | F9: =IFERROR(F8/F4,0) -> 0 | G9: =IFERROR(G8/G4,0) -> 0 | H9: =IFERROR(H8/H4,0) -> 0 | I9: =IFERROR(I8/I4,0) -> 0 | J9: =IFERROR(J8/J4,0) -> 0 | ... M9: =IFERROR(M8/M4,0) -> 0 | N9: =N8/N4 -> 0.19811082
A10: Admitted Pts ALOS (HCA Dashboard) | B10: 459 | C10: 448 | D10: 362 | N10: =SUM(B10:M10) -> 1269 | P10: As of January
A11: Departed Pts % | B11: =B12/B4 -> 0.78843609 | C11: =IFERROR(C12/C4,0) -> 0.82894737 | D11: =IFERROR(D12/D4,0) -> 0.78902903 | E11: =IFERROR(E12/E4,0) -> 0 | F11: =IFERROR(F12/F4,0) -> 0 | G11: =IFERROR(G12/G4,0) -> 0 | H11: =IFERROR(H12/H4,0) -> 0 | I11: =IFERROR(I12/I4,0) -> 0 | J11: =IFERROR(J12/J4,0) -> 0 | ... M11: =IFERROR(M12/M4,0) -> 0 | N11: =N12/N4 -> 0.80188918 | P11: Total Pts | Q11: Arr to Greet | R11: Duplicate MSE | S11: Departed pts ALOS | T11: LPMSE + LPT | U11: AMA
A12: Departed Pts | B12: =B4-B8 -> 5959 | C12: =C4-C8 -> 6426 | D12: =D4-D8 -> 6631 | N12: =SUM(B12:M12) -> 19016
A13: Departed pts ALOS | B13: 186 | C13: 194 | D13: 173 | N13: =SUMPRODUCT(B13:M13,B12:M12)/SUM(B12:M12) -> 184.17023 | P13: =SUM(B4,B36,B52,B68) -> 16405 | Q13: =((B5*B4)+(B37*B36)+(B53*B52)+(B69*B68))/SUM(B68,B52,B36,B4) -> 12.597318 | R13: =SUM(B6,B38,B54,B70) -> 480 | S13: =((B13*B12)+(B45*B44)+(B61*B60)+(B77*B76))/SUM(B76,B60,B44,B12) -> 167.50852 | T13: =SUM(B14,B46,B62,B78) -> 383 | U13: =SUM(B16,B48,B64,B80) -> 197
A14: LPMSE + LPT (HCA Dashboard) | B14: =3+284 -> 287 | C14: 305 | D14: 146 | N14: =SUM(B14:M14) -> 738 | R14: =R13/P13 -> 0.029259372 | T14: =T13/P13 -> 0.023346541 | U14: =U13/P13 -> 0.012008534
A15: LPMSE + LPT % | B15: =B14/B4 -> 0.037973009 | C15: =IFERROR(C14/C4,0) -> 0.039344685 | D15: =IFERROR(D14/D4,0) -> 0.01737268 | E15: =IFERROR(E14/E4,0) -> 0 | F15: =IFERROR(F14/F4,0) -> 0 | G15: =IFERROR(G14/G4,0) -> 0 | H15: =IFERROR(H14/H4,0) -> 0 | I15: =IFERROR(I14/I4,0) -> 0 | J15: =IFERROR(J14/J4,0) -> 0 | ... M15: =IFERROR(M14/M4,0) -> 0 | N15: =N14/N4 -> 0.031120857
A16: AMA | B16: 54 | C16: 47 | D16: 55 | N16: =SUM(B16:M16) -> 156
A17: AMA % | B17: =B16/B4 -> 0.0071447473 | C17: =IFERROR(C16/C4,0) -> 0.0060629515 | D17: =IFERROR(D16/D4,0) -> 0.0065445026 | E17: =IFERROR(E16/E4,0) -> 0 | F17: =IFERROR(F16/F4,0) -> 0 | G17: =IFERROR(G16/G4,0) -> 0 | H17: =IFERROR(H16/H4,0) -> 0 | I17: =IFERROR(I16/I4,0) -> 0 | J17: =IFERROR(J16/J4,0) -> 0 | ... M17: =IFERROR(M16/M4,0) -> 0 | N17: =N16/N4 -> 0.0065783925
A18: Kendall PEDS
A20: Total Pts | B20: 7558 | C20: 2067 | D20: 2197 | N20: =SUM(B20:M20) -> 11822
A21: Arrival to Provider Greet (Min) | N21: =SUMPRODUCT(B21:K21,B20:K20)/SUM(B20:K20) -> 0
A22: Duplicate MSE | N22: =SUM(B22:M22) -> 0
A23: Duplicate MSE % | B23: =B22/B20 -> 0 | C23: =IFERROR(C22/C20,0) -> 0 | D23: =IFERROR(D22/D20,0) -> 0 | E23: =IFERROR(E22/E20,0) -> 0 | F23: =IFERROR(F22/F20,0) -> 0 | G23: =IFERROR(G22/G20,0) -> 0 | H23: =IFERROR(H22/H20,0) -> 0 | I23: =IFERROR(I22/I20,0) -> 0 | J23: =IFERROR(J22/J20,0) -> 0 | ... M23: =IFERROR(M22/M20,0) -> 0 | N23: =N22/N20 -> 0
A24: Admitted Pts (HCA Dashboard) | N24: =SUM(B24:M24) -> 0
A25: % Admitted Pts (HCA Dashboard) | B25: =B24/B20 -> 0 | C25: =IFERROR(C24/C20,0) -> 0 | D25: =IFERROR(D24/D20,0) -> 0 | E25: =IFERROR(E24/E20,0) -> 0 | F25: =IFERROR(F24/F20,0) -> 0 | G25: =IFERROR(G24/G20,0) -> 0 | H25: =IFERROR(H24/H20,0) -> 0 | I25: =IFERROR(I24/I20,0) -> 0 | J25: =IFERROR(J24/J20,0) -> 0 | ... M25: =IFERROR(M24/M20,0) -> 0 | N25: =N24/N20 -> 0
A26: Admitted Pts ALOS (HCA Dashboard) | N26: =SUM(B26:M26) -> 0
A27: Departed Pts % | B27: =B28/B20 -> 1 | C27: =IFERROR(C28/C20,0) -> 1 | D27: =IFERROR(D28/D20,0) -> 1 | E27: =IFERROR(E28/E20,0) -> 0 | F27: =IFERROR(F28/F20,0) -> 0 | G27: =IFERROR(G28/G20,0) -> 0 | H27: =IFERROR(H28/H20,0) -> 0 | I27: =IFERROR(I28/I20,0) -> 0 | J27: =IFERROR(J28/J20,0) -> 0 | ... M27: =IFERROR(M28/M20,0) -> 0 | N27: =N28/N20 -> 1
A28: Departed Pts | B28: =B20-B24 -> 7558 | C28: =C20-C24 -> 2067 | D28: =D20-D24 -> 2197 | N28: =SUM(B28:M28) -> 11822
A29: Departed pts ALOS | N29: =SUMPRODUCT(B29:M29,B28:M28)/SUM(B28:M28) -> 0
A30: LPMSE + LPT (HCA Dashboard) | N30: =SUM(B30:M30) -> 0
A31: LPMSE + LPT % | B31: =B30/B20 -> 0 | C31: =IFERROR(C30/C20,0) -> 0 | D31: =IFERROR(D30/D20,0) -> 0 | E31: =IFERROR(E30/E20,0) -> 0 | F31: =IFERROR(F30/F20,0) -> 0 | G31: =IFERROR(G30/G20,0) -> 0 | H31: =IFERROR(H30/H20,0) -> 0 | I31: =IFERROR(I30/I20,0) -> 0 | J31: =IFERROR(J30/J20,0) -> 0 | ... M31: =IFERROR(M30/M20,0) -> 0 | N31: =N30/N20 -> 0
A32: AMA | N32: =SUM(B32:M32) -> 0
A33: AMA % | B33: =B32/B20 -> 0 | C33: =IFERROR(C32/C20,0) -> 0 | D33: =IFERROR(D32/D20,0) -> 0 | E33: =IFERROR(E32/E20,0) -> 0 | F33: =IFERROR(F32/F20,0) -> 0 | G33: =IFERROR(G32/G20,0) -> 0 | H33: =IFERROR(H32/H20,0) -> 0 | I33: =IFERROR(I32/I20,0) -> 0 | J33: =IFERROR(J32/J20,0) -> 0 | ... M33: =IFERROR(M32/M20,0) -> 0 | N33: =N32/N20 -> 0
A34: JFK Main
A36: Total Pts | B36: 7515 | C36: 7460 | D36: 8153 | N36: =SUM(B36:M36) -> 23128
A37: Arrival to Provider Greet (Min) | B37: 10 | C37: 9 | D37: 10 | N37: =SUMPRODUCT(B37:M37,B36:M36)/SUM(B36:M36) -> 9.6774473
A38: Duplicate MSE | B38: 303 | C38: 308 | D38: 143 | N38: =SUM(B38:M38) -> 754
A39: Duplicate MSE % | B39: =B38/B36 -> 0.040319361 | C39: =IFERROR(C38/C36,0) -> 0.041286863 | D39: =IFERROR(D38/D36,0) -> 0.017539556 | E39: =IFERROR(E38/E36,0) -> 0 | F39: =IFERROR(F38/F36,0) -> 0 | G39: =IFERROR(G38/G36,0) -> 0 | H39: =IFERROR(H38/H36,0) -> 0 | I39: =IFERROR(I38/I36,0) -> 0 | J39: =IFERROR(J38/J36,0) -> 0 | ... M39: =IFERROR(M38/M36,0) -> 0 | N39: =N38/N36 -> 0.032601176
A40: Admitted Pts (HCA Dashboard) | B40: 3008 | C40: 2853 | D40: 3055 | N40: =SUM(B40:M40) -> 8916
A41: Admitted Pts % (HCA Dashboard) | B41: =B40/B36 -> 0.40026613 | C41: =IFERROR(C40/C36,0) -> 0.38243968 | D41: =IFERROR(D40/D36,0) -> 0.3747087 | E41: =IFERROR(E40/E36,0) -> 0 | F41: =IFERROR(F40/F36,0) -> 0 | G41: =IFERROR(G40/G36,0) -> 0 | H41: =IFERROR(H40/H36,0) -> 0 | I41: =IFERROR(I40/I36,0) -> 0 | J41: =IFERROR(J40/J36,0) -> 0 | ... M41: =IFERROR(M40/M36,0) -> 0 | N41: =N40/N36 -> 0.38550675
A42: Admitted Pts ALOS (HCA Dashboard) | B42: 352 | C42: 392 | D42: 367 | N42: =SUM(B42:M42) -> 1111
...

Sheet EDP PREMIUM LABOR (COST & HRS)
B17: PREMIUM HOURS
B18: Month | C18: DIVISION TOTAL | F18: BAPTIST | I18: JFK | L18: JFK BB | O18: JFK PBG | R18: JUPITER | U18: KENDALL | X18: MOBERLY | AA18: MONROE | AD18: OCALA | AG18: SAN RAMON | AJ18: ST MARY'S | AM18: W MARION QC | AP18: W MARION | AS18: WESTCHESTER | AV18: PROVIDENCE | AY18: ST JOHN | BB18: OSCEOLA
C19: Transition Team | D19: Shift Incentive | E19: Locum | F19: Transition Team | G19: Shift Incentive | H19: Locum | I19: Transition Team | J19: Shift Incentive | K19: Locum | L19: Transition Team | M19: Shift Incentive | N19: Locum | O19: Transition Team | P19: Shift Incentive | Q19: Locum | R19: Transition Team | S19: Shift Incentive | T19: Locum | U19: Transition Team | V19: Shift Incentive | W19: Locum | X19: Transition Team | Y19: Shift Incentive | Z19: Locum | AA19: Transition Team | AB19: Shift Incentive | AC19: Locum | AD19: Transition Team | AE19: Shift Incentive | AF19: Locum | AG19: Transition Team | AH19: Shift Incentive | AI19: Locum | AJ19: Transition Team | AK19: Shift Incentive | AL19: Locum | AM19: Transition Team | AN19: Shift Incentive | AO19: Locum | AP19: Transition Team | AQ19: Shift Incentive | AR19: Locum | AS19: Transition Team | AT19: Shift Incentive | AU19: Locum | AV19: Transition Team | AW19: Shift Incentive | AX19: Locum | AY19: Transition Team | AZ19: Shift Incentive | BA19: Locum | BB19: Transition Team | BC19: Shift Incentive | BD19: Locum
B20: 42370 | C20: =COMPOSITE!B$199 -> 2542 | D20: =COMPOSITE!C$199 -> 69 | E20: =COMPOSITE!D$199 -> 482 | F20: =COMPOSITE!$B$176 -> 0 | G20: =COMPOSITE!$C$176 -> 0 | I20: =COMPOSITE!$B$177 -> 0 | J20: =COMPOSITE!$C$177 -> 0 | K20: =COMPOSITE!$D$177 -> 0 | L20: =COMPOSITE!$B$178 -> 60 | M20: =COMPOSITE!C$178 -> 24 | O20: =COMPOSITE!B$179 -> 0 | P20: =COMPOSITE!C$179 -> 24 | Q20: =COMPOSITE!D$179 -> 0 | R20: =COMPOSITE!B$180 -> 1.5 | S20: =COMPOSITE!C$180 -> 0 | T20: =COMPOSITE!D$180 -> 0 | U20: =COMPOSITE!B$181 -> 452 | V20: =COMPOSITE!C$181 -> 0 | W20: =COMPOSITE!D$181 -> 0 | X20: =COMPOSITE!B$182 -> 165 | Y20: =COMPOSITE!C$182 -> 0 | Z20: =COMPOSITE!D$182 -> 0 | AA20: =COMPOSITE!B183 -> 0 | AB20: =COMPOSITE!C183 -> 0 | AC20: =COMPOSITE!D183 -> 132 | AD20: =COMPOSITE!B$184 -> 608.5 | AE20: =COMPOSITE!C$184 -> 0 | AF20: =COMPOSITE!D$184 -> 0 | AG20: =COMPOSITE!B185 -> 0 | AH20: =COMPOSITE!C185 -> 0 | AI20: =COMPOSITE!D185 -> 0 | AJ20: =COMPOSITE!B$186 -> 0 | AK20: =COMPOSITE!C$186 -> 21 | AL20: =COMPOSITE!D$186 -> 0 | AM20: =COMPOSITE!B$188 -> 24 | AN20: =COMPOSITE!C$188 -> 0 | AO20: =COMPOSITE!D$188 -> 0 | AP20: =COMPOSITE!B$187 -> 297 | AQ20: =COMPOSITE!C$187 -> 0 | AR20: =COMPOSITE!D$187 -> 0 | AS20: =COMPOSITE!B$189 -> 324 | AT20: =COMPOSITE!C$189 -> 0 | AU20: =COMPOSITE!D$189 -> 0 | AV20: =COMPOSITE!B190 -> 174 | AW20: =COMPOSITE!C190 -> 0 | AX20: =COMPOSITE!D190 -> 0 | AY20: =COMPOSITE!B191 -> 0 | AZ20: =COMPOSITE!C191 -> 0 | BA20: =COMPOSITE!D191 -> 26 | BB20: =COMPOSITE!B192 -> 436 | BC20: =COMPOSITE!C192 -> 0 | BD20: =COMPOSITE!D192 -> 300
B21: 42401 | C21: =COMPOSITE!E$199 -> 2253 | D21: =COMPOSITE!F$199 -> 111 | E21: =COMPOSITE!G$199 -> 594 | F21: =COMPOSITE!$E$176 -> 0 | G21: =COMPOSITE!$F$176 -> 0 | I21: =COMPOSITE!$E$177 -> 0 | J21: =COMPOSITE!$F$177 -> 0 | K21: =COMPOSITE!$G$177 -> 0 | L21: =COMPOSITE!$E$178 -> 24 | M21: =COMPOSITE!F$178 -> 48 | O21: =COMPOSITE!E$179 -> 0 | P21: =COMPOSITE!F$179 -> 24 | Q21: =COMPOSITE!G$179 -> 0 | R21: =COMPOSITE!E$180 -> 0 | S21: =COMPOSITE!F$180 -> 0 | T21: =COMPOSITE!G$180 -> 0 | U21: =COMPOSITE!E$181 -> 173 | V21: =COMPOSITE!F$181 -> 10 | W21: =COMPOSITE!G$181 -> 91 | X21: =COMPOSITE!E$182 -> 180 | Y21: =COMPOSITE!F$182 -> 0 | Z21: =COMPOSITE!G$182 -> 0 | AA21: =COMPOSITE!E183 -> 187 | AB21: =COMPOSITE!F183 -> 0 | AC21: =COMPOSITE!G183 -> 359 | AD21: =COMPOSITE!E$184 -> 698 | AE21: =COMPOSITE!F$184 -> 0 | AF21: =COMPOSITE!G$184 -> 13 | AG21: =COMPOSITE!E185 -> 0 | AH21: =COMPOSITE!F185 -> 0 | AI21: =COMPOSITE!G185 -> 0 | AJ21: =COMPOSITE!E$186 -> 0 | AK21: =COMPOSITE!F$186 -> 17 | AL21: =COMPOSITE!G$186 -> 0 | AM21: =COMPOSITE!E$188 -> 67 | AN21: =COMPOSITE!F$188 -> 12 | AO21: =COMPOSITE!G$188 -> 0 | AP21: =COMPOSITE!E$187 -> 236 | AQ21: =COMPOSITE!F$187 -> 0 | AR21: =COMPOSITE!G$187 -> 13 | AS21: =COMPOSITE!E$189 -> 36 | AT21: =COMPOSITE!F$189 -> 0 | AU21: =COMPOSITE!G$189 -> 0 | AV21: =COMPOSITE!E190 -> 186 | AW21: =COMPOSITE!F190 -> 0 | AX21: =COMPOSITE!G190 -> 0 | AY21: =COMPOSITE!E191 -> 72 | AZ21: =COMPOSITE!F191 -> 0 | BA21: =COMPOSITE!G191 -> 24 | BB21: =COMPOSITE!E192 -> 370 | BC21: =COMPOSITE!F192 -> 0 | BD21: =COMPOSITE!G192 -> 94
B22: 42430 | C22: =COMPOSITE!H$199 -> 2443 | D22: =COMPOSITE!I$199 -> 34 | E22: =COMPOSITE!J$199 -> 438 | F22: =COMPOSITE!$H$176 -> 0 | G22: =COMPOSITE!$I$176 -> 0 | I22: =COMPOSITE!$H$177 -> 0 | J22: =COMPOSITE!$I$177 -> 0 | K22: =COMPOSITE!$J$177 -> 0 | L22: =COMPOSITE!$H$178 -> 48 | M22: =COMPOSITE!I$178 -> 24 | O22: =COMPOSITE!H$179 -> 12 | P22: =COMPOSITE!I$179 -> 0 | Q22: =COMPOSITE!J$179 -> 0 | R22: =COMPOSITE!H$180 -> 130 | S22: =COMPOSITE!I$180 -> 0 | T22: =COMPOSITE!J$180 -> 0 | U22: =COMPOSITE!H$181 -> 197 | V22: =COMPOSITE!I$181 -> 10 | W22: =COMPOSITE!J$181 -> 101 | X22: =COMPOSITE!H$182 -> 240 | Y22: =COMPOSITE!I$182 -> 0 | Z22: =COMPOSITE!J$182 -> 0 | AA22: =COMPOSITE!H183 -> 217.5 | AB22: =COMPOSITE!I183 -> 0 | AC22: =COMPOSITE!J183 -> 195 | AD22: =COMPOSITE!H$184 -> 752.5 | AE22: =COMPOSITE!I$184 -> 0 | AF22: =COMPOSITE!J$184 -> 0 | AG22: =COMPOSITE!H185 -> 0 | AH22: =COMPOSITE!I185 -> 0 | AI22: =COMPOSITE!J185 -> 0 | AJ22: =COMPOSITE!H$186 -> 0 | AK22: =COMPOSITE!I$186 -> 0 | AL22: =COMPOSITE!J$186 -> 0 | AM22: =COMPOSITE!H$188 -> 54 | AN22: =COMPOSITE!I$188 -> 0 | AO22: =COMPOSITE!J$188 -> 0 | AP22: =COMPOSITE!H$187 -> 250 | AQ22: =COMPOSITE!I$187 -> 0 | AR22: =COMPOSITE!J$187 -> 0 | AS22: =COMPOSITE!H$189 -> 36 | AT22: =COMPOSITE!I$189 -> 0 | AU22: =COMPOSITE!J$189 -> 0 | AV22: =COMPOSITE!H191 -> 48 | AW22: =COMPOSITE!I190 -> 0 | AX22: =COMPOSITE!J190 -> 0 | AY22: =COMPOSITE!H191 -> 48 | AZ22: =COMPOSITE!I191 -> 0 | BA22: =COMPOSITE!J191 -> 0 | BB22: =COMPOSITE!H192 -> 257 | BC22: =COMPOSITE!I192 -> 0 | BD22: =COMPOSITE!J192 -> 142
B23: 42461 | C23: =COMPOSITE!K$199 -> 2728 | D23: =COMPOSITE!L$199 -> 240 | E23: =COMPOSITE!J$199 -> 438
B24: 42491
B25: 42522
B26: 42552
B27: 42583
B28: 42614
B29: 42644
B30: 42675
B31: 42705
B32: YTD Total | C32: =SUM(C20:C31) -> 9966 | D32: =SUM(D20:D31) -> 454 | E32: =SUM(E20:E31) -> 1952 | F32: =SUM(F20:F31) -> 0 | G32: =SUM(G20:G31) -> 0 | H32: =SUM(H20:H31) -> 0 | I32: =SUM(I20:I31) -> 0 | J32: =SUM(J20:J31) -> 0 | ... BD32: =SUM(BD20:BD31) -> 536
B34: PREMIUM COSTS
B35: Month | C35: DIVISION TOTAL | F35: BAPTIST | I35: JFK | L35: JFK BB | O35: JFK PBG | R35: JUPITER | U35: KENDALL | X35: MOBERLY | AA35: MONROE | AD35: OCALA | AG35: SAN RAMON | AJ35: ST MARY'S | AM35: W Marion QC | AP35: W MARION | AS35: WESTCHESTER | AV35: PROVIDENCE | AY35: ST JOHN | BB35: OSCEOLA
C36: Transition Team | D36: Shift Incentive | E36: Locum | F36: Transition Team | G36: Shift Incentive | H36: Locum | I36: Transition Team | J36: Shift Incentive | K36: Locum | L36: Transition Team | M36: Shift Incentive | N36: Locum | O36: Transition Team | P36: Shift Incentive | Q36: Locum | R36: Transition Team | S36: Shift Incentive | T36: Locum | U36: Transition Team | V36: Shift Incentive | W36: Locum | X36: Transition Team | Y36: Shift Incentive | Z36: Locum | AA36: Transition Team | AB36: Shift Incentive | AC36: Locum | AD36: Transition Team | AE36: Shift Incentive | AF36: Locum | AG36: Transition Team | AH36: Shift Incentive | AI36: Locum | AJ36: Transition Team | AK36: Shift Incentive | AL36: Locum | AM36: Transition Team | AN36: Shift Incentive | AO36: Locum | AP36: Transition Team | AQ36: Shift Incentive | AR36: Locum | AS36: Transition Team | AT36: Shift Incentive | AU36: Locum | AV36: Transition Team | AW36: Shift Incentive | AX36: Locum | AY36: Transition Team | AZ36: Shift Incentive | BA36: Locum | BB36: Transition Team | BC36: Shift Incentive | BD36: Locum
B37: 42370 | C37: =COMPOSITE!B$226 -> 479749.4 | D37: =COMPOSITE!C$226 -> 42081 | E37: =COMPOSITE!D$226 -> 0 | F37: =COMPOSITE!$B$204 -> 0 | G37: =COMPOSITE!$C$204 -> 240 | H37: =COMPOSITE!$D$204 -> 0 | I37: =COMPOSITE!$B$205 -> 0 | J37: =COMPOSITE!$C$205 -> 0 | K37: =COMPOSITE!$D$205 -> 0 | L37: =COMPOSITE!B$206 -> 10500 | M37: =COMPOSITE!C$206 -> 8600 | N37: =COMPOSITE!$D$206 -> 0 | O37: =COMPOSITE!B$207 -> 0 | P37: =COMPOSITE!C$207 -> 4011 | Q37: =COMPOSITE!$D$207 -> 0 | R37: =COMPOSITE!B$208 -> 300 | S37: =COMPOSITE!C$208 -> 0 | T37: =COMPOSITE!$D$208 -> 0 | U37: =COMPOSITE!B$209 -> 38000 | V37: =COMPOSITE!C$209 -> 1130 | W37: =COMPOSITE!$D$209 -> 0 | X37: =COMPOSITE!B$210 -> 30420 | Y37: =COMPOSITE!C$210 -> 0 | Z37: =COMPOSITE!$D$209 -> 0 | AA37: =COMPOSITE!B211 -> 42000 | AB37: =COMPOSITE!C211 -> 7000 | AC37: =COMPOSITE!D211 -> 0 | AD37: =COMPOSITE!B$212 -> 126658 | AE37: =COMPOSITE!C$212 -> 4112 | AF37: =COMPOSITE!D212 -> 0 | AG37: =COMPOSITE!B213 -> 0 | AH37: =COMPOSITE!C213 -> 0 | AI37: =COMPOSITE!D213 -> 0 | AJ37: =COMPOSITE!B$214 -> 0 | AK37: =COMPOSITE!C$214 -> 1300 | AL37: =COMPOSITE!D214 -> 0 | AM37: =COMPOSITE!B$216 -> 6000 | AN37: =COMPOSITE!C$216 -> 3988 | AO37: =COMPOSITE!D216 -> 0 | AP37: =COMPOSITE!B$215 -> 57915 | AQ37: =COMPOSITE!C$215 -> 0 | AR37: =COMPOSITE!D215 -> 0 | AS37: =COMPOSITE!B$217 -> 32400 | AT37: =COMPOSITE!C$217 -> 1700 | AU37: =COMPOSITE!D217 | AV37: =COMPOSITE!B218 -> 37410 | AW37: =COMPOSITE!C218 -> 8500 | AX37: =COMPOSITE!D218 -> 0 | AY37: =COMPOSITE!B219 -> 0 | AZ37: =COMPOSITE!C219 -> 500 | BA37: =COMPOSITE!D219 -> 0 | BB37: =COMPOSITE!B220 -> 98146.4 | BC37: =COMPOSITE!C220 -> 1000 | BD37: =COMPOSITE!D220 -> 0
B38: 42401 | C38: =COMPOSITE!E$226 -> 108007.2 | D38: =COMPOSITE!F$226 -> 40083 | E38: =COMPOSITE!G$226 -> 0 | F38: =COMPOSITE!$E$204 -> 0 | G38: =COMPOSITE!$F$204 -> 0 | H38: =COMPOSITE!$G$204 -> 0 | I38: =COMPOSITE!$E$205 -> 0 | J38: =COMPOSITE!$F$205 -> 1500 | K38: =COMPOSITE!$G$205 -> 0 | L38: =COMPOSITE!E$206 -> 1800 | M38: =COMPOSITE!F$206 -> 8000 | N38: =COMPOSITE!$G$206 -> 0 | O38: =COMPOSITE!E$207 -> 0 | P38: =COMPOSITE!F$207 -> 0 | Q38: =COMPOSITE!$G$207 -> 0 | R38: =COMPOSITE!E$208 -> 0 | S38: =COMPOSITE!F$208 -> 1680 | T38: =COMPOSITE!$G$208 -> 0 | U38: =COMPOSITE!E$209 -> 4325 | V38: =COMPOSITE!F$209 -> 2500 | W38: =COMPOSITE!$G$209 -> 0 | X38: =COMPOSITE!E$210 -> 9900 | Y38: =COMPOSITE!F$210 -> 2000 | Z38: =COMPOSITE!$G$209 -> 0 | AA38: =COMPOSITE!E211 -> 14025 | AB38: =COMPOSITE!F211 -> 2000 | AC38: =COMPOSITE!G211 -> 0 | AD38: =COMPOSITE!E$212 -> 29316 | AE38: =COMPOSITE!F$212 -> 3500 | AF38: =COMPOSITE!G212 -> 0 | AG38: =COMPOSITE!E213 -> 5400 | AH38: =COMPOSITE!F213 -> 0 | AI38: =COMPOSITE!G213 -> 0 | AJ38: =COMPOSITE!E$214 -> 0 | AK38: =COMPOSITE!F$214 -> 700 | AL38: =COMPOSITE!G214 -> 0 | AM38: =COMPOSITE!E$216 -> 6030 | AN38: =COMPOSITE!F$216 -> 5443 | AO38: =COMPOSITE!J216 -> 0 | AP38: =COMPOSITE!E$215 -> 12980 | AQ38: =COMPOSITE!F$215 -> 0 | AR38: =COMPOSITE!G215 -> 0 | AS38: =COMPOSITE!E$217 -> 3600 | AT38: =COMPOSITE!F$217 -> 1260 | AU38: =COMPOSITE!G217 | AV38: =COMPOSITE!E218 -> 6510 | AW38: =COMPOSITE!F218 -> 9000 | AX38: =COMPOSITE!G218 -> 0 | AY38: =COMPOSITE!E219 -> 0 | AZ38: =COMPOSITE!F219 -> 0 | BA38: =COMPOSITE!G219 -> 0 | BB38: =COMPOSITE!E220 -> 12950 | BC38: =COMPOSITE!F220 -> 2500 | BD38: =COMPOSITE!G220 -> 0
B39: 42430 | C39: =COMPOSITE!H$226 -> 119379.3 | D39: =COMPOSITE!I$226 -> 39240 | E39: =COMPOSITE!J$226 -> 0 | F39: =COMPOSITE!$H$204 -> 0 | G39: =COMPOSITE!$I$204 -> 0 | H39: =COMPOSITE!$J$204 -> 0 | I39: =COMPOSITE!$H$205 -> 0 | J39: =COMPOSITE!$I$205 -> 6000 | K39: =COMPOSITE!$J$205 -> 0 | L39: =COMPOSITE!H$206 -> 3600 | M39: =COMPOSITE!I$206 -> 4000 | N39: =COMPOSITE!$J$206 -> 0 | O39: =COMPOSITE!H$207 -> 900 | P39: =COMPOSITE!I$207 -> 0 | Q39: =COMPOSITE!$J$207 -> 0 | R39: =COMPOSITE!H$208 -> 6500 | S39: =COMPOSITE!I$208 -> 0 | T39: =COMPOSITE!$J$208 -> 0 | U39: =COMPOSITE!H$209 -> 4925 | V39: =COMPOSITE!I$209 -> 500 | W39: =COMPOSITE!$J$209 -> 0 | X39: =COMPOSITE!E$210 -> 9900 | Y39: =COMPOSITE!FI210 -> 0 | Z39: =COMPOSITE!$J$208 -> 0 | AA39: =COMPOSITE!H211 -> 16312.5 | AB39: =COMPOSITE!I211 -> 3000 | AC39: =COMPOSITE!J213 -> 0 | AD39: =COMPOSITE!H$212 -> 31605 | AE39: =COMPOSITE!I$212 -> 8000 | AF39: =COMPOSITE!J212 -> 0 | AG39: =COMPOSITE!H213 -> 0 | AH39: =COMPOSITE!I213 -> 0 | AI39: =COMPOSITE!J213 -> 0 | AJ39: =COMPOSITE!H$214 -> 0 | AK39: =COMPOSITE!I$214 -> 0 | AL39: =COMPOSITE!J214 -> 0 | AM39: =COMPOSITE!H$216 -> 4860 | AN39: =COMPOSITE!I$216 -> 0 | AO39: =COMPOSITE!J216 -> 0 | AP39: =COMPOSITE!H$215 -> 13750 | AQ39: =COMPOSITE!I$215 -> 1000 | AR39: =COMPOSITE!J215 -> 0 | AS39: =COMPOSITE!H$217 -> 3600 | AT39: =COMPOSITE!I$217 -> 240 | AU39: =COMPOSITE!J217 -> 0 | AV39: =COMPOSITE!H218 -> 5775 | AW39: =COMPOSITE!I218 -> 7000 | AX39: =COMPOSITE!J218 -> 0 | AY39: =COMPOSITE!H219 -> 3600 | AZ39: =COMPOSITE!I219 -> 500 | BA39: =COMPOSITE!J219 -> 0 | BB39: =COMPOSITE!H220 -> 8995 | BC39: =COMPOSITE!I220 -> 0 | BD39: =COMPOSITE!J220 -> 0
B40: 42461
B41: 42491
B42: 42522
B43: 42552
B44: 42583
B45: 42614
B46: 42644
B47: 42675
B48: 42705
B49: YTD Total | C49: =SUM(C37:C48) -> 707135.9 | D49: =SUM(D37:D48) -> 121404 | F49: =SUM(F37:F48) -> 0 | G49: =SUM(G37:G48) -> 240 | I49: =SUM(I37:I48) -> 0 | J49: =SUM(J37:J48) -> 7500 | L49: =SUM(L37:L48) -> 15900 | M49: =SUM(M37:M48) -> 20600 | O49: =SUM(O37:O48) -> 900 | P49: =SUM(P37:P48) -> 4011 | R49: =SUM(R37:R48) -> 6800 | S49: =SUM(S37:S48) -> 1680 | U49: =SUM(U37:U48) -> 47250 | V49: =SUM(V37:V48) -> 4130 | X49: =SUM(X37:X48) -> 50220 | Y49: =SUM(Y37:Y48) -> 2000 | Z49: =SUM(Z37:Z48) -> 0 | AA49: =SUM(AA37:AA48) -> 72337.5 | AB49: =SUM(AB37:AB48) -> 12000 | AD49: =SUM(AD37:AD48) -> 187579 | AE49: =SUM(AE37:AE48) -> 15612 | AG49: =SUM(AG37:AG48) -> 5400 | AH49: =SUM(AH37:AH48) -> 0 | AJ49: =SUM(AJ37:AJ48) -> 0 | AK49: =SUM(AK37:AK48) -> 2000 | AM49: =SUM(AM37:AM48) -> 16890 | AN49: =SUM(AN37:AN48) -> 9431 | AP49: =SUM(AP37:AP48) -> 84645 | AQ49: =SUM(AQ37:AQ48) -> 1000 | AS49: =SUM(AS37:AS48) -> 39600 | AT49: =SUM(AT37:AT48) -> 3200 | AV49: =SUM(AV37:AV48) -> 49695 | AW49: =SUM(AW37:AW48) -> 24500 | AY49: =SUM(AY37:AY48) -> 3600 | AZ49: =SUM(AZ37:AZ48) -> 1000 | BB49: =SUM(BB37:BB48) -> 120091.4 | BC49: =SUM(BC37:BC48) -> 3500

Sheet BUDGET HOURS
B19: ED PHYSICIANS HOURS
B20: Month | C20: DIVISION TOTAL | G20: BAPTIST | I20: JFK | K20: JFK BB | M20: JFK PBG | O20: JUPITER | Q20: KENDALL | S20: MOBERLY | U20: MONROE | W20: OCALA | Y20: SAN RAMON | AA20: ST. MARY'S | AC20: W MARION QC | AE20: W MARION | AG20: WESTCHESTER | AI20: PROVIDENCE | AK20: ST. JOHN | AM20: OSCEOLA | AO20: HUNTERS CREEK | AQ20: CHANDLER | AS20: MERCY GILBERT
C21: EDP Budget | D21: EDP Actual | E21: QC PCP Budget | F21: QC PCP Actual | G21: EDP Budget | H21: EDP Actual | I21: EDP Budget | J21: EDP Actual | K21: EDP Budget | L21: EDP Actual | M21: EDP Budget | N21: EDP Actual | O21: EDP Budget | P21: EDP Actual | Q21: EDP Budget | R21: EDP Actual | S21: EDP Budget | T21: EDP Actual | U21: EDP Budget | V21: EDP Actual | W21: EDP Budget | X21: EDP Actual | Y21: EDP Budget | Z21: EDP Actual | AA21: EDP Budget | AB21: EDP Actual | AC21: PCP Budget | AD21: PCP Actual | AE21: EDP Budget | AF21: EDP Actual | AG21: EDP Budget | AH21: EDP Actual | AI21: EDP Budget | AJ21: EDP Actual | AK21: EDP Budget | AL21: EDP Actual | AM21: EDP Budget | AN21: EDP Actual | AO21: EDP Budget | AP21: EDP Actual | AQ21: EDP Budget | AR21: EDP Actual | AS21: EDP Budget | AT21: EDP Actual
B22: 42370 | C22: =COMPOSITE!B$297-COMPOSITE!B$287 -> 946.85671 | D22: =(COMPOSITE!D$297-COMPOSITE!D$287)/31 -> 950.54839 | E22: =COMPOSITE!B$287 -> 24 | F22: =COMPOSITE!D$287/31 -> 24 | G22: =COMPOSITE!B$273 -> 120 | H22: =COMPOSITE!D$273/31 -> 120 | I22: =COMPOSITE!B$274 -> 85.814208 | J22: =COMPOSITE!D$274/31 -> 86.193548 | K22: =COMPOSITE!B$275 -> 24 | L22: =COMPOSITE!D$275/31 -> 24 | M22: =COMPOSITE!B$276 -> 24 | N22: =COMPOSITE!D$276/31 -> 24.032258 | O22: =COMPOSITE!B$277 -> 37 | P22: =COMPOSITE!D$277/31 -> 37.032258 | Q22: =COMPOSITE!B$279 -> 82.57 | R22: =COMPOSITE!D$279/31 -> 80.419355 | S22: =COMPOSITE!B$281 -> 24 | T22: =COMPOSITE!D$281/31 -> 24.258065 | U22: =COMPOSITE!B282 -> 24 | V22: =COMPOSITE!D282/31 -> 24 | W22: =COMPOSITE!B$283 -> 42 | X22: =COMPOSITE!D$283/31 -> 42.806452 | Y22: =COMPOSITE!B284 -> 32 | Z22: =COMPOSITE!D284/31 -> 31.983871 | AA22: =COMPOSITE!B$285 -> 24 | AB22: =COMPOSITE!D$285/31 -> 24 | AC22: =COMPOSITE!B$287 -> 24 | AD22: =COMPOSITE!D$287/31 -> 24 | AE22: =COMPOSITE!B$286 -> 24 | AF22: =COMPOSITE!D$286/31 -> 26.096774 | AG22: =COMPOSITE!B$288 -> 24 | AH22: =COMPOSITE!D$288/31 -> 24 | AI22: =COMPOSITE!B289 -> 36 | AJ22: =COMPOSITE!D289/31 -> 36 | AK22: =COMPOSITE!B290 -> 24 | AL22: =COMPOSITE!D290/31 -> 24 | AM22: =COMPOSITE!B291 -> 63.8125 | AN22: =COMPOSITE!D291/31 -> 63.032258 | AO22: =COMPOSITE!B293 -> 24 | AP22: =COMPOSITE!D293/31 -> 24 | AQ22: =COMPOSITE!B294 -> 110 | AR22: =COMPOSITE!D294/31 -> 110 | AS22: =COMPOSITE!B295 -> 68 | AT22: =COMPOSITE!D295/31 -> 68
B23: 42401 | C23: =COMPOSITE!E$297-COMPOSITE!E$287 -> 947.62671 | D23: =(COMPOSITE!G$297-COMPOSITE!G$287)/29 -> 956.72414 | E23: =COMPOSITE!E$287 -> 22 | F23: =COMPOSITE!G$287/29 -> 22.905172 | G23: =COMPOSITE!E$273 -> 120 | H23: =COMPOSITE!G$273/29 -> 120 | I23: =COMPOSITE!E$274 -> 85.814208 | J23: =COMPOSITE!G$274/29 -> 86.482759 | K23: =COMPOSITE!E$275 -> 24 | L23: =COMPOSITE!G$275/29 -> 24 | M23: =COMPOSITE!E$276 -> 24 | N23: =COMPOSITE!G$276/29 -> 24 | O23: =COMPOSITE!E$277 -> 37 | P23: =COMPOSITE!G$277/29 -> 37 | Q23: =COMPOSITE!E$279 -> 83 | R23: =COMPOSITE!G$279/29 -> 81.551724 | S23: =COMPOSITE!E$281 -> 24 | T23: =COMPOSITE!G$281/29 -> 24.241379 | U23: =COMPOSITE!E282 -> 24 | V23: =COMPOSITE!G282/29 -> 24 | W23: =COMPOSITE!E$283 -> 42 | X23: =COMPOSITE!G$283/29 -> 46.275862 | Y23: =COMPOSITE!E284 -> 32 | Z23: =COMPOSITE!G284/29 -> 32.206897 | AA23: =COMPOSITE!E$285 -> 24 | AB23: =COMPOSITE!G$285/29 -> 24 | AC23: =COMPOSITE!E$287 -> 22 | AD23: =COMPOSITE!G$287/29 -> 22.905172 | AE23: =COMPOSITE!E$286 -> 24 | AF23: =COMPOSITE!G$286/29 -> 25.655172 | AG23: =COMPOSITE!E$288 -> 24 | AH23: =COMPOSITE!G$288/29 -> 24 | AI23: =COMPOSITE!E289 -> 36 | AJ23: =COMPOSITE!G289/29 -> 36 | AK23: =COMPOSITE!E290 -> 24 | AL23: =COMPOSITE!G290/29 -> 24 | AM23: =COMPOSITE!E291 -> 63.8125 | AN23: =COMPOSITE!G291/29 -> 64.724138 | AO23: =COMPOSITE!E293 -> 24 | AP23: =COMPOSITE!G293/29 -> 24.086207 | AQ23: =COMPOSITE!E294 -> 110 | AR23: =COMPOSITE!G294/29 -> 110 | AS23: =COMPOSITE!E295 -> 68 | AT23: =COMPOSITE!G295/29 -> 68
B24: 42430 | C24: =COMPOSITE!H$297-COMPOSITE!H$287 -> 953.62671 | D24: =(COMPOSITE!J$297-COMPOSITE!J$287)/31 -> 958.55387 | E24: =COMPOSITE!H$287 -> 22 | F24: =COMPOSITE!J$287/31 -> 22.258065 | G24: =COMPOSITE!H$273 -> 120 | H24: =COMPOSITE!J$273/31 -> 118.03226 | I24: =COMPOSITE!H$274 -> 85.814208 | J24: =COMPOSITE!J$274/31 -> 86.451613 | K24: =COMPOSITE!H$275 -> 24 | L24: =COMPOSITE!J$275/31 -> 24 | M24: =COMPOSITE!H$276 -> 24 | N24: =COMPOSITE!J$276/31 -> 23.967742 | O24: =COMPOSITE!H$277 -> 37 | P24: =COMPOSITE!J$277/31 -> 38.967742 | Q24: =COMPOSITE!H$279 -> 83 | R24: =COMPOSITE!J$279/31 -> 82.596774 | S24: =COMPOSITE!H$281 -> 24 | T24: =COMPOSITE!J$281/31 -> 24.5 | U24: =COMPOSITE!H282 -> 24 | V24: =COMPOSITE!J282/31 -> 24 | W24: =COMPOSITE!H$283 -> 48 | X24: =COMPOSITE!J$283/31 -> 48.247419 | Y24: =COMPOSITE!H284 -> 32 | Z24: =COMPOSITE!J284/31 -> 32.096774 | AA24: =COMPOSITE!H$285 -> 24 | AB24: =COMPOSITE!J$285/31 -> 24 | AC24: =COMPOSITE!H$287 -> 22 | AD24: =COMPOSITE!J$287/31 -> 22.258065 | AE24: =COMPOSITE!H$286 -> 24 | AF24: =COMPOSITE!J$286/31 -> 25 | AG24: =COMPOSITE!H$288 -> 24 | AH24: =COMPOSITE!J$288/31 -> 24.064516 | AI24: =COMPOSITE!H289 -> 36 | AJ24: =COMPOSITE!J289/31 -> 36.290323 | AK24: =COMPOSITE!H290 -> 24 | AL24: =COMPOSITE!J290/31 -> 24 | AM24: =COMPOSITE!H291 -> 63.8125 | AN24: =COMPOSITE!J291/31 -> 64.096774 | AO24: =COMPOSITE!H293 -> 24 | AP24: =COMPOSITE!J293/31 -> 24 | AQ24: =COMPOSITE!H294 -> 110 | AR24: =COMPOSITE!J294/31 -> 111.43548 | AS24: =COMPOSITE!H295 -> 68 | AT24: =COMPOSITE!J295/31 -> 67.935484
B25: 42461 | C25: =COMPOSITE!K$297-COMPOSITE!K$287 -> 953.62671 | D25: =(COMPOSITE!M$297-COMPOSITE!M$287)/30 -> 949.37767 | E25: =COMPOSITE!K$287 -> 22 | F25: =COMPOSITE!M$287/30 -> 22 | G25: =COMPOSITE!K$273 -> 120 | H25: =COMPOSITE!M$273/30 -> 117.26667 | I25: =COMPOSITE!H$274 -> 85.814208 | J25: =COMPOSITE!M$274/31 -> 81.881613 | K25: =COMPOSITE!H$275 -> 24 | L25: =COMPOSITE!M$275/30 -> 23.883333 | M25: =COMPOSITE!H$276 -> 24 | N25: =COMPOSITE!M$276/30 -> 23.891667 | O25: =COMPOSITE!H$277 -> 37 | P25: =COMPOSITE!M$277/30 -> 37.6 | Q25: =COMPOSITE!H$279 -> 83 | R25: =COMPOSITE!M$279/30 -> 81.733333 | S25: =COMPOSITE!H$281 -> 24 | T25: =COMPOSITE!M$281/30 -> 23.75 | U25: =COMPOSITE!H283 -> 48 | V25: =COMPOSITE!M282/30 -> 24 | W25: =COMPOSITE!H$283 -> 48 | X25: =COMPOSITE!M$283/30 -> 48 | Y25: =COMPOSITE!H285 -> 24 | Z25: =COMPOSITE!J284/30 -> 33.166667 | AA25: =COMPOSITE!H$285 -> 24 | AB25: =COMPOSITE!M$285/30 -> 24 | AC25: =COMPOSITE!H$287 -> 22 | AD25: =COMPOSITE!M$287/30 -> 22 | AE25: =COMPOSITE!H$286 -> 24 | AF25: =COMPOSITE!M$286/30 -> 24 | AG25: =COMPOSITE!H$288 -> 24 | AH25: =COMPOSITE!M$288/30 -> 24 | AI25: =COMPOSITE!H290 -> 24 | AJ25: =COMPOSITE!M289/30 -> 36 | AK25: =COMPOSITE!H291 -> 63.8125 | AL25: =COMPOSITE!M290/30 -> 24 | AM25: =COMPOSITE!H292 -> 21 | AN25: =COMPOSITE!M291/30 -> 63.8 | AO25: =COMPOSITE!H294 -> 110 | AP25: =COMPOSITE!M293/30 -> 24 | AQ25: =COMPOSITE!H295 -> 68 | AR25: =COMPOSITE!M294/30 -> 110.425 | AS25: =COMPOSITE!H296 -> 0 | AT25: =COMPOSITE!M295/30 -> 68.1
B26: 42491
B27: 42522
B28: 42552
B29: 42583
B30: 42614
B31: 42644
B32: 42675
B33: 42705
B34: YTD Total | C34: =SUM(C22:C33) -> 3801.7368 | D34: =SUM(D22:D33) -> 3815.2041 | E34: =SUM(E22:E33) -> 90 | F34: =SUM(F22:F33) -> 91.163237 | G34: =SUM(G22:G33) -> 480 | H34: =SUM(H22:H33) -> 475.29892 | I34: =SUM(I22:I33) -> 343.25683 | J34: =SUM(J22:J33) -> 341.00953 | ... AT34: =SUM(AT22:AT33) -> 272.03548
B36: APP / MLP HOURS
B37: Month | C37: DIVISION TOTAL | E37: JFK | G37: JUPITER | I37: KENDALL | K37: KENDALL PEDS | M37: OCALA | O37: ST MARY'S | Q37: W MARION | S37: W MARION QC | U37: PROVIDENCE | W37: OSCEOLA | Y37: HUNTERS CREEK | AA37: CHANDLER | AC37: M GILBERT
C38: Budget | D38: Actual | E38: Budget | F38: Actual | G38: Budget | H38: Actual | I38: Budget | J38: Actual | K38: Budget | L38: Actual | M38: Budget | N38: Actual | O38: Budget | P38: Actual | Q38: Budget | R38: Actual | S38: Budget | T38: Actual | U38: Budget | V38: Actual | W38: Budget | X38: Actual | Y38: Budget | Z38: Actual | AA38: Budget | AB38: Actual | AC38: Budget | AD38: Actual
B39: 42370 | C39: =COMPOSITE!B$321 -> 438.92481 | D39: =COMPOSITE!D$321/31 -> 430.72581 | E39: =COMPOSITE!B$302 -> 58.819672 | F39: =COMPOSITE!D$302/31 -> 53.741935 | G39: =COMPOSITE!B$303 -> 24 | H39: =COMPOSITE!D$303/31 -> 24 | I39: =COMPOSITE!B$305 -> 35.803279 | J39: =COMPOSITE!D$305/31 -> 40.814516 | K39: =COMPOSITE!B306 -> 14.28 | L39: =COMPOSITE!D306/31 -> 8.0241935 | M39: =COMPOSITE!B$309 -> 36 | N39: =COMPOSITE!D$309/31 -> 36 | O39: =COMPOSITE!B308 -> 20 | P39: =COMPOSITE!D308/31 -> 19.145161 | Q39: =COMPOSITE!B$310 -> 20 | R39: =COMPOSITE!D310/31 -> 20.129032 | S39: =COMPOSITE!B$311 -> 10 | T39: =COMPOSITE!D$311/31 -> 6.7741935 | U39: =COMPOSITE!B313 -> 20 | V39: =COMPOSITE!D313/31 -> 20 | W39: =COMPOSITE!B315 -> 50 | X39: =COMPOSITE!D315/31 -> 52.096774 | Y39: =COMPOSITE!B317 -> 12.010929 | Z39: =COMPOSITE!D317/31 -> 12 | AA39: =COMPOSITE!B318 -> 76 | AB39: =COMPOSITE!D318/31 -> 76 | AC39: =COMPOSITE!B319 -> 50 | AD39: =COMPOSITE!D319/31 -> 50
B40: 42401 | C40: =COMPOSITE!E$321 -> 438.64481 | D40: =COMPOSITE!G$321/29 -> 449.32989 | E40: =COMPOSITE!E$302 -> 58.819672 | F40: =COMPOSITE!G$302/29 -> 56.456897 | G40: =COMPOSITE!E$303 -> 24 | H40: =COMPOSITE!G$303/29 -> 25.172414 | I40: =COMPOSITE!E$305 -> 35.803279 | J40: =COMPOSITE!G$305/29 -> 39.939655 | K40: =COMPOSITE!E306 -> 14 | L40: =COMPOSITE!G306/29 -> 18.913793 | M40: =COMPOSITE!E$309 -> 36 | N40: =COMPOSITE!G$309/29 -> 35.094828 | O40: =COMPOSITE!E308 -> 20 | P40: =COMPOSITE!G308/29 -> 18.784483 | Q40: =COMPOSITE!E$310 -> 20 | R40: =COMPOSITE!G310/29 -> 20.25 | S40: =COMPOSITE!E$311 -> 10 | T40: =COMPOSITE!G$311/29 -> 7.2413793 | U40: =COMPOSITE!E313 -> 20 | V40: =COMPOSITE!G313/29 -> 20.137931 | W40: =COMPOSITE!E315 -> 50 | X40: =COMPOSITE!G315/29 -> 56.482759 | Y40: =COMPOSITE!E317 -> 12.010929 | Z40: =COMPOSITE!G317/29 -> 12.844828 | AA40: =COMPOSITE!E318 -> 76 | AB40: =COMPOSITE!G318/29 -> 76 | AC40: =COMPOSITE!E319 -> 50 | AD40: =COMPOSITE!G319/29 -> 50
B41: 42430 | C41: =COMPOSITE!H$321 -> 431.90295 | D41: =COMPOSITE!J$321/31 -> 429.64516 | E41: =COMPOSITE!H$302 -> 58.819672 | F41: =COMPOSITE!J$302/31 -> 58.806452 | G41: =COMPOSITE!H$303 -> 24 | H41: =COMPOSITE!J$303/29 -> 26.068966 | I41: =COMPOSITE!H$305 -> 35.803279 | J41: =COMPOSITE!J$305/31 -> 36.193548 | K41: =COMPOSITE!H306 -> 14.28 | L41: =COMPOSITE!J307/31 -> 0 | M41: =COMPOSITE!H$309 -> 36 | N41: =COMPOSITE!J$309/31 -> 36 | O41: =COMPOSITE!H308 -> 20 | P41: =COMPOSITE!J309/31 -> 36 | Q41: =COMPOSITE!H$310 -> 20 | R41: =COMPOSITE!J310/31 -> 20 | S41: =COMPOSITE!H$311 -> 10 | T41: =COMPOSITE!J$311/31 -> 7.4193548 | U41: =COMPOSITE!H313 -> 20 | V41: =COMPOSITE!J313/31 -> 20 | W41: =COMPOSITE!H315 -> 50 | X41: =COMPOSITE!J315/31 -> 50 | Y41: =COMPOSITE!H317 -> 17 | Z41: =COMPOSITE!J317/31 -> 13.935484 | AA41: =COMPOSITE!H318 -> 76 | AB41: =COMPOSITE!J318/31 -> 74.451613 | AC41: =COMPOSITE!H319 -> 50 | AD41: =COMPOSITE!J319/31 -> 50
B42: 42461 | C42: =COMPOSITE!K$321 -> 431.81967 | D42: =COMPOSITE!M$321/31 -> 420.45968 | E42: =COMPOSITE!K$302 -> 58.819672 | F42: =COMPOSITE!M$302/30 -> 58.8 | G42: =COMPOSITE!K$303 -> 24 | H42: =COMPOSITE!M$303/30 -> 24.458333 | I42: =COMPOSITE!K$305 -> 36 | J42: =COMPOSITE!M$305/30 -> 37.666667 | K42: =COMPOSITE!K306 -> 14 | L42: =COMPOSITE!M308/30 -> 20 | M42: =COMPOSITE!K$309 -> 36 | N42: =COMPOSITE!M$309/30 -> 36.491667 | O42: =COMPOSITE!K308 -> 20 | P42: =COMPOSITE!M310/30 -> 21.208333 | Q42: =COMPOSITE!K$310 -> 20 | R42: =COMPOSITE!M310/30 -> 21.208333 | S42: =COMPOSITE!K$311 -> 10 | T42: =COMPOSITE!M$311/30 -> 7 | U42: =COMPOSITE!K313 -> 20 | V42: =COMPOSITE!M313/30 -> 20.666667 | W42: =COMPOSITE!K315 -> 50 | X42: =COMPOSITE!M317/30 -> 17.466667 | Y42: =COMPOSITE!K317 -> 17 | Z42: =COMPOSITE!M317/31 -> 16.903226 | AA42: =COMPOSITE!K318 -> 76 | AB42: =COMPOSITE!M318/31 -> 73.290323 | AC42: =COMPOSITE!K319 -> 50 | AD42: =COMPOSITE!M319/31 -> 48.209677
B43: 42491
B44: 42522
B45: 42552
B46: 42583
B47: 42614
B48: 42644
B49: 42675
B50: 42705
B51: YTD Total | C51: =SUM(C39:C50) -> 1741.2922 | D51: =SUM(D39:D50) -> 1730.1605 | E51: =SUM(E39:E50) -> 235.27869 | F51: =SUM(F39:F50) -> 227.80528 | G51: =SUM(G39:G50) -> 96 | H51: =SUM(H39:H50) -> 99.699713 | I51: =SUM(I39:I50) -> 143.40984 | J51: =SUM(J39:J50) -> 154.61439 | ... AD51: =SUM(AD39:AD50) -> 198.20968
B53: SCRIBE HOURS
B54: Month | C54: DIVISION TOTAL | E54: BAPTIST | G54: JUPITER | I54: KENDALL | K54: MOBERLY | M54: ST MARY'S | O54: OSCEOLA | Q54: OSCEOLA PEDS | S54: HUNTERS CREEK | U54: OCALA | W54: W MARION
C55: Budget | D55: Actual | E55: Budget | F55: Actual | G55: Budget | H55: Actual | I55: Budget | J55: Actual | K55: Budget | L55: Actual | M55: Budget | N55: Actual | O55: Budget | P55: Actual | Q55: Budget | R55: Actual | S55: Budget | T55: Actual | U55: Budget | V55: Actual | W55: Budget | X55: Actual
B56: 42370 | C56: =COMPOSITE!B$340 -> 452 | D56: =COMPOSITE!C$340 -> 476.58032 | E56: =COMPOSITE!B$325 -> 100 | F56: =COMPOSITE!C$325 -> 101.49194 | G56: =COMPOSITE!B326 -> 10 | H56: =COMPOSITE!C326 -> 12.26 | I56: =COMPOSITE!B$327 -> 73 | J56: =COMPOSITE!C$327 -> 90.668387 | K56: =COMPOSITE!B$328 -> 8 | L56: =COMPOSITE!C$328 -> 8.38 | M56: =COMPOSITE!B$329 -> 24 | N56: =COMPOSITE!C$329 -> 24.36 | O56: =COMPOSITE!B332 -> 65 | P56: =COMPOSITE!C332 -> 69 | Q56: =COMPOSITE!B333 -> 18 | R56: =COMPOSITE!C333 -> 13.34 | S56: =COMPOSITE!B334 -> 12 | T56: =COMPOSITE!C334 -> 11.58 | U56: =COMPOSITE!B337 -> 24 | V56: =COMPOSITE!C337 -> 25.69 | W56: =COMPOSITE!B338 -> 16 | X56: =COMPOSITE!C338 -> 17.81
B57: 42401 | C57: =COMPOSITE!D$340 -> 451.90452 | D57: =COMPOSITE!E$340 -> 461.53276 | E57: =COMPOSITE!D$325 -> 100 | F57: =COMPOSITE!E$325 -> 102 | G57: =COMPOSITE!D326 -> 10 | H57: =COMPOSITE!E326 -> 12 | I57: =COMPOSITE!D$327 -> 73 | J57: =COMPOSITE!E$327 -> 73 | K57: =COMPOSITE!D$328 -> 8 | L57: =COMPOSITE!E$328 -> 8.5 | M57: =COMPOSITE!D$329 -> 24 | N57: =COMPOSITE!E$329 -> 24.18 | O57: =COMPOSITE!D332 -> 65 | P57: =COMPOSITE!E332 -> 67 | Q57: =COMPOSITE!D333 -> 18 | R57: =COMPOSITE!E333 -> 19 | S57: =COMPOSITE!D334 -> 11.904516 | T57: =COMPOSITE!E334 -> 10.852759 | U57: =COMPOSITE!D337 -> 24 | V57: =COMPOSITE!E337 -> 26 | W57: =COMPOSITE!D338 -> 16 | X57: =COMPOSITE!E338 -> 17
B58: 42430 | C58: =COMPOSITE!F$340 -> 452 | D58: =COMPOSITE!G$340 -> 492.43194 | E58: =COMPOSITE!F$325 -> 100 | F58: =COMPOSITE!G$325 -> 102 | G58: =COMPOSITE!F326 -> 10 | H58: =COMPOSITE!G326 -> 12.290323 | I58: =COMPOSITE!F$327 -> 73 | J58: =COMPOSITE!G$327 -> 93.563226 | K58: =COMPOSITE!F$328 -> 8 | L58: =COMPOSITE!G$328 -> 8.5 | M58: =COMPOSITE!F$329 -> 24 | N58: =COMPOSITE!G$329 -> 25.567419 | O58: =COMPOSITE!F332 -> 65 | P58: =COMPOSITE!G332 -> 68.994839 | Q58: =COMPOSITE!F333 -> 18 | R58: =COMPOSITE!G333 -> 18.600968 | S58: =COMPOSITE!F334 -> 12 | T58: =COMPOSITE!E334 -> 10.852759 | U58: =COMPOSITE!F337 -> 24 | V58: =COMPOSITE!G337 -> 31.870323 | W58: =COMPOSITE!F338 -> 16 | X58: =COMPOSITE!G338 -> 17.140323
B59: 42461 | C59: =COMPOSITE!H$340 -> 452 | D59: =COMPOSITE!I$340 -> 451.81967 | E59: =COMPOSITE!H$325 -> 100 | F59: =COMPOSITE!I$325 -> 99 | G59: =COMPOSITE!H326 -> 10 | H59: =COMPOSITE!I326 -> 8.3833333 | I59: =COMPOSITE!H$327 -> 73 | J59: =COMPOSITE!I$327 -> 96.328667 | K59: =COMPOSITE!H$328 -> 8 | L59: =COMPOSITE!I$328 -> 8.7 | M59: =COMPOSITE!H$329 -> 24 | N59: =COMPOSITE!I$329 -> 27.551333 | O59: =COMPOSITE!H332 -> 65 | P59: =COMPOSITE!I332 -> 53 | Q59: =COMPOSITE!H333 -> 18 | R59: =COMPOSITE!I333 -> 12.485333 | S59: =COMPOSITE!H334 -> 12 | T59: =COMPOSITE!E334 -> 10.852759 | U59: =COMPOSITE!H337 -> 24 | V59: =COMPOSITE!I337 -> 24.995333 | W59: =COMPOSITE!H338 -> 16 | X59: =COMPOSITE!I338 -> 11.652333
B60: 42491
...

Sheet MLP PREMIUM LABOR
A1: PREMIUM HOURS
A2: Month | B2: DIVISION TOTAL | F2: JFK | J2: JUPITER | N2: KENDALL | R2: KENDALL PEDS | V2: OCALA | Z2: ST MARY'S | AD2: W MARION QC | AH2: W MARION | AL2: PROVICENCE | AP2: ST JOHN | AT2: OSCEOLA | AX2: OSCEOLA PEDS | BB2: HUNTERS CREEK
B3: Transition Team | C3: Shift Incentive | D3: Total OT | E3: Locums | F3: Transition Team | G3: Shift Incentive | H3: Total OT | I3: Locums | J3: Transition Team | K3: Shift Incentive | L3: Total OT | M3: Locums | N3: Transition Team | O3: Shift Incentive | P3: Total OT | Q3: Locums | R3: Transition Team | S3: Shift Incentive | T3: Total OT | U3: Locums | V3: Transition Team | W3: Shift Incentive | X3: Total OT | Y3: Locums | Z3: Transition Team | AA3: Shift Incentive | AB3: Total OT | AC3: Locums | AD3: Transition Team | AE3: Shift Incentive | AF3: Total OT | AG3: Locums | AH3: Transition Team | AI3: Shift Incentive | AJ3: Total OT | AK3: Locums | AL3: Transition Team | AM3: Shift Incentive | AN3: Total OT | AO3: Locums | AP3: Transition Team | AQ3: Shift Incentive | AR3: Total OT | AS3: Locums | AT3: Transition Team | AU3: Shift Incentive | AV3: Total OT | AW3: Locums | AX3: Transition Team | AY3: Shift Incentive | AZ3: Total OT | BA3: Locums | BB3: Transition Team | BC3: Shift Incentive | BD3: Total OT | BE3: Locums
A4: 42370 | B4: =COMPOSITE!B$247 -> 0 | C4: =COMPOSITE!C$247 -> 93.75 | D4: =COMPOSITE!D$247 -> 725.25 | E4: =COMPOSITE!E$247 -> 92 | F4: =COMPOSITE!B$230 -> 0 | G4: =COMPOSITE!C$230 -> 0 | H4: =COMPOSITE!D$230 -> 280.75 | I4: =COMPOSITE!E$230 -> 0 | J4: =COMPOSITE!B$231 -> 0 | K4: =COMPOSITE!C$231 -> 0 | L4: =COMPOSITE!D$231 -> 0 | M4: =COMPOSITE!E$231 -> 0 | N4: =COMPOSITE!B$232 -> 0 | O4: =COMPOSITE!C$232 -> 12 | P4: =COMPOSITE!D$232 -> 64.5 | Q4: =COMPOSITE!E$232 -> 0 | R4: =COMPOSITE!B233 -> 0 | S4: =COMPOSITE!C233 -> 0 | T4: =COMPOSITE!D233 -> 38.75 | U4: =COMPOSITE!E233 -> 0 | V4: =COMPOSITE!B$234 -> 0 | W4: =COMPOSITE!C$234 -> 14.25 | X4: =COMPOSITE!D$234 -> 80.75 | Y4: =COMPOSITE!E$234 -> 92 | Z4: =COMPOSITE!B$236 -> 0 | AA4: =COMPOSITE!C$236 -> 67.5 | AB4: =COMPOSITE!D$236 -> 9 | AC4: =COMPOSITE!E$236 -> 0 | AD4: =COMPOSITE!B238 -> 0 | AE4: =COMPOSITE!C238 -> 0 | AF4: =COMPOSITE!D238 -> 0 | AG4: =COMPOSITE!E238 -> 0 | AH4: =COMPOSITE!B$237 -> 0 | AI4: =COMPOSITE!C$237 -> 0 | AJ4: =COMPOSITE!D$237 -> 37.25 | AK4: =COMPOSITE!E$237 -> 0 | AL4: =COMPOSITE!B239 -> 0 | AM4: =COMPOSITE!C239 -> 0 | AN4: =COMPOSITE!D239 -> 70.25 | AO4: =COMPOSITE!E239 -> 0 | AT4: =COMPOSITE!B241 -> 0 | AU4: =COMPOSITE!C241 -> 0 | AV4: =COMPOSITE!D241 -> 116 | AW4: =COMPOSITE!E241 -> 0 | BB4: =COMPOSITE!B243 -> 0 | BC4: =COMPOSITE!C243 -> 0 | BD4: =COMPOSITE!D243 -> 28 | BE4: =COMPOSITE!E243 -> 0
A5: 42401 | B5: =COMPOSITE!F$247 -> 0 | C5: =COMPOSITE!G$247 -> 43 | D5: =COMPOSITE!H$247 -> 793.75 | E5: =COMPOSITE!I$247 -> 256 | F5: =COMPOSITE!F$230 -> 0 | G5: =COMPOSITE!G$230 -> 0 | H5: =COMPOSITE!H$230 -> 255 | I5: =COMPOSITE!I$230 -> 0 | J5: =COMPOSITE!F$231 -> 0 | K5: =COMPOSITE!G$231 -> 0 | L5: =COMPOSITE!H$231 -> 6 | M5: =COMPOSITE!I$231 -> 0 | N5: =COMPOSITE!F$232 -> 0 | O5: =COMPOSITE!G$232 -> 12 | P5: =COMPOSITE!H$232 -> 84.5 | Q5: =COMPOSITE!I$232 -> 0 | R5: =COMPOSITE!F233 -> 0 | S5: =COMPOSITE!G233 -> 0 | T5: =COMPOSITE!H233 -> 47.75 | U5: =COMPOSITE!I233 -> 0 | V5: =COMPOSITE!F$234 -> 0 | W5: =COMPOSITE!G$234 -> 0 | X5: =COMPOSITE!H$234 -> 81.5 | Y5: =COMPOSITE!I$234 -> 256 | Z5: =COMPOSITE!F$236 -> 0 | AA5: =COMPOSITE!G$236 -> 31 | AB5: =COMPOSITE!H$236 -> 15 | AC5: =COMPOSITE!I$236 -> 0 | AD5: =COMPOSITE!F238 -> 0 | AE5: =COMPOSITE!G238 -> 0 | AF5: =COMPOSITE!H238 -> 0 | AG5: =COMPOSITE!I238 -> 0 | AH5: =COMPOSITE!F$237 -> 0 | AI5: =COMPOSITE!G$237 -> 0 | AJ5: =COMPOSITE!H$237 -> 80 | AK5: =COMPOSITE!I$237 -> 0 | AL5: =COMPOSITE!F239 -> 0 | AM5: =COMPOSITE!G239 -> 0 | AN5: =COMPOSITE!H239 -> 20 | AO5: =COMPOSITE!I239 -> 0 | AT5: =COMPOSITE!F241 -> 0 | AU5: =COMPOSITE!G241 -> 0 | AV5: =COMPOSITE!H241 -> 138 | AW5: =COMPOSITE!I241 -> 0 | BB5: =COMPOSITE!F243 -> 0 | BC5: =COMPOSITE!G243 -> 0 | BD5: =COMPOSITE!H243 -> 58 | BE5: =COMPOSITE!I243 -> 0
A6: 42430 | B6: =COMPOSITE!J$247 -> 0 | C6: =COMPOSITE!K$247 -> 1022 | D6: =COMPOSITE!L$247 -> 614 | E6: =COMPOSITE!M$247 -> 233 | F6: =COMPOSITE!J$230 -> 0 | G6: =COMPOSITE!K$230 -> 0 | H6: =COMPOSITE!L$230 -> 167 | I6: =COMPOSITE!M$230 -> 0 | J6: =COMPOSITE!J$231 -> 0 | K6: =COMPOSITE!K$231 -> 0 | L6: =COMPOSITE!L$231 -> 20 | M6: =COMPOSITE!M$231 -> 0 | N6: =COMPOSITE!J$232 -> 0 | O6: =COMPOSITE!K$232 -> 22 | P6: =COMPOSITE!L$232 -> 77.75 | Q6: =COMPOSITE!M$232 -> 0 | R6: =COMPOSITE!J233 -> 0 | S6: =COMPOSITE!K233 -> 0 | T6: =COMPOSITE!L233 -> 67 | U6: =COMPOSITE!M233 -> 0 | V6: =COMPOSITE!J$234 -> 0 | W6: =COMPOSITE!K$234 -> 0 | X6: =COMPOSITE!L$234 -> 137.5 | Y6: =COMPOSITE!M$234 -> 233 | Z6: =COMPOSITE!J$236 -> 0 | AA6: =COMPOSITE!K$236 -> 0 | AB6: =COMPOSITE!L$236 -> 7.5 | AC6: =COMPOSITE!M$236 -> 0 | AD6: =COMPOSITE!J238 -> 0 | AE6: =COMPOSITE!K238 -> 0 | AF6: =COMPOSITE!L238 -> 0 | AG6: =COMPOSITE!M238 -> 0 | AH6: =COMPOSITE!J$237 -> 0 | AI6: =COMPOSITE!K$237 -> 0 | AJ6: =COMPOSITE!L$237 -> 40.25 | AK6: =COMPOSITE!M$237 -> 0 | AL6: =COMPOSITE!J239 -> 0 | AM6: =COMPOSITE!K239 -> 0 | AN6: =COMPOSITE!L239 -> 11 | AO6: =COMPOSITE!M239 -> 0 | AT6: =COMPOSITE!J241 -> 0 | AU6: =COMPOSITE!K241 -> 600 | AV6: =COMPOSITE!L241 -> 61 | AW6: =COMPOSITE!M241 -> 0 | BB6: =COMPOSITE!J243 -> 0 | BC6: =COMPOSITE!K243 -> 400 | BD6: =COMPOSITE!L243 -> 2.75 | BE6: =COMPOSITE!M243 -> 0
A7: 42461
A8: 42491
A9: 42522
A10: 42552
A11: 42583
A12: 42614
A13: 42644
A14: 42675
A15: 42705
A16: YTD Total | B16: =SUM(B4:B15) -> 0 | C16: =SUM(C4:C15) -> 1158.75 | D16: =SUM(D4:D15) -> 2133 | E16: =SUM(E4:E15) -> 581 | F16: =SUM(F4:F15) -> 0 | G16: =SUM(G4:G15) -> 0 | H16: =SUM(H4:H15) -> 702.75 | I16: =SUM(I4:I15) -> 0 | ... BE16: =SUM(BE4:BE15) -> 0
A18: PREMIUM COSTS
A19: Month | B19: DIVISION TOTAL | F19: JFK | J19: JUPITER | N19: KENDALL | R19: KENDALL PEDS | V19: OCALA | Z19: ST MARY'S | AD19: W MARION QC | AH19: W MARION | AL19: PROVIDENCE | AP19: ST JOHN | AT19: OSCEOLA | AX19: OSCEOLA PEDS | BB19: HUNTERS CREEK
B20: Transition Team | C20: Shift Incentive | D20: Total OT | E20: Incremental OT | F20: Transition Team | G20: Shift Incentive | H20: Total OT | I20: Incremental OT | J20: Transition Team | K20: Shift Incentive | L20: Total OT | M20: Incremental OT | N20: Transition Team | O20: Shift Incentive | P20: Total OT | Q20: Incremental OT | R20: Transition Team | S20: Shift Incentive | T20: Total OT | U20: Incremental OT | V20: Transition Team | W20: Shift Incentive | X20: Total OT | Y20: Incremental OT | Z20: Transition Team | AA20: Shift Incentive | AB20: Total OT | AC20: Incremental OT | AD20: Transition Team | AE20: Shift Incentive | AF20: Total OT | AG20: Incremental OT | AH20: Transition Team | AI20: Shift Incentive | AJ20: Total OT | AK20: Incremental OT | AL20: Transition Team | AM20: Shift Incentive | AN20: Total OT | AO20: Incremental OT | AP20: Transition Team | AQ20: Shift Incentive | AR20: Total OT | AS20: Incremental OT | AT20: Transition Team | AU20: Shift Incentive | AV20: Total OT | AW20: Incremental OT | AX20: Transition Team | AY20: Shift Incentive | AZ20: Total OT | BA20: Incremental OT | BB20: Transition Team | BC20: Shift Incentive | BD20: Total OT | BE20: Incremental OT
A21: 42370 | B21: =COMPOSITE!B$269 -> 0 | C21: =COMPOSITE!C$269 -> 3940 | D21: =COMPOSITE!D$269 -> 57119.52 | E21: =COMPOSITE!E$269 -> 30707.49 | F21: =COMPOSITE!B$252 -> 0 | G21: =COMPOSITE!C$252 -> 0 | H21: =COMPOSITE!D$252 -> 20820.42 | I21: =COMPOSITE!E$252 -> 10410.21 | J21: =COMPOSITE!B$253 -> 0 | K21: =COMPOSITE!C$253 -> 0 | L21: =COMPOSITE!D$253 -> 75 | M21: =COMPOSITE!E$253 -> 75 | N21: =COMPOSITE!B$254 -> 0 | O21: =COMPOSITE!C$254 -> 500 | P21: =COMPOSITE!D$254 -> 5603.2 | Q21: =COMPOSITE!E$254 -> 3085.52 | R21: =COMPOSITE!B255 -> 0 | S21: =COMPOSITE!C255 -> 0 | T21: =COMPOSITE!D255 -> 2939.71 | U21: =COMPOSITE!E255 -> 1781.16 | V21: =COMPOSITE!B$256 -> 0 | W21: =COMPOSITE!C$256 -> 500 | X21: =COMPOSITE!D$256 -> 8149.88 | Y21: =COMPOSITE!E$256 -> 4074.94 | Z21: =COMPOSITE!B$257 -> 0 | AA21: =COMPOSITE!C$257 -> 2440 | AB21: =COMPOSITE!D$257 -> 585 | AC21: =COMPOSITE!E$257 -> 427.5 | AD21: =COMPOSITE!B$259 -> 0 | AE21: =COMPOSITE!C$259 -> 0 | AF21: =COMPOSITE!D$259 -> 0 | AG21: =COMPOSITE!E$259 -> 0 | AH21: =COMPOSITE!B$258 -> 0 | AI21: =COMPOSITE!C$258 -> 0 | AJ21: =COMPOSITE!D$258 -> 2877.56 | AK21: =COMPOSITE!E$258 -> 1438.78 | AL21: =COMPOSITE!B260 -> 0 | AM21: =COMPOSITE!C260 -> 0 | AN21: =COMPOSITE!D260 -> 5268.75 | AO21: =COMPOSITE!E260 -> 2634.38 | AT21: =COMPOSITE!B262 -> 0 | AU21: =COMPOSITE!C262 -> 500 | AV21: =COMPOSITE!D262 -> 8700 | AW21: =COMPOSITE!E262 -> 5220 | BB21: =COMPOSITE!B264 -> 0 | BC21: =COMPOSITE!C264 -> 0 | BD21: =COMPOSITE!D264 -> 2100 | BE21: =COMPOSITE!E264 -> 1560
A22: 42401 | B22: =COMPOSITE!F$269 -> 0 | C22: =COMPOSITE!G$269 -> 3012.5 | D22: =COMPOSITE!H$269 -> 96061.27 | E22: =COMPOSITE!I$269 -> 34013.3 | F22: =COMPOSITE!F$252 -> 0 | G22: =COMPOSITE!G$252 -> 0 | H22: =COMPOSITE!H$252 -> 28366.2 | I22: =COMPOSITE!I$252 -> 9455.4 | J22: =COMPOSITE!F$253 -> 0 | K22: =COMPOSITE!G$253 -> 0 | L22: =COMPOSITE!H$253 -> 675 | M22: =COMPOSITE!I$253 -> 225 | N22: =COMPOSITE!F$254 -> 0 | O22: =COMPOSITE!G$254 -> 0 | P22: =COMPOSITE!H$254 -> 10853.79 | Q22: =COMPOSITE!I$254 -> 3867.3 | R22: =COMPOSITE!F255 -> 0 | S22: =COMPOSITE!G255 -> 0 | T22: =COMPOSITE!H255 -> 5262.47 | U22: =COMPOSITE!I255 -> 1817.79 | V22: =COMPOSITE!F$256 -> 0 | W22: =COMPOSITE!G$256 -> 250 | X22: =COMPOSITE!H$256 -> 11461.22 | Y22: =COMPOSITE!I$256 -> 3832.78 | Z22: =COMPOSITE!F$257 -> 0 | AA22: =COMPOSITE!G$257 -> 1762.5 | AB22: =COMPOSITE!H$257 -> 1687.5 | AC22: =COMPOSITE!I$257 -> 712.5 | AD22: =COMPOSITE!F$259 -> 0 | AE22: =COMPOSITE!G$259 -> 0 | AF22: =COMPOSITE!H$259 -> 0 | AG22: =COMPOSITE!I$259 -> 0 | AH22: =COMPOSITE!F$258 -> 0 | AI22: =COMPOSITE!G$258 -> 0 | AJ22: =COMPOSITE!H$258 -> 10110.09 | AK22: =COMPOSITE!I$258 -> 3370.03 | AL22: =COMPOSITE!F260 -> 0 | AM22: =COMPOSITE!G260 -> 500 | AN22: =COMPOSITE!H260 -> 2250 | AO22: =COMPOSITE!I260 -> 750 | AT22: =COMPOSITE!F262 -> 0 | AU22: =COMPOSITE!G262 -> 500 | AV22: =COMPOSITE!H262 -> 16560 | AW22: =COMPOSITE!I262 -> 6210 | BB22: =COMPOSITE!F264 -> 0 | BC22: =COMPOSITE!G264 -> 0 | BD22: =COMPOSITE!H264 -> 7470 | BE22: =COMPOSITE!I264 -> 3120
A23: 42430 | B23: =COMPOSITE!J$269 -> 0 | C23: =COMPOSITE!K$269 -> 2000 | D23: =COMPOSITE!L$269 -> 70274.89 | E23: =COMPOSITE!M$269 -> 23814.76 | F23: =COMPOSITE!J$252 -> 0 | G23: =COMPOSITE!K$252 -> 0 | H23: =COMPOSITE!L$252 -> 18577.08 | I23: =COMPOSITE!M$252 -> 6192.36 | J23: =COMPOSITE!J$253 -> 0 | K23: =COMPOSITE!K$253 -> 0 | L23: =COMPOSITE!L$253 -> 2250 | M23: =COMPOSITE!M$253 -> 750 | N23: =COMPOSITE!J$254 -> 0 | O23: =COMPOSITE!K$254 -> 1250 | P23: =COMPOSITE!L$254 -> 8821.61 | Q23: =COMPOSITE!M$254 -> 3130.86 | R23: =COMPOSITE!J255 -> 0 | S23: =COMPOSITE!K255 -> 0 | T23: =COMPOSITE!L255 -> 7305.37 | U23: =COMPOSITE!M255 -> 2473.33 | V23: =COMPOSITE!J$256 -> 0 | W23: =COMPOSITE!K$256 -> 0 | X23: =COMPOSITE!L$256 -> 16338.38 | Y23: =COMPOSITE!M$256 -> 5446.13 | Z23: =COMPOSITE!J$257 -> 0 | AA23: =COMPOSITE!K$257 -> 0 | AB23: =COMPOSITE!L$257 -> 843.75 | AC23: =COMPOSITE!M$257 -> 356.25 | AD23: =COMPOSITE!J$259 -> 0 | AE23: =COMPOSITE!K$259 -> 0 | AF23: =COMPOSITE!L$259 -> 0 | AG23: =COMPOSITE!M$259 -> 0 | AH23: =COMPOSITE!J$258 -> 0 | AI23: =COMPOSITE!K$258 -> 0 | AJ23: =COMPOSITE!L$258 -> 5040.56 | AK23: =COMPOSITE!M$258 -> 1680.19 | AL23: =COMPOSITE!J260 -> 0 | AM23: =COMPOSITE!K260 -> 250 | AN23: =COMPOSITE!L260 -> 1237.5 | AO23: =COMPOSITE!M260 -> 412.5 | AT23: =COMPOSITE!J262 -> 0 | AU23: =COMPOSITE!K262 -> 500 | AV23: =COMPOSITE!L262 -> 5971.88 | AW23: =COMPOSITE!M262 -> 2034.38 | BB23: =COMPOSITE!J264 -> 0 | BC23: =COMPOSITE!K264 -> 0 | BD23: =COMPOSITE!L264 -> 309.38 | BE23: =COMPOSITE!M264 -> 103.13
A24: 42461
A25: 42491
A26: 42522
A27: 42552
A28: 42583
A29: 42614
A30: 42644
A31: 42675
A32: 42705
