Workbook
Name Category: survey_data!$F$2:$F$1699
Name n_apr: Satisfaction!$K$9:$K$40,Satisfaction!$K$48:$K$79,Satisfaction!$K$87:$K$118,Satisfaction!$K$126:$K$157,Satisfaction!$K$165:$K$196,Satisfaction!$K$204:$K$235
Name Period: survey_data!$B$2:$B$1699
Name Provider: survey_data!$E$2:$E$1699
Name Responses: survey_data!$H$2:$H$1699
Name Score: survey_data!$G$2:$G$1699

Sheet Sheet1
A3: Month | B3: Person | C3: Task | D3: y | E3: x | J3: patients | K3: y_satisf | M3: patients | N3: y_satisf
A4: Jan | B4: Smith | C4: Fishing | D4: 34 | E4: 4 | J4: 7 | K4: 85.7 | M4: 7 | N4: 85.7
A5: Jan | B5: Jim | C5: Fishing | D5: 56 | E5: 5 | J5: 7 | K5: 82.1 | M5: 7 | N5: 82.1
A6: Jan | B6: John | C6: Fishing | D6: 85 | E6: 4 | J6: 7 | K6: 92.9 | M6: 7 | N6: 92.9
A7: Jan | B7: Fred | C7: Fishing | D7: 35 | E7: 6 | J7: 4 | K7: 68.8 | M7: 4 | N7: 68.8
A8: Jan | B8: Smith | C8: Running | D8: 45 | E8: 2 | J8: 7 | K8: 85.7 | M8: 7 | N8: 85.7
A9: Jan | B9: Jim | C9: Running | D9: 34 | E9: 8 | J9: 4 | K9: 50 | M9: 4 | N9: 50
A10: Jan | B10: John | C10: Running | D10: 45 | E10: 7 | J10: 4 | K10: 93.8 | M10: 4 | N10: 93.8
A11: Jan | B11: Fred | C11: Running | D11: 56 | E11: 9 | J11: 5 | K11: 90 | M11: 5 | N11: 90
A12: Feb | B12: Smith | C12: Fishing | D12: .. | E12: .. | J12: 8 | K12: 78.1 | M12: 8 | N12: 78.1
A13: Feb | B13: Jim | C13: Fishing | D13: .. | E13: .. | J13: 8 | K13: 93.8 | M13: 8 | N13: 93.8
A14: Feb | B14: John | C14: Fishing | D14: .. | E14: .. | J14: 4 | K14: 93.8 | M14: 4 | N14: 93.8
A15: Feb | B15: Fred | C15: Fishing | D15: .. | E15: .. | J15: 11 | K15: 88.6 | M15: 11 | N15: 88.6
A16: Feb | B16: Smith | C16: Running | D16: .. | E16: .. | J16: 9 | K16: 80.6 | M16: 9 | N16: 80.6
A17: Feb | B17: Jim | C17: Running | D17: .. | E17: .. | J17: 1 | K17: 75 | M17: 1 | N17: 75
A18: Feb | B18: John | C18: Running | D18: .. | E18: .. | J18: 7 | K18: 71.4 | M18: 7 | N18: 71.4
A19: Feb | B19: Fred | C19: Running | D19: .. | E19: .. | J19: 11 | K19: 86.4 | M19: 11 | N19: 86.4
A20: Mar | B20: Smith | C20: Fishing | D20: .. | E20: .. | J20: 1 | K20: 100 | M20: 1 | N20: 100
A21: Mar | B21: Jim | C21: Fishing | D21: .. | E21: .. | J21: 11 | K21: 61.4 | M21: 11 | N21: 61.4
A22: Mar | B22: John | C22: Fishing | D22: .. | E22: .. | J22: 6 | K22: 83.3 | M22: 6 | N22: 83.3
A23: Mar | B23: Fred | C23: Fishing | D23: .. | E23: .. | J23: 8 | K23: 59.4 | M23: 8 | N23: 59.4
... A28: .. | B28: .. | C28: .. | D28: .. | E28: .. | J28: 1 | K28: 75 | M28: 1 | N28: 75
J29: 3 | K29: 58.3 | M29: 3 | N29: 58.3
A30: 12 Mths | B30: 4 People | C30: 2 tasks each | D30: Y variable | E30: X variable | J30: 6 | K30: 100 | M30: 6 | N30: 100
J31: 6 | K31: 87.5 | M31: 6 | N31: 87.5
J32: 9 | K32: 16.7 | M32: 7 | N32: 82.1
J33: 7 | K33: 82.1 | M33: 5 | N33: 90
J34: 5 | K34: 90 | M34: 13 | N34: 71.2
J35: 13 | K35: 71.2

Sheet Reg1
A1: Doctor informative re treatment | H1: β1 | I1: β0 | R1: Doctor took time to listen | Y1: β1 | Z1: β0 | AI1: Doctors concern for comfort | AP1: β1 | AQ1: β0 | AZ1: Doctors courtesy | BG1: β1 | BH1: β0 | BQ1: Std Doctors | BX1: β1 | BY1: β0
H2: -0.8596 | I2: 78.797 | Y2: -0.643 | Z2: 79.571 | AP2: -1.3854 | AQ2: 83.09 | BG2: -0.8974 | BH2: 85.371 | BX2: -0.9511 | BY2: 81.857
B4: patients | C4: y_satisf | D4: ŷ | E4: ε | S4: patients | T4: y_satisf | U4: ŷ | V4: ε | AJ4: patients | AK4: y_satisf | AL4: ŷ | AM4: ε | BA4: patients | BB4: y_satisf | BC4: ŷ | BD4: ε | BR4: patients | BS4: y_satisf | BT4: ŷ | BU4: ε
A5: 1 | B5: =Satisfaction!K9 -> 7 | C5: =Satisfaction!I9 -> 85.7 | D5: =($H$2*B5)+$I$2 -> 72.7798 | E5: =C5-D5 -> 12.9202 | R5: 1 | S5: 7 | T5: 89.3 | U5: =($Y$2*S5)+$Z$2 -> 75.07 | V5: =T5-U5 -> 14.23 | AI5: 1 | AJ5: 7 | AK5: 89.3 | AL5: =($AP$2*AJ5)+$AQ$2 -> 73.3922 | AM5: =AK5-AL5 -> 15.9078 | AZ5: 1 | BA5: 7 | BB5: 85.7 | BC5: =($BG$2*BA5)+$BH$2 -> 79.0892 | BD5: =BB5-BC5 -> 6.6108 | BQ5: 1 | BR5: 7 | BS5: 87.5 | BT5: =($BX$2*BR5)+$BY$2 -> 75.1993 | BU5: =BS5-BT5 -> 12.3007
A6: 2 | B6: =Satisfaction!K10 -> 7 | C6: =Satisfaction!I10 -> 71.4 | D6: =($H$2*B6)+$I$2 -> 72.7798 | E6: =C6-D6 -> -1.3798 | R6: 2 | S6: 7 | T6: 82.1 | U6: =($Y$2*S6)+$Z$2 -> 75.07 | V6: =T6-U6 -> 7.03 | AI6: 2 | AJ6: 7 | AK6: 78.6 | AL6: =($AP$2*AJ6)+$AQ$2 -> 73.3922 | AM6: =AK6-AL6 -> 5.2078 | AZ6: 2 | BA6: 7 | BB6: 82.1 | BC6: =($BG$2*BA6)+$BH$2 -> 79.0892 | BD6: =BB6-BC6 -> 3.0108 | BQ6: 2 | BR6: 7 | BS6: 78.6 | BT6: =($BX$2*BR6)+$BY$2 -> 75.1993 | BU6: =BS6-BT6 -> 3.4007
A7: 3 | B7: =Satisfaction!K11 -> 7 | C7: =Satisfaction!I11 -> 92.9 | D7: =($H$2*B7)+$I$2 -> 72.7798 | E7: =C7-D7 -> 20.1202 | R7: 3 | S7: 7 | T7: 92.9 | U7: =($Y$2*S7)+$Z$2 -> 75.07 | V7: =T7-U7 -> 17.83 | AI7: 3 | AJ7: 7 | AK7: 96.4 | AL7: =($AP$2*AJ7)+$AQ$2 -> 73.3922 | AM7: =AK7-AL7 -> 23.0078 | AZ7: 3 | BA7: 7 | BB7: 92.9 | BC7: =($BG$2*BA7)+$BH$2 -> 79.0892 | BD7: =BB7-BC7 -> 13.8108 | BQ7: 3 | BR7: 7 | BS7: 93.8 | BT7: =($BX$2*BR7)+$BY$2 -> 75.1993 | BU7: =BS7-BT7 -> 18.6007
A8: 4 | B8: =Satisfaction!K12 -> 4 | C8: =Satisfaction!I12 -> 62.5 | D8: =($H$2*B8)+$I$2 -> 75.3586 | E8: =C8-D8 -> -12.8586 | R8: 4 | S8: 4 | T8: 68.8 | U8: =($Y$2*S8)+$Z$2 -> 76.999 | V8: =T8-U8 -> -8.199 | AI8: 4 | AJ8: 4 | AK8: 62.5 | AL8: =($AP$2*AJ8)+$AQ$2 -> 77.5484 | AM8: =AK8-AL8 -> -15.0484 | AZ8: 4 | BA8: 4 | BB8: 68.8 | BC8: =($BG$2*BA8)+$BH$2 -> 81.7814 | BD8: =BB8-BC8 -> -12.9814 | BQ8: 4 | BR8: 4 | BS8: 65.6 | BT8: =($BX$2*BR8)+$BY$2 -> 78.0526 | BU8: =BS8-BT8 -> -12.4526
A9: 5 | B9: =Satisfaction!K13 -> 7 | C9: =Satisfaction!I13 -> 78.6 | D9: =($H$2*B9)+$I$2 -> 72.7798 | E9: =C9-D9 -> 5.8202 | R9: 5 | S9: 7 | T9: 85.7 | U9: =($Y$2*S9)+$Z$2 -> 75.07 | V9: =T9-U9 -> 10.63 | AI9: 5 | AJ9: 7 | AK9: 78.6 | AL9: =($AP$2*AJ9)+$AQ$2 -> 73.3922 | AM9: =AK9-AL9 -> 5.2078 | AZ9: 5 | BA9: 7 | BB9: 85.7 | BC9: =($BG$2*BA9)+$BH$2 -> 79.0892 | BD9: =BB9-BC9 -> 6.6108 | BQ9: 5 | BR9: 7 | BS9: 82.1 | BT9: =($BX$2*BR9)+$BY$2 -> 75.1993 | BU9: =BS9-BT9 -> 6.9007
A10: 6 | B10: =Satisfaction!K14 -> 4 | C10: =Satisfaction!I14 -> 50 | D10: =($H$2*B10)+$I$2 -> 75.3586 | E10: =C10-D10 -> -25.3586 | R10: 6 | S10: 4 | T10: 56.3 | U10: =($Y$2*S10)+$Z$2 -> 76.999 | V10: =T10-U10 -> -20.699 | AI10: 6 | AJ10: 4 | AK10: 50 | AL10: =($AP$2*AJ10)+$AQ$2 -> 77.5484 | AM10: =AK10-AL10 -> -27.5484 | AZ10: 6 | BA10: 4 | BB10: 50 | BC10: =($BG$2*BA10)+$BH$2 -> 81.7814 | BD10: =BB10-BC10 -> -31.7814 | BQ10: 6 | BR10: 4 | BS10: 51.6 | BT10: =($BX$2*BR10)+$BY$2 -> 78.0526 | BU10: =BS10-BT10 -> -26.4526
A11: 7 | B11: =Satisfaction!K15 -> 4 | C11: =Satisfaction!I15 -> 81.3 | D11: =($H$2*B11)+$I$2 -> 75.3586 | E11: =C11-D11 -> 5.9414 | R11: 7 | S11: 4 | T11: 87.5 | U11: =($Y$2*S11)+$Z$2 -> 76.999 | V11: =T11-U11 -> 10.501 | AI11: 7 | AJ11: 4 | AK11: 87.5 | AL11: =($AP$2*AJ11)+$AQ$2 -> 77.5484 | AM11: =AK11-AL11 -> 9.9516 | AZ11: 7 | BA11: 4 | BB11: 93.8 | BC11: =($BG$2*BA11)+$BH$2 -> 81.7814 | BD11: =BB11-BC11 -> 12.0186 | BQ11: 7 | BR11: 4 | BS11: 87.5 | BT11: =($BX$2*BR11)+$BY$2 -> 78.0526 | BU11: =BS11-BT11 -> 9.4474
A12: 8 | B12: =Satisfaction!K16 -> 5 | C12: =Satisfaction!I16 -> 85 | D12: =($H$2*B12)+$I$2 -> 74.499 | E12: =C12-D12 -> 10.501 | R12: 8 | S12: 5 | T12: 95 | U12: =($Y$2*S12)+$Z$2 -> 76.356 | V12: =T12-U12 -> 18.644 | AI12: 8 | AJ12: 5 | AK12: 80 | AL12: =($AP$2*AJ12)+$AQ$2 -> 76.163 | AM12: =AK12-AL12 -> 3.837 | AZ12: 8 | BA12: 5 | BB12: 90 | BC12: =($BG$2*BA12)+$BH$2 -> 80.884 | BD12: =BB12-BC12 -> 9.116 | BQ12: 8 | BR12: 5 | BS12: 87.5 | BT12: =($BX$2*BR12)+$BY$2 -> 77.1015 | BU12: =BS12-BT12 -> 10.3985
A13: 9 | B13: =Satisfaction!K17 -> 8 | C13: =Satisfaction!I17 -> 75 | D13: =($H$2*B13)+$I$2 -> 71.9202 | E13: =C13-D13 -> 3.0798 | R13: 9 | S13: 8 | T13: 75 | U13: =($Y$2*S13)+$Z$2 -> 74.427 | V13: =T13-U13 -> 0.573 | AI13: 9 | AJ13: 8 | AK13: 71.9 | AL13: =($AP$2*AJ13)+$AQ$2 -> 72.0068 | AM13: =AK13-AL13 -> -0.1068 | AZ13: 9 | BA13: 8 | BB13: 78.1 | BC13: =($BG$2*BA13)+$BH$2 -> 78.1918 | BD13: =BB13-BC13 -> -0.0918 | BQ13: 9 | BR13: 8 | BS13: 75 | BT13: =($BX$2*BR13)+$BY$2 -> 74.2482 | BU13: =BS13-BT13 -> 0.7518
A14: 10 | B14: =Satisfaction!K18 -> 8 | C14: =Satisfaction!I18 -> 87.5 | D14: =($H$2*B14)+$I$2 -> 71.9202 | E14: =C14-D14 -> 15.5798 | R14: 10 | S14: 8 | T14: 90.6 | U14: =($Y$2*S14)+$Z$2 -> 74.427 | V14: =T14-U14 -> 16.173 | AI14: 10 | AJ14: 8 | AK14: 93.8 | AL14: =($AP$2*AJ14)+$AQ$2 -> 72.0068 | AM14: =AK14-AL14 -> 21.7932 | AZ14: 10 | BA14: 8 | BB14: 93.8 | BC14: =($BG$2*BA14)+$BH$2 -> 78.1918 | BD14: =BB14-BC14 -> 15.6082 | BQ14: 10 | BR14: 8 | BS14: 91.4 | BT14: =($BX$2*BR14)+$BY$2 -> 74.2482 | BU14: =BS14-BT14 -> 17.1518
A15: 11 | B15: =Satisfaction!K19 -> 4 | C15: =Satisfaction!I19 -> 81.3 | D15: =($H$2*B15)+$I$2 -> 75.3586 | E15: =C15-D15 -> 5.9414 | R15: 11 | S15: 4 | T15: 87.5 | U15: =($Y$2*S15)+$Z$2 -> 76.999 | V15: =T15-U15 -> 10.501 | AI15: 11 | AJ15: 4 | AK15: 93.8 | AL15: =($AP$2*AJ15)+$AQ$2 -> 77.5484 | AM15: =AK15-AL15 -> 16.2516 | AZ15: 11 | BA15: 4 | BB15: 93.8 | BC15: =($BG$2*BA15)+$BH$2 -> 81.7814 | BD15: =BB15-BC15 -> 12.0186 | BQ15: 11 | BR15: 4 | BS15: 89.1 | BT15: =($BX$2*BR15)+$BY$2 -> 78.0526 | BU15: =BS15-BT15 -> 11.0474
A16: 12 | B16: =Satisfaction!K20 -> 11 | C16: =Satisfaction!I20 -> 79.6 | D16: =($H$2*B16)+$I$2 -> 69.3414 | E16: =C16-D16 -> 10.2586 | R16: 12 | S16: 11 | T16: 81.8 | U16: =($Y$2*S16)+$Z$2 -> 72.498 | V16: =T16-U16 -> 9.302 | AI16: 12 | AJ16: 11 | AK16: 75 | AL16: =($AP$2*AJ16)+$AQ$2 -> 67.8506 | AM16: =AK16-AL16 -> 7.1494 | AZ16: 12 | BA16: 11 | BB16: 88.6 | BC16: =($BG$2*BA16)+$BH$2 -> 75.4996 | BD16: =BB16-BC16 -> 13.1004 | BQ16: 12 | BR16: 11 | BS16: 81.3 | BT16: =($BX$2*BR16)+$BY$2 -> 71.3949 | BU16: =BS16-BT16 -> 9.9051
... A23: 19 | B23: =Satisfaction!K27 -> 6 | C23: =Satisfaction!I27 -> 70.8 | D23: =($H$2*B23)+$I$2 -> 73.6394 | E23: =C23-D23 -> -2.8394 | R23: 19 | S23: 6 | T23: 75 | U23: =($Y$2*S23)+$Z$2 -> 75.713 | V23: =T23-U23 -> -0.713 | AI23: 19 | AJ23: 6 | AK23: 66.7 | AL23: =($AP$2*AJ23)+$AQ$2 -> 74.7776 | AM23: =AK23-AL23 -> -8.0776 | AZ23: 19 | BA23: 6 | BB23: 83.3 | BC23: =($BG$2*BA23)+$BH$2 -> 79.9866 | BD23: =BB23-BC23 -> 3.3134 | BQ23: 19 | BR23: 6 | BS23: 74 | BT23: =($BX$2*BR23)+$BY$2 -> 76.1504 | BU23: =BS23-BT23 -> -2.1504
A24: 20 | B24: =Satisfaction!K28 -> 8 | C24: =Satisfaction!I28 -> 53.1 | D24: =($H$2*B24)+$I$2 -> 71.9202 | E24: =C24-D24 -> -18.8202 | H24: Residuals: | R24: 20 | S24: 8 | T24: 50 | U24: =($Y$2*S24)+$Z$2 -> 74.427 | V24: =T24-U24 -> -24.427 | Y24: Residuals: | AI24: 20 | AJ24: 8 | AK24: 50 | AL24: =($AP$2*AJ24)+$AQ$2 -> 72.0068 | AM24: =AK24-AL24 -> -22.0068 | AP24: Residuals: | AZ24: 20 | BA24: 8 | BB24: 59.4 | BC24: =($BG$2*BA24)+$BH$2 -> 78.1918 | BD24: =BB24-BC24 -> -18.7918 | BG24: Residuals: | BQ24: 20 | BR24: 8 | BS24: 53.1 | BT24: =($BX$2*BR24)+$BY$2 -> 74.2482 | BU24: =BS24-BT24 -> -21.1482 | BX24: Residuals:
A25: 21 | B25: =Satisfaction!K29 -> 9 | C25: =Satisfaction!I29 -> 77.8 | D25: =($H$2*B25)+$I$2 -> 71.0606 | E25: =C25-D25 -> 6.7394 | R25: 21 | S25: 9 | T25: 77.8 | U25: =($Y$2*S25)+$Z$2 -> 73.784 | V25: =T25-U25 -> 4.016 | AI25: 21 | AJ25: 9 | AK25: 80.6 | AL25: =($AP$2*AJ25)+$AQ$2 -> 70.6214 | AM25: =AK25-AL25 -> 9.9786 | AZ25: 21 | BA25: 9 | BB25: 88.9 | BC25: =($BG$2*BA25)+$BH$2 -> 77.2944 | BD25: =BB25-BC25 -> 11.6056 | BQ25: 21 | BR25: 9 | BS25: 81.3 | BT25: =($BX$2*BR25)+$BY$2 -> 73.2971 | BU25: =BS25-BT25 -> 8.0029
A26: 22 | B26: =Satisfaction!K30 -> 4 | C26: =Satisfaction!I30 -> 81.3 | D26: =($H$2*B26)+$I$2 -> 75.3586 | E26: =C26-D26 -> 5.9414 | R26: 22 | S26: 4 | T26: 75 | U26: =($Y$2*S26)+$Z$2 -> 76.999 | V26: =T26-U26 -> -1.999 | AI26: 22 | AJ26: 3 | AK26: 75 | AL26: =($AP$2*AJ26)+$AQ$2 -> 78.9338 | AM26: =AK26-AL26 -> -3.9338 | AZ26: 22 | BA26: 4 | BB26: 81.3 | BC26: =($BG$2*BA26)+$BH$2 -> 81.7814 | BD26: =BB26-BC26 -> -0.4814 | BQ26: 22 | BR26: 4 | BS26: 79.7 | BT26: =($BX$2*BR26)+$BY$2 -> 78.0526 | BU26: =BS26-BT26 -> 1.6474
A27: 23 | B27: =Satisfaction!K31 -> 5 | C27: =Satisfaction!I31 -> 85 | D27: =($H$2*B27)+$I$2 -> 74.499 | E27: =C27-D27 -> 10.501 | R27: 23 | S27: 5 | T27: 85 | U27: =($Y$2*S27)+$Z$2 -> 76.356 | V27: =T27-U27 -> 8.644 | AI27: 23 | AJ27: 5 | AK27: 80 | AL27: =($AP$2*AJ27)+$AQ$2 -> 76.163 | AM27: =AK27-AL27 -> 3.837 | AZ27: 23 | BA27: 5 | BB27: 85 | BC27: =($BG$2*BA27)+$BH$2 -> 80.884 | BD27: =BB27-BC27 -> 4.116 | BQ27: 23 | BR27: 5 | BS27: 83.8 | BT27: =($BX$2*BR27)+$BY$2 -> 77.1015 | BU27: =BS27-BT27 -> 6.6985
A28: 24 | B28: =Satisfaction!K32 -> 4 | C28: =Satisfaction!I32 -> 75 | D28: =($H$2*B28)+$I$2 -> 75.3586 | E28: =C28-D28 -> -0.3586 | R28: 24 | S28: 4 | T28: 75 | U28: =($Y$2*S28)+$Z$2 -> 76.999 | V28: =T28-U28 -> -1.999 | AI28: 24 | AJ28: 4 | AK28: 81.3 | AL28: =($AP$2*AJ28)+$AQ$2 -> 77.5484 | AM28: =AK28-AL28 -> 3.7516 | AZ28: 24 | BA28: 4 | BB28: 93.8 | BC28: =($BG$2*BA28)+$BH$2 -> 81.7814 | BD28: =BB28-BC28 -> 12.0186 | BQ28: 24 | BR28: 4 | BS28: 81.3 | BT28: =($BX$2*BR28)+$BY$2 -> 78.0526 | BU28: =BS28-BT28 -> 3.2474
A29: 25 | B29: =Satisfaction!K33 -> 1 | C29: =Satisfaction!I33 -> 75 | D29: =($H$2*B29)+$I$2 -> 77.9374 | E29: =C29-D29 -> -2.9374 | R29: 25 | S29: 1 | T29: 75 | U29: =($Y$2*S29)+$Z$2 -> 78.928 | V29: =T29-U29 -> -3.928 | AI29: 25 | AJ29: 1 | AK29: 75 | AL29: =($AP$2*AJ29)+$AQ$2 -> 81.7046 | AM29: =AK29-AL29 -> -6.7046 | AZ29: 25 | BA29: 1 | BB29: 75 | BC29: =($BG$2*BA29)+$BH$2 -> 84.4736 | BD29: =BB29-BC29 -> -9.4736 | BQ29: 25 | BR29: 1 | BS29: 75 | BT29: =($BX$2*BR29)+$BY$2 -> 80.9059 | BU29: =BS29-BT29 -> -5.9059
A30: 26 | B30: =Satisfaction!K34 -> 3 | C30: =Satisfaction!I34 -> 58.3 | D30: =($H$2*B30)+$I$2 -> 76.2182 | E30: =C30-D30 -> -17.9182 | R30: 26 | S30: 3 | T30: 58.3 | U30: =($Y$2*S30)+$Z$2 -> 77.642 | V30: =T30-U30 -> -19.342 | AI30: 26 | AJ30: 3 | AK30: 58.3 | AL30: =($AP$2*AJ30)+$AQ$2 -> 78.9338 | AM30: =AK30-AL30 -> -20.6338 | AZ30: 26 | BA30: 3 | BB30: 58.3 | BC30: =($BG$2*BA30)+$BH$2 -> 82.6788 | BD30: =BB30-BC30 -> -24.3788 | BQ30: 26 | BR30: 3 | BS30: 58.3 | BT30: =($BX$2*BR30)+$BY$2 -> 79.0037 | BU30: =BS30-BT30 -> -20.7037
A31: 27 | B31: =Satisfaction!K35 -> 6 | C31: =Satisfaction!I35 -> 100 | D31: =($H$2*B31)+$I$2 -> 73.6394 | E31: =C31-D31 -> 26.3606 | R31: 27 | S31: 6 | T31: 91.7 | U31: =($Y$2*S31)+$Z$2 -> 75.713 | V31: =T31-U31 -> 15.987 | AI31: 27 | AJ31: 6 | AK31: 100 | AL31: =($AP$2*AJ31)+$AQ$2 -> 74.7776 | AM31: =AK31-AL31 -> 25.2224 | AZ31: 27 | BA31: 6 | BB31: 100 | BC31: =($BG$2*BA31)+$BH$2 -> 79.9866 | BD31: =BB31-BC31 -> 20.0134 | BQ31: 27 | BR31: 6 | BS31: 97.9 | BT31: =($BX$2*BR31)+$BY$2 -> 76.1504 | BU31: =BS31-BT31 -> 21.7496
A32: 28 | B32: =Satisfaction!K36 -> 6 | C32: =Satisfaction!I36 -> 79.2 | D32: =($H$2*B32)+$I$2 -> 73.6394 | E32: =C32-D32 -> 5.5606 | R32: 28 | S32: 6 | T32: 83.3 | U32: =($Y$2*S32)+$Z$2 -> 75.713 | V32: =T32-U32 -> 7.587 | AI32: 28 | AJ32: 6 | AK32: 79.2 | AL32: =($AP$2*AJ32)+$AQ$2 -> 74.7776 | AM32: =AK32-AL32 -> 4.4224 | AZ32: 28 | BA32: 6 | BB32: 87.5 | BC32: =($BG$2*BA32)+$BH$2 -> 79.9866 | BD32: =BB32-BC32 -> 7.5134 | BQ32: 28 | BR32: 6 | BS32: 82.3 | BT32: =($BX$2*BR32)+$BY$2 -> 76.1504 | BU32: =BS32-BT32 -> 6.1496
A33: 29 | B33: =Satisfaction!K37 -> 9 | C33: =Satisfaction!I37 -> 11.1 | D33: =($H$2*B33)+$I$2 -> 71.0606 | E33: =C33-D33 -> -59.9606 | R33: 29 | S33: 9 | T33: 11.1 | U33: =($Y$2*S33)+$Z$2 -> 73.784 | V33: =T33-U33 -> -62.684 | AI33: 29 | AJ33: 9 | AK33: 11.1 | AL33: =($AP$2*AJ33)+$AQ$2 -> 70.6214 | AM33: =AK33-AL33 -> -59.5214 | AZ33: 29 | BA33: 9 | BB33: 16.7 | BC33: =($BG$2*BA33)+$BH$2 -> 77.2944 | BD33: =BB33-BC33 -> -60.5944 | BQ33: 29 | BR33: 9 | BS33: 12.5 | BT33: =($BX$2*BR33)+$BY$2 -> 73.2971 | BU33: =BS33-BT33 -> -60.7971
A34: 30 | B34: =Satisfaction!K38 -> 6 | C34: =Satisfaction!I38 -> 83.3 | D34: =($H$2*B34)+$I$2 -> 73.6394 | E34: =C34-D34 -> 9.6606 | R34: 30 | S34: 7 | T34: 71.4 | U34: =($Y$2*S34)+$Z$2 -> 75.07 | V34: =T34-U34 -> -3.67 | AI34: 30 | AJ34: 7 | AK34: 75 | AL34: =($AP$2*AJ34)+$AQ$2 -> 73.3922 | AM34: =AK34-AL34 -> 1.6078 | AZ34: 30 | BA34: 7 | BB34: 82.1 | BC34: =($BG$2*BA34)+$BH$2 -> 79.0892 | BD34: =BB34-BC34 -> 3.0108 | BQ34: 30 | BR34: 7 | BS34: 78.6 | BT34: =($BX$2*BR34)+$BY$2 -> 75.1993 | BU34: =BS34-BT34 -> 3.4007
A35: 31 | B35: =Satisfaction!K39 -> 5 | C35: =Satisfaction!I39 -> 80 | D35: =($H$2*B35)+$I$2 -> 74.499 | E35: =C35-D35 -> 5.501 | R35: 31 | S35: 5 | T35: 85 | U35: =($Y$2*S35)+$Z$2 -> 76.356 | V35: =T35-U35 -> 8.644 | AI35: 31 | AJ35: 5 | AK35: 85 | AL35: =($AP$2*AJ35)+$AQ$2 -> 76.163 | AM35: =AK35-AL35 -> 8.837 | AZ35: 31 | BA35: 5 | BB35: 90 | BC35: =($BG$2*BA35)+$BH$2 -> 80.884 | BD35: =BB35-BC35 -> 9.116 | BQ35: 31 | BR35: 5 | BS35: 85 | BT35: =($BX$2*BR35)+$BY$2 -> 77.1015 | BU35: =BS35-BT35 -> 7.8985
A36: 32 | B36: =Satisfaction!K40 -> 13 | C36: =Satisfaction!I40 -> 67.3 | D36: =($H$2*B36)+$I$2 -> 67.6222 | E36: =C36-D36 -> -0.3222 | R36: 32 | S36: 13 | T36: 71.2 | U36: =($Y$2*S36)+$Z$2 -> 71.212 | V36: =T36-U36 -> -0.012 | AI36: 32 | AJ36: 13 | AK36: 67.3 | AL36: =($AP$2*AJ36)+$AQ$2 -> 65.0798 | AM36: =AK36-AL36 -> 2.2202 | AZ36: 32 | BA36: 13 | BB36: 71.2 | BC36: =($BG$2*BA36)+$BH$2 -> 73.7048 | BD36: =BB36-BC36 -> -2.5048 | BQ36: 32 | BR36: 13 | BS36: 69.2 | BT36: =($BX$2*BR36)+$BY$2 -> 69.4927 | BU36: =BS36-BT36 -> -0.2927
A37: 33 | B37: =Satisfaction!K41 -> 0 | C37: =Satisfaction!I41 -> 0 | D37: =($H$2*B37)+$I$2 -> 78.797 | E37: =C37-D37 -> -78.797 | R37: 33 | S37: =Satisfaction!AD41 -> 0 | T37: =Satisfaction!AB41 -> 0 | U37: =($Y$2*S37)+$Z$2 -> 79.571 | V37: =T37-U37 -> -79.571 | AI37: 33 | AJ37: 0 | AK37: 0 | AL37: =($AP$2*AJ37)+$AQ$2 -> 83.09 | AM37: =AK37-AL37 -> -83.09 | AZ37: 33 | BA37: =Satisfaction!BL41 -> 0 | BB37: =Satisfaction!BJ41 -> 0 | BC37: =($BG$2*BA37)+$BH$2 -> 85.371 | BD37: =BB37-BC37 -> -85.371 | BQ37: 33 | BR37: =Satisfaction!CC41 -> 0 | BS37: 0 | BT37: =($BX$2*BR37)+$BY$2 -> 81.857 | BU37: =BS37-BT37 -> -81.857
A38: 34 | B38: =Satisfaction!K42 -> 0 | C38: =Satisfaction!I42 -> 0 | D38: =($H$2*B38)+$I$2 -> 78.797 | E38: =C38-D38 -> -78.797 | R38: 34 | S38: =Satisfaction!AD42 -> 0 | T38: =Satisfaction!AB42 -> 0 | U38: =($Y$2*S38)+$Z$2 -> 79.571 | V38: =T38-U38 -> -79.571 | AI38: 34 | AJ38: =Satisfaction!AU42 -> 0 | AK38: =Satisfaction!AS42 -> 0 | AL38: =($AP$2*AJ38)+$AQ$2 -> 83.09 | AM38: =AK38-AL38 -> -83.09 | AZ38: 34 | BA38: =Satisfaction!BL42 -> 0 | BB38: =Satisfaction!BJ42 -> 0 | BC38: =($BG$2*BA38)+$BH$2 -> 85.371 | BD38: =BB38-BC38 -> -85.371 | BQ38: 34 | BR38: =Satisfaction!CC42 -> 0 | BS38: =Satisfaction!CA42 -> 0 | BT38: =($BX$2*BR38)+$BY$2 -> 81.857 | BU38: =BS38-BT38 -> -81.857
B42: =NA() -> #N/A | C42: =NA() -> #N/A | S42: =NA() -> #N/A | T42: =NA() -> #N/A | AJ42: =NA() -> #N/A | AK42: =NA() -> #N/A | BA42: =NA() -> #N/A | BB42: =NA() -> #N/A | BR42: =NA() -> #N/A | BS42: =NA() -> #N/A

Sheet Satisfaction
A1: Patient Satisfaction Survey
A2: Baptist ER, Oct YTD
C4: Jan | E4: Feb | G4: Mar | I4: Apr | Q4: May | Y4: Jun | AG4: Jul | AO4: Aug | AW4: Sep | BE4: Oct | BM4: Nov | BU4: Dec
M6: Category | O6: Overall | U6: Category | W6: Overall | AC6: Category | AE6: Overall | AK6: Category | AM6: Overall | AS6: Category | AU6: Overall | BA6: Category | BC6: Overall | BI6: Category | BK6: Overall | BQ6: Category | BS6: Overall | BY6: Category | CA6: Overall
I7: Score | K7: n | M7: Weight | O7: Weight | Q7: Score | S7: n | U7: Weight | W7: Weight | Y7: Score | AA7: n | AC7: Weight | AE7: Weight | AG7: Score | AI7: n | AK7: Weight | AM7: Weight | AO7: Score | AQ7: n | AS7: Weight | AU7: Weight | AW7: Score | AY7: n | BA7: Weight | BC7: Weight | BE7: Score | BG7: n | BI7: Weight | BK7: Weight | BM7: Score | BO7: n | BQ7: Weight | BS7: Weight | BU7: Score | BW7: n | BY7: Weight | CA7: Weight
A8: Doctor informative re treatment
B9: ALAN ITZKOWITZ | C9: 0 | E9: 0 | G9: 0 | I9: {=SUM(IF(Period=I$4,IF(Category=$A$8,IF(Provider=$B9,Score))))} -> 85.7 | K9: {=SUM(IF(Period=I$4,IF(Category=$A$8,IF(Provider=$B9,Responses))))} -> 7 | M9: =I9*(K9/SUM(K$9:K$42)) -> 2.9995 | O9: =I9*(K9/(SUM(K$9:K$42)+SUM(K$48:K$81)+SUM(K$87:K$120)+SUM(K$126:K$159)+SUM(K$165:K$198)+SUM(K$204:K$237))) -> 0.4961952 | Q9: {=SUM(IF(Period=Q$4,IF(Category=$A$8,IF(Provider=$B9,Score))))} -> 81.3 | S9: {=SUM(IF(Period=Q$4,IF(Category=$A$8,IF(Provider=$B9,Responses))))} -> 4 | U9: =Q9*(S9/SUM(S$9:S$42)) -> 1.7297872 | W9: =Q9*(S9/(SUM(S$9:S$42)+SUM(S$48:S$81)+SUM(S$87:S$120)+SUM(S$126:S$159)+SUM(S$165:S$198)+SUM(S$204:S$237))) -> 0.28983957 | Y9: {=SUM(IF(Period=Y$4,IF(Category=$A$8,IF(Provider=$B9,Score))))} -> 87.5 | AA9: {=SUM(IF(Period=Y$4,IF(Category=$A$8,IF(Provider=$B9,Responses))))} -> 14 | AC9: =Y9*(AA9/SUM(AA$9:AA$42)) -> 4.0296053 | AE9: =Y9*(AA9/(SUM(AA$9:AA$42)+SUM(AA$48:AA$81)+SUM(AA$87:AA$120)+SUM(AA$126:AA$159)+SUM(AA$165:AA$198)+SUM(AA$204:AA$237))) -> 0.67567568 | AG9: {=SUM(IF(Period=AG$4,IF(Category=$A$8,IF(Provider=$B9,Score))))} -> 100 | AI9: {=SUM(IF(Period=AG$4,IF(Category=$A$8,IF(Provider=$B9,Responses))))} -> 3 | AK9: =AG9*(AI9/SUM(AI$9:AI$42)) -> 1.171875 | AM9: =AG9*(AI9/(SUM(AI$9:AI$42)+SUM(AI$48:AI$81)+SUM(AI$87:AI$120)+SUM(AI$126:AI$159)+SUM(AI$165:AI$198)+SUM(AI$204:AI$237))) -> 0.19430052 | AO9: {=SUM(IF(Period=AO$4,IF(Category=$A$8,IF(Provider=$B9,Score))))} -> 87.5 | AQ9: {=SUM(IF(Period=AO$4,IF(Category=$A$8,IF(Provider=$B9,Responses))))} -> 2 | AS9: =AO9*(AQ9/SUM(AQ$9:AQ$42)) -> 1.0174419 | AU9: =AO9*(AQ9/(SUM(AQ$9:AQ$42)+SUM(AQ$48:AQ$81)+SUM(AQ$87:AQ$120)+SUM(AQ$126:AQ$159)+SUM(AQ$165:AQ$198)+SUM(AQ$204:AQ$237))) -> 0.1705653 | AW9: {=SUM(IF(Period=AW$4,IF(Category=$A$8,IF(Provider=$B9,Score))))} -> 90 | AY9: {=SUM(IF(Period=AW$4,IF(Category=$A$8,IF(Provider=$B9,Responses))))} -> 5 | BA9: =AW9*(AY9/SUM(AY$9:AY$42)) -> 2.0737327 | BC9: =AW9*(AY9/(SUM(AY$9:AY$42)+SUM(AY$48:AY$81)+SUM(AY$87:AY$120)+SUM(AY$126:AY$159)+SUM(AY$165:AY$198)+SUM(AY$204:AY$237))) -> 0.34562212 | BE9: {=SUM(IF(Period=BE$4,IF(Category=$A$8,IF(Provider=$B9,Score))))} -> 87.5 | BG9: {=SUM(IF(Period=BE$4,IF(Category=$A$8,IF(Provider=$B9,Responses))))} -> 8 | BI9: =BE9*(BG9/SUM(BG$9:BG$42)) -> 2.9787234 | BK9: =BE9*(BG9/(SUM(BG$9:BG$42)+SUM(BG$48:BG$81)+SUM(BG$87:BG$120)+SUM(BG$126:BG$159)+SUM(BG$165:BG$198)+SUM(BG$204:BG$237))) -> 0.49469965 | BM9: {=SUM(IF(Period=BM$4,IF(Category=$A$8,IF(Provider=$B9,Score))))} -> 100 | BO9: {=SUM(IF(Period=BM$4,IF(Category=$A$8,IF(Provider=$B9,Responses))))} -> 6 | BQ9: =BM9*(BO9/SUM(BO$9:BO$42)) -> 2.5862069 | BS9: =BM9*(BO9/(SUM(BO$9:BO$42)+SUM(BO$48:BO$81)+SUM(BO$87:BO$120)+SUM(BO$126:BO$159)+SUM(BO$165:BO$198)+SUM(BO$204:BO$237))) -> 0.43290043 | BU9: {=SUM(IF(Period=BU$4,IF(Category=$A$8,IF(Provider=$B9,Score))))} -> 90 | BW9: {=SUM(IF(Period=BU$4,IF(Category=$A$8,IF(Provider=$B9,Responses))))} -> 5 | BY9: =BU9*(BW9/SUM(BW$9:BW$42)) -> 1.8595041 | CA9: =BU9*(BW9/(SUM(BW$9:BW$42)+SUM(BW$48:BW$81)+SUM(BW$87:BW$120)+SUM(BW$126:BW$159)+SUM(BW$165:BW$198)+SUM(BW$204:BW$237))) -> 0.31098825
B10: ALEX PALMA | C10: 0 | E10: 0 | G10: 0 | I10: {=SUM(IF(Period=I$4,IF(Category=$A$8,IF(Provider=$B10,Score))))} -> 71.4 | K10: {=SUM(IF(Period=I$4,IF(Category=$A$8,IF(Provider=$B10,Responses))))} -> 7 | M10: =I10*(K10/SUM(K$9:K$42)) -> 2.499 | O10: =I10*(K10/(SUM(K$9:K$42)+SUM(K$48:K$81)+SUM(K$87:K$120)+SUM(K$126:K$159)+SUM(K$165:K$198)+SUM(K$204:K$237))) -> 0.4133995 | Q10: {=SUM(IF(Period=Q$4,IF(Category=$A$8,IF(Provider=$B10,Score))))} -> 95 | S10: {=SUM(IF(Period=Q$4,IF(Category=$A$8,IF(Provider=$B10,Responses))))} -> 10 | U10: =Q10*(S10/SUM(S$9:S$42)) -> 5.0531915 | W10: =Q10*(S10/(SUM(S$9:S$42)+SUM(S$48:S$81)+SUM(S$87:S$120)+SUM(S$126:S$159)+SUM(S$165:S$198)+SUM(S$204:S$237))) -> 0.84670232 | Y10: {=SUM(IF(Period=Y$4,IF(Category=$A$8,IF(Provider=$B10,Score))))} -> 83.3 | AA10: {=SUM(IF(Period=Y$4,IF(Category=$A$8,IF(Provider=$B10,Responses))))} -> 9 | AC10: =Y10*(AA10/SUM(AA$9:AA$42)) -> 2.4661184 | AE10: =Y10*(AA10/(SUM(AA$9:AA$42)+SUM(AA$48:AA$81)+SUM(AA$87:AA$120)+SUM(AA$126:AA$159)+SUM(AA$165:AA$198)+SUM(AA$204:AA$237))) -> 0.41351351 | AG10: {=SUM(IF(Period=AG$4,IF(Category=$A$8,IF(Provider=$B10,Score))))} -> 100 | AI10: {=SUM(IF(Period=AG$4,IF(Category=$A$8,IF(Provider=$B10,Responses))))} -> 6 | AK10: =AG10*(AI10/SUM(AI$9:AI$42)) -> 2.34375 | AM10: =AG10*(AI10/(SUM(AI$9:AI$42)+SUM(AI$48:AI$81)+SUM(AI$87:AI$120)+SUM(AI$126:AI$159)+SUM(AI$165:AI$198)+SUM(AI$204:AI$237))) -> 0.38860104 | AO10: {=SUM(IF(Period=AO$4,IF(Category=$A$8,IF(Provider=$B10,Score))))} -> 37.5 | AQ10: {=SUM(IF(Period=AO$4,IF(Category=$A$8,IF(Provider=$B10,Responses))))} -> 4 | AS10: =AO10*(AQ10/SUM(AQ$9:AQ$42)) -> 0.87209302 | AU10: =AO10*(AQ10/(SUM(AQ$9:AQ$42)+SUM(AQ$48:AQ$81)+SUM(AQ$87:AQ$120)+SUM(AQ$126:AQ$159)+SUM(AQ$165:AQ$198)+SUM(AQ$204:AQ$237))) -> 0.14619883 | AW10: {=SUM(IF(Period=AW$4,IF(Category=$A$8,IF(Provider=$B10,Score))))} -> 85.7 | AY10: {=SUM(IF(Period=AW$4,IF(Category=$A$8,IF(Provider=$B10,Responses))))} -> 7 | BA10: =AW10*(AY10/SUM(AY$9:AY$42)) -> 2.7645161 | BC10: =AW10*(AY10/(SUM(AY$9:AY$42)+SUM(AY$48:AY$81)+SUM(AY$87:AY$120)+SUM(AY$126:AY$159)+SUM(AY$165:AY$198)+SUM(AY$204:AY$237))) -> 0.46075269 | BE10: {=SUM(IF(Period=BE$4,IF(Category=$A$8,IF(Provider=$B10,Score))))} -> 100 | BG10: {=SUM(IF(Period=BE$4,IF(Category=$A$8,IF(Provider=$B10,Responses))))} -> 8 | BI10: =BE10*(BG10/SUM(BG$9:BG$42)) -> 3.4042553 | BK10: =BE10*(BG10/(SUM(BG$9:BG$42)+SUM(BG$48:BG$81)+SUM(BG$87:BG$120)+SUM(BG$126:BG$159)+SUM(BG$165:BG$198)+SUM(BG$204:BG$237))) -> 0.56537102 | BM10: {=SUM(IF(Period=BM$4,IF(Category=$A$8,IF(Provider=$B10,Score))))} -> 87.5 | BO10: {=SUM(IF(Period=BM$4,IF(Category=$A$8,IF(Provider=$B10,Responses))))} -> 6 | BQ10: =BM10*(BO10/SUM(BO$9:BO$42)) -> 2.262931 | BS10: =BM10*(BO10/(SUM(BO$9:BO$42)+SUM(BO$48:BO$81)+SUM(BO$87:BO$120)+SUM(BO$126:BO$159)+SUM(BO$165:BO$198)+SUM(BO$204:BO$237))) -> 0.37878788 | BU10: {=SUM(IF(Period=BU$4,IF(Category=$A$8,IF(Provider=$B10,Score))))} -> 77.3 | BW10: {=SUM(IF(Period=BU$4,IF(Category=$A$8,IF(Provider=$B10,Responses))))} -> 11 | BY10: =BU10*(BW10/SUM(BW$9:BW$42)) -> 3.5136364 | CA10: =BU10*(BW10/(SUM(BW$9:BW$42)+SUM(BW$48:BW$81)+SUM(BW$87:BW$120)+SUM(BW$126:BW$159)+SUM(BW$165:BW$198)+SUM(BW$204:BW$237))) -> 0.58762958
B11: ALEXANDER GARCIA | C11: 0 | E11: 0 | G11: 0 | I11: {=SUM(IF(Period=I$4,IF(Category=$A$8,IF(Provider=$B11,Score))))} -> 92.9 | K11: {=SUM(IF(Period=I$4,IF(Category=$A$8,IF(Provider=$B11,Responses))))} -> 7 | M11: =I11*(K11/SUM(K$9:K$42)) -> 3.2515 | O11: =I11*(K11/(SUM(K$9:K$42)+SUM(K$48:K$81)+SUM(K$87:K$120)+SUM(K$126:K$159)+SUM(K$165:K$198)+SUM(K$204:K$237))) -> 0.53788255 | Q11: {=SUM(IF(Period=Q$4,IF(Category=$A$8,IF(Provider=$B11,Score))))} -> 91.7 | S11: {=SUM(IF(Period=Q$4,IF(Category=$A$8,IF(Provider=$B11,Responses))))} -> 6 | U11: =Q11*(S11/SUM(S$9:S$42)) -> 2.9265957 | W11: =Q11*(S11/(SUM(S$9:S$42)+SUM(S$48:S$81)+SUM(S$87:S$120)+SUM(S$126:S$159)+SUM(S$165:S$198)+SUM(S$204:S$237))) -> 0.49037433 | Y11: {=SUM(IF(Period=Y$4,IF(Category=$A$8,IF(Provider=$B11,Score))))} -> 86.1 | AA11: {=SUM(IF(Period=Y$4,IF(Category=$A$8,IF(Provider=$B11,Responses))))} -> 9 | AC11: =Y11*(AA11/SUM(AA$9:AA$42)) -> 2.5490132 | AE11: =Y11*(AA11/(SUM(AA$9:AA$42)+SUM(AA$48:AA$81)+SUM(AA$87:AA$120)+SUM(AA$126:AA$159)+SUM(AA$165:AA$198)+SUM(AA$204:AA$237))) -> 0.42741313 | AG11: {=SUM(IF(Period=AG$4,IF(Category=$A$8,IF(Provider=$B11,Score))))} -> 96.4 | AI11: {=SUM(IF(Period=AG$4,IF(Category=$A$8,IF(Provider=$B11,Responses))))} -> 7 | AK11: =AG11*(AI11/SUM(AI$9:AI$42)) -> 2.6359375 | AM11: =AG11*(AI11/(SUM(AI$9:AI$42)+SUM(AI$48:AI$81)+SUM(AI$87:AI$120)+SUM(AI$126:AI$159)+SUM(AI$165:AI$198)+SUM(AI$204:AI$237))) -> 0.43704663 | AO11: {=SUM(IF(Period=AO$4,IF(Category=$A$8,IF(Provider=$B11,Score))))} -> 71.9 | AQ11: {=SUM(IF(Period=AO$4,IF(Category=$A$8,IF(Provider=$B11,Responses))))} -> 8 | AS11: =AO11*(AQ11/SUM(AQ$9:AQ$42)) -> 3.344186 | AU11: =AO11*(AQ11/(SUM(AQ$9:AQ$42)+SUM(AQ$48:AQ$81)+SUM(AQ$87:AQ$120)+SUM(AQ$126:AQ$159)+SUM(AQ$165:AQ$198)+SUM(AQ$204:AQ$237))) -> 0.56062378 | AW11: {=SUM(IF(Period=AW$4,IF(Category=$A$8,IF(Provider=$B11,Score))))} -> 100 | AY11: {=SUM(IF(Period=AW$4,IF(Category=$A$8,IF(Provider=$B11,Responses))))} -> 6 | BA11: =AW11*(AY11/SUM(AY$9:AY$42)) -> 2.764977 | BC11: =AW11*(AY11/(SUM(AY$9:AY$42)+SUM(AY$48:AY$81)+SUM(AY$87:AY$120)+SUM(AY$126:AY$159)+SUM(AY$165:AY$198)+SUM(AY$204:AY$237))) -> 0.46082949 | BE11: {=SUM(IF(Period=BE$4,IF(Category=$A$8,IF(Provider=$B11,Score))))} -> 87.5 | BG11: {=SUM(IF(Period=BE$4,IF(Category=$A$8,IF(Provider=$B11,Responses))))} -> 8 | BI11: =BE11*(BG11/SUM(BG$9:BG$42)) -> 2.9787234 | BK11: =BE11*(BG11/(SUM(BG$9:BG$42)+SUM(BG$48:BG$81)+SUM(BG$87:BG$120)+SUM(BG$126:BG$159)+SUM(BG$165:BG$198)+SUM(BG$204:BG$237))) -> 0.49469965 | BM11: {=SUM(IF(Period=BM$4,IF(Category=$A$8,IF(Provider=$B11,Score))))} -> 56.3 | BO11: {=SUM(IF(Period=BM$4,IF(Category=$A$8,IF(Provider=$B11,Responses))))} -> 8 | BQ11: =BM11*(BO11/SUM(BO$9:BO$42)) -> 1.9413793 | BS11: =BM11*(BO11/(SUM(BO$9:BO$42)+SUM(BO$48:BO$81)+SUM(BO$87:BO$120)+SUM(BO$126:BO$159)+SUM(BO$165:BO$198)+SUM(BO$204:BO$237))) -> 0.32496392 | BU11: {=SUM(IF(Period=BU$4,IF(Category=$A$8,IF(Provider=$B11,Score))))} -> 75 | BW11: {=SUM(IF(Period=BU$4,IF(Category=$A$8,IF(Provider=$B11,Responses))))} -> 6 | BY11: =BU11*(BW11/SUM(BW$9:BW$42)) -> 1.8595041 | CA11: =BU11*(BW11/(SUM(BW$9:BW$42)+SUM(BW$48:BW$81)+SUM(BW$87:BW$120)+SUM(BW$126:BW$159)+SUM(BW$165:BW$198)+SUM(BW$204:BW$237))) -> 0.31098825
B12: ANDREA J BETANCOURT | C12: 0 | E12: 0 | G12: 0 | I12: {=SUM(IF(Period=I$4,IF(Category=$A$8,IF(Provider=$B12,Score))))} -> 62.5 | K12: {=SUM(IF(Period=I$4,IF(Category=$A$8,IF(Provider=$B12,Responses))))} -> 4 | M12: =I12*(K12/SUM(K$9:K$42)) -> 1.25 | O12: =I12*(K12/(SUM(K$9:K$42)+SUM(K$48:K$81)+SUM(K$87:K$120)+SUM(K$126:K$159)+SUM(K$165:K$198)+SUM(K$204:K$237))) -> 0.20678246 | Q12: {=SUM(IF(Period=Q$4,IF(Category=$A$8,IF(Provider=$B12,Score))))} -> 85.7 | S12: {=SUM(IF(Period=Q$4,IF(Category=$A$8,IF(Provider=$B12,Responses))))} -> 7 | U12: =Q12*(S12/SUM(S$9:S$42)) -> 3.1909574 | W12: =Q12*(S12/(SUM(S$9:S$42)+SUM(S$48:S$81)+SUM(S$87:S$120)+SUM(S$126:S$159)+SUM(S$165:S$198)+SUM(S$204:S$237))) -> 0.53467023 | Y12: {=SUM(IF(Period=Y$4,IF(Category=$A$8,IF(Provider=$B12,Score))))} -> 77.3 | AA12: {=SUM(IF(Period=Y$4,IF(Category=$A$8,IF(Provider=$B12,Responses))))} -> 11 | AC12: =Y12*(AA12/SUM(AA$9:AA$42)) -> 2.7970395 | AE12: =Y12*(AA12/(SUM(AA$9:AA$42)+SUM(AA$48:AA$81)+SUM(AA$87:AA$120)+SUM(AA$126:AA$159)+SUM(AA$165:AA$198)+SUM(AA$204:AA$237))) -> 0.46900165 | AG12: {=SUM(IF(Period=AG$4,IF(Category=$A$8,IF(Provider=$B12,Score))))} -> 68.8 | AI12: {=SUM(IF(Period=AG$4,IF(Category=$A$8,IF(Provider=$B12,Responses))))} -> 4 | AK12: =AG12*(AI12/SUM(AI$9:AI$42)) -> 1.075 | AM12: =AG12*(AI12/(SUM(AI$9:AI$42)+SUM(AI$48:AI$81)+SUM(AI$87:AI$120)+SUM(AI$126:AI$159)+SUM(AI$165:AI$198)+SUM(AI$204:AI$237))) -> 0.17823834 | AO12: {=SUM(IF(Period=AO$4,IF(Category=$A$8,IF(Provider=$B12,Score))))} -> 77.8 | AQ12: {=SUM(IF(Period=AO$4,IF(Category=$A$8,IF(Provider=$B12,Responses))))} -> 9 | AS12: =AO12*(AQ12/SUM(AQ$9:AQ$42)) -> 4.0709302 | AU12: =AO12*(AQ12/(SUM(AQ$9:AQ$42)+SUM(AQ$48:AQ$81)+SUM(AQ$87:AQ$120)+SUM(AQ$126:AQ$159)+SUM(AQ$165:AQ$198)+SUM(AQ$204:AQ$237))) -> 0.68245614 | AW12: {=SUM(IF(Period=AW$4,IF(Category=$A$8,IF(Provider=$B12,Score))))} -> 62.5 | AY12: {=SUM(IF(Period=AW$4,IF(Category=$A$8,IF(Provider=$B12,Responses))))} -> 2 | BA12: =AW12*(AY12/SUM(AY$9:AY$42)) -> 0.57603687 | BC12: =AW12*(AY12/(SUM(AY$9:AY$42)+SUM(AY$48:AY$81)+SUM(AY$87:AY$120)+SUM(AY$126:AY$159)+SUM(AY$165:AY$198)+SUM(AY$204:AY$237))) -> 0.096006144 | BE12: {=SUM(IF(Period=BE$4,IF(Category=$A$8,IF(Provider=$B12,Score))))} -> 75 | BG12: {=SUM(IF(Period=BE$4,IF(Category=$A$8,IF(Provider=$B12,Responses))))} -> 2 | BI12: =BE12*(BG12/SUM(BG$9:BG$42)) -> 0.63829787 | BK12: =BE12*(BG12/(SUM(BG$9:BG$42)+SUM(BG$48:BG$81)+SUM(BG$87:BG$120)+SUM(BG$126:BG$159)+SUM(BG$165:BG$198)+SUM(BG$204:BG$237))) -> 0.10600707 | BM12: {=SUM(IF(Period=BM$4,IF(Category=$A$8,IF(Provider=$B12,Score))))} -> 87.5 | BO12: {=SUM(IF(Period=BM$4,IF(Category=$A$8,IF(Provider=$B12,Responses))))} -> 6 | BQ12: =BM12*(BO12/SUM(BO$9:BO$42)) -> 2.262931 | BS12: =BM12*(BO12/(SUM(BO$9:BO$42)+SUM(BO$48:BO$81)+SUM(BO$87:BO$120)+SUM(BO$126:BO$159)+SUM(BO$165:BO$198)+SUM(BO$204:BO$237))) -> 0.37878788 | BU12: {=SUM(IF(Period=BU$4,IF(Category=$A$8,IF(Provider=$B12,Score))))} -> 96.9 | BW12: {=SUM(IF(Period=BU$4,IF(Category=$A$8,IF(Provider=$B12,Responses))))} -> 8 | BY12: =BU12*(BW12/SUM(BW$9:BW$42)) -> 3.2033058 | CA12: =BU12*(BW12/(SUM(BW$9:BW$42)+SUM(BW$48:BW$81)+SUM(BW$87:BW$120)+SUM(BW$126:BW$159)+SUM(BW$165:BW$198)+SUM(BW$204:BW$237))) -> 0.53572909
B13: ANDREW MASON | C13: 0 | E13: 0 | G13: 0 | I13: {=SUM(IF(Period=I$4,IF(Category=$A$8,IF(Provider=$B13,Score))))} -> 78.6 | K13: {=SUM(IF(Period=I$4,IF(Category=$A$8,IF(Provider=$B13,Responses))))} -> 7 | M13: =I13*(K13/SUM(K$9:K$42)) -> 2.751 | O13: =I13*(K13/(SUM(K$9:K$42)+SUM(K$48:K$81)+SUM(K$87:K$120)+SUM(K$126:K$159)+SUM(K$165:K$198)+SUM(K$204:K$237))) -> 0.45508685 | Q13: {=SUM(IF(Period=Q$4,IF(Category=$A$8,IF(Provider=$B13,Score))))} -> 79.2 | S13: {=SUM(IF(Period=Q$4,IF(Category=$A$8,IF(Provider=$B13,Responses))))} -> 6 | U13: =Q13*(S13/SUM(S$9:S$42)) -> 2.5276596 | W13: =Q13*(S13/(SUM(S$9:S$42)+SUM(S$48:S$81)+SUM(S$87:S$120)+SUM(S$126:S$159)+SUM(S$165:S$198)+SUM(S$204:S$237))) -> 0.42352941 | Y13: {=SUM(IF(Period=Y$4,IF(Category=$A$8,IF(Provider=$B13,Score))))} -> 70.8 | AA13: {=SUM(IF(Period=Y$4,IF(Category=$A$8,IF(Provider=$B13,Responses))))} -> 12 | AC13: =Y13*(AA13/SUM(AA$9:AA$42)) -> 2.7947368 | AE13: =Y13*(AA13/(SUM(AA$9:AA$42)+SUM(AA$48:AA$81)+SUM(AA$87:AA$120)+SUM(AA$126:AA$159)+SUM(AA$165:AA$198)+SUM(AA$204:AA$237))) -> 0.46861555 | AG13: {=SUM(IF(Period=AG$4,IF(Category=$A$8,IF(Provider=$B13,Score))))} -> 86.1 | AI13: {=SUM(IF(Period=AG$4,IF(Category=$A$8,IF(Provider=$B13,Responses))))} -> 9 | AK13: =AG13*(AI13/SUM(AI$9:AI$42)) -> 3.0269531 | AM13: =AG13*(AI13/(SUM(AI$9:AI$42)+SUM(AI$48:AI$81)+SUM(AI$87:AI$120)+SUM(AI$126:AI$159)+SUM(AI$165:AI$198)+SUM(AI$204:AI$237))) -> 0.50187824 | AO13: {=SUM(IF(Period=AO$4,IF(Category=$A$8,IF(Provider=$B13,Score))))} -> 100 | AQ13: {=SUM(IF(Period=AO$4,IF(Category=$A$8,IF(Provider=$B13,Responses))))} -> 4 | AS13: =AO13*(AQ13/SUM(AQ$9:AQ$42)) -> 2.3255814 | AU13: =AO13*(AQ13/(SUM(AQ$9:AQ$42)+SUM(AQ$48:AQ$81)+SUM(AQ$87:AQ$120)+SUM(AQ$126:AQ$159)+SUM(AQ$165:AQ$198)+SUM(AQ$204:AQ$237))) -> 0.38986355 | AW13: {=SUM(IF(Period=AW$4,IF(Category=$A$8,IF(Provider=$B13,Score))))} -> 83.3 | AY13: {=SUM(IF(Period=AW$4,IF(Category=$A$8,IF(Provider=$B13,Responses))))} -> 6 | BA13: =AW13*(AY13/SUM(AY$9:AY$42)) -> 2.3032258 | BC13: =AW13*(AY13/(SUM(AY$9:AY$42)+SUM(AY$48:AY$81)+SUM(AY$87:AY$120)+SUM(AY$126:AY$159)+SUM(AY$165:AY$198)+SUM(AY$204:AY$237))) -> 0.38387097 | BE13: {=SUM(IF(Period=BE$4,IF(Category=$A$8,IF(Provider=$B13,Score))))} -> 58.3 | BG13: {=SUM(IF(Period=BE$4,IF(Category=$A$8,IF(Provider=$B13,Responses))))} -> 6 | BI13: =BE13*(BG13/SUM(BG$9:BG$42)) -> 1.4885106 | BK13: =BE13*(BG13/(SUM(BG$9:BG$42)+SUM(BG$48:BG$81)+SUM(BG$87:BG$120)+SUM(BG$126:BG$159)+SUM(BG$165:BG$198)+SUM(BG$204:BG$237))) -> 0.24720848 | BM13: {=SUM(IF(Period=BM$4,IF(Category=$A$8,IF(Provider=$B13,Score))))} -> 75 | BO13: {=SUM(IF(Period=BM$4,IF(Category=$A$8,IF(Provider=$B13,Responses))))} -> 7 | BQ13: =BM13*(BO13/SUM(BO$9:BO$42)) -> 2.262931 | BS13: =BM13*(BO13/(SUM(BO$9:BO$42)+SUM(BO$48:BO$81)+SUM(BO$87:BO$120)+SUM(BO$126:BO$159)+SUM(BO$165:BO$198)+SUM(BO$204:BO$237))) -> 0.37878788 | BU13: {=SUM(IF(Period=BU$4,IF(Category=$A$8,IF(Provider=$B13,Score))))} -> 85.7 | BW13: {=SUM(IF(Period=BU$4,IF(Category=$A$8,IF(Provider=$B13,Responses))))} -> 7 | BY13: =BU13*(BW13/SUM(BW$9:BW$42)) -> 2.4789256 | CA13: =BU13*(BW13/(SUM(BW$9:BW$42)+SUM(BW$48:BW$81)+SUM(BW$87:BW$120)+SUM(BW$126:BW$159)+SUM(BW$165:BW$198)+SUM(BW$204:BW$237))) -> 0.41458189
B14: ANTONY FRIEDMAN | C14: 0 | E14: 0 | G14: 0 | I14: {=SUM(IF(Period=I$4,IF(Category=$A$8,IF(Provider=$B14,Score))))} -> 50 | K14: {=SUM(IF(Period=I$4,IF(Category=$A$8,IF(Provider=$B14,Responses))))} -> 4 | M14: =I14*(K14/SUM(K$9:K$42)) -> 1 | O14: =I14*(K14/(SUM(K$9:K$42)+SUM(K$48:K$81)+SUM(K$87:K$120)+SUM(K$126:K$159)+SUM(K$165:K$198)+SUM(K$204:K$237))) -> 0.16542597 | Q14: {=SUM(IF(Period=Q$4,IF(Category=$A$8,IF(Provider=$B14,Score))))} -> 35 | S14: {=SUM(IF(Period=Q$4,IF(Category=$A$8,IF(Provider=$B14,Responses))))} -> 10 | U14: =Q14*(S14/SUM(S$9:S$42)) -> 1.8617021 | W14: =Q14*(S14/(SUM(S$9:S$42)+SUM(S$48:S$81)+SUM(S$87:S$120)+SUM(S$126:S$159)+SUM(S$165:S$198)+SUM(S$204:S$237))) -> 0.31194296 | Y14: {=SUM(IF(Period=Y$4,IF(Category=$A$8,IF(Provider=$B14,Score))))} -> 70 | AA14: {=SUM(IF(Period=Y$4,IF(Category=$A$8,IF(Provider=$B14,Responses))))} -> 5 | AC14: =Y14*(AA14/SUM(AA$9:AA$42)) -> 1.1513158 | AE14: =Y14*(AA14/(SUM(AA$9:AA$42)+SUM(AA$48:AA$81)+SUM(AA$87:AA$120)+SUM(AA$126:AA$159)+SUM(AA$165:AA$198)+SUM(AA$204:AA$237))) -> 0.19305019 | AG14: {=SUM(IF(Period=AG$4,IF(Category=$A$8,IF(Provider=$B14,Score))))} -> 75 | AI14: {=SUM(IF(Period=AG$4,IF(Category=$A$8,IF(Provider=$B14,Responses))))} -> 1 | AK14: =AG14*(AI14/SUM(AI$9:AI$42)) -> 0.29296875 | AM14: =AG14*(AI14/(SUM(AI$9:AI$42)+SUM(AI$48:AI$81)+SUM(AI$87:AI$120)+SUM(AI$126:AI$159)+SUM(AI$165:AI$198)+SUM(AI$204:AI$237))) -> 0.04857513 | AO14: {=SUM(IF(Period=AO$4,IF(Category=$A$8,IF(Provider=$B14,Score))))} -> 79.2 | AQ14: {=SUM(IF(Period=AO$4,IF(Category=$A$8,IF(Provider=$B14,Responses))))} -> 6 | AS14: =AO14*(AQ14/SUM(AQ$9:AQ$42)) -> 2.7627907 | AU14: =AO14*(AQ14/(SUM(AQ$9:AQ$42)+SUM(AQ$48:AQ$81)+SUM(AQ$87:AQ$120)+SUM(AQ$126:AQ$159)+SUM(AQ$165:AQ$198)+SUM(AQ$204:AQ$237))) -> 0.46315789 | AW14: {=SUM(IF(Period=AW$4,IF(Category=$A$8,IF(Provider=$B14,Score))))} -> 62.5 | AY14: {=SUM(IF(Period=AW$4,IF(Category=$A$8,IF(Provider=$B14,Responses))))} -> 8 | BA14: =AW14*(AY14/SUM(AY$9:AY$42)) -> 2.3041475 | BC14: =AW14*(AY14/(SUM(AY$9:AY$42)+SUM(AY$48:AY$81)+SUM(AY$87:AY$120)+SUM(AY$126:AY$159)+SUM(AY$165:AY$198)+SUM(AY$204:AY$237))) -> 0.38402458 | BE14: {=SUM(IF(Period=BE$4,IF(Category=$A$8,IF(Provider=$B14,Score))))} -> 58.3 | BG14: {=SUM(IF(Period=BE$4,IF(Category=$A$8,IF(Provider=$B14,Responses))))} -> 15 | BI14: =BE14*(BG14/SUM(BG$9:BG$42)) -> 3.7212766 | BK14: =BE14*(BG14/(SUM(BG$9:BG$42)+SUM(BG$48:BG$81)+SUM(BG$87:BG$120)+SUM(BG$126:BG$159)+SUM(BG$165:BG$198)+SUM(BG$204:BG$237))) -> 0.6180212 | BM14: {=SUM(IF(Period=BM$4,IF(Category=$A$8,IF(Provider=$B14,Score))))} -> 81.8 | BO14: {=SUM(IF(Period=BM$4,IF(Category=$A$8,IF(Provider=$B14,Responses))))} -> 11 | BQ14: =BM14*(BO14/SUM(BO$9:BO$42)) -> 3.8784483 | BS14: =BM14*(BO14/(SUM(BO$9:BO$42)+SUM(BO$48:BO$81)+SUM(BO$87:BO$120)+SUM(BO$126:BO$159)+SUM(BO$165:BO$198)+SUM(BO$204:BO$237))) -> 0.64920635 | BU14: {=SUM(IF(Period=BU$4,IF(Category=$A$8,IF(Provider=$B14,Score))))} -> 65.6 | BW14: {=SUM(IF(Period=BU$4,IF(Category=$A$8,IF(Provider=$B14,Responses))))} -> 8 | BY14: =BU14*(BW14/SUM(BW$9:BW$42)) -> 2.168595 | CA14: =BU14*(BW14/(SUM(BW$9:BW$42)+SUM(BW$48:BW$81)+SUM(BW$87:BW$120)+SUM(BW$126:BW$159)+SUM(BW$165:BW$198)+SUM(BW$204:BW$237))) -> 0.36268141
B15: CHARLES SANZ | C15: 0 | E15: 0 | G15: 0 | I15: {=SUM(IF(Period=I$4,IF(Category=$A$8,IF(Provider=$B15,Score))))} -> 81.3 | K15: {=SUM(IF(Period=I$4,IF(Category=$A$8,IF(Provider=$B15,Responses))))} -> 4 | M15: =I15*(K15/SUM(K$9:K$42)) -> 1.626 | O15: =I15*(K15/(SUM(K$9:K$42)+SUM(K$48:K$81)+SUM(K$87:K$120)+SUM(K$126:K$159)+SUM(K$165:K$198)+SUM(K$204:K$237))) -> 0.26898263 | Q15: {=SUM(IF(Period=Q$4,IF(Category=$A$8,IF(Provider=$B15,Score))))} -> 83.3 | S15: {=SUM(IF(Period=Q$4,IF(Category=$A$8,IF(Provider=$B15,Responses))))} -> 3 | U15: =Q15*(S15/SUM(S$9:S$42)) -> 1.3292553 | W15: =Q15*(S15/(SUM(S$9:S$42)+SUM(S$48:S$81)+SUM(S$87:S$120)+SUM(S$126:S$159)+SUM(S$165:S$198)+SUM(S$204:S$237))) -> 0.22272727 | Y15: {=SUM(IF(Period=Y$4,IF(Category=$A$8,IF(Provider=$B15,Score))))} -> 96.9 | AA15: {=SUM(IF(Period=Y$4,IF(Category=$A$8,IF(Provider=$B15,Responses))))} -> 8 | AC15: =Y15*(AA15/SUM(AA$9:AA$42)) -> 2.55 | AE15: =Y15*(AA15/(SUM(AA$9:AA$42)+SUM(AA$48:AA$81)+SUM(AA$87:AA$120)+SUM(AA$126:AA$159)+SUM(AA$165:AA$198)+SUM(AA$204:AA$237))) -> 0.4275786 | AG15: {=SUM(IF(Period=AG$4,IF(Category=$A$8,IF(Provider=$B15,Score))))} -> 90.6 | AI15: {=SUM(IF(Period=AG$4,IF(Category=$A$8,IF(Provider=$B15,Responses))))} -> 8 | AK15: =AG15*(AI15/SUM(AI$9:AI$42)) -> 2.83125 | AM15: =AG15*(AI15/(SUM(AI$9:AI$42)+SUM(AI$48:AI$81)+SUM(AI$87:AI$120)+SUM(AI$126:AI$159)+SUM(AI$165:AI$198)+SUM(AI$204:AI$237))) -> 0.46943005 | AO15: {=SUM(IF(Period=AO$4,IF(Category=$A$8,IF(Provider=$B15,Score))))} -> 83.3 | AQ15: {=SUM(IF(Period=AO$4,IF(Category=$A$8,IF(Provider=$B15,Responses))))} -> 3 | AS15: =AO15*(AQ15/SUM(AQ$9:AQ$42)) -> 1.452907 | AU15: =AO15*(AQ15/(SUM(AQ$9:AQ$42)+SUM(AQ$48:AQ$81)+SUM(AQ$87:AQ$120)+SUM(AQ$126:AQ$159)+SUM(AQ$165:AQ$198)+SUM(AQ$204:AQ$237))) -> 0.24356725 | AW15: {=SUM(IF(Period=AW$4,IF(Category=$A$8,IF(Provider=$B15,Score))))} -> 91.7 | AY15: {=SUM(IF(Period=AW$4,IF(Category=$A$8,IF(Provider=$B15,Responses))))} -> 3 | BA15: =AW15*(AY15/SUM(AY$9:AY$42)) -> 1.2677419 | BC15: =AW15*(AY15/(SUM(AY$9:AY$42)+SUM(AY$48:AY$81)+SUM(AY$87:AY$120)+SUM(AY$126:AY$159)+SUM(AY$165:AY$198)+SUM(AY$204:AY$237))) -> 0.21129032 | BE15: {=SUM(IF(Period=BE$4,IF(Category=$A$8,IF(Provider=$B15,Score))))} -> 69.2 | BG15: {=SUM(IF(Period=BE$4,IF(Category=$A$8,IF(Provider=$B15,Responses))))} -> 13 | BI15: =BE15*(BG15/SUM(BG$9:BG$42)) -> 3.8280851 | BK15: =BE15*(BG15/(SUM(BG$9:BG$42)+SUM(BG$48:BG$81)+SUM(BG$87:BG$120)+SUM(BG$126:BG$159)+SUM(BG$165:BG$198)+SUM(BG$204:BG$237))) -> 0.63575972 | BM15: {=SUM(IF(Period=BM$4,IF(Category=$A$8,IF(Provider=$B15,Score))))} -> 95.8 | BO15: {=SUM(IF(Period=BM$4,IF(Category=$A$8,IF(Provider=$B15,Responses))))} -> 12 | BQ15: =BM15*(BO15/SUM(BO$9:BO$42)) -> 4.9551724 | BS15: =BM15*(BO15/(SUM(BO$9:BO$42)+SUM(BO$48:BO$81)+SUM(BO$87:BO$120)+SUM(BO$126:BO$159)+SUM(BO$165:BO$198)+SUM(BO$204:BO$237))) -> 0.82943723 | BU15: {=SUM(IF(Period=BU$4,IF(Category=$A$8,IF(Provider=$B15,Score))))} -> 100 | BW15: {=SUM(IF(Period=BU$4,IF(Category=$A$8,IF(Provider=$B15,Responses))))} -> 6 | BY15: =BU15*(BW15/SUM(BW$9:BW$42)) -> 2.4793388 | CA15: =BU15*(BW15/(SUM(BW$9:BW$42)+SUM(BW$48:BW$81)+SUM(BW$87:BW$120)+SUM(BW$126:BW$159)+SUM(BW$165:BW$198)+SUM(BW$204:BW$237))) -> 0.414651
B16: CHRISTIAN KOKINAKOS | C16: 0 | E16: 0 | G16: 0 | I16: {=SUM(IF(Period=I$4,IF(Category=$A$8,IF(Provider=$B16,Score))))} -> 85 | K16: {=SUM(IF(Period=I$4,IF(Category=$A$8,IF(Provider=$B16,Responses))))} -> 5 | M16: =I16*(K16/SUM(K$9:K$42)) -> 2.125 | O16: =I16*(K16/(SUM(K$9:K$42)+SUM(K$48:K$81)+SUM(K$87:K$120)+SUM(K$126:K$159)+SUM(K$165:K$198)+SUM(K$204:K$237))) -> 0.35153019 | Q16: {=SUM(IF(Period=Q$4,IF(Category=$A$8,IF(Provider=$B16,Score))))} -> 83.3 | S16: {=SUM(IF(Period=Q$4,IF(Category=$A$8,IF(Provider=$B16,Responses))))} -> 3 | U16: =Q16*(S16/SUM(S$9:S$42)) -> 1.3292553 | W16: =Q16*(S16/(SUM(S$9:S$42)+SUM(S$48:S$81)+SUM(S$87:S$120)+SUM(S$126:S$159)+SUM(S$165:S$198)+SUM(S$204:S$237))) -> 0.22272727 | Y16: {=SUM(IF(Period=Y$4,IF(Category=$A$8,IF(Provider=$B16,Score))))} -> 0 | AA16: {=SUM(IF(Period=Y$4,IF(Category=$A$8,IF(Provider=$B16,Responses))))} -> 0 | AC16: =Y16*(AA16/SUM(AA$9:AA$42)) -> 0 | AE16: =Y16*(AA16/(SUM(AA$9:AA$42)+SUM(AA$48:AA$81)+SUM(AA$87:AA$120)+SUM(AA$126:AA$159)+SUM(AA$165:AA$198)+SUM(AA$204:AA$237))) -> 0 | AG16: {=SUM(IF(Period=AG$4,IF(Category=$A$8,IF(Provider=$B16,Score))))} -> 0 | AI16: {=SUM(IF(Period=AG$4,IF(Category=$A$8,IF(Provider=$B16,Responses))))} -> 0 | AK16: =AG16*(AI16/SUM(AI$9:AI$42)) -> 0 | AM16: =AG16*(AI16/(SUM(AI$9:AI$42)+SUM(AI$48:AI$81)+SUM(AI$87:AI$120)+SUM(AI$126:AI$159)+SUM(AI$165:AI$198)+SUM(AI$204:AI$237))) -> 0 | AO16: {=SUM(IF(Period=AO$4,IF(Category=$A$8,IF(Provider=$B16,Score))))} -> 0 | AQ16: {=SUM(IF(Period=AO$4,IF(Category=$A$8,IF(Provider=$B16,Responses))))} -> 0 | AS16: =AO16*(AQ16/SUM(AQ$9:AQ$42)) -> 0 | AU16: =AO16*(AQ16/(SUM(AQ$9:AQ$42)+SUM(AQ$48:AQ$81)+SUM(AQ$87:AQ$120)+SUM(AQ$126:AQ$159)+SUM(AQ$165:AQ$198)+SUM(AQ$204:AQ$237))) -> 0 | AW16: {=SUM(IF(Period=AW$4,IF(Category=$A$8,IF(Provider=$B16,Score))))} -> 0 | AY16: {=SUM(IF(Period=AW$4,IF(Category=$A$8,IF(Provider=$B16,Responses))))} -> 0 | BA16: =AW16*(AY16/SUM(AY$9:AY$42)) -> 0 | BC16: =AW16*(AY16/(SUM(AY$9:AY$42)+SUM(AY$48:AY$81)+SUM(AY$87:AY$120)+SUM(AY$126:AY$159)+SUM(AY$165:AY$198)+SUM(AY$204:AY$237))) -> 0 | BE16: {=SUM(IF(Period=BE$4,IF(Category=$A$8,IF(Provider=$B16,Score))))} -> 0 | BG16: {=SUM(IF(Period=BE$4,IF(Category=$A$8,IF(Provider=$B16,Responses))))} -> 0 | BI16: =BE16*(BG16/SUM(BG$9:BG$42)) -> 0 | BK16: =BE16*(BG16/(SUM(BG$9:BG$42)+SUM(BG$48:BG$81)+SUM(BG$87:BG$120)+SUM(BG$126:BG$159)+SUM(BG$165:BG$198)+SUM(BG$204:BG$237))) -> 0 | BM16: {=SUM(IF(Period=BM$4,IF(Category=$A$8,IF(Provider=$B16,Score))))} -> 0 | BO16: {=SUM(IF(Period=BM$4,IF(Category=$A$8,IF(Provider=$B16,Responses))))} -> 0 | BQ16: =BM16*(BO16/SUM(BO$9:BO$42)) -> 0 | BS16: =BM16*(BO16/(SUM(BO$9:BO$42)+SUM(BO$48:BO$81)+SUM(BO$87:BO$120)+SUM(BO$126:BO$159)+SUM(BO$165:BO$198)+SUM(BO$204:BO$237))) -> 0 | BU16: {=SUM(IF(Period=BU$4,IF(Category=$A$8,IF(Provider=$B16,Score))))} -> 0 | BW16: {=SUM(IF(Period=BU$4,IF(Category=$A$8,IF(Provider=$B16,Responses))))} -> 0 | BY16: =BU16*(BW16/SUM(BW$9:BW$42)) -> 0 | CA16: =BU16*(BW16/(SUM(BW$9:BW$42)+SUM(BW$48:BW$81)+SUM(BW$87:BW$120)+SUM(BW$126:BW$159)+SUM(BW$165:BW$198)+SUM(BW$204:BW$237))) -> 0
B17: DANIEL D'AMORE | C17: 0 | E17: 0 | G17: 0 | I17: {=SUM(IF(Period=I$4,IF(Category=$A$8,IF(Provider=$B17,Score))))} -> 75 | K17: {=SUM(IF(Period=I$4,IF(Category=$A$8,IF(Provider=$B17,Responses))))} -> 8 | M17: =I17*(K17/SUM(K$9:K$42)) -> 3 | O17: =I17*(K17/(SUM(K$9:K$42)+SUM(K$48:K$81)+SUM(K$87:K$120)+SUM(K$126:K$159)+SUM(K$165:K$198)+SUM(K$204:K$237))) -> 0.49627792 | Q17: {=SUM(IF(Period=Q$4,IF(Category=$A$8,IF(Provider=$B17,Score))))} -> 65 | S17: {=SUM(IF(Period=Q$4,IF(Category=$A$8,IF(Provider=$B17,Responses))))} -> 5 | U17: =Q17*(S17/SUM(S$9:S$42)) -> 1.7287234 | W17: =Q17*(S17/(SUM(S$9:S$42)+SUM(S$48:S$81)+SUM(S$87:S$120)+SUM(S$126:S$159)+SUM(S$165:S$198)+SUM(S$204:S$237))) -> 0.28966132 | Y17: {=SUM(IF(Period=Y$4,IF(Category=$A$8,IF(Provider=$B17,Score))))} -> 77.1 | AA17: {=SUM(IF(Period=Y$4,IF(Category=$A$8,IF(Provider=$B17,Responses))))} -> 12 | AC17: =Y17*(AA17/SUM(AA$9:AA$42)) -> 3.0434211 | AE17: =Y17*(AA17/(SUM(AA$9:AA$42)+SUM(AA$48:AA$81)+SUM(AA$87:AA$120)+SUM(AA$126:AA$159)+SUM(AA$165:AA$198)+SUM(AA$204:AA$237))) -> 0.5103144 | AG17: {=SUM(IF(Period=AG$4,IF(Category=$A$8,IF(Provider=$B17,Score))))} -> 91.7 | AI17: {=SUM(IF(Period=AG$4,IF(Category=$A$8,IF(Provider=$B17,Responses))))} -> 9 | AK17: =AG17*(AI17/SUM(AI$9:AI$42)) -> 3.2238281 | AM17: =AG17*(AI17/(SUM(AI$9:AI$42)+SUM(AI$48:AI$81)+SUM(AI$87:AI$120)+SUM(AI$126:AI$159)+SUM(AI$165:AI$198)+SUM(AI$204:AI$237))) -> 0.53452073 | AO17: {=SUM(IF(Period=AO$4,IF(Category=$A$8,IF(Provider=$B17,Score))))} -> 81.3 | AQ17: {=SUM(IF(Period=AO$4,IF(Category=$A$8,IF(Provider=$B17,Responses))))} -> 12 | AS17: =AO17*(AQ17/SUM(AQ$9:AQ$42)) -> 5.672093 | AU17: =AO17*(AQ17/(SUM(AQ$9:AQ$42)+SUM(AQ$48:AQ$81)+SUM(AQ$87:AQ$120)+SUM(AQ$126:AQ$159)+SUM(AQ$165:AQ$198)+SUM(AQ$204:AQ$237))) -> 0.95087719 | AW17: {=SUM(IF(Period=AW$4,IF(Category=$A$8,IF(Provider=$B17,Score))))} -> 78.1 | AY17: {=SUM(IF(Period=AW$4,IF(Category=$A$8,IF(Provider=$B17,Responses))))} -> 8 | BA17: =AW17*(AY17/SUM(AY$9:AY$42)) -> 2.8792627 | BC17: =AW17*(AY17/(SUM(AY$9:AY$42)+SUM(AY$48:AY$81)+SUM(AY$87:AY$120)+SUM(AY$126:AY$159)+SUM(AY$165:AY$198)+SUM(AY$204:AY$237))) -> 0.47987711 | BE17: {=SUM(IF(Period=BE$4,IF(Category=$A$8,IF(Provider=$B17,Score))))} -> 68.8 | BG17: {=SUM(IF(Period=BE$4,IF(Category=$A$8,IF(Provider=$B17,Responses))))} -> 4 | BI17: =BE17*(BG17/SUM(BG$9:BG$42)) -> 1.1710638 | BK17: =BE17*(BG17/(SUM(BG$9:BG$42)+SUM(BG$48:BG$81)+SUM(BG$87:BG$120)+SUM(BG$126:BG$159)+SUM(BG$165:BG$198)+SUM(BG$204:BG$237))) -> 0.19448763 | BM17: {=SUM(IF(Period=BM$4,IF(Category=$A$8,IF(Provider=$B17,Score))))} -> 73.1 | BO17: {=SUM(IF(Period=BM$4,IF(Category=$A$8,IF(Provider=$B17,Responses))))} -> 13 | BQ17: =BM17*(BO17/SUM(BO$9:BO$42)) -> 4.0961207 | BS17: =BM17*(BO17/(SUM(BO$9:BO$42)+SUM(BO$48:BO$81)+SUM(BO$87:BO$120)+SUM(BO$126:BO$159)+SUM(BO$165:BO$198)+SUM(BO$204:BO$237))) -> 0.68564214 | BU17: {=SUM(IF(Period=BU$4,IF(Category=$A$8,IF(Provider=$B17,Score))))} -> 69.4 | BW17: {=SUM(IF(Period=BU$4,IF(Category=$A$8,IF(Provider=$B17,Responses))))} -> 9 | BY17: =BU17*(BW17/SUM(BW$9:BW$42)) -> 2.5809917 | CA17: =BU17*(BW17/(SUM(BW$9:BW$42)+SUM(BW$48:BW$81)+SUM(BW$87:BW$120)+SUM(BW$126:BW$159)+SUM(BW$165:BW$198)+SUM(BW$204:BW$237))) -> 0.43165169
B18: DAVID MISHKIN | C18: 0 | E18: 0 | G18: 0 | I18: {=SUM(IF(Period=I$4,IF(Category=$A$8,IF(Provider=$B18,Score))))} -> 87.5 | K18: {=SUM(IF(Period=I$4,IF(Category=$A$8,IF(Provider=$B18,Responses))))} -> 8 | M18: =I18*(K18/SUM(K$9:K$42)) -> 3.5 | O18: =I18*(K18/(SUM(K$9:K$42)+SUM(K$48:K$81)+SUM(K$87:K$120)+SUM(K$126:K$159)+SUM(K$165:K$198)+SUM(K$204:K$237))) -> 0.5789909 | Q18: {=SUM(IF(Period=Q$4,IF(Category=$A$8,IF(Provider=$B18,Score))))} -> 63.9 | S18: {=SUM(IF(Period=Q$4,IF(Category=$A$8,IF(Provider=$B18,Responses))))} -> 9 | U18: =Q18*(S18/SUM(S$9:S$42)) -> 3.0590426 | W18: =Q18*(S18/(SUM(S$9:S$42)+SUM(S$48:S$81)+SUM(S$87:S$120)+SUM(S$126:S$159)+SUM(S$165:S$198)+SUM(S$204:S$237))) -> 0.51256684 | Y18: {=SUM(IF(Period=Y$4,IF(Category=$A$8,IF(Provider=$B18,Score))))} -> 76.9 | AA18: {=SUM(IF(Period=Y$4,IF(Category=$A$8,IF(Provider=$B18,Responses))))} -> 13 | AC18: =Y18*(AA18/SUM(AA$9:AA$42)) -> 3.2884868 | AE18: =Y18*(AA18/(SUM(AA$9:AA$42)+SUM(AA$48:AA$81)+SUM(AA$87:AA$120)+SUM(AA$126:AA$159)+SUM(AA$165:AA$198)+SUM(AA$204:AA$237))) -> 0.55140651 | AG18: {=SUM(IF(Period=AG$4,IF(Category=$A$8,IF(Provider=$B18,Score))))} -> 95 | AI18: {=SUM(IF(Period=AG$4,IF(Category=$A$8,IF(Provider=$B18,Responses))))} -> 10 | AK18: =AG18*(AI18/SUM(AI$9:AI$42)) -> 3.7109375 | AM18: =AG18*(AI18/(SUM(AI$9:AI$42)+SUM(AI$48:AI$81)+SUM(AI$87:AI$120)+SUM(AI$126:AI$159)+SUM(AI$165:AI$198)+SUM(AI$204:AI$237))) -> 0.61528497 | AO18: {=SUM(IF(Period=AO$4,IF(Category=$A$8,IF(Provider=$B18,Score))))} -> 96.9 | AQ18: {=SUM(IF(Period=AO$4,IF(Category=$A$8,IF(Provider=$B18,Responses))))} -> 8 | AS18: =AO18*(AQ18/SUM(AQ$9:AQ$42)) -> 4.5069767 | AU18: =AO18*(AQ18/(SUM(AQ$9:AQ$42)+SUM(AQ$48:AQ$81)+SUM(AQ$87:AQ$120)+SUM(AQ$126:AQ$159)+SUM(AQ$165:AQ$198)+SUM(AQ$204:AQ$237))) -> 0.75555556 | AW18: {=SUM(IF(Period=AW$4,IF(Category=$A$8,IF(Provider=$B18,Score))))} -> 89.3 | AY18: {=SUM(IF(Period=AW$4,IF(Category=$A$8,IF(Provider=$B18,Responses))))} -> 14 | BA18: =AW18*(AY18/SUM(AY$9:AY$42)) -> 5.7612903 | BC18: =AW18*(AY18/(SUM(AY$9:AY$42)+SUM(AY$48:AY$81)+SUM(AY$87:AY$120)+SUM(AY$126:AY$159)+SUM(AY$165:AY$198)+SUM(AY$204:AY$237))) -> 0.96021505 | BE18: {=SUM(IF(Period=BE$4,IF(Category=$A$8,IF(Provider=$B18,Score))))} -> 100 | BG18: {=SUM(IF(Period=BE$4,IF(Category=$A$8,IF(Provider=$B18,Responses))))} -> 11 | BI18: =BE18*(BG18/SUM(BG$9:BG$42)) -> 4.6808511 | BK18: =BE18*(BG18/(SUM(BG$9:BG$42)+SUM(BG$48:BG$81)+SUM(BG$87:BG$120)+SUM(BG$126:BG$159)+SUM(BG$165:BG$198)+SUM(BG$204:BG$237))) -> 0.77738516 | BM18: {=SUM(IF(Period=BM$4,IF(Category=$A$8,IF(Provider=$B18,Score))))} -> 92.9 | BO18: {=SUM(IF(Period=BM$4,IF(Category=$A$8,IF(Provider=$B18,Responses))))} -> 7 | BQ18: =BM18*(BO18/SUM(BO$9:BO$42)) -> 2.8030172 | BS18: =BM18*(BO18/(SUM(BO$9:BO$42)+SUM(BO$48:BO$81)+SUM(BO$87:BO$120)+SUM(BO$126:BO$159)+SUM(BO$165:BO$198)+SUM(BO$204:BO$237))) -> 0.46919192 | BU18: {=SUM(IF(Period=BU$4,IF(Category=$A$8,IF(Provider=$B18,Score))))} -> 83.9 | BW18: {=SUM(IF(Period=BU$4,IF(Category=$A$8,IF(Provider=$B18,Responses))))} -> 14 | BY18: =BU18*(BW18/SUM(BW$9:BW$42)) -> 4.853719 | CA18: =BU18*(BW18/(SUM(BW$9:BW$42)+SUM(BW$48:BW$81)+SUM(BW$87:BW$120)+SUM(BW$126:BW$159)+SUM(BW$165:BW$198)+SUM(BW$204:BW$237))) -> 0.81174845
B19: ELAINE DIAZ | C19: 0 | E19: 0 | G19: 0 | I19: {=SUM(IF(Period=I$4,IF(Category=$A$8,IF(Provider=$B19,Score))))} -> 81.3 | K19: {=SUM(IF(Period=I$4,IF(Category=$A$8,IF(Provider=$B19,Responses))))} -> 4 | M19: =I19*(K19/SUM(K$9:K$42)) -> 1.626 | O19: =I19*(K19/(SUM(K$9:K$42)+SUM(K$48:K$81)+SUM(K$87:K$120)+SUM(K$126:K$159)+SUM(K$165:K$198)+SUM(K$204:K$237))) -> 0.26898263 | Q19: {=SUM(IF(Period=Q$4,IF(Category=$A$8,IF(Provider=$B19,Score))))} -> 81.3 | S19: {=SUM(IF(Period=Q$4,IF(Category=$A$8,IF(Provider=$B19,Responses))))} -> 4 | U19: =Q19*(S19/SUM(S$9:S$42)) -> 1.7297872 | W19: =Q19*(S19/(SUM(S$9:S$42)+SUM(S$48:S$81)+SUM(S$87:S$120)+SUM(S$126:S$159)+SUM(S$165:S$198)+SUM(S$204:S$237))) -> 0.28983957 | Y19: {=SUM(IF(Period=Y$4,IF(Category=$A$8,IF(Provider=$B19,Score))))} -> 80 | AA19: {=SUM(IF(Period=Y$4,IF(Category=$A$8,IF(Provider=$B19,Responses))))} -> 5 | AC19: =Y19*(AA19/SUM(AA$9:AA$42)) -> 1.3157895 | AE19: =Y19*(AA19/(SUM(AA$9:AA$42)+SUM(AA$48:AA$81)+SUM(AA$87:AA$120)+SUM(AA$126:AA$159)+SUM(AA$165:AA$198)+SUM(AA$204:AA$237))) -> 0.22062879 | AG19: {=SUM(IF(Period=AG$4,IF(Category=$A$8,IF(Provider=$B19,Score))))} -> 93.8 | AI19: {=SUM(IF(Period=AG$4,IF(Category=$A$8,IF(Provider=$B19,Responses))))} -> 4 | AK19: =AG19*(AI19/SUM(AI$9:AI$42)) -> 1.465625 | AM19: =AG19*(AI19/(SUM(AI$9:AI$42)+SUM(AI$48:AI$81)+SUM(AI$87:AI$120)+SUM(AI$126:AI$159)+SUM(AI$165:AI$198)+SUM(AI$204:AI$237))) -> 0.24300518 | AO19: {=SUM(IF(Period=AO$4,IF(Category=$A$8,IF(Provider=$B19,Score))))} -> 37.5 | AQ19: {=SUM(IF(Period=AO$4,IF(Category=$A$8,IF(Provider=$B19,Responses))))} -> 2 | AS19: =AO19*(AQ19/SUM(AQ$9:AQ$42)) -> 0.43604651 | AU19: =AO19*(AQ19/(SUM(AQ$9:AQ$42)+SUM(AQ$48:AQ$81)+SUM(AQ$87:AQ$120)+SUM(AQ$126:AQ$159)+SUM(AQ$165:AQ$198)+SUM(AQ$204:AQ$237))) -> 0.073099415 | AW19: {=SUM(IF(Period=AW$4,IF(Category=$A$8,IF(Provider=$B19,Score))))} -> 80 | AY19: {=SUM(IF(Period=AW$4,IF(Category=$A$8,IF(Provider=$B19,Responses))))} -> 5 | BA19: =AW19*(AY19/SUM(AY$9:AY$42)) -> 1.843318 | BC19: =AW19*(AY19/(SUM(AY$9:AY$42)+SUM(AY$48:AY$81)+SUM(AY$87:AY$120)+SUM(AY$126:AY$159)+SUM(AY$165:AY$198)+SUM(AY$204:AY$237))) -> 0.30721966 | BE19: {=SUM(IF(Period=BE$4,IF(Category=$A$8,IF(Provider=$B19,Score))))} -> 100 | BG19: {=SUM(IF(Period=BE$4,IF(Category=$A$8,IF(Provider=$B19,Responses))))} -> 2 | BI19: =BE19*(BG19/SUM(BG$9:BG$42)) -> 0.85106383 | BK19: =BE19*(BG19/(SUM(BG$9:BG$42)+SUM(BG$48:BG$81)+SUM(BG$87:BG$120)+SUM(BG$126:BG$159)+SUM(BG$165:BG$198)+SUM(BG$204:BG$237))) -> 0.14134276 | BM19: {=SUM(IF(Period=BM$4,IF(Category=$A$8,IF(Provider=$B19,Score))))} -> 91.7 | BO19: {=SUM(IF(Period=BM$4,IF(Category=$A$8,IF(Provider=$B19,Responses))))} -> 3 | BQ19: =BM19*(BO19/SUM(BO$9:BO$42)) -> 1.1857759 | BS19: =BM19*(BO19/(SUM(BO$9:BO$42)+SUM(BO$48:BO$81)+SUM(BO$87:BO$120)+SUM(BO$126:BO$159)+SUM(BO$165:BO$198)+SUM(BO$204:BO$237))) -> 0.19848485 | BU19: {=SUM(IF(Period=BU$4,IF(Category=$A$8,IF(Provider=$B19,Score))))} -> 75 | BW19: {=SUM(IF(Period=BU$4,IF(Category=$A$8,IF(Provider=$B19,Responses))))} -> 7 | BY19: =BU19*(BW19/SUM(BW$9:BW$42)) -> 2.1694215 | CA19: =BU19*(BW19/(SUM(BW$9:BW$42)+SUM(BW$48:BW$81)+SUM(BW$87:BW$120)+SUM(BW$126:BW$159)+SUM(BW$165:BW$198)+SUM(BW$204:BW$237))) -> 0.36281963
B20: EVA ESCATEL | C20: 0 | E20: 0 | G20: 0 | I20: {=SUM(IF(Period=I$4,IF(Category=$A$8,IF(Provider=$B20,Score))))} -> 79.6 | K20: {=SUM(IF(Period=I$4,IF(Category=$A$8,IF(Provider=$B20,Responses))))} -> 11 | M20: =I20*(K20/SUM(K$9:K$42)) -> 4.378 | O20: =I20*(K20/(SUM(K$9:K$42)+SUM(K$48:K$81)+SUM(K$87:K$120)+SUM(K$126:K$159)+SUM(K$165:K$198)+SUM(K$204:K$237))) -> 0.7242349 | Q20: {=SUM(IF(Period=Q$4,IF(Category=$A$8,IF(Provider=$B20,Score))))} -> 86.1 | S20: {=SUM(IF(Period=Q$4,IF(Category=$A$8,IF(Provider=$B20,Responses))))} -> 9 | U20: =Q20*(S20/SUM(S$9:S$42)) -> 4.1218085 | W20: =Q20*(S20/(SUM(S$9:S$42)+SUM(S$48:S$81)+SUM(S$87:S$120)+SUM(S$126:S$159)+SUM(S$165:S$198)+SUM(S$204:S$237))) -> 0.69064171 | Y20: {=SUM(IF(Period=Y$4,IF(Category=$A$8,IF(Provider=$B20,Score))))} -> 76.4 | AA20: {=SUM(IF(Period=Y$4,IF(Category=$A$8,IF(Provider=$B20,Responses))))} -> 18 | AC20: =Y20*(AA20/SUM(AA$9:AA$42)) -> 4.5236842 | AE20: =Y20*(AA20/(SUM(AA$9:AA$42)+SUM(AA$48:AA$81)+SUM(AA$87:AA$120)+SUM(AA$126:AA$159)+SUM(AA$165:AA$198)+SUM(AA$204:AA$237))) -> 0.75852179 | AG20: {=SUM(IF(Period=AG$4,IF(Category=$A$8,IF(Provider=$B20,Score))))} -> 81.3 | AI20: {=SUM(IF(Period=AG$4,IF(Category=$A$8,IF(Provider=$B20,Responses))))} -> 16 | AK20: =AG20*(AI20/SUM(AI$9:AI$42)) -> 5.08125 | AM20: =AG20*(AI20/(SUM(AI$9:AI$42)+SUM(AI$48:AI$81)+SUM(AI$87:AI$120)+SUM(AI$126:AI$159)+SUM(AI$165:AI$198)+SUM(AI$204:AI$237))) -> 0.84248705 | AO20: {=SUM(IF(Period=AO$4,IF(Category=$A$8,IF(Provider=$B20,Score))))} -> 83.3 | AQ20: {=SUM(IF(Period=AO$4,IF(Category=$A$8,IF(Provider=$B20,Responses))))} -> 12 | AS20: =AO20*(AQ20/SUM(AQ$9:AQ$42)) -> 5.8116279 | AU20: =AO20*(AQ20/(SUM(AQ$9:AQ$42)+SUM(AQ$48:AQ$81)+SUM(AQ$87:AQ$120)+SUM(AQ$126:AQ$159)+SUM(AQ$165:AQ$198)+SUM(AQ$204:AQ$237))) -> 0.97426901 | AW20: {=SUM(IF(Period=AW$4,IF(Category=$A$8,IF(Provider=$B20,Score))))} -> 92.5 | AY20: {=SUM(IF(Period=AW$4,IF(Category=$A$8,IF(Provider=$B20,Responses))))} -> 10 | BA20: =AW20*(AY20/SUM(AY$9:AY$42)) -> 4.2626728 | BC20: =AW20*(AY20/(SUM(AY$9:AY$42)+SUM(AY$48:AY$81)+SUM(AY$87:AY$120)+SUM(AY$126:AY$159)+SUM(AY$165:AY$198)+SUM(AY$204:AY$237))) -> 0.71044547 | BE20: {=SUM(IF(Period=BE$4,IF(Category=$A$8,IF(Provider=$B20,Score))))} -> 90.6 | BG20: {=SUM(IF(Period=BE$4,IF(Category=$A$8,IF(Provider=$B20,Responses))))} -> 8 | BI20: =BE20*(BG20/SUM(BG$9:BG$42)) -> 3.0842553 | BK20: =BE20*(BG20/(SUM(BG$9:BG$42)+SUM(BG$48:BG$81)+SUM(BG$87:BG$120)+SUM(BG$126:BG$159)+SUM(BG$165:BG$198)+SUM(BG$204:BG$237))) -> 0.51222615 | BM20: {=SUM(IF(Period=BM$4,IF(Category=$A$8,IF(Provider=$B20,Score))))} -> 97.2 | BO20: {=SUM(IF(Period=BM$4,IF(Category=$A$8,IF(Provider=$B20,Responses))))} -> 9 | BQ20: =BM20*(BO20/SUM(BO$9:BO$42)) -> 3.7706897 | BS20: =BM20*(BO20/(SUM(BO$9:BO$42)+SUM(BO$48:BO$81)+SUM(BO$87:BO$120)+SUM(BO$126:BO$159)+SUM(BO$165:BO$198)+SUM(BO$204:BO$237))) -> 0.63116883 | BU20: {=SUM(IF(Period=BU$4,IF(Category=$A$8,IF(Provider=$B20,Score))))} -> 92.9 | BW20: {=SUM(IF(Period=BU$4,IF(Category=$A$8,IF(Provider=$B20,Responses))))} -> 7 | BY20: =BU20*(BW20/SUM(BW$9:BW$42)) -> 2.6871901 | CA20: =BU20*(BW20/(SUM(BW$9:BW$42)+SUM(BW$48:BW$81)+SUM(BW$87:BW$120)+SUM(BW$126:BW$159)+SUM(BW$165:BW$198)+SUM(BW$204:BW$237))) -> 0.44941258
