Workbook

Sheet Doctor_Satisfaction
A1: Satisfaction Scores (Doctors)
B4: Jan | C4: =SUM(Data!I6:I8) -> 0.91633333
B5: Feb | C5: =SUM(Data!I30:I32) -> 0.871
B6: Mar | C6: =SUM(Data!I54:I56) -> 0.89833333
B7: Apr | C7: =SUM(Data!I85:I88) -> 0.78984034
B8: May | C8: =SUM(Data!I120:I123) -> 0.76086943
B9: Jun | C9: =SUM(Data!I155:I158) -> 0.70196764
B10: Jul | C10: =SUM(Data!I190:I193) -> 0.77736861
B11: Aug | C11: =SUM(Data!I225:I228) -> 0.84860991
B12: Sep | C12: =SUM(Data!I260:I263) -> 0.79791582
B13: Oct
B14: Nov
B15: Dec

Sheet Data
A1: Site | B1: Period | C1: Year | D1: Satisfaction_Category | E1: Question | F1: N | G1: Question_Score | H1: Category_Weights | I1: Category_Score | J1: Overall_Score
A2: San Ramon | B2: January | C2: 2017 | D2: Nursing Communication | E2: Nurses courtesy and respect | F2: 50 | G2: 91.5 | H2: =G2*(F2/SUM($F$2:$F$5)) -> 22.875 | I2: =H2/100 -> 0.22875 | J2: =G2*(F2/(SUM($F$2:$F$8)+SUM($F$10:$F$25))) -> 3.9782609
A3: San Ramon | B3: January | C3: 2017 | D3: Nursing Communication | E3: Nurses listened carefully | F3: 50 | G3: 90 | H3: =G3*(F3/SUM($F$2:$F$5)) -> 22.5 | I3: =H3/100 -> 0.225 | J3: =G3*(F3/(SUM($F$2:$F$8)+SUM($F$10:$F$25))) -> 3.9130435
A4: San Ramon | B4: January | C4: 2017 | D4: Nursing Communication | E4: Nurses explanations clear | F4: 50 | G4: 87.8 | H4: =G4*(F4/SUM($F$2:$F$5)) -> 21.95 | I4: =H4/100 -> 0.2195 | J4: =G4*(F4/(SUM($F$2:$F$8)+SUM($F$10:$F$25))) -> 3.8173913
A5: San Ramon | B5: January | C5: 2017 | D5: Nursing Communication | E5: Nurses helped patients feel at ease | F5: 50 | G5: 87.8 | H5: =G5*(F5/SUM($F$2:$F$5)) -> 21.95 | I5: =H5/100 -> 0.2195 | J5: =G5*(F5/(SUM($F$2:$F$8)+SUM($F$10:$F$25))) -> 3.8173913
A6: San Ramon | B6: January | C6: 2017 | D6: Doctor Communication | E6: Doctors courtesy and respect | F6: 50 | G6: 93.6 | H6: =G6*(F6/SUM($F$6:$F$8)) -> 31.2 | I6: =H6/100 -> 0.312 | J6: =G6*(F6/(SUM($F$2:$F$8)+SUM($F$10:$F$25))) -> 4.0695652
A7: San Ramon | B7: January | C7: 2017 | D7: Doctor Communication | E7: Doctors listened carefully | F7: 50 | G7: 91.7 | H7: =G7*(F7/SUM($F$6:$F$8)) -> 30.566667 | I7: =H7/100 -> 0.30566667 | J7: =G7*(F7/(SUM($F$2:$F$8)+SUM($F$10:$F$25))) -> 3.9869565
A8: San Ramon | B8: January | C8: 2017 | D8: Doctor Communication | E8: Doctors explanations clear | F8: 50 | G8: 89.6 | H8: =G8*(F8/SUM($F$6:$F$8)) -> 29.866667 | I8: =H8/100 -> 0.29866667 | J8: =G8*(F8/(SUM($F$2:$F$8)+SUM($F$10:$F$25))) -> 3.8956522
A9: San Ramon | B9: January | C9: 2017 | D9: Patient Access | E9: Staff clearly explained financial/insurance matters | F9: 50 | G9: 0 | H9: =G9*(F9/SUM($F10:$F11)) -> 0 | I9: =H9/100 -> 0 | J9: 0
A10: San Ramon | B10: January | C10: 2017 | D10: Patient Access | E10: Did staff clearly explain financial/insurance matters | F10: 50 | G10: 62.5 | H10: =G10*(F10/SUM($F10:$F11)) -> 31.25 | I10: =H10/100 -> 0.3125 | J10: =G10*(F10/(SUM($F$2:$F$8)+SUM($F$10:$F$25))) -> 2.7173913
A11: San Ramon | B11: January | C11: 2017 | D11: Patient Access | E11: Admissions staff courtesy and respect | F11: 50 | G11: 79.6 | H11: =G11*(F11/SUM($F10:$F11)) -> 39.8 | I11: =H11/100 -> 0.398 | J11: =G11*(F11/(SUM($F$2:$F$8)+SUM($F$10:$F$25))) -> 3.4608696
A12: San Ramon | B12: January | C12: 2017 | D12: Wait Time | E12: Amount of time before taken to treatment room | F12: 50 | G12: 72.9 | H12: =G12*(F12/SUM($F12:$F13)) -> 36.45 | I12: =H12/100 -> 0.3645 | J12: =G12*(F12/(SUM($F$2:$F$8)+SUM($F$10:$F$25))) -> 3.1695652
A13: San Ramon | B13: January | C13: 2017 | D13: Wait Time | E13: Amount of time waited before seeing doctor | F13: 50 | G13: 71.4 | H13: =G13*(F13/SUM($F12:$F13)) -> 35.7 | I13: =H13/100 -> 0.357 | J13: =G13*(F13/(SUM($F$2:$F$8)+SUM($F$10:$F$25))) -> 3.1043478
A14: San Ramon | B14: January | C14: 2017 | D14: Pain Management | E14: Pain well controlled | F14: 50 | G14: 65 | H14: =G14*(F14/SUM($F14:$F15)) -> 32.5 | I14: =H14/100 -> 0.325 | J14: =G14*(F14/(SUM($F$2:$F$8)+SUM($F$10:$F$25))) -> 2.826087
A15: San Ramon | B15: January | C15: 2017 | D15: Pain Management | E15: Staff helped patient with pain | F15: 50 | G15: 86.4 | H15: =G15*(F15/SUM($F14:$F15)) -> 43.2 | I15: =H15/100 -> 0.432 | J15: =G15*(F15/(SUM($F$2:$F$8)+SUM($F$10:$F$25))) -> 3.7565217
A16: San Ramon | B16: January | C16: 2017 | D16: Communication about Medications | E16: Staff explained medicine | F16: 50 | G16: 100 | H16: =G16*(F16/SUM($F16:$F17)) -> 50 | I16: =H16/100 -> 0.5 | J16: =G16*(F16/(SUM($F$2:$F$8)+SUM($F$10:$F$25))) -> 4.3478261
A17: San Ramon | B17: January | C17: 2017 | D17: Communication about Medications | E17: Staff clearly described side effects | F17: 50 | G17: 84.6 | H17: =G17*(F17/SUM($F16:$F17)) -> 42.3 | I17: =H17/100 -> 0.423 | J17: =G17*(F17/(SUM($F$2:$F$8)+SUM($F$10:$F$25))) -> 3.6782609
A18: San Ramon | B18: January | C18: 2017 | D18: Discharge Information | E18: Staff discussed discharge help | F18: 50 | G18: 68.3 | H18: =G18*(F18/SUM($F18:$F19)) -> 34.15 | I18: =H18/100 -> 0.3415 | J18: =G18*(F18/(SUM($F$2:$F$8)+SUM($F$10:$F$25))) -> 2.9695652
A19: San Ramon | B19: January | C19: 2017 | D19: Discharge Information | E19: Written symptoms/health info provided | F19: 50 | G19: 93.6 | H19: =G19*(F19/SUM($F18:$F19)) -> 46.8 | I19: =H19/100 -> 0.468 | J19: =G19*(F19/(SUM($F$2:$F$8)+SUM($F$10:$F$25))) -> 4.0695652
A20: San Ramon | B20: January | C20: 2017 | D20: Hospital Rating Question | E20: Hospital Rating Question | F20: 50 | G20: 83.3 | H20: =G20 -> 83.3 | I20: =H20/100 -> 0.833 | J20: =G20*(F20/(SUM($F$2:$F$8)+SUM($F$10:$F$25))) -> 3.6217391
A21: San Ramon | B21: January | C21: 2017 | D21: Willing to Recommend | E21: Willing to Recommend | F21: 50 | G21: 89.4 | H21: =G21 -> 89.4 | I21: =H21/100 -> 0.894 | J21: =G21*(F21/(SUM($F$2:$F$8)+SUM($F$10:$F$25))) -> 3.8869565
A22: San Ramon | B22: January | C22: 2017 | D22: Tenet Custom | E22: Staff provided safe patient care | F22: 50 | G22: 85.1 | H22: =G22*(F22/SUM($F22:$F25)) -> 21.275 | I22: =H22/100 -> 0.21275 | J22: =G22*(F22/(SUM($F$2:$F$8)+SUM($F$10:$F$25))) -> 3.7
A23: San Ramon | B23: January | C23: 2017 | D23: Tenet Custom | E23: Staff sensitive to families' needs | F23: 50 | G23: 87.2 | H23: =G23*(F23/SUM($F22:$F25)) -> 21.8 | I23: =H23/100 -> 0.218 | J23: =G23*(F23/(SUM($F$2:$F$8)+SUM($F$10:$F$25))) -> 3.7913043
A24: San Ramon | B24: January | C24: 2017 | D24: Tenet Custom | E24: Staff worked together as a team | F24: 50 | G24: 79.6 | H24: =G24*(F24/SUM($F22:$F25)) -> 19.9 | I24: =H24/100 -> 0.199 | J24: =G24*(F24/(SUM($F$2:$F$8)+SUM($F$10:$F$25))) -> 3.4608696
A25: San Ramon | B25: January | C25: 2017 | D25: Tenet Custom | E25: Staff respected patient privacy | F25: 50 | G25: 93.9 | H25: =G25*(F25/SUM($F22:$F25)) -> 23.475 | I25: =H25/100 -> 0.23475 | J25: =G25*(F25/(SUM($F$2:$F$8)+SUM($F$10:$F$25))) -> 4.0826087
A26: San Ramon | B26: February | C26: 2017 | D26: Nursing Communication | E26: Nurses courtesy and respect | F26: 50 | G26: 89.6 | H26: =G26*(F26/SUM($F$26:$F$29)) -> 22.4 | I26: =H26/100 -> 0.224
A27: San Ramon | B27: February | C27: 2017 | D27: Nursing Communication | E27: Nurses listened carefully | F27: 50 | G27: 87.5 | H27: =G27*(F27/SUM($F$26:$F$29)) -> 21.875 | I27: =H27/100 -> 0.21875
A28: San Ramon | B28: February | C28: 2017 | D28: Nursing Communication | E28: Nurses explanations clear | F28: 50 | G28: 88 | H28: =G28*(F28/SUM($F$26:$F$29)) -> 22 | I28: =H28/100 -> 0.22
A29: San Ramon | B29: February | C29: 2017 | D29: Nursing Communication | E29: Nurses helped patients feel at ease | F29: 50 | G29: 86 | H29: =G29*(F29/SUM($F$26:$F$29)) -> 21.5 | I29: =H29/100 -> 0.215
A30: San Ramon | B30: February | C30: 2017 | D30: Doctor Communication | E30: Doctors courtesy and respect | F30: 50 | G30: 84 | H30: =G30*(F30/SUM($F$30:$F$32)) -> 28 | I30: =H30/100 -> 0.28
A31: San Ramon | B31: February | C31: 2017 | D31: Doctor Communication | E31: Doctors listened carefully | F31: 50 | G31: 87.5 | H31: =G31*(F31/SUM($F$30:$F$32)) -> 29.166667 | I31: =H31/100 -> 0.29166667
A32: San Ramon | B32: February | C32: 2017 | D32: Doctor Communication | E32: Doctors explanations clear | F32: 50 | G32: 89.8 | H32: =G32*(F32/SUM($F$30:$F$32)) -> 29.933333 | I32: =H32/100 -> 0.29933333
A33: San Ramon | B33: February | C33: 2017 | D33: Patient Access | E33: Staff clearly explained financial/insurance matters | F33: 50 | G33: 0 | H33: =G33*(F33/SUM($F34:$F35)) -> 0 | I33: =H33/100 -> 0
A34: San Ramon | B34: February | C34: 2017 | D34: Patient Access | E34: Did staff clearly explain financial/insurance matters | F34: 50 | G34: 58.1 | H34: =G34*(F34/SUM($F34:$F35)) -> 29.05 | I34: =H34/100 -> 0.2905
A35: San Ramon | B35: February | C35: 2017 | D35: Patient Access | E35: Admissions staff courtesy and respect | F35: 50 | G35: 84 | H35: =G35*(F35/SUM($F34:$F35)) -> 42 | I35: =H35/100 -> 0.42
A36: San Ramon | B36: February | C36: 2017 | D36: Wait Time | E36: Amount of time before taken to treatment room | F36: 50 | G36: 78 | H36: =G36*(F36/SUM($F36:$F37)) -> 39 | I36: =H36/100 -> 0.39
A37: San Ramon | B37: February | C37: 2017 | D37: Wait Time | E37: Amount of time waited before seeing doctor | F37: 50 | G37: 56 | H37: =G37*(F37/SUM($F36:$F37)) -> 28 | I37: =H37/100 -> 0.28
A38: San Ramon | B38: February | C38: 2017 | D38: Pain Management | E38: Pain well controlled | F38: 50 | G38: 75 | H38: =G38*(F38/SUM($F38:$F39)) -> 37.5 | I38: =H38/100 -> 0.375
A39: San Ramon | B39: February | C39: 2017 | D39: Pain Management | E39: Staff helped patient with pain | F39: 50 | G39: 79.2 | H39: =G39*(F39/SUM($F38:$F39)) -> 39.6 | I39: =H39/100 -> 0.396
A40: San Ramon | B40: February | C40: 2017 | D40: Communication about Medications | E40: Staff explained medicine | F40: 50 | G40: 93.3 | H40: =G40*(F40/SUM($F40:$F41)) -> 46.65 | I40: =H40/100 -> 0.4665
...
